Workbook
Name Annual_Budget: Settings!$B$21
Name Calorie_Target: Settings!$B$26
Name Carb_Target: Settings!$B$28
Name Category_List: OFFSET('Lists'!$C$5,0,0,MAX(1,COUNTIF('Lists'!$C$5:$C$44,"?*")),1)
Name Cuisine_List: OFFSET('Lists'!$D$5,0,0,MAX(1,COUNTIF('Lists'!$D$5:$D$44,"?*")),1)
Name Currency_Code: Settings!$B$14
Name Currency_Symbol: Settings!$B$13
Name Default_Servings: Settings!$B$10
Name Diet_List: OFFSET('Lists'!$G$5,0,0,MAX(1,COUNTIF('Lists'!$G$5:$G$44,"?*")),1)
Name Eating_Out_Budget: Settings!$B$22
Name Expiry_Warning_Days: Settings!$B$36
Name Fat_Target: Settings!$B$29
Name Fibre_Target: Settings!$B$30
Name Freezer_Review_Days: Settings!$B$38
Name Grocery_Items: OFFSET('Grocery List'!$A$5,0,0,MAX(1,COUNTIF('Grocery List'!$A$5:$A$304,"?*")),1)
Name Home_Cooked_Target: Settings!$B$44
Name Household_Name: Settings!$B$6
Name Household_Size: Settings!$B$7
Name Ingredient_Names: OFFSET('Ingredients'!$A$5,0,0,MAX(1,COUNTIF('Ingredients'!$A$5:$A$304,"?*")),1)
Name Leftover_Items: OFFSET('Leftovers'!$B$5,0,0,MAX(1,COUNTIF('Leftovers'!$B$5:$B$124,"?*")),1)
Name Leftover_Safe_Days: Settings!$B$37
Name Low_Stock_Days: Settings!$B$39
Name Meal_Slots: OFFSET('Lists'!$A$5,0,0,MAX(1,COUNTIF('Lists'!$A$5:$A$44,"?*")),1)
Name Measurement_System: Settings!$B$12
Name Monthly_Budget: Settings!$B$20
Name New_Recipe_Target: Settings!$B$45
Name Packed_Lunch_Target: Settings!$B$47
Name Pantry_Items: OFFSET('Pantry'!$A$5,0,0,MAX(1,COUNTIF('Pantry'!$A$5:$A$304,"?*")),1)
Name Plan_Cook: Settings!$B$8
Name Plan_Month: Dashboard!$F$6
Name Plan_Week: Dashboard!$C$6
Name Plan_Year: Settings!$B$9
Name Prep_Day: Settings!$B$16
Name Prep_Reminder_Days: Settings!$B$40
Name Print_List_Store: 'Print Shopping'!$B$3
Name Print_Recipe_Title: 'Print Recipe'!$B$3
Name Print_Week_Start: 'Print Week'!$B$3
Name Protein_Target: Settings!$B$27
Name Recipe_Category_List: OFFSET('Lists'!$J$5,0,0,MAX(1,COUNTIF('Lists'!$J$5:$J$44,"?*")),1)
Name Recipe_Titles: OFFSET('Recipes'!$A$5,0,0,MAX(1,COUNTIF('Recipes'!$A$5:$A$204,"?*")),1)
Name Rep_From: Reports!$B$6
Name Rep_To: Reports!$B$7
Name Rotation_Gap_Days: Settings!$B$41
Name Shopping_Day: Settings!$B$15
Name Sodium_Limit: Settings!$B$32
Name Status_List: OFFSET('Lists'!$H$5,0,0,MAX(1,COUNTIF('Lists'!$H$5:$H$44,"?*")),1)
Name Store_List: OFFSET('Lists'!$F$5,0,0,MAX(1,COUNTIF('Lists'!$F$5:$F$44,"?*")),1)
Name Sugar_Limit: Settings!$B$31
Name Tag_List: OFFSET('Lists'!$E$5,0,0,MAX(1,COUNTIF('Lists'!$E$5:$E$44,"?*")),1)
Name Takeaway_Limit: Settings!$B$46
Name Top_Rows: Settings!$B$49
Name Unit_List: OFFSET('Lists'!$B$5,0,0,MAX(1,COUNTIF('Lists'!$B$5:$B$44,"?*")),1)
Name Waste_Cost_Target: Settings!$B$23
Name Waste_Reduction_Target: Settings!$B$48
Name Water_Target: Settings!$B$33
Name Week_Start_Day: Settings!$B$11
Name Weekly_Budget: Settings!$B$19

Sheet Start Here
A1: MEAL PLANNER & GROCERY LIST
A2: Weekly & Monthly Meal Planner, Recipe Organizer, Automatic Grocery List, Pantry Inventory, Food Budget & Nutrition Tracker
A3: Version 1.0.0 | Novality Store | 36 tabs | Start at Settings, then Recipes, then Weekly Planner
A5: WELCOME - THIS WORKBOOK PLANS YOUR MEALS AND WRITES YOUR SHOPPING LIST
B6: Plan breakfast, lunch and dinner for the week, see the calories and the cost of every meal, keep an eye on what is in the pantry, and print a grocery list that is already grouped by aisle. Fill in the cream cells only - the soft sage cells calculate themselves.
A10: SET IT UP IN FIVE STEPS
B11: 1. Set up your household | C11: Settings tab: household name, number of people, servings per meal, currency, measurement system, grocery budget and your nutrition targets. Everything else reads from here.
B12: 2. Add your ingredients | C12: Ingredients tab: name, category, unit, price and the nutrition per unit. These prices drive every recipe cost and grocery total, so add the staples you buy most often first.
B13: 3. Build your recipe book | C13: Recipes tab: title, category, servings, timings and the nutrition per serving. Recipe Ingredients tab: list each ingredient with its quantity and the cost per serving is calculated for you.
B14: 4. Plan the week | C14: Weekly Planner tab: pick a week starting date, then choose a recipe for each day and slot. The planner works out the calories, protein and cost of the whole week as you type.
B15: 5. Shop and cook | C15: Grocery List tab: everything you planned is already there, grouped by aisle, with quantities scaled to your household. Print it with Print Shopping, then tick items off as you fill the basket.
A17: COLOUR KEY
B18: Cream cells | C18: You type here. These cells are unlocked.
B19: Soft sage cells | C19: Calculated by the spreadsheet. Leave them alone.
B20: Green headers | C20: Column titles - hover for a note about the column.
B21: Terracotta | C21: Totals, targets and anything that needs attention.
A23: WHAT IS ON EACH TAB
B24: Start Here | C24: This page.
B25: Dashboard | C25: The week at a glance: calories, budget, what to cook, what is expiring and how your habits are going.
B26: Weekly Planner | C26: Pick the meals for one week, day by day.
B27: Monthly Planner | C27: The whole month on one page with the food budget per week.
B28: Settings | C28: Household, budget, nutrition targets and reminder windows.
B29: Lists | C29: Every drop down source: meal slots, units, categories, cuisines, stores, diets.
B30: Household | C30: Who you are cooking for, their diets, allergies and calorie needs.
B31: Recipes | C31: Your recipe book with nutrition, cost and rankings.
B32: Recipe Ingredients | C32: What goes into each recipe and what it costs.
B33: Ingredients | C33: Master ingredient list with prices and nutrition.
B34: Meal Plan | C34: Every planned meal in one long register - the engine behind the planner.
B35: Grocery List | C35: The automatic shopping list, grouped by aisle.
... B60: Help | C60: Frequently asked questions and troubleshooting.
A62: SHEET PROTECTION
B63: Every tab is protected so the formulas cannot be deleted by accident. The cream input cells stay editable. If you want to change the look of the whole workbook, unprotect the sheets from Review > Unprotect Sheet (password: premium) and re-protect them when you are done.
A65: Novality Store - thank you for buying this workbook!

Sheet Dashboard
A1: DASHBOARD
A2: The week at a glance - meals, calories, cost, expiry dates and habits
A3: | Start Here | Weekly Planner | Meal Plan | Grocery List | Pantry | Reports
A5: WHICH WEEK ARE YOU LOOKING AT?
B6: Week starting | C6: 2026-10-05 | F6: Month | G6: =TEXT($C$7,"mmmm yyyy") -> 0 | I6: Household | J6: =Household_Name -> 0 | L6: People | M6: =Household_Size -> 0 | O6: Servings | P6: =Default_Servings -> 0
B7: Shopping day | C7: =Shopping_Day -> 0 | F7: Prep day | G7: =Prep_Day -> 0 | I7: Weekly budget | J7: =Weekly_Budget -> 0
A9: THIS WEEK
A10: Meals planned | D10: Calories a day | G10: Grocery cost | J10: Budget left | M10: Items to buy | P10: Use it or lose it
A11: =COUNTIFS('Meal Plan'!$C$5:$C$504,$C$7) -> 0 | D11: =IFERROR(SUMIFS('Meal Plan'!$L$5:$L$504,'Meal Plan'!$C$5:$C$504,$C$7)/MAX(1,Household_Size)/7,0) -> 0 | G11: =SUMIFS('Meal Plan'!$Q$5:$Q$504,'Meal Plan'!$C$5:$C$504,$C$7) -> 0 | J11: =Weekly_Budget-SUMIFS('Meal Plan'!$Q$5:$Q$504,'Meal Plan'!$C$5:$C$504,$C$7) -> 0 | M11: =COUNTIFS('Grocery List'!$N$5:$N$304,"Yes") -> 0 | P11: =COUNTIFS(Pantry!$K$5:$K$304,"Use soon")+COUNTIFS(Pantry!$K$5:$K$304,"Expired") -> 0
A12: rows on the Meal Plan | D12: ="target "&TEXT(Calorie_Target,"#,##0") -> 0 | G12: ="budget "&TEXT(Weekly_Budget,"#,##0.00") -> 0 | J12: planned vs budget | M12: on the grocery list | P12: pantry items
A14: YOUR WEEK
A15: Day | B15: Date | C15: Breakfast | D15: Lunch | E15: Dinner | F15: Snack | G15: Calories | H15: Cost | I15: Status
A16: =TEXT($C$7+0,"ddd") -> 0 | B16: =$C$7+0 -> 0 | C16: =IFERROR(INDEX('Meal Plan'!$G$5:$G$504,MATCH(1,INDEX(('Meal Plan'!$B$5:$B$504=$B16)*('Meal Plan'!$F$5:$F$504="Breakfast"),0),0)),"") -> 0 | D16: =IFERROR(INDEX('Meal Plan'!$G$5:$G$504,MATCH(1,INDEX(('Meal Plan'!$B$5:$B$504=$B16)*('Meal Plan'!$F$5:$F$504="Lunch"),0),0)),"") -> 0 | E16: =IFERROR(INDEX('Meal Plan'!$G$5:$G$504,MATCH(1,INDEX(('Meal Plan'!$B$5:$B$504=$B16)*('Meal Plan'!$F$5:$F$504="Dinner"),0),0)),"") -> 0 | F16: =IFERROR(INDEX('Meal Plan'!$G$5:$G$504,MATCH(1,INDEX(('Meal Plan'!$B$5:$B$504=$B16)*('Meal Plan'!$F$5:$F$504="Afternoon snack"),0),0)),"") -> 0 | G16: =SUMIFS('Meal Plan'!$L$5:$L$504,'Meal Plan'!$B$5:$B$504,$B16) -> 0 | H16: =SUMIFS('Meal Plan'!$Q$5:$Q$504,'Meal Plan'!$B$5:$B$504,$B16) -> 0 | I16: =IF(COUNTIFS('Meal Plan'!$B$5:$B$504,$B16)=0,"Nothing planned",TEXT(COUNTIFS('Meal Plan'!$B$5:$B$504,$B16,'Meal Plan'!$S$5:$S$504,"Cooked")+COUNTIFS('Meal Plan'!$B$5:$B$504,$B16,'Meal Plan'!$S$5:$S$504,"Eaten"),"0")&" of "&TEXT(COUNTIFS('Meal Plan'!$B$5:$B$504,$B16),"0")&" cooked") -> 0
A17: =TEXT($C$7+1,"ddd") -> 0 | B17: =$C$7+1 -> 0 | C17: =IFERROR(INDEX('Meal Plan'!$G$5:$G$504,MATCH(1,INDEX(('Meal Plan'!$B$5:$B$504=$B17)*('Meal Plan'!$F$5:$F$504="Breakfast"),0),0)),"") -> 0 | D17: =IFERROR(INDEX('Meal Plan'!$G$5:$G$504,MATCH(1,INDEX(('Meal Plan'!$B$5:$B$504=$B17)*('Meal Plan'!$F$5:$F$504="Lunch"),0),0)),"") -> 0 | E17: =IFERROR(INDEX('Meal Plan'!$G$5:$G$504,MATCH(1,INDEX(('Meal Plan'!$B$5:$B$504=$B17)*('Meal Plan'!$F$5:$F$504="Dinner"),0),0)),"") -> 0 | F17: =IFERROR(INDEX('Meal Plan'!$G$5:$G$504,MATCH(1,INDEX(('Meal Plan'!$B$5:$B$504=$B17)*('Meal Plan'!$F$5:$F$504="Afternoon snack"),0),0)),"") -> 0 | G17: =SUMIFS('Meal Plan'!$L$5:$L$504,'Meal Plan'!$B$5:$B$504,$B17) -> 0 | H17: =SUMIFS('Meal Plan'!$Q$5:$Q$504,'Meal Plan'!$B$5:$B$504,$B17) -> 0 | I17: =IF(COUNTIFS('Meal Plan'!$B$5:$B$504,$B17)=0,"Nothing planned",TEXT(COUNTIFS('Meal Plan'!$B$5:$B$504,$B17,'Meal Plan'!$S$5:$S$504,"Cooked")+COUNTIFS('Meal Plan'!$B$5:$B$504,$B17,'Meal Plan'!$S$5:$S$504,"Eaten"),"0")&" of "&TEXT(COUNTIFS('Meal Plan'!$B$5:$B$504,$B17),"0")&" cooked") -> 0
A18: =TEXT($C$7+2,"ddd") -> 0 | B18: =$C$7+2 -> 0 | C18: =IFERROR(INDEX('Meal Plan'!$G$5:$G$504,MATCH(1,INDEX(('Meal Plan'!$B$5:$B$504=$B18)*('Meal Plan'!$F$5:$F$504="Breakfast"),0),0)),"") -> 0 | D18: =IFERROR(INDEX('Meal Plan'!$G$5:$G$504,MATCH(1,INDEX(('Meal Plan'!$B$5:$B$504=$B18)*('Meal Plan'!$F$5:$F$504="Lunch"),0),0)),"") -> 0 | E18: =IFERROR(INDEX('Meal Plan'!$G$5:$G$504,MATCH(1,INDEX(('Meal Plan'!$B$5:$B$504=$B18)*('Meal Plan'!$F$5:$F$504="Dinner"),0),0)),"") -> 0 | F18: =IFERROR(INDEX('Meal Plan'!$G$5:$G$504,MATCH(1,INDEX(('Meal Plan'!$B$5:$B$504=$B18)*('Meal Plan'!$F$5:$F$504="Afternoon snack"),0),0)),"") -> 0 | G18: =SUMIFS('Meal Plan'!$L$5:$L$504,'Meal Plan'!$B$5:$B$504,$B18) -> 0 | H18: =SUMIFS('Meal Plan'!$Q$5:$Q$504,'Meal Plan'!$B$5:$B$504,$B18) -> 0 | I18: =IF(COUNTIFS('Meal Plan'!$B$5:$B$504,$B18)=0,"Nothing planned",TEXT(COUNTIFS('Meal Plan'!$B$5:$B$504,$B18,'Meal Plan'!$S$5:$S$504,"Cooked")+COUNTIFS('Meal Plan'!$B$5:$B$504,$B18,'Meal Plan'!$S$5:$S$504,"Eaten"),"0")&" of "&TEXT(COUNTIFS('Meal Plan'!$B$5:$B$504,$B18),"0")&" cooked") -> 0
A19: =TEXT($C$7+3,"ddd") -> 0 | B19: =$C$7+3 -> 0 | C19: =IFERROR(INDEX('Meal Plan'!$G$5:$G$504,MATCH(1,INDEX(('Meal Plan'!$B$5:$B$504=$B19)*('Meal Plan'!$F$5:$F$504="Breakfast"),0),0)),"") -> 0 | D19: =IFERROR(INDEX('Meal Plan'!$G$5:$G$504,MATCH(1,INDEX(('Meal Plan'!$B$5:$B$504=$B19)*('Meal Plan'!$F$5:$F$504="Lunch"),0),0)),"") -> 0 | E19: =IFERROR(INDEX('Meal Plan'!$G$5:$G$504,MATCH(1,INDEX(('Meal Plan'!$B$5:$B$504=$B19)*('Meal Plan'!$F$5:$F$504="Dinner"),0),0)),"") -> 0 | F19: =IFERROR(INDEX('Meal Plan'!$G$5:$G$504,MATCH(1,INDEX(('Meal Plan'!$B$5:$B$504=$B19)*('Meal Plan'!$F$5:$F$504="Afternoon snack"),0),0)),"") -> 0 | G19: =SUMIFS('Meal Plan'!$L$5:$L$504,'Meal Plan'!$B$5:$B$504,$B19) -> 0 | H19: =SUMIFS('Meal Plan'!$Q$5:$Q$504,'Meal Plan'!$B$5:$B$504,$B19) -> 0 | I19: =IF(COUNTIFS('Meal Plan'!$B$5:$B$504,$B19)=0,"Nothing planned",TEXT(COUNTIFS('Meal Plan'!$B$5:$B$504,$B19,'Meal Plan'!$S$5:$S$504,"Cooked")+COUNTIFS('Meal Plan'!$B$5:$B$504,$B19,'Meal Plan'!$S$5:$S$504,"Eaten"),"0")&" of "&TEXT(COUNTIFS('Meal Plan'!$B$5:$B$504,$B19),"0")&" cooked") -> 0
A20: =TEXT($C$7+4,"ddd") -> 0 | B20: =$C$7+4 -> 0 | C20: =IFERROR(INDEX('Meal Plan'!$G$5:$G$504,MATCH(1,INDEX(('Meal Plan'!$B$5:$B$504=$B20)*('Meal Plan'!$F$5:$F$504="Breakfast"),0),0)),"") -> 0 | D20: =IFERROR(INDEX('Meal Plan'!$G$5:$G$504,MATCH(1,INDEX(('Meal Plan'!$B$5:$B$504=$B20)*('Meal Plan'!$F$5:$F$504="Lunch"),0),0)),"") -> 0 | E20: =IFERROR(INDEX('Meal Plan'!$G$5:$G$504,MATCH(1,INDEX(('Meal Plan'!$B$5:$B$504=$B20)*('Meal Plan'!$F$5:$F$504="Dinner"),0),0)),"") -> 0 | F20: =IFERROR(INDEX('Meal Plan'!$G$5:$G$504,MATCH(1,INDEX(('Meal Plan'!$B$5:$B$504=$B20)*('Meal Plan'!$F$5:$F$504="Afternoon snack"),0),0)),"") -> 0 | G20: =SUMIFS('Meal Plan'!$L$5:$L$504,'Meal Plan'!$B$5:$B$504,$B20) -> 0 | H20: =SUMIFS('Meal Plan'!$Q$5:$Q$504,'Meal Plan'!$B$5:$B$504,$B20) -> 0 | I20: =IF(COUNTIFS('Meal Plan'!$B$5:$B$504,$B20)=0,"Nothing planned",TEXT(COUNTIFS('Meal Plan'!$B$5:$B$504,$B20,'Meal Plan'!$S$5:$S$504,"Cooked")+COUNTIFS('Meal Plan'!$B$5:$B$504,$B20,'Meal Plan'!$S$5:$S$504,"Eaten"),"0")&" of "&TEXT(COUNTIFS('Meal Plan'!$B$5:$B$504,$B20),"0")&" cooked") -> 0
A21: =TEXT($C$7+5,"ddd") -> 0 | B21: =$C$7+5 -> 0 | C21: =IFERROR(INDEX('Meal Plan'!$G$5:$G$504,MATCH(1,INDEX(('Meal Plan'!$B$5:$B$504=$B21)*('Meal Plan'!$F$5:$F$504="Breakfast"),0),0)),"") -> 0 | D21: =IFERROR(INDEX('Meal Plan'!$G$5:$G$504,MATCH(1,INDEX(('Meal Plan'!$B$5:$B$504=$B21)*('Meal Plan'!$F$5:$F$504="Lunch"),0),0)),"") -> 0 | E21: =IFERROR(INDEX('Meal Plan'!$G$5:$G$504,MATCH(1,INDEX(('Meal Plan'!$B$5:$B$504=$B21)*('Meal Plan'!$F$5:$F$504="Dinner"),0),0)),"") -> 0 | F21: =IFERROR(INDEX('Meal Plan'!$G$5:$G$504,MATCH(1,INDEX(('Meal Plan'!$B$5:$B$504=$B21)*('Meal Plan'!$F$5:$F$504="Afternoon snack"),0),0)),"") -> 0 | G21: =SUMIFS('Meal Plan'!$L$5:$L$504,'Meal Plan'!$B$5:$B$504,$B21) -> 0 | H21: =SUMIFS('Meal Plan'!$Q$5:$Q$504,'Meal Plan'!$B$5:$B$504,$B21) -> 0 | I21: =IF(COUNTIFS('Meal Plan'!$B$5:$B$504,$B21)=0,"Nothing planned",TEXT(COUNTIFS('Meal Plan'!$B$5:$B$504,$B21,'Meal Plan'!$S$5:$S$504,"Cooked")+COUNTIFS('Meal Plan'!$B$5:$B$504,$B21,'Meal Plan'!$S$5:$S$504,"Eaten"),"0")&" of "&TEXT(COUNTIFS('Meal Plan'!$B$5:$B$504,$B21),"0")&" cooked") -> 0
A22: =TEXT($C$7+6,"ddd") -> 0 | B22: =$C$7+6 -> 0 | C22: =IFERROR(INDEX('Meal Plan'!$G$5:$G$504,MATCH(1,INDEX(('Meal Plan'!$B$5:$B$504=$B22)*('Meal Plan'!$F$5:$F$504="Breakfast"),0),0)),"") -> 0 | D22: =IFERROR(INDEX('Meal Plan'!$G$5:$G$504,MATCH(1,INDEX(('Meal Plan'!$B$5:$B$504=$B22)*('Meal Plan'!$F$5:$F$504="Lunch"),0),0)),"") -> 0 | E22: =IFERROR(INDEX('Meal Plan'!$G$5:$G$504,MATCH(1,INDEX(('Meal Plan'!$B$5:$B$504=$B22)*('Meal Plan'!$F$5:$F$504="Dinner"),0),0)),"") -> 0 | F22: =IFERROR(INDEX('Meal Plan'!$G$5:$G$504,MATCH(1,INDEX(('Meal Plan'!$B$5:$B$504=$B22)*('Meal Plan'!$F$5:$F$504="Afternoon snack"),0),0)),"") -> 0 | G22: =SUMIFS('Meal Plan'!$L$5:$L$504,'Meal Plan'!$B$5:$B$504,$B22) -> 0 | H22: =SUMIFS('Meal Plan'!$Q$5:$Q$504,'Meal Plan'!$B$5:$B$504,$B22) -> 0 | I22: =IF(COUNTIFS('Meal Plan'!$B$5:$B$504,$B22)=0,"Nothing planned",TEXT(COUNTIFS('Meal Plan'!$B$5:$B$504,$B22,'Meal Plan'!$S$5:$S$504,"Cooked")+COUNTIFS('Meal Plan'!$B$5:$B$504,$B22,'Meal Plan'!$S$5:$S$504,"Eaten"),"0")&" of "&TEXT(COUNTIFS('Meal Plan'!$B$5:$B$504,$B22),"0")&" cooked") -> 0
A23: =Week -> 0 | G23: =SUMIFS('Meal Plan'!$L$5:$L$504,'Meal Plan'!$C$5:$C$504,$C$7) -> 0 | H23: =SUMIFS('Meal Plan'!$Q$5:$Q$504,'Meal Plan'!$C$5:$C$504,$C$7) -> 0 | I23: =TEXT(IFERROR(SUMIFS('Meal Plan'!$L$5:$L$504,'Meal Plan'!$C$5:$C$504,$C$7)/MAX(1,Household_Size)/7/Calorie_Target,0),"0%")&" of target" -> 0
A25: MEALS OVERDUE FOR ANOTHER TURN
A26: Rank | B26: Recipe | C26: Last cooked | D26: Days since | E26: Rating | F26: Cost / serving
A27: 1 | B27: =IFERROR(INDEX(Recipes!$A$5:$A$204,MATCH($A27,Recipes!$AX$5:$AX$204,0)),"") -> 0 | C27: =IFERROR(INDEX(Recipes!$X$5:$X$204,MATCH($A27,Recipes!$AX$5:$AX$204,0)),"") -> 0 | D27: =IFERROR(INDEX(Recipes!$Y$5:$Y$204,MATCH($A27,Recipes!$AX$5:$AX$204,0)),"") -> 0 | E27: =IFERROR(INDEX(Recipes!$AN$5:$AN$204,MATCH($A27,Recipes!$AX$5:$AX$204,0)),"") -> 0 | F27: =IFERROR(INDEX(Recipes!$Q$5:$Q$204,MATCH($A27,Recipes!$AX$5:$AX$204,0)),"") -> 0
A28: 2 | B28: =IFERROR(INDEX(Recipes!$A$5:$A$204,MATCH($A28,Recipes!$AX$5:$AX$204,0)),"") -> 0 | C28: =IFERROR(INDEX(Recipes!$X$5:$X$204,MATCH($A28,Recipes!$AX$5:$AX$204,0)),"") -> 0 | D28: =IFERROR(INDEX(Recipes!$Y$5:$Y$204,MATCH($A28,Recipes!$AX$5:$AX$204,0)),"") -> 0 | E28: =IFERROR(INDEX(Recipes!$AN$5:$AN$204,MATCH($A28,Recipes!$AX$5:$AX$204,0)),"") -> 0 | F28: =IFERROR(INDEX(Recipes!$Q$5:$Q$204,MATCH($A28,Recipes!$AX$5:$AX$204,0)),"") -> 0
A29: 3 | B29: =IFERROR(INDEX(Recipes!$A$5:$A$204,MATCH($A29,Recipes!$AX$5:$AX$204,0)),"") -> 0 | C29: =IFERROR(INDEX(Recipes!$X$5:$X$204,MATCH($A29,Recipes!$AX$5:$AX$204,0)),"") -> 0 | D29: =IFERROR(INDEX(Recipes!$Y$5:$Y$204,MATCH($A29,Recipes!$AX$5:$AX$204,0)),"") -> 0 | E29: =IFERROR(INDEX(Recipes!$AN$5:$AN$204,MATCH($A29,Recipes!$AX$5:$AX$204,0)),"") -> 0 | F29: =IFERROR(INDEX(Recipes!$Q$5:$Q$204,MATCH($A29,Recipes!$AX$5:$AX$204,0)),"") -> 0
A30: 4 | B30: =IFERROR(INDEX(Recipes!$A$5:$A$204,MATCH($A30,Recipes!$AX$5:$AX$204,0)),"") -> 0 | C30: =IFERROR(INDEX(Recipes!$X$5:$X$204,MATCH($A30,Recipes!$AX$5:$AX$204,0)),"") -> 0 | D30: =IFERROR(INDEX(Recipes!$Y$5:$Y$204,MATCH($A30,Recipes!$AX$5:$AX$204,0)),"") -> 0 | E30: =IFERROR(INDEX(Recipes!$AN$5:$AN$204,MATCH($A30,Recipes!$AX$5:$AX$204,0)),"") -> 0 | F30: =IFERROR(INDEX(Recipes!$Q$5:$Q$204,MATCH($A30,Recipes!$AX$5:$AX$204,0)),"") -> 0
A31: 5 | B31: =IFERROR(INDEX(Recipes!$A$5:$A$204,MATCH($A31,Recipes!$AX$5:$AX$204,0)),"") -> 0 | C31: =IFERROR(INDEX(Recipes!$X$5:$X$204,MATCH($A31,Recipes!$AX$5:$AX$204,0)),"") -> 0 | D31: =IFERROR(INDEX(Recipes!$Y$5:$Y$204,MATCH($A31,Recipes!$AX$5:$AX$204,0)),"") -> 0 | E31: =IFERROR(INDEX(Recipes!$AN$5:$AN$204,MATCH($A31,Recipes!$AX$5:$AX$204,0)),"") -> 0 | F31: =IFERROR(INDEX(Recipes!$Q$5:$Q$204,MATCH($A31,Recipes!$AX$5:$AX$204,0)),"") -> 0
A33: CHEAPEST MEALS IN YOUR RECIPE BOOK
A34: Rank | B34: Recipe | C34: Cost / serving | D34: Calories | E34: Total time (min) | F34: Cost / 1000 kcal
A35: 1 | B35: =IFERROR(INDEX(Recipes!$A$5:$A$204,MATCH($A35,Recipes!$AV$5:$AV$204,0)),"") -> 0 | C35: =IFERROR(INDEX(Recipes!$Q$5:$Q$204,MATCH($A35,Recipes!$AV$5:$AV$204,0)),"") -> 0 | D35: =IFERROR(INDEX(Recipes!$H$5:$H$204,MATCH($A35,Recipes!$AV$5:$AV$204,0)),"") -> 0 | E35: =IFERROR(INDEX(Recipes!$G$5:$G$204,MATCH($A35,Recipes!$AV$5:$AV$204,0)),"") -> 0 | F35: =IFERROR(INDEX(Recipes!$R$5:$R$204,MATCH($A35,Recipes!$AV$5:$AV$204,0)),"") -> 0
A36: 2 | B36: =IFERROR(INDEX(Recipes!$A$5:$A$204,MATCH($A36,Recipes!$AV$5:$AV$204,0)),"") -> 0 | C36: =IFERROR(INDEX(Recipes!$Q$5:$Q$204,MATCH($A36,Recipes!$AV$5:$AV$204,0)),"") -> 0 | D36: =IFERROR(INDEX(Recipes!$H$5:$H$204,MATCH($A36,Recipes!$AV$5:$AV$204,0)),"") -> 0 | E36: =IFERROR(INDEX(Recipes!$G$5:$G$204,MATCH($A36,Recipes!$AV$5:$AV$204,0)),"") -> 0 | F36: =IFERROR(INDEX(Recipes!$R$5:$R$204,MATCH($A36,Recipes!$AV$5:$AV$204,0)),"") -> 0
A37: 3 | B37: =IFERROR(INDEX(Recipes!$A$5:$A$204,MATCH($A37,Recipes!$AV$5:$AV$204,0)),"") -> 0 | C37: =IFERROR(INDEX(Recipes!$Q$5:$Q$204,MATCH($A37,Recipes!$AV$5:$AV$204,0)),"") -> 0 | D37: =IFERROR(INDEX(Recipes!$H$5:$H$204,MATCH($A37,Recipes!$AV$5:$AV$204,0)),"") -> 0 | E37: =IFERROR(INDEX(Recipes!$G$5:$G$204,MATCH($A37,Recipes!$AV$5:$AV$204,0)),"") -> 0 | F37: =IFERROR(INDEX(Recipes!$R$5:$R$204,MATCH($A37,Recipes!$AV$5:$AV$204,0)),"") -> 0
A38: 4 | B38: =IFERROR(INDEX(Recipes!$A$5:$A$204,MATCH($A38,Recipes!$AV$5:$AV$204,0)),"") -> 0 | C38: =IFERROR(INDEX(Recipes!$Q$5:$Q$204,MATCH($A38,Recipes!$AV$5:$AV$204,0)),"") -> 0 | D38: =IFERROR(INDEX(Recipes!$H$5:$H$204,MATCH($A38,Recipes!$AV$5:$AV$204,0)),"") -> 0 | E38: =IFERROR(INDEX(Recipes!$G$5:$G$204,MATCH($A38,Recipes!$AV$5:$AV$204,0)),"") -> 0 | F38: =IFERROR(INDEX(Recipes!$R$5:$R$204,MATCH($A38,Recipes!$AV$5:$AV$204,0)),"") -> 0
A39: 5 | B39: =IFERROR(INDEX(Recipes!$A$5:$A$204,MATCH($A39,Recipes!$AV$5:$AV$204,0)),"") -> 0 | C39: =IFERROR(INDEX(Recipes!$Q$5:$Q$204,MATCH($A39,Recipes!$AV$5:$AV$204,0)),"") -> 0 | D39: =IFERROR(INDEX(Recipes!$H$5:$H$204,MATCH($A39,Recipes!$AV$5:$AV$204,0)),"") -> 0 | E39: =IFERROR(INDEX(Recipes!$G$5:$G$204,MATCH($A39,Recipes!$AV$5:$AV$204,0)),"") -> 0 | F39: =IFERROR(INDEX(Recipes!$R$5:$R$204,MATCH($A39,Recipes!$AV$5:$AV$204,0)),"") -> 0
A41: USE IT OR LOSE IT
A42: Rank | B42: Item | C42: Days left | D42: Quantity | E42: Storage | F42: Status
A43: 1 | B43: =IFERROR(INDEX(Pantry!$A$5:$A$304,MATCH($A43,Pantry!$Q$5:$Q$304,0)),"") -> 0 | C43: =IFERROR(INDEX(Pantry!$J$5:$J$304,MATCH($A43,Pantry!$Q$5:$Q$304,0)),"") -> 0 | D43: =IFERROR(INDEX(Pantry!$C$5:$C$304,MATCH($A43,Pantry!$Q$5:$Q$304,0)),"") -> 0 | E43: =IFERROR(INDEX(Pantry!$E$5:$E$304,MATCH($A43,Pantry!$Q$5:$Q$304,0)),"") -> 0 | F43: =IFERROR(INDEX(Pantry!$K$5:$K$304,MATCH($A43,Pantry!$Q$5:$Q$304,0)),"") -> 0
A44: 2 | B44: =IFERROR(INDEX(Pantry!$A$5:$A$304,MATCH($A44,Pantry!$Q$5:$Q$304,0)),"") -> 0 | C44: =IFERROR(INDEX(Pantry!$J$5:$J$304,MATCH($A44,Pantry!$Q$5:$Q$304,0)),"") -> 0 | D44: =IFERROR(INDEX(Pantry!$C$5:$C$304,MATCH($A44,Pantry!$Q$5:$Q$304,0)),"") -> 0 | E44: =IFERROR(INDEX(Pantry!$E$5:$E$304,MATCH($A44,Pantry!$Q$5:$Q$304,0)),"") -> 0 | F44: =IFERROR(INDEX(Pantry!$K$5:$K$304,MATCH($A44,Pantry!$Q$5:$Q$304,0)),"") -> 0
A45: 3 | B45: =IFERROR(INDEX(Pantry!$A$5:$A$304,MATCH($A45,Pantry!$Q$5:$Q$304,0)),"") -> 0 | C45: =IFERROR(INDEX(Pantry!$J$5:$J$304,MATCH($A45,Pantry!$Q$5:$Q$304,0)),"") -> 0 | D45: =IFERROR(INDEX(Pantry!$C$5:$C$304,MATCH($A45,Pantry!$Q$5:$Q$304,0)),"") -> 0 | E45: =IFERROR(INDEX(Pantry!$E$5:$E$304,MATCH($A45,Pantry!$Q$5:$Q$304,0)),"") -> 0 | F45: =IFERROR(INDEX(Pantry!$K$5:$K$304,MATCH($A45,Pantry!$Q$5:$Q$304,0)),"") -> 0
A46: 4 | B46: =IFERROR(INDEX(Pantry!$A$5:$A$304,MATCH($A46,Pantry!$Q$5:$Q$304,0)),"") -> 0 | C46: =IFERROR(INDEX(Pantry!$J$5:$J$304,MATCH($A46,Pantry!$Q$5:$Q$304,0)),"") -> 0 | D46: =IFERROR(INDEX(Pantry!$C$5:$C$304,MATCH($A46,Pantry!$Q$5:$Q$304,0)),"") -> 0 | E46: =IFERROR(INDEX(Pantry!$E$5:$E$304,MATCH($A46,Pantry!$Q$5:$Q$304,0)),"") -> 0 | F46: =IFERROR(INDEX(Pantry!$K$5:$K$304,MATCH($A46,Pantry!$Q$5:$Q$304,0)),"") -> 0
...

Sheet Weekly Planner
A1: WEEKLY PLANNER
A2: One week, day by day - meals, calories and cost
A3: | Dashboard | Meal Plan | Grocery List | Print Week | Monthly Planner
A5: WHICH WEEK?
A6: Week starting | B6: 2026-10-05 | D6: Household | E6: =Household_Name -> 0 | G6: People | H6: =Household_Size -> 0 | J6: Budget | K6: =Weekly_Budget -> 0
A7: Planned | B7: =COUNTIFS('Meal Plan'!$C$5:$C$504,$B$8)&" meals this week" -> 0 | D7: Week cost | E7: =SUMIFS('Meal Plan'!$Q$5:$Q$504,'Meal Plan'!$C$5:$C$504,$B$8) -> 0 | G7: Budget left | H7: =Weekly_Budget-$E$7 -> 0 | J7: Calories / day | K7: =IFERROR(SUMIFS('Meal Plan'!$L$5:$L$504,'Meal Plan'!$C$5:$C$504,$B$8)/MAX(1,Household_Size)/7,0) -> 0
A8: Day | B8: Date | C8: Breakfast | D8: Lunch | E8: Dinner | F8: Snacks | G8: Dessert | H8: Servings | I8: Calories | J8: Cost | K8: Notes
A10: =TEXT($B$8+0,"dddd") -> 0 | B10: =$B$8+0 -> 0 | C10: =IFERROR(INDEX('Meal Plan'!$G$5:$G$504,MATCH(1,INDEX(('Meal Plan'!$B$5:$B$504=$B10)*('Meal Plan'!$F$5:$F$504="Breakfast"),0),0)),"") -> 0 | D10: =IFERROR(INDEX('Meal Plan'!$G$5:$G$504,MATCH(1,INDEX(('Meal Plan'!$B$5:$B$504=$B10)*('Meal Plan'!$F$5:$F$504="Lunch"),0),0)),"") -> 0 | E10: =IFERROR(INDEX('Meal Plan'!$G$5:$G$504,MATCH(1,INDEX(('Meal Plan'!$B$5:$B$504=$B10)*('Meal Plan'!$F$5:$F$504="Dinner"),0),0)),"") -> 0 | F10: =IFERROR(INDEX('Meal Plan'!$G$5:$G$504,MATCH(1,INDEX(('Meal Plan'!$B$5:$B$504=$B10)*('Meal Plan'!$F$5:$F$504="Afternoon snack"),0),0)),"") -> 0 | G10: =IFERROR(INDEX('Meal Plan'!$G$5:$G$504,MATCH(1,INDEX(('Meal Plan'!$B$5:$B$504=$B10)*('Meal Plan'!$F$5:$F$504="Dessert"),0),0)),"") -> 0 | H10: =SUMIFS('Meal Plan'!$H$5:$H$504,'Meal Plan'!$B$5:$B$504,$B10) -> 0 | I10: =SUMIFS('Meal Plan'!$L$5:$L$504,'Meal Plan'!$B$5:$B$504,$B10) -> 0 | J10: =SUMIFS('Meal Plan'!$Q$5:$Q$504,'Meal Plan'!$B$5:$B$504,$B10) -> 0
A11: =TEXT($B$8+1,"dddd") -> 0 | B11: =$B$8+1 -> 0 | C11: =IFERROR(INDEX('Meal Plan'!$G$5:$G$504,MATCH(1,INDEX(('Meal Plan'!$B$5:$B$504=$B11)*('Meal Plan'!$F$5:$F$504="Breakfast"),0),0)),"") -> 0 | D11: =IFERROR(INDEX('Meal Plan'!$G$5:$G$504,MATCH(1,INDEX(('Meal Plan'!$B$5:$B$504=$B11)*('Meal Plan'!$F$5:$F$504="Lunch"),0),0)),"") -> 0 | E11: =IFERROR(INDEX('Meal Plan'!$G$5:$G$504,MATCH(1,INDEX(('Meal Plan'!$B$5:$B$504=$B11)*('Meal Plan'!$F$5:$F$504="Dinner"),0),0)),"") -> 0 | F11: =IFERROR(INDEX('Meal Plan'!$G$5:$G$504,MATCH(1,INDEX(('Meal Plan'!$B$5:$B$504=$B11)*('Meal Plan'!$F$5:$F$504="Afternoon snack"),0),0)),"") -> 0 | G11: =IFERROR(INDEX('Meal Plan'!$G$5:$G$504,MATCH(1,INDEX(('Meal Plan'!$B$5:$B$504=$B11)*('Meal Plan'!$F$5:$F$504="Dessert"),0),0)),"") -> 0 | H11: =SUMIFS('Meal Plan'!$H$5:$H$504,'Meal Plan'!$B$5:$B$504,$B11) -> 0 | I11: =SUMIFS('Meal Plan'!$L$5:$L$504,'Meal Plan'!$B$5:$B$504,$B11) -> 0 | J11: =SUMIFS('Meal Plan'!$Q$5:$Q$504,'Meal Plan'!$B$5:$B$504,$B11) -> 0
A12: =TEXT($B$8+2,"dddd") -> 0 | B12: =$B$8+2 -> 0 | C12: =IFERROR(INDEX('Meal Plan'!$G$5:$G$504,MATCH(1,INDEX(('Meal Plan'!$B$5:$B$504=$B12)*('Meal Plan'!$F$5:$F$504="Breakfast"),0),0)),"") -> 0 | D12: =IFERROR(INDEX('Meal Plan'!$G$5:$G$504,MATCH(1,INDEX(('Meal Plan'!$B$5:$B$504=$B12)*('Meal Plan'!$F$5:$F$504="Lunch"),0),0)),"") -> 0 | E12: =IFERROR(INDEX('Meal Plan'!$G$5:$G$504,MATCH(1,INDEX(('Meal Plan'!$B$5:$B$504=$B12)*('Meal Plan'!$F$5:$F$504="Dinner"),0),0)),"") -> 0 | F12: =IFERROR(INDEX('Meal Plan'!$G$5:$G$504,MATCH(1,INDEX(('Meal Plan'!$B$5:$B$504=$B12)*('Meal Plan'!$F$5:$F$504="Afternoon snack"),0),0)),"") -> 0 | G12: =IFERROR(INDEX('Meal Plan'!$G$5:$G$504,MATCH(1,INDEX(('Meal Plan'!$B$5:$B$504=$B12)*('Meal Plan'!$F$5:$F$504="Dessert"),0),0)),"") -> 0 | H12: =SUMIFS('Meal Plan'!$H$5:$H$504,'Meal Plan'!$B$5:$B$504,$B12) -> 0 | I12: =SUMIFS('Meal Plan'!$L$5:$L$504,'Meal Plan'!$B$5:$B$504,$B12) -> 0 | J12: =SUMIFS('Meal Plan'!$Q$5:$Q$504,'Meal Plan'!$B$5:$B$504,$B12) -> 0
A13: =TEXT($B$8+3,"dddd") -> 0 | B13: =$B$8+3 -> 0 | C13: =IFERROR(INDEX('Meal Plan'!$G$5:$G$504,MATCH(1,INDEX(('Meal Plan'!$B$5:$B$504=$B13)*('Meal Plan'!$F$5:$F$504="Breakfast"),0),0)),"") -> 0 | D13: =IFERROR(INDEX('Meal Plan'!$G$5:$G$504,MATCH(1,INDEX(('Meal Plan'!$B$5:$B$504=$B13)*('Meal Plan'!$F$5:$F$504="Lunch"),0),0)),"") -> 0 | E13: =IFERROR(INDEX('Meal Plan'!$G$5:$G$504,MATCH(1,INDEX(('Meal Plan'!$B$5:$B$504=$B13)*('Meal Plan'!$F$5:$F$504="Dinner"),0),0)),"") -> 0 | F13: =IFERROR(INDEX('Meal Plan'!$G$5:$G$504,MATCH(1,INDEX(('Meal Plan'!$B$5:$B$504=$B13)*('Meal Plan'!$F$5:$F$504="Afternoon snack"),0),0)),"") -> 0 | G13: =IFERROR(INDEX('Meal Plan'!$G$5:$G$504,MATCH(1,INDEX(('Meal Plan'!$B$5:$B$504=$B13)*('Meal Plan'!$F$5:$F$504="Dessert"),0),0)),"") -> 0 | H13: =SUMIFS('Meal Plan'!$H$5:$H$504,'Meal Plan'!$B$5:$B$504,$B13) -> 0 | I13: =SUMIFS('Meal Plan'!$L$5:$L$504,'Meal Plan'!$B$5:$B$504,$B13) -> 0 | J13: =SUMIFS('Meal Plan'!$Q$5:$Q$504,'Meal Plan'!$B$5:$B$504,$B13) -> 0
A14: =TEXT($B$8+4,"dddd") -> 0 | B14: =$B$8+4 -> 0 | C14: =IFERROR(INDEX('Meal Plan'!$G$5:$G$504,MATCH(1,INDEX(('Meal Plan'!$B$5:$B$504=$B14)*('Meal Plan'!$F$5:$F$504="Breakfast"),0),0)),"") -> 0 | D14: =IFERROR(INDEX('Meal Plan'!$G$5:$G$504,MATCH(1,INDEX(('Meal Plan'!$B$5:$B$504=$B14)*('Meal Plan'!$F$5:$F$504="Lunch"),0),0)),"") -> 0 | E14: =IFERROR(INDEX('Meal Plan'!$G$5:$G$504,MATCH(1,INDEX(('Meal Plan'!$B$5:$B$504=$B14)*('Meal Plan'!$F$5:$F$504="Dinner"),0),0)),"") -> 0 | F14: =IFERROR(INDEX('Meal Plan'!$G$5:$G$504,MATCH(1,INDEX(('Meal Plan'!$B$5:$B$504=$B14)*('Meal Plan'!$F$5:$F$504="Afternoon snack"),0),0)),"") -> 0 | G14: =IFERROR(INDEX('Meal Plan'!$G$5:$G$504,MATCH(1,INDEX(('Meal Plan'!$B$5:$B$504=$B14)*('Meal Plan'!$F$5:$F$504="Dessert"),0),0)),"") -> 0 | H14: =SUMIFS('Meal Plan'!$H$5:$H$504,'Meal Plan'!$B$5:$B$504,$B14) -> 0 | I14: =SUMIFS('Meal Plan'!$L$5:$L$504,'Meal Plan'!$B$5:$B$504,$B14) -> 0 | J14: =SUMIFS('Meal Plan'!$Q$5:$Q$504,'Meal Plan'!$B$5:$B$504,$B14) -> 0
A15: =TEXT($B$8+5,"dddd") -> 0 | B15: =$B$8+5 -> 0 | C15: =IFERROR(INDEX('Meal Plan'!$G$5:$G$504,MATCH(1,INDEX(('Meal Plan'!$B$5:$B$504=$B15)*('Meal Plan'!$F$5:$F$504="Breakfast"),0),0)),"") -> 0 | D15: =IFERROR(INDEX('Meal Plan'!$G$5:$G$504,MATCH(1,INDEX(('Meal Plan'!$B$5:$B$504=$B15)*('Meal Plan'!$F$5:$F$504="Lunch"),0),0)),"") -> 0 | E15: =IFERROR(INDEX('Meal Plan'!$G$5:$G$504,MATCH(1,INDEX(('Meal Plan'!$B$5:$B$504=$B15)*('Meal Plan'!$F$5:$F$504="Dinner"),0),0)),"") -> 0 | F15: =IFERROR(INDEX('Meal Plan'!$G$5:$G$504,MATCH(1,INDEX(('Meal Plan'!$B$5:$B$504=$B15)*('Meal Plan'!$F$5:$F$504="Afternoon snack"),0),0)),"") -> 0 | G15: =IFERROR(INDEX('Meal Plan'!$G$5:$G$504,MATCH(1,INDEX(('Meal Plan'!$B$5:$B$504=$B15)*('Meal Plan'!$F$5:$F$504="Dessert"),0),0)),"") -> 0 | H15: =SUMIFS('Meal Plan'!$H$5:$H$504,'Meal Plan'!$B$5:$B$504,$B15) -> 0 | I15: =SUMIFS('Meal Plan'!$L$5:$L$504,'Meal Plan'!$B$5:$B$504,$B15) -> 0 | J15: =SUMIFS('Meal Plan'!$Q$5:$Q$504,'Meal Plan'!$B$5:$B$504,$B15) -> 0
A16: Week total | H16: =SUM($H$10:$H$15) -> 0 | I16: =SUM($I$10:$I$15) -> 0 | J16: =SUM($J$10:$J$15) -> 0 | K16: =IFERROR(TEXT($I16/MAX(1,Household_Size)/7,"#,##0")&" kcal a day","") -> 0

Sheet Monthly Planner
A1: MONTHLY PLANNER
A2: The whole month on one page - themes, planned cost and actual spend
A3: | Dashboard | Weekly Planner | Meal Plan | Grocery Spending | Budget
A5: WHICH MONTH?
A6: Month | B6: October 2026 | D6: Weeks in the month | E6: =6 -> 0 | G6: Monthly budget | H6: =Monthly_Budget -> 0
B7: =DATEVALUE("1 "&$B$6) -> 0 | D7: Month planned | E7: =SUM($G$9:$G$14) -> 0 | G7: Month actual | H7: =SUM($H$9:$H$14) -> 0 | J7: Variance
A8: Week | B8: Week starting | C8: Breakfast theme | D8: Lunch theme | E8: Dinner theme | F8: Planned cost | G8: Actual spend | H8: Budget | I8: Variance | J8: Notes
A10: 1 | B10: =$B$7+0*7-WEEKDAY($B$7,2)+1 -> 0 | F10: =SUMIFS('Meal Plan'!$Q$5:$Q$504,'Meal Plan'!$C$5:$C$504,$B10) -> 0 | G10: =SUMIFS('Grocery Spending'!$J$5:$J$404,'Grocery Spending'!$B$5:$B$404,$B10) -> 0 | H10: =Weekly_Budget -> 0 | I10: =$H10-$G10 -> 0
A11: 2 | B11: =$B$7+1*7-WEEKDAY($B$7,2)+1 -> 0 | F11: =SUMIFS('Meal Plan'!$Q$5:$Q$504,'Meal Plan'!$C$5:$C$504,$B11) -> 0 | G11: =SUMIFS('Grocery Spending'!$J$5:$J$404,'Grocery Spending'!$B$5:$B$404,$B11) -> 0 | H11: =Weekly_Budget -> 0 | I11: =$H11-$G11 -> 0
A12: 3 | B12: =$B$7+2*7-WEEKDAY($B$7,2)+1 -> 0 | F12: =SUMIFS('Meal Plan'!$Q$5:$Q$504,'Meal Plan'!$C$5:$C$504,$B12) -> 0 | G12: =SUMIFS('Grocery Spending'!$J$5:$J$404,'Grocery Spending'!$B$5:$B$404,$B12) -> 0 | H12: =Weekly_Budget -> 0 | I12: =$H12-$G12 -> 0
A13: 4 | B13: =$B$7+3*7-WEEKDAY($B$7,2)+1 -> 0 | F13: =SUMIFS('Meal Plan'!$Q$5:$Q$504,'Meal Plan'!$C$5:$C$504,$B13) -> 0 | G13: =SUMIFS('Grocery Spending'!$J$5:$J$404,'Grocery Spending'!$B$5:$B$404,$B13) -> 0 | H13: =Weekly_Budget -> 0 | I13: =$H13-$G13 -> 0
A14: 5 | B14: =$B$7+4*7-WEEKDAY($B$7,2)+1 -> 0 | F14: =SUMIFS('Meal Plan'!$Q$5:$Q$504,'Meal Plan'!$C$5:$C$504,$B14) -> 0 | G14: =SUMIFS('Grocery Spending'!$J$5:$J$404,'Grocery Spending'!$B$5:$B$404,$B14) -> 0 | H14: =Weekly_Budget -> 0 | I14: =$H14-$G14 -> 0
A15: Month | F15: =SUM($F$9:$F$14) -> 0 | G15: =SUM($G$9:$G$14) -> 0 | H15: =SUM($H$9:$H$14) -> 0 | I15: =$H15-$G15 -> 0 | J15: =IF($H15=0,"",TEXT(($G15-$H15)/$H15,"0%")&" of budget left") -> 0

Sheet Settings
A1: SETTINGS
A2: Household, budget, nutrition targets and reminder windows - every tab reads these cells
A3: | Dashboard | Weekly Planner | Budget | Nutrition | Reports
A5: HOUSEHOLD
A6: Household name | B6: The Harper Household | C6: Shown on every print out.
A7: People in the household | B7: 4 | C7: Drives servings, budget per person and the grocery quantities.
A8: Main cook / planner | B8: Maya Harper | C8: Who owns the plan this year.
A9: Planning year | B9: 2026 | C9: Every weekly and monthly plan is built around this year.
A10: Servings per meal | B10: 4 | C10: Default portion count copied into new plan rows.
A11: Week starts on | B11: Monday | C11: Monday or Sunday.
A12: Measurement system | B12: Metric | C12: Metric (g, ml) or Imperial (oz, fl oz).
A13: Currency symbol | B13: $ | C13: Used in every money format.
A14: Currency code | B14: USD | C14: Three letter code, e.g. USD.
A15: Shopping day | B15: Saturday | C15: Day you usually shop.
A16: Meal prep day | B16: Sunday | C16: Day you usually cook ahead.
A18: GROCERY BUDGET
A19: Weekly grocery budget | B19: 180 | C19: Compared with the actual grocery spend on the Dashboard.
A20: Monthly grocery budget | B20: 780
A21: Annual grocery budget | B21: 9360
A22: Eating out budget (monthly) | B22: 120
A23: Food waste cost target (monthly) | B23: 15 | C23: Money you are willing to write off as waste.
A25: DAILY NUTRITION TARGETS PER PERSON
A26: Calories | B26: 2000 | C26: kcal a day.
A27: Protein | B27: 90 | C27: grams a day.
A28: Carbohydrates | B28: 230 | C28: grams a day.
A29: Fat | B29: 70 | C29: grams a day.
A30: Fibre | B30: 30 | C30: grams a day.
A31: Sugar limit | B31: 50 | C31: grams a day.
A32: Sodium limit | B32: 2300 | C32: mg a day.
A33: Water | B33: 8 | C33: glasses a day.
A35: REMINDER WINDOWS
A36: Use it or lose it (days) | B36: 5 | C36: Pantry items inside this window are flagged for use.
A37: Leftover fridge life (days) | B37: 3
A38: Freezer review (days) | B38: 90 | C38: How long before a freezer item is reviewed.
A39: Low stock warning (days of cover) | B39: 7
A40: Prep reminder (days ahead) | B40: 2
A41: Rotation gap (days) | B41: 14 | C41: Minimum days before the same meal is planned again.
A43: HABIT TARGETS
A44: Home cooked meals a week | B44: 18
A45: New recipes a month | B45: 2
...

Sheet Lists
A4: Meal slots | B4: Units | C4: Categories | D4: Cuisines | E4: Tags | F4: Stores | G4: Dietary needs | H4: Status | I4: Yes / No | J4: Recipe categories

Sheet Household
A4: Household member | B4: Role | C4: Age | D4: Dietary need | E4: Allergies | F4: Dislikes | G4: Calories / day | H4: Protein / day (g) | I4: Servings | J4: Packed lunch | K4: Notes | L4: Status
G5: =IF(A5="","",IF(C5="",Calorie_Target,IF(C5<4,Calorie_Target*0.4,IF(C5<9,Calorie_Target*0.6,IF(C5<14,Calorie_Target*0.8,IF(C5<19,Calorie_Target*0.95,Calorie_Target)))))) -> 0 | H5: =IF(A5="","",IF(C5="",Protein_Target,IF(C5<4,Protein_Target*0.5,IF(C5<9,Protein_Target*0.65,IF(C5<14,Protein_Target*0.8,IF(C5<19,Protein_Target*0.9,Protein_Target)))))) -> 0 | L5: =IF(A5="","",IF(E5<>"","Allergy noted","OK")) -> 0
G6: =IF(A6="","",IF(C6="",Calorie_Target,IF(C6<4,Calorie_Target*0.4,IF(C6<9,Calorie_Target*0.6,IF(C6<14,Calorie_Target*0.8,IF(C6<19,Calorie_Target*0.95,Calorie_Target)))))) -> 0 | H6: =IF(A6="","",IF(C6="",Protein_Target,IF(C6<4,Protein_Target*0.5,IF(C6<9,Protein_Target*0.65,IF(C6<14,Protein_Target*0.8,IF(C6<19,Protein_Target*0.9,Protein_Target)))))) -> 0 | L6: =IF(A6="","",IF(E6<>"","Allergy noted","OK")) -> 0
G7: =IF(A7="","",IF(C7="",Calorie_Target,IF(C7<4,Calorie_Target*0.4,IF(C7<9,Calorie_Target*0.6,IF(C7<14,Calorie_Target*0.8,IF(C7<19,Calorie_Target*0.95,Calorie_Target)))))) -> 0 | H7: =IF(A7="","",IF(C7="",Protein_Target,IF(C7<4,Protein_Target*0.5,IF(C7<9,Protein_Target*0.65,IF(C7<14,Protein_Target*0.8,IF(C7<19,Protein_Target*0.9,Protein_Target)))))) -> 0 | L7: =IF(A7="","",IF(E7<>"","Allergy noted","OK")) -> 0
G8: =IF(A8="","",IF(C8="",Calorie_Target,IF(C8<4,Calorie_Target*0.4,IF(C8<9,Calorie_Target*0.6,IF(C8<14,Calorie_Target*0.8,IF(C8<19,Calorie_Target*0.95,Calorie_Target)))))) -> 0 | H8: =IF(A8="","",IF(C8="",Protein_Target,IF(C8<4,Protein_Target*0.5,IF(C8<9,Protein_Target*0.65,IF(C8<14,Protein_Target*0.8,IF(C8<19,Protein_Target*0.9,Protein_Target)))))) -> 0 | L8: =IF(A8="","",IF(E8<>"","Allergy noted","OK")) -> 0
G9: =IF(A9="","",IF(C9="",Calorie_Target,IF(C9<4,Calorie_Target*0.4,IF(C9<9,Calorie_Target*0.6,IF(C9<14,Calorie_Target*0.8,IF(C9<19,Calorie_Target*0.95,Calorie_Target)))))) -> 0 | H9: =IF(A9="","",IF(C9="",Protein_Target,IF(C9<4,Protein_Target*0.5,IF(C9<9,Protein_Target*0.65,IF(C9<14,Protein_Target*0.8,IF(C9<19,Protein_Target*0.9,Protein_Target)))))) -> 0 | L9: =IF(A9="","",IF(E9<>"","Allergy noted","OK")) -> 0
G10: =IF(A10="","",IF(C10="",Calorie_Target,IF(C10<4,Calorie_Target*0.4,IF(C10<9,Calorie_Target*0.6,IF(C10<14,Calorie_Target*0.8,IF(C10<19,Calorie_Target*0.95,Calorie_Target)))))) -> 0 | H10: =IF(A10="","",IF(C10="",Protein_Target,IF(C10<4,Protein_Target*0.5,IF(C10<9,Protein_Target*0.65,IF(C10<14,Protein_Target*0.8,IF(C10<19,Protein_Target*0.9,Protein_Target)))))) -> 0 | L10: =IF(A10="","",IF(E10<>"","Allergy noted","OK")) -> 0
G11: =IF(A11="","",IF(C11="",Calorie_Target,IF(C11<4,Calorie_Target*0.4,IF(C11<9,Calorie_Target*0.6,IF(C11<14,Calorie_Target*0.8,IF(C11<19,Calorie_Target*0.95,Calorie_Target)))))) -> 0 | H11: =IF(A11="","",IF(C11="",Protein_Target,IF(C11<4,Protein_Target*0.5,IF(C11<9,Protein_Target*0.65,IF(C11<14,Protein_Target*0.8,IF(C11<19,Protein_Target*0.9,Protein_Target)))))) -> 0 | L11: =IF(A11="","",IF(E11<>"","Allergy noted","OK")) -> 0
G12: =IF(A12="","",IF(C12="",Calorie_Target,IF(C12<4,Calorie_Target*0.4,IF(C12<9,Calorie_Target*0.6,IF(C12<14,Calorie_Target*0.8,IF(C12<19,Calorie_Target*0.95,Calorie_Target)))))) -> 0 | H12: =IF(A12="","",IF(C12="",Protein_Target,IF(C12<4,Protein_Target*0.5,IF(C12<9,Protein_Target*0.65,IF(C12<14,Protein_Target*0.8,IF(C12<19,Protein_Target*0.9,Protein_Target)))))) -> 0 | L12: =IF(A12="","",IF(E12<>"","Allergy noted","OK")) -> 0
G13: =IF(A13="","",IF(C13="",Calorie_Target,IF(C13<4,Calorie_Target*0.4,IF(C13<9,Calorie_Target*0.6,IF(C13<14,Calorie_Target*0.8,IF(C13<19,Calorie_Target*0.95,Calorie_Target)))))) -> 0 | H13: =IF(A13="","",IF(C13="",Protein_Target,IF(C13<4,Protein_Target*0.5,IF(C13<9,Protein_Target*0.65,IF(C13<14,Protein_Target*0.8,IF(C13<19,Protein_Target*0.9,Protein_Target)))))) -> 0 | L13: =IF(A13="","",IF(E13<>"","Allergy noted","OK")) -> 0
G14: =IF(A14="","",IF(C14="",Calorie_Target,IF(C14<4,Calorie_Target*0.4,IF(C14<9,Calorie_Target*0.6,IF(C14<14,Calorie_Target*0.8,IF(C14<19,Calorie_Target*0.95,Calorie_Target)))))) -> 0 | H14: =IF(A14="","",IF(C14="",Protein_Target,IF(C14<4,Protein_Target*0.5,IF(C14<9,Protein_Target*0.65,IF(C14<14,Protein_Target*0.8,IF(C14<19,Protein_Target*0.9,Protein_Target)))))) -> 0 | L14: =IF(A14="","",IF(E14<>"","Allergy noted","OK")) -> 0
G15: =IF(A15="","",IF(C15="",Calorie_Target,IF(C15<4,Calorie_Target*0.4,IF(C15<9,Calorie_Target*0.6,IF(C15<14,Calorie_Target*0.8,IF(C15<19,Calorie_Target*0.95,Calorie_Target)))))) -> 0 | H15: =IF(A15="","",IF(C15="",Protein_Target,IF(C15<4,Protein_Target*0.5,IF(C15<9,Protein_Target*0.65,IF(C15<14,Protein_Target*0.8,IF(C15<19,Protein_Target*0.9,Protein_Target)))))) -> 0 | L15: =IF(A15="","",IF(E15<>"","Allergy noted","OK")) -> 0
G16: =IF(A16="","",IF(C16="",Calorie_Target,IF(C16<4,Calorie_Target*0.4,IF(C16<9,Calorie_Target*0.6,IF(C16<14,Calorie_Target*0.8,IF(C16<19,Calorie_Target*0.95,Calorie_Target)))))) -> 0 | H16: =IF(A16="","",IF(C16="",Protein_Target,IF(C16<4,Protein_Target*0.5,IF(C16<9,Protein_Target*0.65,IF(C16<14,Protein_Target*0.8,IF(C16<19,Protein_Target*0.9,Protein_Target)))))) -> 0 | L16: =IF(A16="","",IF(E16<>"","Allergy noted","OK")) -> 0

Sheet Recipes
A4: Recipe | B4: Category | C4: Cuisine | D4: Servings | E4: Prep (min) | F4: Cook (min) | G4: Total (min) | H4: Calories | I4: Protein (g) | J4: Carbs (g) | K4: Fat (g) | L4: Fibre (g) | M4: Sugar (g) | N4: Sodium (mg) | O4: Ingredients | P4: Total cost | Q4: Cost / serving | R4: Cost / 1000 kcal | S4: kcal / $ | T4: Protein / $ | U4: kcal / 10 min | V4: Match score | W4: Times cooked | X4: Last cooked | Y4: Days since | Z4: Rotation | AA4: Plan flag | AB4: Favourite | AC4: Vegetarian | AD4: Vegan | AE4: Gluten free | AF4: Dairy free | AG4: Nut free | AH4: Kid friendly | AI4: Batch cook | AJ4: Freezer | AK4: Quick (30 min) | AL4: Season | AM4: Added on | AN4: Rating (1-5) | AO4: Source | AP4: Link | AQ4: Tags | AR4: Notes | AS4: Calorie rank | AT4: Protein rank | AU4: Fibre rank | AV4: Cost rank | AW4: Match rank | AX4: Rotation rank | AY4: Popularity rank
G5: =IF(A5="","",E5+F5) -> 0 | O5: =IF(A5="","",COUNTIFS('Recipe Ingredients'!$A$5:$A$1204,A5)) -> 0 | P5: =IF(A5="","",SUMIFS('Recipe Ingredients'!$H$5:$H$1204,'Recipe Ingredients'!$A$5:$A$1204,A5)) -> 0 | Q5: =IF(OR(A5="",D5=0,D5=""),"",P5/D5) -> 0 | R5: =IF(OR(A5="",H5=0,H5=""),"",IFERROR(Q5/H5*1000,"")) -> 0 | S5: =IF(OR(A5="",Q5="",Q5=0),"",IFERROR(H5/Q5,"")) -> 0 | T5: =IF(OR(A5="",Q5="",Q5=0),"",IFERROR(I5/Q5,"")) -> 0 | U5: =IF(OR(A5="",G5="",G5=0),"",IFERROR(H5/G5*10,"")) -> 0 | V5: =IF(A5="","",(AC5="Yes")*1+(AD5="Yes")*1+(AE5="Yes")*1+(AF5="Yes")*1+(AG5="Yes")*1+(AH5="Yes")*1) -> 0 | W5: =IF(A5="","",COUNTIFS('Meal Plan'!$G$5:$G$504,A5,'Meal Plan'!$S$5:$S$504,"Cooked")+COUNTIFS('Meal Plan'!$G$5:$G$504,A5,'Meal Plan'!$S$5:$S$504,"Eaten")) -> 0 | X5: =IF(A5="","",IF(SUMPRODUCT(MAX(('Meal Plan'!$G$5:$G$504=A5)*'Meal Plan'!$B$5:$B$504))=0,"",SUMPRODUCT(MAX(('Meal Plan'!$G$5:$G$504=A5)*'Meal Plan'!$B$5:$B$504)))) -> 0 | Y5: =IF(OR(A5="",X5=""),"",TODAY()-X5) -> 0 | Z5: =IF(A5="","",IF(Y5="","Yes",IF(Y5>=Rotation_Gap_Days,"Yes","No"))) -> 0 | AA5: =IF(A5="","",IF(Z5="No","Too soon",IF(AND(AN5<>"",AN5>=4),"Plan it","Available"))) -> 0 | AK5: =IF(A5="","",IF(G5<=30,"Yes","No")) -> 0 | AS5: =IF(A5="","",COUNTIFS($H$5:$H$204,">"&H5)+1) -> 0 | AT5: =IF(A5="","",COUNTIFS($I$5:$I$204,">"&I5)+1) -> 0 | AU5: =IF(A5="","",COUNTIFS($L$5:$L$204,">"&L5)+1) -> 0 | AV5: =IF(OR(A5="",Q5=""),"",COUNTIFS($Q$5:$Q$204,"<"&Q5)+1) -> 0 | AW5: =IF(A5="","",COUNTIFS($V$5:$V$204,">"&V5)+1) -> 0 | AX5: =IF(A5="","",COUNTIFS($Y$5:$Y$204,"<"&Y5)+1) -> 0 | AY5: =IF(A5="","",COUNTIFS($W$5:$W$204,">"&W5)+1) -> 0
G6: =IF(A6="","",E6+F6) -> 0 | O6: =IF(A6="","",COUNTIFS('Recipe Ingredients'!$A$5:$A$1204,A6)) -> 0 | P6: =IF(A6="","",SUMIFS('Recipe Ingredients'!$H$5:$H$1204,'Recipe Ingredients'!$A$5:$A$1204,A6)) -> 0 | Q6: =IF(OR(A6="",D6=0,D6=""),"",P6/D6) -> 0 | R6: =IF(OR(A6="",H6=0,H6=""),"",IFERROR(Q6/H6*1000,"")) -> 0 | S6: =IF(OR(A6="",Q6="",Q6=0),"",IFERROR(H6/Q6,"")) -> 0 | T6: =IF(OR(A6="",Q6="",Q6=0),"",IFERROR(I6/Q6,"")) -> 0 | U6: =IF(OR(A6="",G6="",G6=0),"",IFERROR(H6/G6*10,"")) -> 0 | V6: =IF(A6="","",(AC6="Yes")*1+(AD6="Yes")*1+(AE6="Yes")*1+(AF6="Yes")*1+(AG6="Yes")*1+(AH6="Yes")*1) -> 0 | W6: =IF(A6="","",COUNTIFS('Meal Plan'!$G$5:$G$504,A6,'Meal Plan'!$S$5:$S$504,"Cooked")+COUNTIFS('Meal Plan'!$G$5:$G$504,A6,'Meal Plan'!$S$5:$S$504,"Eaten")) -> 0 | X6: =IF(A6="","",IF(SUMPRODUCT(MAX(('Meal Plan'!$G$5:$G$504=A6)*'Meal Plan'!$B$5:$B$504))=0,"",SUMPRODUCT(MAX(('Meal Plan'!$G$5:$G$504=A6)*'Meal Plan'!$B$5:$B$504)))) -> 0 | Y6: =IF(OR(A6="",X6=""),"",TODAY()-X6) -> 0 | Z6: =IF(A6="","",IF(Y6="","Yes",IF(Y6>=Rotation_Gap_Days,"Yes","No"))) -> 0 | AA6: =IF(A6="","",IF(Z6="No","Too soon",IF(AND(AN6<>"",AN6>=4),"Plan it","Available"))) -> 0 | AK6: =IF(A6="","",IF(G6<=30,"Yes","No")) -> 0 | AS6: =IF(A6="","",COUNTIFS($H$5:$H$204,">"&H6)+1) -> 0 | AT6: =IF(A6="","",COUNTIFS($I$5:$I$204,">"&I6)+1) -> 0 | AU6: =IF(A6="","",COUNTIFS($L$5:$L$204,">"&L6)+1) -> 0 | AV6: =IF(OR(A6="",Q6=""),"",COUNTIFS($Q$5:$Q$204,"<"&Q6)+1) -> 0 | AW6: =IF(A6="","",COUNTIFS($V$5:$V$204,">"&V6)+1) -> 0 | AX6: =IF(A6="","",COUNTIFS($Y$5:$Y$204,"<"&Y6)+1) -> 0 | AY6: =IF(A6="","",COUNTIFS($W$5:$W$204,">"&W6)+1) -> 0
G7: =IF(A7="","",E7+F7) -> 0 | O7: =IF(A7="","",COUNTIFS('Recipe Ingredients'!$A$5:$A$1204,A7)) -> 0 | P7: =IF(A7="","",SUMIFS('Recipe Ingredients'!$H$5:$H$1204,'Recipe Ingredients'!$A$5:$A$1204,A7)) -> 0 | Q7: =IF(OR(A7="",D7=0,D7=""),"",P7/D7) -> 0 | R7: =IF(OR(A7="",H7=0,H7=""),"",IFERROR(Q7/H7*1000,"")) -> 0 | S7: =IF(OR(A7="",Q7="",Q7=0),"",IFERROR(H7/Q7,"")) -> 0 | T7: =IF(OR(A7="",Q7="",Q7=0),"",IFERROR(I7/Q7,"")) -> 0 | U7: =IF(OR(A7="",G7="",G7=0),"",IFERROR(H7/G7*10,"")) -> 0 | V7: =IF(A7="","",(AC7="Yes")*1+(AD7="Yes")*1+(AE7="Yes")*1+(AF7="Yes")*1+(AG7="Yes")*1+(AH7="Yes")*1) -> 0 | W7: =IF(A7="","",COUNTIFS('Meal Plan'!$G$5:$G$504,A7,'Meal Plan'!$S$5:$S$504,"Cooked")+COUNTIFS('Meal Plan'!$G$5:$G$504,A7,'Meal Plan'!$S$5:$S$504,"Eaten")) -> 0 | X7: =IF(A7="","",IF(SUMPRODUCT(MAX(('Meal Plan'!$G$5:$G$504=A7)*'Meal Plan'!$B$5:$B$504))=0,"",SUMPRODUCT(MAX(('Meal Plan'!$G$5:$G$504=A7)*'Meal Plan'!$B$5:$B$504)))) -> 0 | Y7: =IF(OR(A7="",X7=""),"",TODAY()-X7) -> 0 | Z7: =IF(A7="","",IF(Y7="","Yes",IF(Y7>=Rotation_Gap_Days,"Yes","No"))) -> 0 | AA7: =IF(A7="","",IF(Z7="No","Too soon",IF(AND(AN7<>"",AN7>=4),"Plan it","Available"))) -> 0 | AK7: =IF(A7="","",IF(G7<=30,"Yes","No")) -> 0 | AS7: =IF(A7="","",COUNTIFS($H$5:$H$204,">"&H7)+1) -> 0 | AT7: =IF(A7="","",COUNTIFS($I$5:$I$204,">"&I7)+1) -> 0 | AU7: =IF(A7="","",COUNTIFS($L$5:$L$204,">"&L7)+1) -> 0 | AV7: =IF(OR(A7="",Q7=""),"",COUNTIFS($Q$5:$Q$204,"<"&Q7)+1) -> 0 | AW7: =IF(A7="","",COUNTIFS($V$5:$V$204,">"&V7)+1) -> 0 | AX7: =IF(A7="","",COUNTIFS($Y$5:$Y$204,"<"&Y7)+1) -> 0 | AY7: =IF(A7="","",COUNTIFS($W$5:$W$204,">"&W7)+1) -> 0
G8: =IF(A8="","",E8+F8) -> 0 | O8: =IF(A8="","",COUNTIFS('Recipe Ingredients'!$A$5:$A$1204,A8)) -> 0 | P8: =IF(A8="","",SUMIFS('Recipe Ingredients'!$H$5:$H$1204,'Recipe Ingredients'!$A$5:$A$1204,A8)) -> 0 | Q8: =IF(OR(A8="",D8=0,D8=""),"",P8/D8) -> 0 | R8: =IF(OR(A8="",H8=0,H8=""),"",IFERROR(Q8/H8*1000,"")) -> 0 | S8: =IF(OR(A8="",Q8="",Q8=0),"",IFERROR(H8/Q8,"")) -> 0 | T8: =IF(OR(A8="",Q8="",Q8=0),"",IFERROR(I8/Q8,"")) -> 0 | U8: =IF(OR(A8="",G8="",G8=0),"",IFERROR(H8/G8*10,"")) -> 0 | V8: =IF(A8="","",(AC8="Yes")*1+(AD8="Yes")*1+(AE8="Yes")*1+(AF8="Yes")*1+(AG8="Yes")*1+(AH8="Yes")*1) -> 0 | W8: =IF(A8="","",COUNTIFS('Meal Plan'!$G$5:$G$504,A8,'Meal Plan'!$S$5:$S$504,"Cooked")+COUNTIFS('Meal Plan'!$G$5:$G$504,A8,'Meal Plan'!$S$5:$S$504,"Eaten")) -> 0 | X8: =IF(A8="","",IF(SUMPRODUCT(MAX(('Meal Plan'!$G$5:$G$504=A8)*'Meal Plan'!$B$5:$B$504))=0,"",SUMPRODUCT(MAX(('Meal Plan'!$G$5:$G$504=A8)*'Meal Plan'!$B$5:$B$504)))) -> 0 | Y8: =IF(OR(A8="",X8=""),"",TODAY()-X8) -> 0 | Z8: =IF(A8="","",IF(Y8="","Yes",IF(Y8>=Rotation_Gap_Days,"Yes","No"))) -> 0 | AA8: =IF(A8="","",IF(Z8="No","Too soon",IF(AND(AN8<>"",AN8>=4),"Plan it","Available"))) -> 0 | AK8: =IF(A8="","",IF(G8<=30,"Yes","No")) -> 0 | AS8: =IF(A8="","",COUNTIFS($H$5:$H$204,">"&H8)+1) -> 0 | AT8: =IF(A8="","",COUNTIFS($I$5:$I$204,">"&I8)+1) -> 0 | AU8: =IF(A8="","",COUNTIFS($L$5:$L$204,">"&L8)+1) -> 0 | AV8: =IF(OR(A8="",Q8=""),"",COUNTIFS($Q$5:$Q$204,"<"&Q8)+1) -> 0 | AW8: =IF(A8="","",COUNTIFS($V$5:$V$204,">"&V8)+1) -> 0 | AX8: =IF(A8="","",COUNTIFS($Y$5:$Y$204,"<"&Y8)+1) -> 0 | AY8: =IF(A8="","",COUNTIFS($W$5:$W$204,">"&W8)+1) -> 0
G9: =IF(A9="","",E9+F9) -> 0 | O9: =IF(A9="","",COUNTIFS('Recipe Ingredients'!$A$5:$A$1204,A9)) -> 0 | P9: =IF(A9="","",SUMIFS('Recipe Ingredients'!$H$5:$H$1204,'Recipe Ingredients'!$A$5:$A$1204,A9)) -> 0 | Q9: =IF(OR(A9="",D9=0,D9=""),"",P9/D9) -> 0 | R9: =IF(OR(A9="",H9=0,H9=""),"",IFERROR(Q9/H9*1000,"")) -> 0 | S9: =IF(OR(A9="",Q9="",Q9=0),"",IFERROR(H9/Q9,"")) -> 0 | T9: =IF(OR(A9="",Q9="",Q9=0),"",IFERROR(I9/Q9,"")) -> 0 | U9: =IF(OR(A9="",G9="",G9=0),"",IFERROR(H9/G9*10,"")) -> 0 | V9: =IF(A9="","",(AC9="Yes")*1+(AD9="Yes")*1+(AE9="Yes")*1+(AF9="Yes")*1+(AG9="Yes")*1+(AH9="Yes")*1) -> 0 | W9: =IF(A9="","",COUNTIFS('Meal Plan'!$G$5:$G$504,A9,'Meal Plan'!$S$5:$S$504,"Cooked")+COUNTIFS('Meal Plan'!$G$5:$G$504,A9,'Meal Plan'!$S$5:$S$504,"Eaten")) -> 0 | X9: =IF(A9="","",IF(SUMPRODUCT(MAX(('Meal Plan'!$G$5:$G$504=A9)*'Meal Plan'!$B$5:$B$504))=0,"",SUMPRODUCT(MAX(('Meal Plan'!$G$5:$G$504=A9)*'Meal Plan'!$B$5:$B$504)))) -> 0 | Y9: =IF(OR(A9="",X9=""),"",TODAY()-X9) -> 0 | Z9: =IF(A9="","",IF(Y9="","Yes",IF(Y9>=Rotation_Gap_Days,"Yes","No"))) -> 0 | AA9: =IF(A9="","",IF(Z9="No","Too soon",IF(AND(AN9<>"",AN9>=4),"Plan it","Available"))) -> 0 | AK9: =IF(A9="","",IF(G9<=30,"Yes","No")) -> 0 | AS9: =IF(A9="","",COUNTIFS($H$5:$H$204,">"&H9)+1) -> 0 | AT9: =IF(A9="","",COUNTIFS($I$5:$I$204,">"&I9)+1) -> 0 | AU9: =IF(A9="","",COUNTIFS($L$5:$L$204,">"&L9)+1) -> 0 | AV9: =IF(OR(A9="",Q9=""),"",COUNTIFS($Q$5:$Q$204,"<"&Q9)+1) -> 0 | AW9: =IF(A9="","",COUNTIFS($V$5:$V$204,">"&V9)+1) -> 0 | AX9: =IF(A9="","",COUNTIFS($Y$5:$Y$204,"<"&Y9)+1) -> 0 | AY9: =IF(A9="","",COUNTIFS($W$5:$W$204,">"&W9)+1) -> 0
G10: =IF(A10="","",E10+F10) -> 0 | O10: =IF(A10="","",COUNTIFS('Recipe Ingredients'!$A$5:$A$1204,A10)) -> 0 | P10: =IF(A10="","",SUMIFS('Recipe Ingredients'!$H$5:$H$1204,'Recipe Ingredients'!$A$5:$A$1204,A10)) -> 0 | Q10: =IF(OR(A10="",D10=0,D10=""),"",P10/D10) -> 0 | R10: =IF(OR(A10="",H10=0,H10=""),"",IFERROR(Q10/H10*1000,"")) -> 0 | S10: =IF(OR(A10="",Q10="",Q10=0),"",IFERROR(H10/Q10,"")) -> 0 | T10: =IF(OR(A10="",Q10="",Q10=0),"",IFERROR(I10/Q10,"")) -> 0 | U10: =IF(OR(A10="",G10="",G10=0),"",IFERROR(H10/G10*10,"")) -> 0 | V10: =IF(A10="","",(AC10="Yes")*1+(AD10="Yes")*1+(AE10="Yes")*1+(AF10="Yes")*1+(AG10="Yes")*1+(AH10="Yes")*1) -> 0 | W10: =IF(A10="","",COUNTIFS('Meal Plan'!$G$5:$G$504,A10,'Meal Plan'!$S$5:$S$504,"Cooked")+COUNTIFS('Meal Plan'!$G$5:$G$504,A10,'Meal Plan'!$S$5:$S$504,"Eaten")) -> 0 | X10: =IF(A10="","",IF(SUMPRODUCT(MAX(('Meal Plan'!$G$5:$G$504=A10)*'Meal Plan'!$B$5:$B$504))=0,"",SUMPRODUCT(MAX(('Meal Plan'!$G$5:$G$504=A10)*'Meal Plan'!$B$5:$B$504)))) -> 0 | Y10: =IF(OR(A10="",X10=""),"",TODAY()-X10) -> 0 | Z10: =IF(A10="","",IF(Y10="","Yes",IF(Y10>=Rotation_Gap_Days,"Yes","No"))) -> 0 | AA10: =IF(A10="","",IF(Z10="No","Too soon",IF(AND(AN10<>"",AN10>=4),"Plan it","Available"))) -> 0 | AK10: =IF(A10="","",IF(G10<=30,"Yes","No")) -> 0 | AS10: =IF(A10="","",COUNTIFS($H$5:$H$204,">"&H10)+1) -> 0 | AT10: =IF(A10="","",COUNTIFS($I$5:$I$204,">"&I10)+1) -> 0 | AU10: =IF(A10="","",COUNTIFS($L$5:$L$204,">"&L10)+1) -> 0 | AV10: =IF(OR(A10="",Q10=""),"",COUNTIFS($Q$5:$Q$204,"<"&Q10)+1) -> 0 | AW10: =IF(A10="","",COUNTIFS($V$5:$V$204,">"&V10)+1) -> 0 | AX10: =IF(A10="","",COUNTIFS($Y$5:$Y$204,"<"&Y10)+1) -> 0 | AY10: =IF(A10="","",COUNTIFS($W$5:$W$204,">"&W10)+1) -> 0
G11: =IF(A11="","",E11+F11) -> 0 | O11: =IF(A11="","",COUNTIFS('Recipe Ingredients'!$A$5:$A$1204,A11)) -> 0 | P11: =IF(A11="","",SUMIFS('Recipe Ingredients'!$H$5:$H$1204,'Recipe Ingredients'!$A$5:$A$1204,A11)) -> 0 | Q11: =IF(OR(A11="",D11=0,D11=""),"",P11/D11) -> 0 | R11: =IF(OR(A11="",H11=0,H11=""),"",IFERROR(Q11/H11*1000,"")) -> 0 | S11: =IF(OR(A11="",Q11="",Q11=0),"",IFERROR(H11/Q11,"")) -> 0 | T11: =IF(OR(A11="",Q11="",Q11=0),"",IFERROR(I11/Q11,"")) -> 0 | U11: =IF(OR(A11="",G11="",G11=0),"",IFERROR(H11/G11*10,"")) -> 0 | V11: =IF(A11="","",(AC11="Yes")*1+(AD11="Yes")*1+(AE11="Yes")*1+(AF11="Yes")*1+(AG11="Yes")*1+(AH11="Yes")*1) -> 0 | W11: =IF(A11="","",COUNTIFS('Meal Plan'!$G$5:$G$504,A11,'Meal Plan'!$S$5:$S$504,"Cooked")+COUNTIFS('Meal Plan'!$G$5:$G$504,A11,'Meal Plan'!$S$5:$S$504,"Eaten")) -> 0 | X11: =IF(A11="","",IF(SUMPRODUCT(MAX(('Meal Plan'!$G$5:$G$504=A11)*'Meal Plan'!$B$5:$B$504))=0,"",SUMPRODUCT(MAX(('Meal Plan'!$G$5:$G$504=A11)*'Meal Plan'!$B$5:$B$504)))) -> 0 | Y11: =IF(OR(A11="",X11=""),"",TODAY()-X11) -> 0 | Z11: =IF(A11="","",IF(Y11="","Yes",IF(Y11>=Rotation_Gap_Days,"Yes","No"))) -> 0 | AA11: =IF(A11="","",IF(Z11="No","Too soon",IF(AND(AN11<>"",AN11>=4),"Plan it","Available"))) -> 0 | AK11: =IF(A11="","",IF(G11<=30,"Yes","No")) -> 0 | AS11: =IF(A11="","",COUNTIFS($H$5:$H$204,">"&H11)+1) -> 0 | AT11: =IF(A11="","",COUNTIFS($I$5:$I$204,">"&I11)+1) -> 0 | AU11: =IF(A11="","",COUNTIFS($L$5:$L$204,">"&L11)+1) -> 0 | AV11: =IF(OR(A11="",Q11=""),"",COUNTIFS($Q$5:$Q$204,"<"&Q11)+1) -> 0 | AW11: =IF(A11="","",COUNTIFS($V$5:$V$204,">"&V11)+1) -> 0 | AX11: =IF(A11="","",COUNTIFS($Y$5:$Y$204,"<"&Y11)+1) -> 0 | AY11: =IF(A11="","",COUNTIFS($W$5:$W$204,">"&W11)+1) -> 0
G12: =IF(A12="","",E12+F12) -> 0 | O12: =IF(A12="","",COUNTIFS('Recipe Ingredients'!$A$5:$A$1204,A12)) -> 0 | P12: =IF(A12="","",SUMIFS('Recipe Ingredients'!$H$5:$H$1204,'Recipe Ingredients'!$A$5:$A$1204,A12)) -> 0 | Q12: =IF(OR(A12="",D12=0,D12=""),"",P12/D12) -> 0 | R12: =IF(OR(A12="",H12=0,H12=""),"",IFERROR(Q12/H12*1000,"")) -> 0 | S12: =IF(OR(A12="",Q12="",Q12=0),"",IFERROR(H12/Q12,"")) -> 0 | T12: =IF(OR(A12="",Q12="",Q12=0),"",IFERROR(I12/Q12,"")) -> 0 | U12: =IF(OR(A12="",G12="",G12=0),"",IFERROR(H12/G12*10,"")) -> 0 | V12: =IF(A12="","",(AC12="Yes")*1+(AD12="Yes")*1+(AE12="Yes")*1+(AF12="Yes")*1+(AG12="Yes")*1+(AH12="Yes")*1) -> 0 | W12: =IF(A12="","",COUNTIFS('Meal Plan'!$G$5:$G$504,A12,'Meal Plan'!$S$5:$S$504,"Cooked")+COUNTIFS('Meal Plan'!$G$5:$G$504,A12,'Meal Plan'!$S$5:$S$504,"Eaten")) -> 0 | X12: =IF(A12="","",IF(SUMPRODUCT(MAX(('Meal Plan'!$G$5:$G$504=A12)*'Meal Plan'!$B$5:$B$504))=0,"",SUMPRODUCT(MAX(('Meal Plan'!$G$5:$G$504=A12)*'Meal Plan'!$B$5:$B$504)))) -> 0 | Y12: =IF(OR(A12="",X12=""),"",TODAY()-X12) -> 0 | Z12: =IF(A12="","",IF(Y12="","Yes",IF(Y12>=Rotation_Gap_Days,"Yes","No"))) -> 0 | AA12: =IF(A12="","",IF(Z12="No","Too soon",IF(AND(AN12<>"",AN12>=4),"Plan it","Available"))) -> 0 | AK12: =IF(A12="","",IF(G12<=30,"Yes","No")) -> 0 | AS12: =IF(A12="","",COUNTIFS($H$5:$H$204,">"&H12)+1) -> 0 | AT12: =IF(A12="","",COUNTIFS($I$5:$I$204,">"&I12)+1) -> 0 | AU12: =IF(A12="","",COUNTIFS($L$5:$L$204,">"&L12)+1) -> 0 | AV12: =IF(OR(A12="",Q12=""),"",COUNTIFS($Q$5:$Q$204,"<"&Q12)+1) -> 0 | AW12: =IF(A12="","",COUNTIFS($V$5:$V$204,">"&V12)+1) -> 0 | AX12: =IF(A12="","",COUNTIFS($Y$5:$Y$204,"<"&Y12)+1) -> 0 | AY12: =IF(A12="","",COUNTIFS($W$5:$W$204,">"&W12)+1) -> 0
G13: =IF(A13="","",E13+F13) -> 0 | O13: =IF(A13="","",COUNTIFS('Recipe Ingredients'!$A$5:$A$1204,A13)) -> 0 | P13: =IF(A13="","",SUMIFS('Recipe Ingredients'!$H$5:$H$1204,'Recipe Ingredients'!$A$5:$A$1204,A13)) -> 0 | Q13: =IF(OR(A13="",D13=0,D13=""),"",P13/D13) -> 0 | R13: =IF(OR(A13="",H13=0,H13=""),"",IFERROR(Q13/H13*1000,"")) -> 0 | S13: =IF(OR(A13="",Q13="",Q13=0),"",IFERROR(H13/Q13,"")) -> 0 | T13: =IF(OR(A13="",Q13="",Q13=0),"",IFERROR(I13/Q13,"")) -> 0 | U13: =IF(OR(A13="",G13="",G13=0),"",IFERROR(H13/G13*10,"")) -> 0 | V13: =IF(A13="","",(AC13="Yes")*1+(AD13="Yes")*1+(AE13="Yes")*1+(AF13="Yes")*1+(AG13="Yes")*1+(AH13="Yes")*1) -> 0 | W13: =IF(A13="","",COUNTIFS('Meal Plan'!$G$5:$G$504,A13,'Meal Plan'!$S$5:$S$504,"Cooked")+COUNTIFS('Meal Plan'!$G$5:$G$504,A13,'Meal Plan'!$S$5:$S$504,"Eaten")) -> 0 | X13: =IF(A13="","",IF(SUMPRODUCT(MAX(('Meal Plan'!$G$5:$G$504=A13)*'Meal Plan'!$B$5:$B$504))=0,"",SUMPRODUCT(MAX(('Meal Plan'!$G$5:$G$504=A13)*'Meal Plan'!$B$5:$B$504)))) -> 0 | Y13: =IF(OR(A13="",X13=""),"",TODAY()-X13) -> 0 | Z13: =IF(A13="","",IF(Y13="","Yes",IF(Y13>=Rotation_Gap_Days,"Yes","No"))) -> 0 | AA13: =IF(A13="","",IF(Z13="No","Too soon",IF(AND(AN13<>"",AN13>=4),"Plan it","Available"))) -> 0 | AK13: =IF(A13="","",IF(G13<=30,"Yes","No")) -> 0 | AS13: =IF(A13="","",COUNTIFS($H$5:$H$204,">"&H13)+1) -> 0 | AT13: =IF(A13="","",COUNTIFS($I$5:$I$204,">"&I13)+1) -> 0 | AU13: =IF(A13="","",COUNTIFS($L$5:$L$204,">"&L13)+1) -> 0 | AV13: =IF(OR(A13="",Q13=""),"",COUNTIFS($Q$5:$Q$204,"<"&Q13)+1) -> 0 | AW13: =IF(A13="","",COUNTIFS($V$5:$V$204,">"&V13)+1) -> 0 | AX13: =IF(A13="","",COUNTIFS($Y$5:$Y$204,"<"&Y13)+1) -> 0 | AY13: =IF(A13="","",COUNTIFS($W$5:$W$204,">"&W13)+1) -> 0
G14: =IF(A14="","",E14+F14) -> 0 | O14: =IF(A14="","",COUNTIFS('Recipe Ingredients'!$A$5:$A$1204,A14)) -> 0 | P14: =IF(A14="","",SUMIFS('Recipe Ingredients'!$H$5:$H$1204,'Recipe Ingredients'!$A$5:$A$1204,A14)) -> 0 | Q14: =IF(OR(A14="",D14=0,D14=""),"",P14/D14) -> 0 | R14: =IF(OR(A14="",H14=0,H14=""),"",IFERROR(Q14/H14*1000,"")) -> 0 | S14: =IF(OR(A14="",Q14="",Q14=0),"",IFERROR(H14/Q14,"")) -> 0 | T14: =IF(OR(A14="",Q14="",Q14=0),"",IFERROR(I14/Q14,"")) -> 0 | U14: =IF(OR(A14="",G14="",G14=0),"",IFERROR(H14/G14*10,"")) -> 0 | V14: =IF(A14="","",(AC14="Yes")*1+(AD14="Yes")*1+(AE14="Yes")*1+(AF14="Yes")*1+(AG14="Yes")*1+(AH14="Yes")*1) -> 0 | W14: =IF(A14="","",COUNTIFS('Meal Plan'!$G$5:$G$504,A14,'Meal Plan'!$S$5:$S$504,"Cooked")+COUNTIFS('Meal Plan'!$G$5:$G$504,A14,'Meal Plan'!$S$5:$S$504,"Eaten")) -> 0 | X14: =IF(A14="","",IF(SUMPRODUCT(MAX(('Meal Plan'!$G$5:$G$504=A14)*'Meal Plan'!$B$5:$B$504))=0,"",SUMPRODUCT(MAX(('Meal Plan'!$G$5:$G$504=A14)*'Meal Plan'!$B$5:$B$504)))) -> 0 | Y14: =IF(OR(A14="",X14=""),"",TODAY()-X14) -> 0 | Z14: =IF(A14="","",IF(Y14="","Yes",IF(Y14>=Rotation_Gap_Days,"Yes","No"))) -> 0 | AA14: =IF(A14="","",IF(Z14="No","Too soon",IF(AND(AN14<>"",AN14>=4),"Plan it","Available"))) -> 0 | AK14: =IF(A14="","",IF(G14<=30,"Yes","No")) -> 0 | AS14: =IF(A14="","",COUNTIFS($H$5:$H$204,">"&H14)+1) -> 0 | AT14: =IF(A14="","",COUNTIFS($I$5:$I$204,">"&I14)+1) -> 0 | AU14: =IF(A14="","",COUNTIFS($L$5:$L$204,">"&L14)+1) -> 0 | AV14: =IF(OR(A14="",Q14=""),"",COUNTIFS($Q$5:$Q$204,"<"&Q14)+1) -> 0 | AW14: =IF(A14="","",COUNTIFS($V$5:$V$204,">"&V14)+1) -> 0 | AX14: =IF(A14="","",COUNTIFS($Y$5:$Y$204,"<"&Y14)+1) -> 0 | AY14: =IF(A14="","",COUNTIFS($W$5:$W$204,">"&W14)+1) -> 0
G15: =IF(A15="","",E15+F15) -> 0 | O15: =IF(A15="","",COUNTIFS('Recipe Ingredients'!$A$5:$A$1204,A15)) -> 0 | P15: =IF(A15="","",SUMIFS('Recipe Ingredients'!$H$5:$H$1204,'Recipe Ingredients'!$A$5:$A$1204,A15)) -> 0 | Q15: =IF(OR(A15="",D15=0,D15=""),"",P15/D15) -> 0 | R15: =IF(OR(A15="",H15=0,H15=""),"",IFERROR(Q15/H15*1000,"")) -> 0 | S15: =IF(OR(A15="",Q15="",Q15=0),"",IFERROR(H15/Q15,"")) -> 0 | T15: =IF(OR(A15="",Q15="",Q15=0),"",IFERROR(I15/Q15,"")) -> 0 | U15: =IF(OR(A15="",G15="",G15=0),"",IFERROR(H15/G15*10,"")) -> 0 | V15: =IF(A15="","",(AC15="Yes")*1+(AD15="Yes")*1+(AE15="Yes")*1+(AF15="Yes")*1+(AG15="Yes")*1+(AH15="Yes")*1) -> 0 | W15: =IF(A15="","",COUNTIFS('Meal Plan'!$G$5:$G$504,A15,'Meal Plan'!$S$5:$S$504,"Cooked")+COUNTIFS('Meal Plan'!$G$5:$G$504,A15,'Meal Plan'!$S$5:$S$504,"Eaten")) -> 0 | X15: =IF(A15="","",IF(SUMPRODUCT(MAX(('Meal Plan'!$G$5:$G$504=A15)*'Meal Plan'!$B$5:$B$504))=0,"",SUMPRODUCT(MAX(('Meal Plan'!$G$5:$G$504=A15)*'Meal Plan'!$B$5:$B$504)))) -> 0 | Y15: =IF(OR(A15="",X15=""),"",TODAY()-X15) -> 0 | Z15: =IF(A15="","",IF(Y15="","Yes",IF(Y15>=Rotation_Gap_Days,"Yes","No"))) -> 0 | AA15: =IF(A15="","",IF(Z15="No","Too soon",IF(AND(AN15<>"",AN15>=4),"Plan it","Available"))) -> 0 | AK15: =IF(A15="","",IF(G15<=30,"Yes","No")) -> 0 | AS15: =IF(A15="","",COUNTIFS($H$5:$H$204,">"&H15)+1) -> 0 | AT15: =IF(A15="","",COUNTIFS($I$5:$I$204,">"&I15)+1) -> 0 | AU15: =IF(A15="","",COUNTIFS($L$5:$L$204,">"&L15)+1) -> 0 | AV15: =IF(OR(A15="",Q15=""),"",COUNTIFS($Q$5:$Q$204,"<"&Q15)+1) -> 0 | AW15: =IF(A15="","",COUNTIFS($V$5:$V$204,">"&V15)+1) -> 0 | AX15: =IF(A15="","",COUNTIFS($Y$5:$Y$204,"<"&Y15)+1) -> 0 | AY15: =IF(A15="","",COUNTIFS($W$5:$W$204,">"&W15)+1) -> 0
G16: =IF(A16="","",E16+F16) -> 0 | O16: =IF(A16="","",COUNTIFS('Recipe Ingredients'!$A$5:$A$1204,A16)) -> 0 | P16: =IF(A16="","",SUMIFS('Recipe Ingredients'!$H$5:$H$1204,'Recipe Ingredients'!$A$5:$A$1204,A16)) -> 0 | Q16: =IF(OR(A16="",D16=0,D16=""),"",P16/D16) -> 0 | R16: =IF(OR(A16="",H16=0,H16=""),"",IFERROR(Q16/H16*1000,"")) -> 0 | S16: =IF(OR(A16="",Q16="",Q16=0),"",IFERROR(H16/Q16,"")) -> 0 | T16: =IF(OR(A16="",Q16="",Q16=0),"",IFERROR(I16/Q16,"")) -> 0 | U16: =IF(OR(A16="",G16="",G16=0),"",IFERROR(H16/G16*10,"")) -> 0 | V16: =IF(A16="","",(AC16="Yes")*1+(AD16="Yes")*1+(AE16="Yes")*1+(AF16="Yes")*1+(AG16="Yes")*1+(AH16="Yes")*1) -> 0 | W16: =IF(A16="","",COUNTIFS('Meal Plan'!$G$5:$G$504,A16,'Meal Plan'!$S$5:$S$504,"Cooked")+COUNTIFS('Meal Plan'!$G$5:$G$504,A16,'Meal Plan'!$S$5:$S$504,"Eaten")) -> 0 | X16: =IF(A16="","",IF(SUMPRODUCT(MAX(('Meal Plan'!$G$5:$G$504=A16)*'Meal Plan'!$B$5:$B$504))=0,"",SUMPRODUCT(MAX(('Meal Plan'!$G$5:$G$504=A16)*'Meal Plan'!$B$5:$B$504)))) -> 0 | Y16: =IF(OR(A16="",X16=""),"",TODAY()-X16) -> 0 | Z16: =IF(A16="","",IF(Y16="","Yes",IF(Y16>=Rotation_Gap_Days,"Yes","No"))) -> 0 | AA16: =IF(A16="","",IF(Z16="No","Too soon",IF(AND(AN16<>"",AN16>=4),"Plan it","Available"))) -> 0 | AK16: =IF(A16="","",IF(G16<=30,"Yes","No")) -> 0 | AS16: =IF(A16="","",COUNTIFS($H$5:$H$204,">"&H16)+1) -> 0 | AT16: =IF(A16="","",COUNTIFS($I$5:$I$204,">"&I16)+1) -> 0 | AU16: =IF(A16="","",COUNTIFS($L$5:$L$204,">"&L16)+1) -> 0 | AV16: =IF(OR(A16="",Q16=""),"",COUNTIFS($Q$5:$Q$204,"<"&Q16)+1) -> 0 | AW16: =IF(A16="","",COUNTIFS($V$5:$V$204,">"&V16)+1) -> 0 | AX16: =IF(A16="","",COUNTIFS($Y$5:$Y$204,"<"&Y16)+1) -> 0 | AY16: =IF(A16="","",COUNTIFS($W$5:$W$204,">"&W16)+1) -> 0
