Workbook
Name ProjectTypes: 'Lists & Helpers'!$A$2:$A$7
Name ProjectStatuses: 'Lists & Helpers'!$B$2:$B$6
Name YesNo: 'Lists & Helpers'!$C$2:$C$3
Name BillingMethods: 'Lists & Helpers'!$D$2:$D$5
Name RoomTypes: 'Lists & Helpers'!$E$2:$E$12
Name DesignStatuses: 'Lists & Helpers'!$F$2:$F$8
Name PriorityLevels: 'Lists & Helpers'!$G$2:$G$5
Name FFECategories: 'Lists & Helpers'!$H$2:$H$19
Name OrderStatuses: 'Lists & Helpers'!$I$2:$I$14
Name ApprovalStatuses: 'Lists & Helpers'!$J$2:$J$7
Name DeliveryStatuses: 'Lists & Helpers'!$K$2:$K$9
Name InstallStatuses: 'Lists & Helpers'!$L$2:$L$7
Name FixtureTypes: 'Lists & Helpers'!$M$2:$M$12
Name FinishTypes: 'Lists & Helpers'!$N$2:$N$14
Name SurfaceApplications: 'Lists & Helpers'!$O$2:$O$10
Name PreferredOptions: 'Lists & Helpers'!$P$2:$P$6
Name VendorTypes: 'Lists & Helpers'!$Q$2:$Q$15
Name POStatuses: 'Lists & Helpers'!$R$2:$R$10
Name DamageChecks: 'Lists & Helpers'!$S$2:$S$6
Name TimelinePhases: 'Lists & Helpers'!$T$2:$T$13
Name TaskStatuses: 'Lists & Helpers'!$U$2:$U$7
Name MeasurementTypes: 'Lists & Helpers'!$V$2:$V$9
Name Trades: 'Lists & Helpers'!$W$2:$W$13
Name PaymentStatuses: 'Lists & Helpers'!$X$2:$X$7
Name PaymentMethods: 'Lists & Helpers'!$Y$2:$Y$7
Name MeetingTypes: 'Lists & Helpers'!$Z$2:$Z$7
Name TaskCategories: 'Lists & Helpers'!$AA$2:$AA$10
Name RoomNames: 'Room List - Area Tracker'!$A$7:$A$56
Name VendorNames: 'Vendor & Supplier Database'!$A$7:$A$106
Name BudgetCategories: 'Lists & Helpers'!$AB$2:$AB$15
Name ApprovalTypes: 'Lists & Helpers'!$AC$2:$AC$9

Sheet Welcome
A1: INTERIOR DESIGN PROJECT HUB
A3: A polished, editable project tracker for interior designers • compatible with Microsoft Excel + Google Sheets
A5: Welcome! Start with the five steps below, then use the dashboard to see the whole project at a glance.
A7: QUICK START GUIDE
A8: Step 1 | B8: Add client/project details | C8: Complete the Client & Project Profile tab. The project name, budget, dates, and status flow into the dashboard.
A9: Step 2 | B9: Add rooms | C9: List each area in Room List - Area Tracker. Use the room type, design status, budget allocation, and priority dropdowns.
A10: Step 3 | B10: Add FF&E items | C10: Enter furniture, fixtures, and equipment in Master FF&E Schedule. Total cost and final cost calculate automatically.
A11: Step 4 | B11: Track budget, orders, approvals, and delivery | C11: Use the Budget, Purchase Order, Client Approval, Delivery, Timeline, and Task tabs as work progresses.
A12: Step 5 | B12: Use dashboard for overview | C12: Review KPIs and charts for budget, item status, delivery, rooms, approvals, and open orders.
A15: WHAT EACH TAB IS USED FOR
A16: Tab | B16: Use it for
A17: Project Dashboard | B17: Main overview: KPI cards and charts for budget, items, approvals, delivery, and orders.
A18: Client & Project Profile | B18: Project summary, client contact details, dates, budget, scope, notes, and status.
A19: Room List - Area Tracker | B19: Room-by-room planning, budget allocation, estimated/actual spend, design status, and priorities.
A20: Master FF&E Schedule | B20: Core Furniture, Fixtures & Equipment register with pricing, links, vendors, approvals, delivery, and install status.
A21: Furniture Schedule | B21: Furniture-only view for quick sourcing and purchasing.
A22: Fixtures Schedule | B22: Lighting, plumbing, hardware, appliances, and built-in fixtures.
A23: Finishes Schedule | B23: Paint, wallpaper, flooring, tile, stone, fabric, and other finish selections.
A24: Product Sourcing Tracker | B24: Compare up to three product options before selecting a final item.
A25: Vendor & Supplier Database | B25: Central vendor contacts, trade terms, discounts, lead times, and policies.
A26: Budget Tracker | B26: Category budget, estimated/actual spend, paid amount, and balance due.
A27: Purchase Order - Order Tracker | B27: POs, order dates, delivery expectations, tracking, invoices, and paid status.
... A36: Printable Reports | B36: Client-facing FF&E, room budget, vendor order, installation, and final punch-list print views.
A38: HOW TO ENTER DATA
A39: Warm cream cells | B39: Editable input cells. Click a cell and type; use dropdown arrows wherever they appear.
A40: Blue cells | B40: Formula cells. They calculate automatically; you can still edit the workbook because this is an unlocked template.
A41: Dropdowns | B41: Choose a value from the dropdown for consistent reporting. Add rooms and vendors in their dedicated tabs first; those lists power the dropdowns.
A42: Links | B42: Paste full product, image, website, tracking, or invoice links. Keep links in the dedicated link columns.
A44: COLOR CODING
A45: Green | B45: Yellow | C45: Red | D45: Gray
A46: Complete / approved / delivered / installed / paid / on budget | C46: Overdue / over budget / delayed / damaged / rejected
A48: COMPATIBILITY, EDITING & SUPPORT
A49: Compatibility note: this workbook is designed for Microsoft Excel and Google Sheets. Upload the .xlsx file to Google Drive and choose Open with Google Sheets. Standard formulas, filters, dropdowns, conditional formatting, and charts are used for broad compatibility.
A50: Editable / unlocked version: no sheet protection is applied. Update labels, formulas, colors, dropdown source lists, and layouts to fit your studio workflow. Keep formula cells intact if you want the dashboard to stay accurate.
A51: Support / contact: replace this line with your studio name, support email, website, or template help desk before sharing with clients.

Sheet Project Dashboard
A1: PROJECT DASHBOARD
A3: A decision-ready overview of budget, scope, approvals, orders, deliveries, and installation.
A4: Tip: enter data in the warm cream cells on the project tabs. Dashboard formulas recalculate automatically.
A5: Total project budget | D5: Total estimated cost | G5: Total actual cost | J5: Remaining budget | M5: Budget used % | P5: Number of rooms
A6: =IFERROR(IF('Client & Project Profile'!$B$15>0,'Client & Project Profile'!$B$15,SUM('Budget Tracker'!$B$7:$B$306)),0) | D6: =SUM('Budget Tracker'!$C$7:$C$306) | G6: =SUM('Budget Tracker'!$D$7:$D$306) | J6: =A6-G6 | M6: =IFERROR(G6/A6,0) | P6: =COUNTIF('Room List - Area Tracker'!$A$7:$A$56,"<>")
A9: Total FF&E items | D9: Items approved | G9: Items ordered | J9: Items delivered | M9: Items installed | P9: Overdue tasks
A10: =COUNTIF('Master FF&E Schedule'!$D$7:$D$306,"<>") | D10: =COUNTIF('Master FF&E Schedule'!$W$7:$W$306,"Approved") | G10: =COUNTIF('Master FF&E Schedule'!$V$7:$V$306,"Ordered")+COUNTIF('Master FF&E Schedule'!$V$7:$V$306,"Confirmed")+COUNTIF('Master FF&E Schedule'!$V$7:$V$306,"In production")+COUNTIF('Master FF&E Schedule'!$V$7:$V$306,"Shipped")+COUNTIF('Master FF&E Schedule'!$V$7:$V$306,"Delivered")+COUNTIF('Master FF&E Schedule'!$V$7:$V$306,"Installed") | J10: =COUNTIF('Master FF&E Schedule'!$X$7:$X$306,"Delivered") | M10: =COUNTIF('Master FF&E Schedule'!$Y$7:$Y$306,"Installed") | P10: =COUNTIFS('Task & To-Do List'!$F$7:$F$306,"<"&TODAY(),'Task & To-Do List'!$F$7:$F$306,"<>",'Task & To-Do List'!$G$7:$G$306,"<>Complete",'Task & To-Do List'!$A$7:$A$306,"<>")
A13: Pending client approvals | D13: Open vendor orders | G13: Items not ordered | J13: Delivered but not installed
A14: =COUNTIF('Client Approval Tracker'!$F$7:$F$206,"Sent")+COUNTIF('Client Approval Tracker'!$F$7:$F$206,"Revisions requested")+COUNTIF('Client Approval Tracker'!$F$7:$F$206,"On hold") | D14: =COUNTIFS('Purchase Order - Order Tracker'!$A$7:$A$306,"<>",'Purchase Order - Order Tracker'!$J$7:$J$306,"<>Delivered",'Purchase Order - Order Tracker'!$J$7:$J$306,"<>Cancelled",'Purchase Order - Order Tracker'!$J$7:$J$306,"<>Returned") | G14: =COUNTIFS('Master FF&E Schedule'!$D$7:$D$306,"<>",'Master FF&E Schedule'!$V$7:$V$306,"") | J14: =COUNTIFS('Master FF&E Schedule'!$X$7:$X$306,"Delivered",'Master FF&E Schedule'!$Y$7:$Y$306,"<>Installed")
A17: VISUAL PROJECT OVERVIEW
A66: Dashboard data is formula-driven from the input tabs. If the dashboard is blank, start with the Client & Project Profile, Room List, Budget Tracker, and Master FF&E Schedule.

Sheet Client & Project Profile
A1: CLIENT & PROJECT PROFILE
A3: Complete this clean project summary first. Key fields feed the Project Dashboard.
A5: CLIENT & CONTACT | D5: PROJECT SUMMARY
A6: Client name | D6: Client notes
A7: Client email
A8: Phone number
A9: Project name
A10: Project address | D10: Scope summary
A11: Project type
A12: Design style
A13: Start date
A14: Target completion date
A15: Total budget | D15: Project status notes
A16: Designer name
A17: Project status
A18: Contract signed
A19: Deposit paid
A20: Design package selected
A21: Billing method

Sheet Room List - Area Tracker
A1: Room List - Area Tracker
A3: Organize the project by room or area. Remaining budget calculates as allocation less actual spend.
A4: Tip: enter data in the warm cream cells. Blue cells calculate automatically. Use the filter arrows in row 6 to focus the view.
A6: Room name | B6: Room type | C6: Floor/level | D6: Square footage | E6: Design status | F6: Budget allocation | G6: Estimated spend | H6: Actual spend | I6: Remaining budget | J6: Priority level | K6: Notes
I7: =IF(A7="","",F7-H7)
I8: =IF(A8="","",F8-H8)
I9: =IF(A9="","",F9-H9)
I10: =IF(A10="","",F10-H10)
I11: =IF(A11="","",F11-H11)
I12: =IF(A12="","",F12-H12)
I13: =IF(A13="","",F13-H13)
I14: =IF(A14="","",F14-H14)
I15: =IF(A15="","",F15-H15)
I16: =IF(A16="","",F16-H16)
I17: =IF(A17="","",F17-H17)
I18: =IF(A18="","",F18-H18)
... I56: =IF(A56="","",F56-H56)

Sheet Master FF&E Schedule
A1: Master FF&E Schedule
A3: Core Furniture, Fixtures & Equipment schedule. Enter quantity and unit cost; total cost and final cost calculate automatically.
A4: Tip: enter data in the warm cream cells. Blue cells calculate automatically. Use the filter arrows in row 6 to focus the view.
A6: Item ID | B6: Room | C6: Category | D6: Item name | E6: Description | F6: Quantity | G6: Dimensions | H6: Material | I6: Finish | J6: Color | K6: Vendor | L6: Brand | M6: Product link | N6: SKU/model number | O6: Unit cost | P6: Total cost | Q6: Tax | R6: Shipping | S6: Discount | T6: Final cost | U6: Lead time | V6: Order status | W6: Approval status | X6: Delivery status | Y6: Install status | Z6: Notes | AA6: Image link
P7: =IF(D7="","",F7*O7) | T7: =IF(D7="","",P7+Q7+R7-S7)
P8: =IF(D8="","",F8*O8) | T8: =IF(D8="","",P8+Q8+R8-S8)
P9: =IF(D9="","",F9*O9) | T9: =IF(D9="","",P9+Q9+R9-S9)
P10: =IF(D10="","",F10*O10) | T10: =IF(D10="","",P10+Q10+R10-S10)
P11: =IF(D11="","",F11*O11) | T11: =IF(D11="","",P11+Q11+R11-S11)
P12: =IF(D12="","",F12*O12) | T12: =IF(D12="","",P12+Q12+R12-S12)
P13: =IF(D13="","",F13*O13) | T13: =IF(D13="","",P13+Q13+R13-S13)
P14: =IF(D14="","",F14*O14) | T14: =IF(D14="","",P14+Q14+R14-S14)
P15: =IF(D15="","",F15*O15) | T15: =IF(D15="","",P15+Q15+R15-S15)
P16: =IF(D16="","",F16*O16) | T16: =IF(D16="","",P16+Q16+R16-S16)
P17: =IF(D17="","",F17*O17) | T17: =IF(D17="","",P17+Q17+R17-S17)
P18: =IF(D18="","",F18*O18) | T18: =IF(D18="","",P18+Q18+R18-S18)
... P306: =IF(D306="","",F306*O306) | T306: =IF(D306="","",P306+Q306+R306-S306)

Sheet Furniture Schedule
A1: Furniture Schedule
A3: A focused furniture-only list for quick sourcing, approval, and purchasing.
A4: Tip: enter data in the warm cream cells. Blue cells calculate automatically. Use the filter arrows in row 6 to focus the view.
A6: Room | B6: Furniture item | C6: Dimensions | D6: Quantity | E6: Vendor | F6: Product link | G6: Fabric/material | H6: Finish | I6: Cost | J6: Approval status | K6: Order status | L6: Delivery date | M6: Install date

Sheet Fixtures Schedule
A1: Fixtures Schedule
A3: Lighting, plumbing, hardware, appliances, and built-in fixtures.
A4: Tip: enter data in the warm cream cells. Blue cells calculate automatically. Use the filter arrows in row 6 to focus the view.
A6: Room | B6: Fixture type | C6: Item name | D6: Finish | E6: Size | F6: Vendor | G6: Model/SKU | H6: Quantity | I6: Unit cost | J6: Total cost | K6: Required rough-in date | L6: Order deadline | M6: Delivery date | N6: Installer notes
J7: =IF(C7="","",H7*I7)
J8: =IF(C8="","",H8*I8)
J9: =IF(C9="","",H9*I9)
J10: =IF(C10="","",H10*I10)
J11: =IF(C11="","",H11*I11)
J12: =IF(C12="","",H12*I12)
J13: =IF(C13="","",H13*I13)
J14: =IF(C14="","",H14*I14)
J15: =IF(C15="","",H15*I15)
J16: =IF(C16="","",H16*I16)
J17: =IF(C17="","",H17*I17)
J18: =IF(C18="","",H18*I18)
... J156: =IF(C156="","",H156*I156)

Sheet Finishes Schedule
A1: Finishes Schedule
A3: Track finish selections, samples, quantities, pricing, and installer notes by room.
A4: Tip: enter data in the warm cream cells. Blue cells calculate automatically. Use the filter arrows in row 6 to focus the view.
A6: Room | B6: Surface/application | C6: Finish type | D6: Product name | E6: Color/finish | F6: Material | G6: Vendor | H6: Product link | I6: SKU | J6: Quantity needed | K6: Unit cost | L6: Total cost | M6: Sample ordered | N6: Sample approved | O6: Installer notes
L7: =IF(D7="","",J7*K7)
L8: =IF(D8="","",J8*K8)
L9: =IF(D9="","",J9*K9)
L10: =IF(D10="","",J10*K10)
L11: =IF(D11="","",J11*K11)
L12: =IF(D12="","",J12*K12)
L13: =IF(D13="","",J13*K13)
L14: =IF(D14="","",J14*K14)
L15: =IF(D15="","",J15*K15)
L16: =IF(D16="","",J16*K16)
L17: =IF(D17="","",J17*K17)
L18: =IF(D18="","",J18*K18)
... L156: =IF(D156="","",J156*K156)

Sheet Product Sourcing Tracker
A1: Product Sourcing Tracker
A3: Compare up to three options before committing to a final FF&E selection.
A4: Tip: enter data in the warm cream cells. Blue cells calculate automatically. Use the filter arrows in row 6 to focus the view.
A6: Room | B6: Item needed | C6: Option 1 link | D6: Option 1 price | E6: Option 2 link | F6: Option 2 price | G6: Option 3 link | H6: Option 3 price | I6: Preferred option | J6: Pros | K6: Cons | L6: Client feedback | M6: Final selection

Sheet Vendor & Supplier Database
A1: Vendor & Supplier Database
A3: Create your vendor list first; vendor names then appear in dropdowns throughout the workbook.
A4: Tip: enter data in the warm cream cells. Blue cells calculate automatically. Use the filter arrows in row 6 to focus the view.
A6: Vendor name | B6: Vendor type | C6: Contact person | D6: Email | E6: Phone | F6: Website | G6: Account number | H6: Trade discount % | I6: Lead time | J6: Shipping terms | K6: Return policy | L6: Notes

Sheet Budget Tracker
A1: Budget Tracker
A3: Track category budgets, estimates, actuals, payments, and balance due. Difference = budgeted less estimated.
A4: Tip: enter data in the warm cream cells. Blue cells calculate automatically. Use the filter arrows in row 6 to focus the view.
A6: Budget category | B6: Budgeted amount | C6: Estimated amount | D6: Actual amount | E6: Difference | F6: Paid amount | G6: Balance due | H6: Payment status | I6: Notes
E7: =IF(A7="","",B7-C7) | G7: =IF(A7="","",D7-F7)
E8: =IF(A8="","",B8-C8) | G8: =IF(A8="","",D8-F8)
E9: =IF(A9="","",B9-C9) | G9: =IF(A9="","",D9-F9)
E10: =IF(A10="","",B10-C10) | G10: =IF(A10="","",D10-F10)
E11: =IF(A11="","",B11-C11) | G11: =IF(A11="","",D11-F11)
E12: =IF(A12="","",B12-C12) | G12: =IF(A12="","",D12-F12)
E13: =IF(A13="","",B13-C13) | G13: =IF(A13="","",D13-F13)
E14: =IF(A14="","",B14-C14) | G14: =IF(A14="","",D14-F14)
E15: =IF(A15="","",B15-C15) | G15: =IF(A15="","",D15-F15)
E16: =IF(A16="","",B16-C16) | G16: =IF(A16="","",D16-F16)
E17: =IF(A17="","",B17-C17) | G17: =IF(A17="","",D17-F17)
E18: =IF(A18="","",B18-C18) | G18: =IF(A18="","",D18-F18)
... E306: =IF(A306="","",B306-C306) | G306: =IF(A306="","",D306-F306)
A308: TOTAL PROJECT BUDGET | B308: =SUM(B7:B306) | C308: =SUM(C7:C306) | D308: =SUM(D7:D306) | E308: =B308-C308 | F308: =SUM(F7:F306) | G308: =D308-F308 | H308: =COUNTIF(H7:H306,"Paid")&" paid / "&COUNTIFS(A7:A306,"<>",H7:H306,"<>Paid")&" unpaid" | I308: Auto-calculated totals

Sheet Purchase Order - Order Tracker
A1: Purchase Order - Order Tracker
A3: Track every vendor order from PO creation through delivery, tracking, invoicing, and payment.
A4: Tip: enter data in the warm cream cells. Blue cells calculate automatically. Use the filter arrows in row 6 to focus the view.
A6: PO number | B6: Vendor | C6: Room | D6: Item | E6: Quantity | F6: Order date | G6: Expected ship date | H6: Expected delivery date | I6: Actual delivery date | J6: Order status | K6: Tracking number | L6: Carrier | M6: Invoice number | N6: Amount | O6: Paid status | P6: Notes

Sheet Delivery & Installation Tracker
A1: Delivery & Installation Tracker
A3: Keep deliveries organized: expected dates, damage checks, storage, installers, and installation status.
A4: Tip: enter data in the warm cream cells. Blue cells calculate automatically. Use the filter arrows in row 6 to focus the view.
A6: Item | B6: Room | C6: Vendor | D6: Delivery address | E6: Expected delivery date | F6: Actual delivery date | G6: Delivery status | H6: Received by | I6: Damage check | J6: Damage notes | K6: Storage location | L6: Install date | M6: Installer | N6: Installation status | O6: Punch list notes

Sheet Client Approval Tracker
A1: Client Approval Tracker
A3: Make client decisions visible: send, respond, revise, and record final approval dates.
A4: Tip: enter data in the warm cream cells. Blue cells calculate automatically. Use the filter arrows in row 6 to focus the view.
A6: Item/design decision | B6: Room | C6: Approval type | D6: Sent to client date | E6: Client response date | F6: Status | G6: Approved option | H6: Client comments | I6: Revision needed | J6: Final approval date

Sheet Project Timeline - Gantt
A1: Project Timeline - Gantt
A3: Manage phases, tasks, owners, dependencies, dates, and priorities. Use the dates for a simple Gantt-style workflow.
A4: Tip: enter data in the warm cream cells. Blue cells calculate automatically. Use the filter arrows in row 6 to focus the view.
A6: Phase | B6: Task | C6: Assigned to | D6: Start date | E6: Due date | F6: Completion date | G6: Status | H6: Priority | I6: Dependencies | J6: Notes

Sheet Task & To-Do List
A1: Task & To-Do List
A3: Use this as the daily action list. Overdue open tasks are counted on the dashboard.
A4: Tip: enter data in the warm cream cells. Blue cells calculate automatically. Use the filter arrows in row 6 to focus the view.
A6: Task | B6: Room | C6: Category | D6: Assigned to | E6: Priority | F6: Due date | G6: Status | H6: Notes

Sheet Measurement Log
A1: Measurement Log
A3: Record dimensions for rooms, walls, openings, furniture spaces, rugs, and lighting locations.
A4: Tip: enter data in the warm cream cells. Blue cells calculate automatically. Use the filter arrows in row 6 to focus the view.
A6: Room | B6: Measurement type | C6: Width | D6: Height | E6: Depth | F6: Length | G6: Ceiling height | H6: Window size | I6: Door size | J6: Wall length | K6: Notes

Sheet Contractor - Installer Tracker
A1: Contractor - Installer Tracker
A3: Coordinate construction and installation partners, scope, quotes, dates, documents, and payments.
A4: Tip: enter data in the warm cream cells. Blue cells calculate automatically. Use the filter arrows in row 6 to focus the view.
A6: Contractor/vendor name | B6: Trade | C6: Contact | D6: Scope | E6: Quote amount | F6: Start date | G6: End date | H6: Payment status | I6: Insurance received | J6: Contract signed | K6: Notes

Sheet Invoice & Payment Tracker
A1: Invoice & Payment Tracker
A3: Track client billing, due dates, paid dates, status, and payment method.
A4: Tip: enter data in the warm cream cells. Blue cells calculate automatically. Use the filter arrows in row 6 to focus the view.
A6: Invoice number | B6: Invoice date | C6: Client | D6: Description | E6: Amount | F6: Due date | G6: Paid date | H6: Payment status | I6: Payment method | J6: Notes

Sheet Project Notes - Meeting Notes
A1: Project Notes - Meeting Notes
A3: Capture conversations, decisions, action items, and follow-up dates in one searchable log.
A4: Tip: enter data in the warm cream cells. Blue cells calculate automatically. Use the filter arrows in row 6 to focus the view.
A6: Date | B6: Meeting type | C6: Attendees | D6: Discussion points | E6: Decisions made | F6: Action items | G6: Follow-up date | H6: Notes

Sheet Client FF&E Report
A1: Client FF&E Report
A3: A clean, client-facing selection report. Filter by room or approval status before sharing.
A4: Printable report view • linked to the project tracker. Filter rows before printing or sharing.
A6: Room | B6: Category | C6: Item | D6: Description | E6: Brand / Vendor | F6: Product link | G6: Final cost | H6: Approval status
A7: =IF('Master FF&E Schedule'!D7="","",'Master FF&E Schedule'!B7) | B7: =IF('Master FF&E Schedule'!D7="","",'Master FF&E Schedule'!C7) | C7: =IF('Master FF&E Schedule'!D7="","",'Master FF&E Schedule'!D7) | D7: =IF('Master FF&E Schedule'!D7="","",'Master FF&E Schedule'!E7) | E7: =IF('Master FF&E Schedule'!D7="","",IF('Master FF&E Schedule'!L7<>"",'Master FF&E Schedule'!L7,'Master FF&E Schedule'!K7)) | F7: =IF('Master FF&E Schedule'!D7="","",'Master FF&E Schedule'!M7) | G7: =IF('Master FF&E Schedule'!D7="","",'Master FF&E Schedule'!T7) | H7: =IF('Master FF&E Schedule'!D7="","",'Master FF&E Schedule'!W7)
A8: =IF('Master FF&E Schedule'!D8="","",'Master FF&E Schedule'!B8) | B8: =IF('Master FF&E Schedule'!D8="","",'Master FF&E Schedule'!C8) | C8: =IF('Master FF&E Schedule'!D8="","",'Master FF&E Schedule'!D8) | D8: =IF('Master FF&E Schedule'!D8="","",'Master FF&E Schedule'!E8) | E8: =IF('Master FF&E Schedule'!D8="","",IF('Master FF&E Schedule'!L8<>"",'Master FF&E Schedule'!L8,'Master FF&E Schedule'!K8)) | F8: =IF('Master FF&E Schedule'!D8="","",'Master FF&E Schedule'!M8) | G8: =IF('Master FF&E Schedule'!D8="","",'Master FF&E Schedule'!T8) | H8: =IF('Master FF&E Schedule'!D8="","",'Master FF&E Schedule'!W8)
A9: =IF('Master FF&E Schedule'!D9="","",'Master FF&E Schedule'!B9) | B9: =IF('Master FF&E Schedule'!D9="","",'Master FF&E Schedule'!C9) | C9: =IF('Master FF&E Schedule'!D9="","",'Master FF&E Schedule'!D9) | D9: =IF('Master FF&E Schedule'!D9="","",'Master FF&E Schedule'!E9) | E9: =IF('Master FF&E Schedule'!D9="","",IF('Master FF&E Schedule'!L9<>"",'Master FF&E Schedule'!L9,'Master FF&E Schedule'!K9)) | F9: =IF('Master FF&E Schedule'!D9="","",'Master FF&E Schedule'!M9) | G9: =IF('Master FF&E Schedule'!D9="","",'Master FF&E Schedule'!T9) | H9: =IF('Master FF&E Schedule'!D9="","",'Master FF&E Schedule'!W9)
A10: =IF('Master FF&E Schedule'!D10="","",'Master FF&E Schedule'!B10) | B10: =IF('Master FF&E Schedule'!D10="","",'Master FF&E Schedule'!C10) | C10: =IF('Master FF&E Schedule'!D10="","",'Master FF&E Schedule'!D10) | D10: =IF('Master FF&E Schedule'!D10="","",'Master FF&E Schedule'!E10) | E10: =IF('Master FF&E Schedule'!D10="","",IF('Master FF&E Schedule'!L10<>"",'Master FF&E Schedule'!L10,'Master FF&E Schedule'!K10)) | F10: =IF('Master FF&E Schedule'!D10="","",'Master FF&E Schedule'!M10) | G10: =IF('Master FF&E Schedule'!D10="","",'Master FF&E Schedule'!T10) | H10: =IF('Master FF&E Schedule'!D10="","",'Master FF&E Schedule'!W10)
A11: =IF('Master FF&E Schedule'!D11="","",'Master FF&E Schedule'!B11) | B11: =IF('Master FF&E Schedule'!D11="","",'Master FF&E Schedule'!C11) | C11: =IF('Master FF&E Schedule'!D11="","",'Master FF&E Schedule'!D11) | D11: =IF('Master FF&E Schedule'!D11="","",'Master FF&E Schedule'!E11) | E11: =IF('Master FF&E Schedule'!D11="","",IF('Master FF&E Schedule'!L11<>"",'Master FF&E Schedule'!L11,'Master FF&E Schedule'!K11)) | F11: =IF('Master FF&E Schedule'!D11="","",'Master FF&E Schedule'!M11) | G11: =IF('Master FF&E Schedule'!D11="","",'Master FF&E Schedule'!T11) | H11: =IF('Master FF&E Schedule'!D11="","",'Master FF&E Schedule'!W11)
A12: =IF('Master FF&E Schedule'!D12="","",'Master FF&E Schedule'!B12) | B12: =IF('Master FF&E Schedule'!D12="","",'Master FF&E Schedule'!C12) | C12: =IF('Master FF&E Schedule'!D12="","",'Master FF&E Schedule'!D12) | D12: =IF('Master FF&E Schedule'!D12="","",'Master FF&E Schedule'!E12) | E12: =IF('Master FF&E Schedule'!D12="","",IF('Master FF&E Schedule'!L12<>"",'Master FF&E Schedule'!L12,'Master FF&E Schedule'!K12)) | F12: =IF('Master FF&E Schedule'!D12="","",'Master FF&E Schedule'!M12) | G12: =IF('Master FF&E Schedule'!D12="","",'Master FF&E Schedule'!T12) | H12: =IF('Master FF&E Schedule'!D12="","",'Master FF&E Schedule'!W12)
A13: =IF('Master FF&E Schedule'!D13="","",'Master FF&E Schedule'!B13) | B13: =IF('Master FF&E Schedule'!D13="","",'Master FF&E Schedule'!C13) | C13: =IF('Master FF&E Schedule'!D13="","",'Master FF&E Schedule'!D13) | D13: =IF('Master FF&E Schedule'!D13="","",'Master FF&E Schedule'!E13) | E13: =IF('Master FF&E Schedule'!D13="","",IF('Master FF&E Schedule'!L13<>"",'Master FF&E Schedule'!L13,'Master FF&E Schedule'!K13)) | F13: =IF('Master FF&E Schedule'!D13="","",'Master FF&E Schedule'!M13) | G13: =IF('Master FF&E Schedule'!D13="","",'Master FF&E Schedule'!T13) | H13: =IF('Master FF&E Schedule'!D13="","",'Master FF&E Schedule'!W13)
A14: =IF('Master FF&E Schedule'!D14="","",'Master FF&E Schedule'!B14) | B14: =IF('Master FF&E Schedule'!D14="","",'Master FF&E Schedule'!C14) | C14: =IF('Master FF&E Schedule'!D14="","",'Master FF&E Schedule'!D14) | D14: =IF('Master FF&E Schedule'!D14="","",'Master FF&E Schedule'!E14) | E14: =IF('Master FF&E Schedule'!D14="","",IF('Master FF&E Schedule'!L14<>"",'Master FF&E Schedule'!L14,'Master FF&E Schedule'!K14)) | F14: =IF('Master FF&E Schedule'!D14="","",'Master FF&E Schedule'!M14) | G14: =IF('Master FF&E Schedule'!D14="","",'Master FF&E Schedule'!T14) | H14: =IF('Master FF&E Schedule'!D14="","",'Master FF&E Schedule'!W14)
A15: =IF('Master FF&E Schedule'!D15="","",'Master FF&E Schedule'!B15) | B15: =IF('Master FF&E Schedule'!D15="","",'Master FF&E Schedule'!C15) | C15: =IF('Master FF&E Schedule'!D15="","",'Master FF&E Schedule'!D15) | D15: =IF('Master FF&E Schedule'!D15="","",'Master FF&E Schedule'!E15) | E15: =IF('Master FF&E Schedule'!D15="","",IF('Master FF&E Schedule'!L15<>"",'Master FF&E Schedule'!L15,'Master FF&E Schedule'!K15)) | F15: =IF('Master FF&E Schedule'!D15="","",'Master FF&E Schedule'!M15) | G15: =IF('Master FF&E Schedule'!D15="","",'Master FF&E Schedule'!T15) | H15: =IF('Master FF&E Schedule'!D15="","",'Master FF&E Schedule'!W15)
A16: =IF('Master FF&E Schedule'!D16="","",'Master FF&E Schedule'!B16) | B16: =IF('Master FF&E Schedule'!D16="","",'Master FF&E Schedule'!C16) | C16: =IF('Master FF&E Schedule'!D16="","",'Master FF&E Schedule'!D16) | D16: =IF('Master FF&E Schedule'!D16="","",'Master FF&E Schedule'!E16) | E16: =IF('Master FF&E Schedule'!D16="","",IF('Master FF&E Schedule'!L16<>"",'Master FF&E Schedule'!L16,'Master FF&E Schedule'!K16)) | F16: =IF('Master FF&E Schedule'!D16="","",'Master FF&E Schedule'!M16) | G16: =IF('Master FF&E Schedule'!D16="","",'Master FF&E Schedule'!T16) | H16: =IF('Master FF&E Schedule'!D16="","",'Master FF&E Schedule'!W16)
A17: =IF('Master FF&E Schedule'!D17="","",'Master FF&E Schedule'!B17) | B17: =IF('Master FF&E Schedule'!D17="","",'Master FF&E Schedule'!C17) | C17: =IF('Master FF&E Schedule'!D17="","",'Master FF&E Schedule'!D17) | D17: =IF('Master FF&E Schedule'!D17="","",'Master FF&E Schedule'!E17) | E17: =IF('Master FF&E Schedule'!D17="","",IF('Master FF&E Schedule'!L17<>"",'Master FF&E Schedule'!L17,'Master FF&E Schedule'!K17)) | F17: =IF('Master FF&E Schedule'!D17="","",'Master FF&E Schedule'!M17) | G17: =IF('Master FF&E Schedule'!D17="","",'Master FF&E Schedule'!T17) | H17: =IF('Master FF&E Schedule'!D17="","",'Master FF&E Schedule'!W17)
A18: =IF('Master FF&E Schedule'!D18="","",'Master FF&E Schedule'!B18) | B18: =IF('Master FF&E Schedule'!D18="","",'Master FF&E Schedule'!C18) | C18: =IF('Master FF&E Schedule'!D18="","",'Master FF&E Schedule'!D18) | D18: =IF('Master FF&E Schedule'!D18="","",'Master FF&E Schedule'!E18) | E18: =IF('Master FF&E Schedule'!D18="","",IF('Master FF&E Schedule'!L18<>"",'Master FF&E Schedule'!L18,'Master FF&E Schedule'!K18)) | F18: =IF('Master FF&E Schedule'!D18="","",'Master FF&E Schedule'!M18) | G18: =IF('Master FF&E Schedule'!D18="","",'Master FF&E Schedule'!T18) | H18: =IF('Master FF&E Schedule'!D18="","",'Master FF&E Schedule'!W18)
... A106: =IF('Master FF&E Schedule'!D106="","",'Master FF&E Schedule'!B106) | B106: =IF('Master FF&E Schedule'!D106="","",'Master FF&E Schedule'!C106) | C106: =IF('Master FF&E Schedule'!D106="","",'Master FF&E Schedule'!D106) | D106: =IF('Master FF&E Schedule'!D106="","",'Master FF&E Schedule'!E106) | E106: =IF('Master FF&E Schedule'!D106="","",IF('Master FF&E Schedule'!L106<>"",'Master FF&E Schedule'!L106,'Master FF&E Schedule'!K106)) | F106: =IF('Master FF&E Schedule'!D106="","",'Master FF&E Schedule'!M106) | G106: =IF('Master FF&E Schedule'!D106="","",'Master FF&E Schedule'!T106) | H106: =IF('Master FF&E Schedule'!D106="","",'Master FF&E Schedule'!W106)

Sheet Room-by-Room Budget Report
A1: Room-by-Room Budget Report
A3: Printable room-level budget report linked to the Room List - Area Tracker.
A4: Printable report view • linked to the project tracker. Filter rows before printing or sharing.
A6: Room | B6: Budget allocation | C6: Estimated spend | D6: Actual spend | E6: Remaining budget | F6: Design status | G6: Priority | H6: Notes
A7: ='Room List - Area Tracker'!A7 | B7: ='Room List - Area Tracker'!F7 | C7: ='Room List - Area Tracker'!G7 | D7: ='Room List - Area Tracker'!H7 | E7: ='Room List - Area Tracker'!I7 | F7: ='Room List - Area Tracker'!E7 | G7: ='Room List - Area Tracker'!J7 | H7: ='Room List - Area Tracker'!K7
A8: ='Room List - Area Tracker'!A8 | B8: ='Room List - Area Tracker'!F8 | C8: ='Room List - Area Tracker'!G8 | D8: ='Room List - Area Tracker'!H8 | E8: ='Room List - Area Tracker'!I8 | F8: ='Room List - Area Tracker'!E8 | G8: ='Room List - Area Tracker'!J8 | H8: ='Room List - Area Tracker'!K8
A9: ='Room List - Area Tracker'!A9 | B9: ='Room List - Area Tracker'!F9 | C9: ='Room List - Area Tracker'!G9 | D9: ='Room List - Area Tracker'!H9 | E9: ='Room List - Area Tracker'!I9 | F9: ='Room List - Area Tracker'!E9 | G9: ='Room List - Area Tracker'!J9 | H9: ='Room List - Area Tracker'!K9
A10: ='Room List - Area Tracker'!A10 | B10: ='Room List - Area Tracker'!F10 | C10: ='Room List - Area Tracker'!G10 | D10: ='Room List - Area Tracker'!H10 | E10: ='Room List - Area Tracker'!I10 | F10: ='Room List - Area Tracker'!E10 | G10: ='Room List - Area Tracker'!J10 | H10: ='Room List - Area Tracker'!K10
A11: ='Room List - Area Tracker'!A11 | B11: ='Room List - Area Tracker'!F11 | C11: ='Room List - Area Tracker'!G11 | D11: ='Room List - Area Tracker'!H11 | E11: ='Room List - Area Tracker'!I11 | F11: ='Room List - Area Tracker'!E11 | G11: ='Room List - Area Tracker'!J11 | H11: ='Room List - Area Tracker'!K11
A12: ='Room List - Area Tracker'!A12 | B12: ='Room List - Area Tracker'!F12 | C12: ='Room List - Area Tracker'!G12 | D12: ='Room List - Area Tracker'!H12 | E12: ='Room List - Area Tracker'!I12 | F12: ='Room List - Area Tracker'!E12 | G12: ='Room List - Area Tracker'!J12 | H12: ='Room List - Area Tracker'!K12
A13: ='Room List - Area Tracker'!A13 | B13: ='Room List - Area Tracker'!F13 | C13: ='Room List - Area Tracker'!G13 | D13: ='Room List - Area Tracker'!H13 | E13: ='Room List - Area Tracker'!I13 | F13: ='Room List - Area Tracker'!E13 | G13: ='Room List - Area Tracker'!J13 | H13: ='Room List - Area Tracker'!K13
A14: ='Room List - Area Tracker'!A14 | B14: ='Room List - Area Tracker'!F14 | C14: ='Room List - Area Tracker'!G14 | D14: ='Room List - Area Tracker'!H14 | E14: ='Room List - Area Tracker'!I14 | F14: ='Room List - Area Tracker'!E14 | G14: ='Room List - Area Tracker'!J14 | H14: ='Room List - Area Tracker'!K14
A15: ='Room List - Area Tracker'!A15 | B15: ='Room List - Area Tracker'!F15 | C15: ='Room List - Area Tracker'!G15 | D15: ='Room List - Area Tracker'!H15 | E15: ='Room List - Area Tracker'!I15 | F15: ='Room List - Area Tracker'!E15 | G15: ='Room List - Area Tracker'!J15 | H15: ='Room List - Area Tracker'!K15
A16: ='Room List - Area Tracker'!A16 | B16: ='Room List - Area Tracker'!F16 | C16: ='Room List - Area Tracker'!G16 | D16: ='Room List - Area Tracker'!H16 | E16: ='Room List - Area Tracker'!I16 | F16: ='Room List - Area Tracker'!E16 | G16: ='Room List - Area Tracker'!J16 | H16: ='Room List - Area Tracker'!K16
A17: ='Room List - Area Tracker'!A17 | B17: ='Room List - Area Tracker'!F17 | C17: ='Room List - Area Tracker'!G17 | D17: ='Room List - Area Tracker'!H17 | E17: ='Room List - Area Tracker'!I17 | F17: ='Room List - Area Tracker'!E17 | G17: ='Room List - Area Tracker'!J17 | H17: ='Room List - Area Tracker'!K17
A18: ='Room List - Area Tracker'!A18 | B18: ='Room List - Area Tracker'!F18 | C18: ='Room List - Area Tracker'!G18 | D18: ='Room List - Area Tracker'!H18 | E18: ='Room List - Area Tracker'!I18 | F18: ='Room List - Area Tracker'!E18 | G18: ='Room List - Area Tracker'!J18 | H18: ='Room List - Area Tracker'!K18
... A56: ='Room List - Area Tracker'!A56 | B56: ='Room List - Area Tracker'!F56 | C56: ='Room List - Area Tracker'!G56 | D56: ='Room List - Area Tracker'!H56 | E56: ='Room List - Area Tracker'!I56 | F56: ='Room List - Area Tracker'!E56 | G56: ='Room List - Area Tracker'!J56 | H56: ='Room List - Area Tracker'!K56

Sheet Vendor Order Report
A1: Vendor Order Report
A3: Printable open-order view for vendor follow-up and purchasing meetings.
A4: Printable report view • linked to the project tracker. Filter rows before printing or sharing.
A6: PO number | B6: Vendor | C6: Room | D6: Item | E6: Expected delivery | F6: Order status | G6: Tracking number | H6: Amount | I6: Paid status
A7: =IF('Purchase Order - Order Tracker'!A7="","",'Purchase Order - Order Tracker'!A7) | B7: =IF('Purchase Order - Order Tracker'!A7="","",'Purchase Order - Order Tracker'!B7) | C7: =IF('Purchase Order - Order Tracker'!A7="","",'Purchase Order - Order Tracker'!C7) | D7: =IF('Purchase Order - Order Tracker'!A7="","",'Purchase Order - Order Tracker'!D7) | E7: =IF('Purchase Order - Order Tracker'!A7="","",'Purchase Order - Order Tracker'!H7) | F7: =IF('Purchase Order - Order Tracker'!A7="","",'Purchase Order - Order Tracker'!J7) | G7: =IF('Purchase Order - Order Tracker'!A7="","",'Purchase Order - Order Tracker'!K7) | H7: =IF('Purchase Order - Order Tracker'!A7="","",'Purchase Order - Order Tracker'!N7) | I7: =IF('Purchase Order - Order Tracker'!A7="","",'Purchase Order - Order Tracker'!O7)
A8: =IF('Purchase Order - Order Tracker'!A8="","",'Purchase Order - Order Tracker'!A8) | B8: =IF('Purchase Order - Order Tracker'!A8="","",'Purchase Order - Order Tracker'!B8) | C8: =IF('Purchase Order - Order Tracker'!A8="","",'Purchase Order - Order Tracker'!C8) | D8: =IF('Purchase Order - Order Tracker'!A8="","",'Purchase Order - Order Tracker'!D8) | E8: =IF('Purchase Order - Order Tracker'!A8="","",'Purchase Order - Order Tracker'!H8) | F8: =IF('Purchase Order - Order Tracker'!A8="","",'Purchase Order - Order Tracker'!J8) | G8: =IF('Purchase Order - Order Tracker'!A8="","",'Purchase Order - Order Tracker'!K8) | H8: =IF('Purchase Order - Order Tracker'!A8="","",'Purchase Order - Order Tracker'!N8) | I8: =IF('Purchase Order - Order Tracker'!A8="","",'Purchase Order - Order Tracker'!O8)
A9: =IF('Purchase Order - Order Tracker'!A9="","",'Purchase Order - Order Tracker'!A9) | B9: =IF('Purchase Order - Order Tracker'!A9="","",'Purchase Order - Order Tracker'!B9) | C9: =IF('Purchase Order - Order Tracker'!A9="","",'Purchase Order - Order Tracker'!C9) | D9: =IF('Purchase Order - Order Tracker'!A9="","",'Purchase Order - Order Tracker'!D9) | E9: =IF('Purchase Order - Order Tracker'!A9="","",'Purchase Order - Order Tracker'!H9) | F9: =IF('Purchase Order - Order Tracker'!A9="","",'Purchase Order - Order Tracker'!J9) | G9: =IF('Purchase Order - Order Tracker'!A9="","",'Purchase Order - Order Tracker'!K9) | H9: =IF('Purchase Order - Order Tracker'!A9="","",'Purchase Order - Order Tracker'!N9) | I9: =IF('Purchase Order - Order Tracker'!A9="","",'Purchase Order - Order Tracker'!O9)
A10: =IF('Purchase Order - Order Tracker'!A10="","",'Purchase Order - Order Tracker'!A10) | B10: =IF('Purchase Order - Order Tracker'!A10="","",'Purchase Order - Order Tracker'!B10) | C10: =IF('Purchase Order - Order Tracker'!A10="","",'Purchase Order - Order Tracker'!C10) | D10: =IF('Purchase Order - Order Tracker'!A10="","",'Purchase Order - Order Tracker'!D10) | E10: =IF('Purchase Order - Order Tracker'!A10="","",'Purchase Order - Order Tracker'!H10) | F10: =IF('Purchase Order - Order Tracker'!A10="","",'Purchase Order - Order Tracker'!J10) | G10: =IF('Purchase Order - Order Tracker'!A10="","",'Purchase Order - Order Tracker'!K10) | H10: =IF('Purchase Order - Order Tracker'!A10="","",'Purchase Order - Order Tracker'!N10) | I10: =IF('Purchase Order - Order Tracker'!A10="","",'Purchase Order - Order Tracker'!O10)
A11: =IF('Purchase Order - Order Tracker'!A11="","",'Purchase Order - Order Tracker'!A11) | B11: =IF('Purchase Order - Order Tracker'!A11="","",'Purchase Order - Order Tracker'!B11) | C11: =IF('Purchase Order - Order Tracker'!A11="","",'Purchase Order - Order Tracker'!C11) | D11: =IF('Purchase Order - Order Tracker'!A11="","",'Purchase Order - Order Tracker'!D11) | E11: =IF('Purchase Order - Order Tracker'!A11="","",'Purchase Order - Order Tracker'!H11) | F11: =IF('Purchase Order - Order Tracker'!A11="","",'Purchase Order - Order Tracker'!J11) | G11: =IF('Purchase Order - Order Tracker'!A11="","",'Purchase Order - Order Tracker'!K11) | H11: =IF('Purchase Order - Order Tracker'!A11="","",'Purchase Order - Order Tracker'!N11) | I11: =IF('Purchase Order - Order Tracker'!A11="","",'Purchase Order - Order Tracker'!O11)
A12: =IF('Purchase Order - Order Tracker'!A12="","",'Purchase Order - Order Tracker'!A12) | B12: =IF('Purchase Order - Order Tracker'!A12="","",'Purchase Order - Order Tracker'!B12) | C12: =IF('Purchase Order - Order Tracker'!A12="","",'Purchase Order - Order Tracker'!C12) | D12: =IF('Purchase Order - Order Tracker'!A12="","",'Purchase Order - Order Tracker'!D12) | E12: =IF('Purchase Order - Order Tracker'!A12="","",'Purchase Order - Order Tracker'!H12) | F12: =IF('Purchase Order - Order Tracker'!A12="","",'Purchase Order - Order Tracker'!J12) | G12: =IF('Purchase Order - Order Tracker'!A12="","",'Purchase Order - Order Tracker'!K12) | H12: =IF('Purchase Order - Order Tracker'!A12="","",'Purchase Order - Order Tracker'!N12) | I12: =IF('Purchase Order - Order Tracker'!A12="","",'Purchase Order - Order Tracker'!O12)
A13: =IF('Purchase Order - Order Tracker'!A13="","",'Purchase Order - Order Tracker'!A13) | B13: =IF('Purchase Order - Order Tracker'!A13="","",'Purchase Order - Order Tracker'!B13) | C13: =IF('Purchase Order - Order Tracker'!A13="","",'Purchase Order - Order Tracker'!C13) | D13: =IF('Purchase Order - Order Tracker'!A13="","",'Purchase Order - Order Tracker'!D13) | E13: =IF('Purchase Order - Order Tracker'!A13="","",'Purchase Order - Order Tracker'!H13) | F13: =IF('Purchase Order - Order Tracker'!A13="","",'Purchase Order - Order Tracker'!J13) | G13: =IF('Purchase Order - Order Tracker'!A13="","",'Purchase Order - Order Tracker'!K13) | H13: =IF('Purchase Order - Order Tracker'!A13="","",'Purchase Order - Order Tracker'!N13) | I13: =IF('Purchase Order - Order Tracker'!A13="","",'Purchase Order - Order Tracker'!O13)
A14: =IF('Purchase Order - Order Tracker'!A14="","",'Purchase Order - Order Tracker'!A14) | B14: =IF('Purchase Order - Order Tracker'!A14="","",'Purchase Order - Order Tracker'!B14) | C14: =IF('Purchase Order - Order Tracker'!A14="","",'Purchase Order - Order Tracker'!C14) | D14: =IF('Purchase Order - Order Tracker'!A14="","",'Purchase Order - Order Tracker'!D14) | E14: =IF('Purchase Order - Order Tracker'!A14="","",'Purchase Order - Order Tracker'!H14) | F14: =IF('Purchase Order - Order Tracker'!A14="","",'Purchase Order - Order Tracker'!J14) | G14: =IF('Purchase Order - Order Tracker'!A14="","",'Purchase Order - Order Tracker'!K14) | H14: =IF('Purchase Order - Order Tracker'!A14="","",'Purchase Order - Order Tracker'!N14) | I14: =IF('Purchase Order - Order Tracker'!A14="","",'Purchase Order - Order Tracker'!O14)
A15: =IF('Purchase Order - Order Tracker'!A15="","",'Purchase Order - Order Tracker'!A15) | B15: =IF('Purchase Order - Order Tracker'!A15="","",'Purchase Order - Order Tracker'!B15) | C15: =IF('Purchase Order - Order Tracker'!A15="","",'Purchase Order - Order Tracker'!C15) | D15: =IF('Purchase Order - Order Tracker'!A15="","",'Purchase Order - Order Tracker'!D15) | E15: =IF('Purchase Order - Order Tracker'!A15="","",'Purchase Order - Order Tracker'!H15) | F15: =IF('Purchase Order - Order Tracker'!A15="","",'Purchase Order - Order Tracker'!J15) | G15: =IF('Purchase Order - Order Tracker'!A15="","",'Purchase Order - Order Tracker'!K15) | H15: =IF('Purchase Order - Order Tracker'!A15="","",'Purchase Order - Order Tracker'!N15) | I15: =IF('Purchase Order - Order Tracker'!A15="","",'Purchase Order - Order Tracker'!O15)
A16: =IF('Purchase Order - Order Tracker'!A16="","",'Purchase Order - Order Tracker'!A16) | B16: =IF('Purchase Order - Order Tracker'!A16="","",'Purchase Order - Order Tracker'!B16) | C16: =IF('Purchase Order - Order Tracker'!A16="","",'Purchase Order - Order Tracker'!C16) | D16: =IF('Purchase Order - Order Tracker'!A16="","",'Purchase Order - Order Tracker'!D16) | E16: =IF('Purchase Order - Order Tracker'!A16="","",'Purchase Order - Order Tracker'!H16) | F16: =IF('Purchase Order - Order Tracker'!A16="","",'Purchase Order - Order Tracker'!J16) | G16: =IF('Purchase Order - Order Tracker'!A16="","",'Purchase Order - Order Tracker'!K16) | H16: =IF('Purchase Order - Order Tracker'!A16="","",'Purchase Order - Order Tracker'!N16) | I16: =IF('Purchase Order - Order Tracker'!A16="","",'Purchase Order - Order Tracker'!O16)
A17: =IF('Purchase Order - Order Tracker'!A17="","",'Purchase Order - Order Tracker'!A17) | B17: =IF('Purchase Order - Order Tracker'!A17="","",'Purchase Order - Order Tracker'!B17) | C17: =IF('Purchase Order - Order Tracker'!A17="","",'Purchase Order - Order Tracker'!C17) | D17: =IF('Purchase Order - Order Tracker'!A17="","",'Purchase Order - Order Tracker'!D17) | E17: =IF('Purchase Order - Order Tracker'!A17="","",'Purchase Order - Order Tracker'!H17) | F17: =IF('Purchase Order - Order Tracker'!A17="","",'Purchase Order - Order Tracker'!J17) | G17: =IF('Purchase Order - Order Tracker'!A17="","",'Purchase Order - Order Tracker'!K17) | H17: =IF('Purchase Order - Order Tracker'!A17="","",'Purchase Order - Order Tracker'!N17) | I17: =IF('Purchase Order - Order Tracker'!A17="","",'Purchase Order - Order Tracker'!O17)
A18: =IF('Purchase Order - Order Tracker'!A18="","",'Purchase Order - Order Tracker'!A18) | B18: =IF('Purchase Order - Order Tracker'!A18="","",'Purchase Order - Order Tracker'!B18) | C18: =IF('Purchase Order - Order Tracker'!A18="","",'Purchase Order - Order Tracker'!C18) | D18: =IF('Purchase Order - Order Tracker'!A18="","",'Purchase Order - Order Tracker'!D18) | E18: =IF('Purchase Order - Order Tracker'!A18="","",'Purchase Order - Order Tracker'!H18) | F18: =IF('Purchase Order - Order Tracker'!A18="","",'Purchase Order - Order Tracker'!J18) | G18: =IF('Purchase Order - Order Tracker'!A18="","",'Purchase Order - Order Tracker'!K18) | H18: =IF('Purchase Order - Order Tracker'!A18="","",'Purchase Order - Order Tracker'!N18) | I18: =IF('Purchase Order - Order Tracker'!A18="","",'Purchase Order - Order Tracker'!O18)
... A106: =IF('Purchase Order - Order Tracker'!A106="","",'Purchase Order - Order Tracker'!A106) | B106: =IF('Purchase Order - Order Tracker'!A106="","",'Purchase Order - Order Tracker'!B106) | C106: =IF('Purchase Order - Order Tracker'!A106="","",'Purchase Order - Order Tracker'!C106) | D106: =IF('Purchase Order - Order Tracker'!A106="","",'Purchase Order - Order Tracker'!D106) | E106: =IF('Purchase Order - Order Tracker'!A106="","",'Purchase Order - Order Tracker'!H106) | F106: =IF('Purchase Order - Order Tracker'!A106="","",'Purchase Order - Order Tracker'!J106) | G106: =IF('Purchase Order - Order Tracker'!A106="","",'Purchase Order - Order Tracker'!K106) | H106: =IF('Purchase Order - Order Tracker'!A106="","",'Purchase Order - Order Tracker'!N106) | I106: =IF('Purchase Order - Order Tracker'!A106="","",'Purchase Order - Order Tracker'!O106)

Sheet Installation Checklist
A1: Installation Checklist
A3: Printable receiving and installation checklist linked to Delivery & Installation Tracker.
A4: Printable report view • linked to the project tracker. Filter rows before printing or sharing.
A6: Item | B6: Room | C6: Vendor | D6: Expected delivery | E6: Delivery status | F6: Damage check | G6: Install date | H6: Installer | I6: Installation status | J6: Punch list notes
A7: =IF('Delivery & Installation Tracker'!A7="","",'Delivery & Installation Tracker'!A7) | B7: =IF('Delivery & Installation Tracker'!A7="","",'Delivery & Installation Tracker'!B7) | C7: =IF('Delivery & Installation Tracker'!A7="","",'Delivery & Installation Tracker'!C7) | D7: =IF('Delivery & Installation Tracker'!A7="","",'Delivery & Installation Tracker'!E7) | E7: =IF('Delivery & Installation Tracker'!A7="","",'Delivery & Installation Tracker'!G7) | F7: =IF('Delivery & Installation Tracker'!A7="","",'Delivery & Installation Tracker'!I7) | G7: =IF('Delivery & Installation Tracker'!A7="","",'Delivery & Installation Tracker'!L7) | H7: =IF('Delivery & Installation Tracker'!A7="","",'Delivery & Installation Tracker'!M7) | I7: =IF('Delivery & Installation Tracker'!A7="","",'Delivery & Installation Tracker'!N7) | J7: =IF('Delivery & Installation Tracker'!A7="","",'Delivery & Installation Tracker'!O7)
A8: =IF('Delivery & Installation Tracker'!A8="","",'Delivery & Installation Tracker'!A8) | B8: =IF('Delivery & Installation Tracker'!A8="","",'Delivery & Installation Tracker'!B8) | C8: =IF('Delivery & Installation Tracker'!A8="","",'Delivery & Installation Tracker'!C8) | D8: =IF('Delivery & Installation Tracker'!A8="","",'Delivery & Installation Tracker'!E8) | E8: =IF('Delivery & Installation Tracker'!A8="","",'Delivery & Installation Tracker'!G8) | F8: =IF('Delivery & Installation Tracker'!A8="","",'Delivery & Installation Tracker'!I8) | G8: =IF('Delivery & Installation Tracker'!A8="","",'Delivery & Installation Tracker'!L8) | H8: =IF('Delivery & Installation Tracker'!A8="","",'Delivery & Installation Tracker'!M8) | I8: =IF('Delivery & Installation Tracker'!A8="","",'Delivery & Installation Tracker'!N8) | J8: =IF('Delivery & Installation Tracker'!A8="","",'Delivery & Installation Tracker'!O8)
A9: =IF('Delivery & Installation Tracker'!A9="","",'Delivery & Installation Tracker'!A9) | B9: =IF('Delivery & Installation Tracker'!A9="","",'Delivery & Installation Tracker'!B9) | C9: =IF('Delivery & Installation Tracker'!A9="","",'Delivery & Installation Tracker'!C9) | D9: =IF('Delivery & Installation Tracker'!A9="","",'Delivery & Installation Tracker'!E9) | E9: =IF('Delivery & Installation Tracker'!A9="","",'Delivery & Installation Tracker'!G9) | F9: =IF('Delivery & Installation Tracker'!A9="","",'Delivery & Installation Tracker'!I9) | G9: =IF('Delivery & Installation Tracker'!A9="","",'Delivery & Installation Tracker'!L9) | H9: =IF('Delivery & Installation Tracker'!A9="","",'Delivery & Installation Tracker'!M9) | I9: =IF('Delivery & Installation Tracker'!A9="","",'Delivery & Installation Tracker'!N9) | J9: =IF('Delivery & Installation Tracker'!A9="","",'Delivery & Installation Tracker'!O9)
A10: =IF('Delivery & Installation Tracker'!A10="","",'Delivery & Installation Tracker'!A10) | B10: =IF('Delivery & Installation Tracker'!A10="","",'Delivery & Installation Tracker'!B10) | C10: =IF('Delivery & Installation Tracker'!A10="","",'Delivery & Installation Tracker'!C10) | D10: =IF('Delivery & Installation Tracker'!A10="","",'Delivery & Installation Tracker'!E10) | E10: =IF('Delivery & Installation Tracker'!A10="","",'Delivery & Installation Tracker'!G10) | F10: =IF('Delivery & Installation Tracker'!A10="","",'Delivery & Installation Tracker'!I10) | G10: =IF('Delivery & Installation Tracker'!A10="","",'Delivery & Installation Tracker'!L10) | H10: =IF('Delivery & Installation Tracker'!A10="","",'Delivery & Installation Tracker'!M10) | I10: =IF('Delivery & Installation Tracker'!A10="","",'Delivery & Installation Tracker'!N10) | J10: =IF('Delivery & Installation Tracker'!A10="","",'Delivery & Installation Tracker'!O10)
A11: =IF('Delivery & Installation Tracker'!A11="","",'Delivery & Installation Tracker'!A11) | B11: =IF('Delivery & Installation Tracker'!A11="","",'Delivery & Installation Tracker'!B11) | C11: =IF('Delivery & Installation Tracker'!A11="","",'Delivery & Installation Tracker'!C11) | D11: =IF('Delivery & Installation Tracker'!A11="","",'Delivery & Installation Tracker'!E11) | E11: =IF('Delivery & Installation Tracker'!A11="","",'Delivery & Installation Tracker'!G11) | F11: =IF('Delivery & Installation Tracker'!A11="","",'Delivery & Installation Tracker'!I11) | G11: =IF('Delivery & Installation Tracker'!A11="","",'Delivery & Installation Tracker'!L11) | H11: =IF('Delivery & Installation Tracker'!A11="","",'Delivery & Installation Tracker'!M11) | I11: =IF('Delivery & Installation Tracker'!A11="","",'Delivery & Installation Tracker'!N11) | J11: =IF('Delivery & Installation Tracker'!A11="","",'Delivery & Installation Tracker'!O11)
A12: =IF('Delivery & Installation Tracker'!A12="","",'Delivery & Installation Tracker'!A12) | B12: =IF('Delivery & Installation Tracker'!A12="","",'Delivery & Installation Tracker'!B12) | C12: =IF('Delivery & Installation Tracker'!A12="","",'Delivery & Installation Tracker'!C12) | D12: =IF('Delivery & Installation Tracker'!A12="","",'Delivery & Installation Tracker'!E12) | E12: =IF('Delivery & Installation Tracker'!A12="","",'Delivery & Installation Tracker'!G12) | F12: =IF('Delivery & Installation Tracker'!A12="","",'Delivery & Installation Tracker'!I12) | G12: =IF('Delivery & Installation Tracker'!A12="","",'Delivery & Installation Tracker'!L12) | H12: =IF('Delivery & Installation Tracker'!A12="","",'Delivery & Installation Tracker'!M12) | I12: =IF('Delivery & Installation Tracker'!A12="","",'Delivery & Installation Tracker'!N12) | J12: =IF('Delivery & Installation Tracker'!A12="","",'Delivery & Installation Tracker'!O12)
A13: =IF('Delivery & Installation Tracker'!A13="","",'Delivery & Installation Tracker'!A13) | B13: =IF('Delivery & Installation Tracker'!A13="","",'Delivery & Installation Tracker'!B13) | C13: =IF('Delivery & Installation Tracker'!A13="","",'Delivery & Installation Tracker'!C13) | D13: =IF('Delivery & Installation Tracker'!A13="","",'Delivery & Installation Tracker'!E13) | E13: =IF('Delivery & Installation Tracker'!A13="","",'Delivery & Installation Tracker'!G13) | F13: =IF('Delivery & Installation Tracker'!A13="","",'Delivery & Installation Tracker'!I13) | G13: =IF('Delivery & Installation Tracker'!A13="","",'Delivery & Installation Tracker'!L13) | H13: =IF('Delivery & Installation Tracker'!A13="","",'Delivery & Installation Tracker'!M13) | I13: =IF('Delivery & Installation Tracker'!A13="","",'Delivery & Installation Tracker'!N13) | J13: =IF('Delivery & Installation Tracker'!A13="","",'Delivery & Installation Tracker'!O13)
A14: =IF('Delivery & Installation Tracker'!A14="","",'Delivery & Installation Tracker'!A14) | B14: =IF('Delivery & Installation Tracker'!A14="","",'Delivery & Installation Tracker'!B14) | C14: =IF('Delivery & Installation Tracker'!A14="","",'Delivery & Installation Tracker'!C14) | D14: =IF('Delivery & Installation Tracker'!A14="","",'Delivery & Installation Tracker'!E14) | E14: =IF('Delivery & Installation Tracker'!A14="","",'Delivery & Installation Tracker'!G14) | F14: =IF('Delivery & Installation Tracker'!A14="","",'Delivery & Installation Tracker'!I14) | G14: =IF('Delivery & Installation Tracker'!A14="","",'Delivery & Installation Tracker'!L14) | H14: =IF('Delivery & Installation Tracker'!A14="","",'Delivery & Installation Tracker'!M14) | I14: =IF('Delivery & Installation Tracker'!A14="","",'Delivery & Installation Tracker'!N14) | J14: =IF('Delivery & Installation Tracker'!A14="","",'Delivery & Installation Tracker'!O14)
A15: =IF('Delivery & Installation Tracker'!A15="","",'Delivery & Installation Tracker'!A15) | B15: =IF('Delivery & Installation Tracker'!A15="","",'Delivery & Installation Tracker'!B15) | C15: =IF('Delivery & Installation Tracker'!A15="","",'Delivery & Installation Tracker'!C15) | D15: =IF('Delivery & Installation Tracker'!A15="","",'Delivery & Installation Tracker'!E15) | E15: =IF('Delivery & Installation Tracker'!A15="","",'Delivery & Installation Tracker'!G15) | F15: =IF('Delivery & Installation Tracker'!A15="","",'Delivery & Installation Tracker'!I15) | G15: =IF('Delivery & Installation Tracker'!A15="","",'Delivery & Installation Tracker'!L15) | H15: =IF('Delivery & Installation Tracker'!A15="","",'Delivery & Installation Tracker'!M15) | I15: =IF('Delivery & Installation Tracker'!A15="","",'Delivery & Installation Tracker'!N15) | J15: =IF('Delivery & Installation Tracker'!A15="","",'Delivery & Installation Tracker'!O15)
A16: =IF('Delivery & Installation Tracker'!A16="","",'Delivery & Installation Tracker'!A16) | B16: =IF('Delivery & Installation Tracker'!A16="","",'Delivery & Installation Tracker'!B16) | C16: =IF('Delivery & Installation Tracker'!A16="","",'Delivery & Installation Tracker'!C16) | D16: =IF('Delivery & Installation Tracker'!A16="","",'Delivery & Installation Tracker'!E16) | E16: =IF('Delivery & Installation Tracker'!A16="","",'Delivery & Installation Tracker'!G16) | F16: =IF('Delivery & Installation Tracker'!A16="","",'Delivery & Installation Tracker'!I16) | G16: =IF('Delivery & Installation Tracker'!A16="","",'Delivery & Installation Tracker'!L16) | H16: =IF('Delivery & Installation Tracker'!A16="","",'Delivery & Installation Tracker'!M16) | I16: =IF('Delivery & Installation Tracker'!A16="","",'Delivery & Installation Tracker'!N16) | J16: =IF('Delivery & Installation Tracker'!A16="","",'Delivery & Installation Tracker'!O16)
A17: =IF('Delivery & Installation Tracker'!A17="","",'Delivery & Installation Tracker'!A17) | B17: =IF('Delivery & Installation Tracker'!A17="","",'Delivery & Installation Tracker'!B17) | C17: =IF('Delivery & Installation Tracker'!A17="","",'Delivery & Installation Tracker'!C17) | D17: =IF('Delivery & Installation Tracker'!A17="","",'Delivery & Installation Tracker'!E17) | E17: =IF('Delivery & Installation Tracker'!A17="","",'Delivery & Installation Tracker'!G17) | F17: =IF('Delivery & Installation Tracker'!A17="","",'Delivery & Installation Tracker'!I17) | G17: =IF('Delivery & Installation Tracker'!A17="","",'Delivery & Installation Tracker'!L17) | H17: =IF('Delivery & Installation Tracker'!A17="","",'Delivery & Installation Tracker'!M17) | I17: =IF('Delivery & Installation Tracker'!A17="","",'Delivery & Installation Tracker'!N17) | J17: =IF('Delivery & Installation Tracker'!A17="","",'Delivery & Installation Tracker'!O17)
A18: =IF('Delivery & Installation Tracker'!A18="","",'Delivery & Installation Tracker'!A18) | B18: =IF('Delivery & Installation Tracker'!A18="","",'Delivery & Installation Tracker'!B18) | C18: =IF('Delivery & Installation Tracker'!A18="","",'Delivery & Installation Tracker'!C18) | D18: =IF('Delivery & Installation Tracker'!A18="","",'Delivery & Installation Tracker'!E18) | E18: =IF('Delivery & Installation Tracker'!A18="","",'Delivery & Installation Tracker'!G18) | F18: =IF('Delivery & Installation Tracker'!A18="","",'Delivery & Installation Tracker'!I18) | G18: =IF('Delivery & Installation Tracker'!A18="","",'Delivery & Installation Tracker'!L18) | H18: =IF('Delivery & Installation Tracker'!A18="","",'Delivery & Installation Tracker'!M18) | I18: =IF('Delivery & Installation Tracker'!A18="","",'Delivery & Installation Tracker'!N18) | J18: =IF('Delivery & Installation Tracker'!A18="","",'Delivery & Installation Tracker'!O18)
... A106: =IF('Delivery & Installation Tracker'!A106="","",'Delivery & Installation Tracker'!A106) | B106: =IF('Delivery & Installation Tracker'!A106="","",'Delivery & Installation Tracker'!B106) | C106: =IF('Delivery & Installation Tracker'!A106="","",'Delivery & Installation Tracker'!C106) | D106: =IF('Delivery & Installation Tracker'!A106="","",'Delivery & Installation Tracker'!E106) | E106: =IF('Delivery & Installation Tracker'!A106="","",'Delivery & Installation Tracker'!G106) | F106: =IF('Delivery & Installation Tracker'!A106="","",'Delivery & Installation Tracker'!I106) | G106: =IF('Delivery & Installation Tracker'!A106="","",'Delivery & Installation Tracker'!L106) | H106: =IF('Delivery & Installation Tracker'!A106="","",'Delivery & Installation Tracker'!M106) | I106: =IF('Delivery & Installation Tracker'!A106="","",'Delivery & Installation Tracker'!N106) | J106: =IF('Delivery & Installation Tracker'!A106="","",'Delivery & Installation Tracker'!O106)

Sheet Final Punch List
A1: Final Punch List
A3: Printable closeout checklist for final walkthrough, installation corrections, and handover.
A4: Printable report view • linked to the project tracker. Filter rows before printing or sharing.
A6: Punch-list item | B6: Room | C6: Due date | D6: Assigned to | E6: Status | F6: Notes

Sheet Lists & Helpers
A1: ProjectTypes | B1: ProjectStatuses | C1: YesNo | D1: BillingMethods | E1: RoomTypes | F1: DesignStatuses | G1: PriorityLevels | H1: FFECategories | I1: OrderStatuses | J1: ApprovalStatuses | K1: DeliveryStatuses | L1: InstallStatuses | M1: FixtureTypes | N1: FinishTypes | O1: SurfaceApplications | P1: PreferredOptions | Q1: VendorTypes | R1: POStatuses | S1: DamageChecks | T1: TimelinePhases | U1: TaskStatuses | V1: MeasurementTypes | W1: Trades | X1: PaymentStatuses | Y1: PaymentMethods | Z1: MeetingTypes | AA1: TaskCategories | AB1: BudgetCategories | AC1: ApprovalTypes
A2: Residential | B2: Planning | C2: Yes | D2: Flat fee | E2: Living room | F2: Not started | G2: Low | H2: Sofa | I2: Not ordered | J2: Not sent | K2: Not shipped | L2: Not scheduled | M2: Lighting | N2: Paint | O2: Wall | P2: Option 1 | Q2: Furniture | R2: Not ordered | S2: Not checked | T2: Consultation | U2: Not started | V2: Room | W2: General contractor | X2: Draft | Y2: ACH | Z2: Client consultation | AA2: Design | AB2: Furniture | AC2: Furniture
A3: Commercial | B3: In progress | C3: No | D3: Hourly | E3: Bedroom | F3: Concept | G3: Medium | H3: Chair | I3: Sourcing | J3: Sent | K3: Shipped | L3: Scheduled | M3: Faucet | N3: Wallpaper | O3: Ceiling | P3: Option 2 | Q3: Lighting | R3: Ordered | S3: Good condition | T3: Measurements | U3: In progress | V3: Wall | W3: Painter | X3: Sent | Y3: Check | Z3: Vendor meeting | AA3: Sourcing | AB3: Lighting | AC3: Finish
A4: Office | B4: On hold | D4: Percentage | E4: Kitchen | F4: Sourcing | G4: High | H4: Table | I4: Option selected | J4: Approved | K4: In transit | L4: In progress | M4: Sink | N4: Flooring | O4: Floor | P4: Option 3 | Q4: Fabric | R4: Confirmed | S4: Damaged | T4: Concept design | U4: Waiting on client | V4: Window | W4: Electrician | X4: Paid | Y4: Credit card | Z4: Site visit | AA4: Client | AB4: Rugs | AC4: Layout
A5: Retail | B5: Complete | D5: Hybrid | E5: Bathroom | F5: Client review | G5: Urgent | H5: Bed | I5: Client review | J5: Revisions requested | K5: Delivered | L5: Installed | M5: Shower fixture | N5: Tile | O5: Cabinet | P5: Custom | Q5: Flooring | R5: In production | S5: Missing item | T5: Sourcing | U5: Waiting on vendor | V5: Door | W5: Plumber | X5: Partially paid | Y5: Cash | Z5: Installation meeting | AA5: Vendor | AB5: Decor | AC5: Color palette
A6: Hospitality | B6: Archived | E6: Dining room | F6: Approved | H6: Rug | I6: Approved | J6: Rejected | K6: Delayed | L6: Punch list | M6: Tub | N6: Countertop | O6: Countertop | P6: Not selected | Q6: Tile | R6: Shipped | S6: Wrong item | T6: Client approval | U6: Complete | V6: Cabinet | W6: Flooring installer | X6: Overdue | Y6: Wire | Z6: Contractor meeting | AA6: Purchasing | AB6: Artwork | AC6: Budget
