Workbook

Sheet Instructions + Setup
A1: 🧁 Cottage Bakery v4 — Donation Stand | C1: Free products + donations tracking (same layout as the Enhanced version)
A3: Customer Review Improvements: Fixed missing formulas, room for more than 1 recipe, grams/lbs/ml/oz/tsp/tbsp conversion, overhead monthly tab, startup costs with break-even graphic
A4: Password for formulas: premium | Yellow cells unlocked | White locked
A6: 📌 HOW IT WORKS v4
A7: Step | B7: Action | C7: Time
A8: 1 | B8: Edit Business Setup yellow cells B15-B26 | C8: 2 min
A9: 2 | B9: Add ingredients in Ingredients + Stock - set unit, cost, stock | C9: 5 min
A10: 3 | B10: Use Unit Conversion tab as reference for tsp/tbsp/cup conversions | C10: 1 min
A11: 4 | B11: Add recipes in Recipe Library (up to 50 recipes) or use Recipe Calculator for 3 recipes at once | C11: 10 min
A12: 5 | B12: Add monthly fixed costs in Overhead tab - see hourly overhead rate auto | C12: 5 min
A13: 6 | B13: Add one-time startup costs in Startup Costs tab - see break-even months & chart auto | C13: 5 min
A14: 7 | B14: Set products to $0 (free) in Product List — cost per item still shows | C14: 5 min
A15: 8 | B15: Log donations in Bookkeeping (Category = Donations) — check Dashboard | C15: Daily
A16: ⚙️ BUSINESS SETUP
A17: Setting | B17: Your Value | C17: Help | D17: Used In
A18: Bakery Name | B18: Rose & Rye Cottage Bakery | C18: Dashboard header | D18: All
A19: Owner | B19: Jane Miller
A20: Currency | B20: $
A21: Sales Tax % | B21: 8.5 | C21: For pricing | D21: Recipe + Bookkeeping
A22: Hourly Labor Rate | B22: 22 | C22: Your time $/hr | D22: Recipe
A23: Overhead % (auto from Overhead tab) | B23: 15 | C23: Manual %, or copy Overhead Expenses!B28 for auto | D23: Recipe
A24: Waste % | B24: 5 | C24: Failed batches | D24: Recipe
A25: Packaging Default $ | B25: 0.85 | C25: Per unit | D25: Recipe
A26: Target Margin % | B26: 70 | C26: Goal margin | D26: Recipe
A27: Fiscal Year Start | B27: 46023 | C27: YTD | D27: Dashboard
A28: Market Hourly Goal $ | B28: 40 | C28: Worth It? | D28: Markets
A29: Monthly Working Hours | B29: 80 | C29: For overhead rate calc | D29: Overhead
A30: Expected Monthly Orders | B30: 100 | C30: For overhead per unit | D30: Overhead
A32: 📦 TABS IN v4
A33: 1 | B33: Dashboard | C33: Net profit, revenue, expenses, open orders, trends, low stock
A34: 2 | B34: Ingredients + Stock | C34: Category, unit, pkg cost, cost/unit, stock, value, status
A35: 3 | B35: Unit Conversion | C35: Reference: g/kg/oz/lb/ml/L/tsp/tbsp/cup conversion factors to base
A36: 4 | B36: Recipe Library | C36: 50 recipes capacity, ingredients database long format, total cost auto SUMIF
A37: 5 | B37: Recipe Calculator | C37: 3 recipes at once, unit conversion handling, fixed missing formulas
A38: 6 | B38: Product List | C38: Linked to Recipe Library cost, profit margin
A39: 7 | B39: Overhead Expenses | C39: NEW: Monthly fixed costs rent/utilities/insurance, hourly rate, per unit
A40: 8 | B40: Startup Costs | C40: NEW: One-time equipment, break-even months =Startup/Monthly Profit + chart
A41: 9 | B41: Orders | C41: Orders tracking
A42: 10 | B42: Bookkeeping | C42: Income/expenses
A43: 11 | B43: Markets & Events | C43: Markets ROI
...

Sheet Unit Conversion
A1: Unit Conversion Reference - For tsp/tbsp/cup etc
A2: Recipe may use tsp/tbsp/cup, stock may be in g/ml. This table converts between units. Only same category (Weight/Volume/Count) converts directly. Weight to Volume needs density note.
A4: Unit | B4: Category | C4: Base Unit | D4: Factor to Base | E4: Example | F4: Notes | H4: All Units List for Dropdown
A5: g | B5: Weight | C5: g | D5: 1 | E5: 1g = 1g | F5: Base weight | H5: g
A6: kg | B6: Weight | C6: g | D6: 1000 | E6: 1kg = 1000g | H6: kg
A7: mg | B7: Weight | C7: g | D7: 0.001 | E7: 1000mg = 1g | H7: mg
A8: oz | B8: Weight | C8: g | D8: 28.3495 | E8: 1oz = 28.3495g | F8: Weight ounce | H8: oz
A9: lb | B9: Weight | C9: g | D9: 453.592 | E9: 1lb = 453.592g | F9: Pound | H9: lb
A10: ml | B10: Volume | C10: ml | D10: 1 | E10: 1ml = 1ml | F10: Base volume | H10: ml
A11: L | B11: Volume | C11: ml | D11: 1000 | E11: 1L = 1000ml | H11: L
A12: tsp | B12: Volume | C12: ml | D12: 4.92892 | E12: 1 tsp = 4.92892ml | F12: Teaspoon | H12: tsp
A13: tbsp | B13: Volume | C13: ml | D13: 14.7868 | E13: 1 tbsp = 3 tsp = 14.7868ml | F13: Tablespoon | H13: tbsp
A14: cup | B14: Volume | C14: ml | D14: 236.588 | E14: 1 cup = 16 tbsp = 236.588ml | F14: US cup | H14: cup
A15: fl oz | B15: Volume | C15: ml | D15: 29.5735 | E15: 1 fl oz = 2 tbsp | F15: Fluid ounce | H15: fl oz
A16: pint | B16: Volume | C16: ml | D16: 473.176 | E16: 1 pint = 2 cups | H16: pint
A17: quart | B17: Volume | C17: ml | D17: 946.353 | E17: 1 quart = 2 pints | H17: quart
A18: gallon | B18: Volume | C18: ml | D18: 3785.41 | E18: 1 gallon = 4 quarts | H18: gallon
A19: pcs | B19: Count | C19: pcs | D19: 1 | E19: 1 pcs | F19: Base count | H19: pcs
A20: dozen | B20: Count | C20: pcs | D20: 12 | E20: 1 dozen = 12 pcs | H20: dozen
A21: tsp | B21: Volume | C21: ml | D21: 4.92892 | E21: Duplicate for search
A22: tbsp | B22: Volume | C22: ml | D22: 14.7868 | E22: Duplicate
A24: How Conversion Works in Recipe Calculator
A25: Converted Qty in Stock Unit = Recipe Qty * (Recipe Unit Factor / Stock Unit Factor) IF same category
A26: Example: Recipe needs 2 tsp vanilla, stock is ml, factor tsp=4.92892, factor ml=1, Converted =2*4.92892/1=9.85784ml, Cost =9.85784*Cost per ml
A27: If Weight (g) vs Volume (ml) mismatch: Shows WARNING - enter weight equivalent manually. For flour, 1 cup ≈ 120-150g depending on type - use kitchen scale for accuracy.

Sheet Ingredients + Stock
A1: ID | B1: Ingredient Name | C1: Category | D1: Unit (Stock Unit) | E1: Pkg Size | F1: Pkg Cost $ | G1: Cost/Unit $ | H1: Current Stock | I1: Min Alert | J1: Stock Value $ | K1: Status | L1: Supplier | M1: Last Purchased | N1: Reorder Qty | O1: Expiry | P1: Location | Q1: Notes | R1: Base Category
A2: 1 | B2: Bread Flour | C2: Flour | D2: g | E2: 2268 | F2: 6.99 | G2: =IF(E2=0,0,F2/E2) | H2: 2500 | I2: 1000 | J2: =H2*G2 | K2: =IF(H2=0,"OUT",IF(H2<=I2,"LOW","OK")) | L2: King Arthur | M2: 46235 | N2: 4536 | O2: 46600 | P2: Pantry A | Q2: 5 lb bag | R2: =IFERROR(VLOOKUP(D2,'Unit Conversion'!A:B,2,FALSE),"Weight")
A3: 2 | B3: All-Purpose Flour | C3: Flour | D3: g | E3: 2268 | F3: 4.99 | G3: =IF(E3=0,0,F3/E3) | H3: 3000 | I3: 1000 | J3: =H3*G3 | K3: =IF(H3=0,"OUT",IF(H3<=I3,"LOW","OK")) | L3: Gold Medal | M3: 46239 | N3: 4536 | O3: 46419 | P3: Pantry A | Q3: 5 lb bag | R3: =IFERROR(VLOOKUP(D3,'Unit Conversion'!A:B,2,FALSE),"Weight")
A4: 3 | B4: Sugar | C4: Sugar | D4: g | E4: 1814 | F4: 3.29 | G4: =IF(E4=0,0,F4/E4) | H4: 800 | I4: 500 | J4: =H4*G4 | K4: =IF(H4=0,"OUT",IF(H4<=I4,"LOW","OK")) | L4: Domino | M4: 46242 | N4: 1814 | O4: 46600 | P4: Pantry A | Q4: 4 lb bag | R4: =IFERROR(VLOOKUP(D4,'Unit Conversion'!A:B,2,FALSE),"Weight")
A5: 4 | B5: Brown Sugar | C5: Sugar | D5: g | E5: 907 | F5: 2.79 | G5: =IF(E5=0,0,F5/E5) | H5: 400 | I5: 250 | J5: =H5*G5 | K5: =IF(H5=0,"OUT",IF(H5<=I5,"LOW","OK")) | L5: Domino | M5: 46242 | N5: 907 | O5: 46600 | P5: Pantry A | Q5: 2 lb bag | R5: =IFERROR(VLOOKUP(D5,'Unit Conversion'!A:B,2,FALSE),"Weight")
A6: 5 | B6: Butter | C6: Dairy | D6: g | E6: 454 | F6: 4.49 | G6: =IF(E6=0,0,F6/E6) | H6: 300 | I6: 200 | J6: =H6*G6 | K6: =IF(H6=0,"OUT",IF(H6<=I6,"LOW","OK")) | L6: Land O'Lakes | M6: 46254 | N6: 908 | O6: 46296 | P6: Fridge | Q6: 1 lb, unsalted | R6: =IFERROR(VLOOKUP(D6,'Unit Conversion'!A:B,2,FALSE),"Weight")
A7: 6 | B7: Eggs | C7: Dairy | D7: pcs | E7: 12 | F7: 3.99 | G7: =IF(E7=0,0,F7/E7) | H7: 18 | I7: 12 | J7: =H7*G7 | K7: =IF(H7=0,"OUT",IF(H7<=I7,"LOW","OK")) | L7: Eggland's Best | M7: 46256 | N7: 24 | O7: 46285 | P7: Fridge | Q7: Large, cage-free | R7: =IFERROR(VLOOKUP(D7,'Unit Conversion'!A:B,2,FALSE),"Weight")
A8: 7 | B8: Vanilla Extract | C8: Flavoring | D8: ml | E8: 59 | F8: 12.99 | G8: =IF(E8=0,0,F8/E8) | H8: 80 | I8: 50 | J8: =H8*G8 | K8: =IF(H8=0,"OUT",IF(H8<=I8,"LOW","OK")) | L8: Nielsen-Massey | M8: 46213 | N8: 118 | O8: 46935 | P8: Rack | Q8: Pure, 2 fl oz | R8: =IFERROR(VLOOKUP(D8,'Unit Conversion'!A:B,2,FALSE),"Weight")
A9: 8 | B9: Chocolate Chips | C9: Chocolate | D9: g | E9: 340 | F9: 4.49 | G9: =IF(E9=0,0,F9/E9) | H9: 1200 | I9: 400 | J9: =H9*G9 | K9: =IF(H9=0,"OUT",IF(H9<=I9,"LOW","OK")) | L9: Nestlé Toll House | M9: 46246 | N9: 680 | O9: 46600 | P9: Pantry B | Q9: Semi-sweet, 12 oz | R9: =IFERROR(VLOOKUP(D9,'Unit Conversion'!A:B,2,FALSE),"Weight")
A10: 9 | B10: Cream Cheese | C10: Dairy | D10: g | E10: 226 | F10: 2.29 | G10: =IF(E10=0,0,F10/E10) | H10: 0 | I10: 250 | J10: =H10*G10 | K10: =IF(H10=0,"OUT",IF(H10<=I10,"LOW","OK")) | L10: Philadelphia | M10: 46249 | N10: 453 | O10: 46275 | P10: Fridge | Q10: 8 oz — OUT OF STOCK | R10: =IFERROR(VLOOKUP(D10,'Unit Conversion'!A:B,2,FALSE),"Weight")
A11: 10 | B11: Cinnamon | C11: Spice | D11: g | E11: 57 | F11: 4.29 | G11: =IF(E11=0,0,F11/E11) | H11: 45 | I11: 20 | J11: =H11*G11 | K11: =IF(H11=0,"OUT",IF(H11<=I11,"LOW","OK")) | L11: McCormick | M11: 46174 | N11: 57 | O11: 46905 | P11: Rack | Q11: Ground, 2 oz | R11: =IFERROR(VLOOKUP(D11,'Unit Conversion'!A:B,2,FALSE),"Weight")
A12: 11 | B12: Sourdough Starter | C12: Other | D12: g | E12: 500 | F12: 0.5 | G12: =IF(E12=0,0,F12/E12) | H12: 350 | I12: 100 | J12: =H12*G12 | K12: =IF(H12=0,"OUT",IF(H12<=I12,"LOW","OK")) | L12: Homemade | M12: 46262 | N12: 500 | P12: Fridge | Q12: Feed weekly | R12: =IFERROR(VLOOKUP(D12,'Unit Conversion'!A:B,2,FALSE),"Weight")
A13: 12 | B13: Heavy Cream | C13: Dairy | D13: ml | E13: 473 | F13: 3.99 | G13: =IF(E13=0,0,F13/E13) | H13: 100 | I13: 250 | J13: =H13*G13 | K13: =IF(H13=0,"OUT",IF(H13<=I13,"LOW","OK")) | L13: Organic Valley | M13: 46259 | N13: 946 | O13: 46280 | P13: Fridge | Q13: Pint — LOW STOCK | R13: =IFERROR(VLOOKUP(D13,'Unit Conversion'!A:B,2,FALSE),"Weight")
A14: 13 | B14: Olive Oil | C14: Oil | D14: ml | E14: 500 | F14: 8.99 | G14: =IF(E14=0,0,F14/E14) | H14: 200 | I14: 100 | J14: =H14*G14 | K14: =IF(H14=0,"OUT",IF(H14<=I14,"LOW","OK")) | L14: California Olive Ranch | M14: 46204 | N14: 500 | O14: 46569 | P14: Pantry A | Q14: Extra virgin | R14: =IFERROR(VLOOKUP(D14,'Unit Conversion'!A:B,2,FALSE),"Weight")
A15: 14 | B15: Salt | C15: Spice | D15: g | E15: 1361 | F15: 3.49 | G15: =IF(E15=0,0,F15/E15) | H15: 600 | I15: 200 | J15: =H15*G15 | K15: =IF(H15=0,"OUT",IF(H15<=I15,"LOW","OK")) | L15: Morton | M15: 46218 | N15: 1361 | O15: 46935 | P15: Pantry A | Q15: Kosher, 3 lb | R15: =IFERROR(VLOOKUP(D15,'Unit Conversion'!A:B,2,FALSE),"Weight")
A16: 15 | B16: Water | C16: Other | D16: ml | E16: 3785 | F16: 0.01 | G16: =IF(E16=0,0,F16/E16) | H16: 100000 | I16: 5000 | J16: =H16*G16 | K16: =IF(H16=0,"OUT",IF(H16<=I16,"LOW","OK")) | L16: Municipal | M16: 46262 | N16: 3785 | P16: Sink | Q16: Tap water | R16: =IFERROR(VLOOKUP(D16,'Unit Conversion'!A:B,2,FALSE),"Weight")
G17: =IF(E17=0,0,F17/E17) | J17: =H17*G17 | K17: =IF(H17="","",IF(H17=0,"OUT",IF(H17<=I17,"LOW","OK"))) | R17: =IF(D17="","",IFERROR(VLOOKUP(D17,'Unit Conversion'!A:B,2,FALSE),""))
G18: =IF(E18=0,0,F18/E18) | J18: =H18*G18 | K18: =IF(H18="","",IF(H18=0,"OUT",IF(H18<=I18,"LOW","OK"))) | R18: =IF(D18="","",IFERROR(VLOOKUP(D18,'Unit Conversion'!A:B,2,FALSE),""))
G19: =IF(E19=0,0,F19/E19) | J19: =H19*G19 | K19: =IF(H19="","",IF(H19=0,"OUT",IF(H19<=I19,"LOW","OK"))) | R19: =IF(D19="","",IFERROR(VLOOKUP(D19,'Unit Conversion'!A:B,2,FALSE),""))
G20: =IF(E20=0,0,F20/E20) | J20: =H20*G20 | K20: =IF(H20="","",IF(H20=0,"OUT",IF(H20<=I20,"LOW","OK"))) | R20: =IF(D20="","",IFERROR(VLOOKUP(D20,'Unit Conversion'!A:B,2,FALSE),""))
G21: =IF(E21=0,0,F21/E21) | J21: =H21*G21 | K21: =IF(H21="","",IF(H21=0,"OUT",IF(H21<=I21,"LOW","OK"))) | R21: =IF(D21="","",IFERROR(VLOOKUP(D21,'Unit Conversion'!A:B,2,FALSE),""))
G22: =IF(E22=0,0,F22/E22) | J22: =H22*G22 | K22: =IF(H22="","",IF(H22=0,"OUT",IF(H22<=I22,"LOW","OK"))) | R22: =IF(D22="","",IFERROR(VLOOKUP(D22,'Unit Conversion'!A:B,2,FALSE),""))
G23: =IF(E23=0,0,F23/E23) | J23: =H23*G23 | K23: =IF(H23="","",IF(H23=0,"OUT",IF(H23<=I23,"LOW","OK"))) | R23: =IF(D23="","",IFERROR(VLOOKUP(D23,'Unit Conversion'!A:B,2,FALSE),""))
G24: =IF(E24=0,0,F24/E24) | J24: =H24*G24 | K24: =IF(H24="","",IF(H24=0,"OUT",IF(H24<=I24,"LOW","OK"))) | R24: =IF(D24="","",IFERROR(VLOOKUP(D24,'Unit Conversion'!A:B,2,FALSE),""))
G25: =IF(E25=0,0,F25/E25) | J25: =H25*G25 | K25: =IF(H25="","",IF(H25=0,"OUT",IF(H25<=I25,"LOW","OK"))) | R25: =IF(D25="","",IFERROR(VLOOKUP(D25,'Unit Conversion'!A:B,2,FALSE),""))
G26: =IF(E26=0,0,F26/E26) | J26: =H26*G26 | K26: =IF(H26="","",IF(H26=0,"OUT",IF(H26<=I26,"LOW","OK"))) | R26: =IF(D26="","",IFERROR(VLOOKUP(D26,'Unit Conversion'!A:B,2,FALSE),""))
G27: =IF(E27=0,0,F27/E27) | J27: =H27*G27 | K27: =IF(H27="","",IF(H27=0,"OUT",IF(H27<=I27,"LOW","OK"))) | R27: =IF(D27="","",IFERROR(VLOOKUP(D27,'Unit Conversion'!A:B,2,FALSE),""))
G28: =IF(E28=0,0,F28/E28) | J28: =H28*G28 | K28: =IF(H28="","",IF(H28=0,"OUT",IF(H28<=I28,"LOW","OK"))) | R28: =IF(D28="","",IFERROR(VLOOKUP(D28,'Unit Conversion'!A:B,2,FALSE),""))
... G51: =IF(E51=0,0,F51/E51) | J51: =H51*G51 | K51: =IF(H51="","",IF(H51=0,"OUT",IF(H51<=I51,"LOW","OK"))) | R51: =IF(D51="","",IFERROR(VLOOKUP(D51,'Unit Conversion'!A:B,2,FALSE),""))
J52: Total Stock Value: | K52: =SUM(J2:J51)

Sheet Recipe Library
A1: Recipe Library - 50 Recipes Capacity (NEW - addresses review: room for more than 1 recipe)
A3: Recipe List - Master
A4: Recipe ID | B4: Recipe Name | C4: Category | D4: Batch Yield | E4: Portion Size | F4: Total Ingredient Cost $ | G4: Labor Hours | H4: Hourly Rate $ | I4: Labor Cost $ | J4: Packaging/Unit $ | K4: Packaging Total $ | L4: Overhead % | M4: Overhead $ | N4: Waste % | O4: Waste $ | P4: Other $ | Q4: Total Batch Cost $ | R4: Cost/Unit $ | S4: Suggested Price 2.5x $ | T4: Status | U4: Notes
A5: REC-001 | B5: Sourdough Loaf | C5: Bread | D5: 2 | E5: 900g loaf | F5: =SUMIF($W$65:$W$500,B5,$AG$65:$AG$500) | G5: 1.5 | H5: 22 | I5: =G5*H5 | J5: 0.85 | K5: =J5*D5 | L5: 15 | M5: =F5*L5/100 | N5: 5 | O5: =(F5+I5+K5+M5)*N5/100 | P5: 0 | Q5: =F5+I5+K5+M5+O5+P5 | R5: =IF(D5=0,0,Q5/D5) | S5: =R5*2.5 | T5: Active | U5: Best seller
A6: REC-002 | B6: Chocolate Chip Cookies | C6: Cookies | D6: 12 | E6: 1 cookie | F6: =SUMIF($W$65:$W$500,B6,$AG$65:$AG$500) | G6: 0.75 | H6: 22 | I6: =G6*H6 | J6: 0.25 | K6: =J6*D6 | L6: 15 | M6: =F6*L6/100 | N6: 5 | O6: =(F6+I6+K6+M6)*N6/100 | P6: 0 | Q6: =F6+I6+K6+M6+O6+P6 | R6: =IF(D6=0,0,Q6/D6) | S6: =R6*2.5 | T6: Active | U6: Dozen
A7: REC-003 | B7: Cinnamon Rolls 6-pack | C7: Pastry | D7: 6 | E7: 1 roll | F7: =SUMIF($W$65:$W$500,B7,$AG$65:$AG$500) | G7: 1 | H7: 22 | I7: =G7*H7 | J7: 0.5 | K7: =J7*D7 | L7: 15 | M7: =F7*L7/100 | N7: 5 | O7: =(F7+I7+K7+M7)*N7/100 | P7: 0 | Q7: =F7+I7+K7+M7+O7+P7 | R7: =IF(D7=0,0,Q7/D7) | S7: =R7*2.5 | T7: Active | U7: Weekend
A8: REC-004 | B8: Banana Bread | C8: Bread | D8: 1 | E8: 1 loaf | F8: =SUMIF($W$65:$W$500,B8,$AG$65:$AG$500) | G8: 0.5 | H8: 22 | I8: =G8*H8 | J8: 0.75 | K8: =J8*D8 | L8: 15 | M8: =F8*L8/100 | N8: 5 | O8: =(F8+I8+K8+M8)*N8/100 | P8: 0 | Q8: =F8+I8+K8+M8+O8+P8 | R8: =IF(D8=0,0,Q8/D8) | S8: =R8*2.5 | T8: Active
A9: REC-005 | B9: Vanilla Cupcakes 6 | C9: Cake | D9: 6 | E9: 1 cupcake | F9: =SUMIF($W$65:$W$500,B9,$AG$65:$AG$500) | G9: 1 | H9: 22 | I9: =G9*H9 | J9: 0.4 | K9: =J9*D9 | L9: 15 | M9: =F9*L9/100 | N9: 5 | O9: =(F9+I9+K9+M9)*N9/100 | P9: 0 | Q9: =F9+I9+K9+M9+O9+P9 | R9: =IF(D9=0,0,Q9/D9) | S9: =R9*2.5 | T9: Active
F10: =SUMIF($W$65:$W$500,B10,$AG$65:$AG$500) | I10: =G10*H10 | K10: =J10*D10 | M10: =F10*L10/100 | O10: =(F10+I10+K10+M10)*N10/100 | Q10: =F10+I10+K10+M10+O10+P10 | R10: =IF(D10=0,0,Q10/D10) | S10: =R10*2.5
F11: =SUMIF($W$65:$W$500,B11,$AG$65:$AG$500) | I11: =G11*H11 | K11: =J11*D11 | M11: =F11*L11/100 | O11: =(F11+I11+K11+M11)*N11/100 | Q11: =F11+I11+K11+M11+O11+P11 | R11: =IF(D11=0,0,Q11/D11) | S11: =R11*2.5
F12: =SUMIF($W$65:$W$500,B12,$AG$65:$AG$500) | I12: =G12*H12 | K12: =J12*D12 | M12: =F12*L12/100 | O12: =(F12+I12+K12+M12)*N12/100 | Q12: =F12+I12+K12+M12+O12+P12 | R12: =IF(D12=0,0,Q12/D12) | S12: =R12*2.5
F13: =SUMIF($W$65:$W$500,B13,$AG$65:$AG$500) | I13: =G13*H13 | K13: =J13*D13 | M13: =F13*L13/100 | O13: =(F13+I13+K13+M13)*N13/100 | Q13: =F13+I13+K13+M13+O13+P13 | R13: =IF(D13=0,0,Q13/D13) | S13: =R13*2.5
F14: =SUMIF($W$65:$W$500,B14,$AG$65:$AG$500) | I14: =G14*H14 | K14: =J14*D14 | M14: =F14*L14/100 | O14: =(F14+I14+K14+M14)*N14/100 | Q14: =F14+I14+K14+M14+O14+P14 | R14: =IF(D14=0,0,Q14/D14) | S14: =R14*2.5
F15: =SUMIF($W$65:$W$500,B15,$AG$65:$AG$500) | I15: =G15*H15 | K15: =J15*D15 | M15: =F15*L15/100 | O15: =(F15+I15+K15+M15)*N15/100 | Q15: =F15+I15+K15+M15+O15+P15 | R15: =IF(D15=0,0,Q15/D15) | S15: =R15*2.5
F16: =SUMIF($W$65:$W$500,B16,$AG$65:$AG$500) | I16: =G16*H16 | K16: =J16*D16 | M16: =F16*L16/100 | O16: =(F16+I16+K16+M16)*N16/100 | Q16: =F16+I16+K16+M16+O16+P16 | R16: =IF(D16=0,0,Q16/D16) | S16: =R16*2.5
F17: =SUMIF($W$65:$W$500,B17,$AG$65:$AG$500) | I17: =G17*H17 | K17: =J17*D17 | M17: =F17*L17/100 | O17: =(F17+I17+K17+M17)*N17/100 | Q17: =F17+I17+K17+M17+O17+P17 | R17: =IF(D17=0,0,Q17/D17) | S17: =R17*2.5
F18: =SUMIF($W$65:$W$500,B18,$AG$65:$AG$500) | I18: =G18*H18 | K18: =J18*D18 | M18: =F18*L18/100 | O18: =(F18+I18+K18+M18)*N18/100 | Q18: =F18+I18+K18+M18+O18+P18 | R18: =IF(D18=0,0,Q18/D18) | S18: =R18*2.5
F19: =SUMIF($W$65:$W$500,B19,$AG$65:$AG$500) | I19: =G19*H19 | K19: =J19*D19 | M19: =F19*L19/100 | O19: =(F19+I19+K19+M19)*N19/100 | Q19: =F19+I19+K19+M19+O19+P19 | R19: =IF(D19=0,0,Q19/D19) | S19: =R19*2.5
F20: =SUMIF($W$65:$W$500,B20,$AG$65:$AG$500) | I20: =G20*H20 | K20: =J20*D20 | M20: =F20*L20/100 | O20: =(F20+I20+K20+M20)*N20/100 | Q20: =F20+I20+K20+M20+O20+P20 | R20: =IF(D20=0,0,Q20/D20) | S20: =R20*2.5
F21: =SUMIF($W$65:$W$500,B21,$AG$65:$AG$500) | I21: =G21*H21 | K21: =J21*D21 | M21: =F21*L21/100 | O21: =(F21+I21+K21+M21)*N21/100 | Q21: =F21+I21+K21+M21+O21+P21 | R21: =IF(D21=0,0,Q21/D21) | S21: =R21*2.5
... F54: =SUMIF($W$65:$W$500,B54,$AG$65:$AG$500) | I54: =G54*H54 | K54: =J54*D54 | M54: =F54*L54/100 | O54: =(F54+I54+K54+M54)*N54/100 | Q54: =F54+I54+K54+M54+O54+P54 | R54: =IF(D54=0,0,Q54/D54) | S54: =R54*2.5
A63: Recipe Ingredients Database - Long Format (Each row = one ingredient for a recipe) - Supports multiple recipes
V64: Row ID | W64: Recipe ID | X64: Recipe Name | Y64: Ingredient Name | Z64: Qty | AA64: Unit (Recipe Unit) | AB64: Stock Unit | AC64: Stock Cost/Unit $ | AD64: Recipe Unit Factor | AE64: Stock Unit Factor | AF64: Converted Qty | AG64: Line Cost $ | AH64: Type Match? | AI64: Notes
V65: 1 | W65: REC-001 | X65: Sourdough Loaf | Y65: Bread Flour | Z65: 1000 | AA65: g | AB65: =IFERROR(VLOOKUP(Y65,'Ingredients + Stock'!B:D,3,FALSE),"") | AC65: =IFERROR(VLOOKUP(Y65,'Ingredients + Stock'!B:G,6,FALSE),0) | AD65: =IFERROR(VLOOKUP(AA65,'Unit Conversion'!A:D,4,FALSE),1) | AE65: =IFERROR(VLOOKUP(AB65,'Unit Conversion'!A:D,4,FALSE),1) | AF65: =IF(AA65="","",Z65*AD65/AE65) | AG65: =AF65*AC65 | AH65: =IFERROR(IF(VLOOKUP(AA65,'Unit Conversion'!A:B,2,FALSE)=VLOOKUP(AB65,'Unit Conversion'!A:B,2,FALSE),"OK","Check W/V mismatch"),"Check unit")
V66: 2 | W66: REC-001 | X66: Sourdough Loaf | Y66: Water | Z66: 700 | AA66: ml | AB66: =IFERROR(VLOOKUP(Y66,'Ingredients + Stock'!B:D,3,FALSE),"") | AC66: =IFERROR(VLOOKUP(Y66,'Ingredients + Stock'!B:G,6,FALSE),0) | AD66: =IFERROR(VLOOKUP(AA66,'Unit Conversion'!A:D,4,FALSE),1) | AE66: =IFERROR(VLOOKUP(AB66,'Unit Conversion'!A:D,4,FALSE),1) | AF66: =IF(AA66="","",Z66*AD66/AE66) | AG66: =AF66*AC66 | AH66: =IFERROR(IF(VLOOKUP(AA66,'Unit Conversion'!A:B,2,FALSE)=VLOOKUP(AB66,'Unit Conversion'!A:B,2,FALSE),"OK","Check W/V mismatch"),"Check unit")
V67: 3 | W67: REC-001 | X67: Sourdough Loaf | Y67: Sourdough Starter | Z67: 200 | AA67: g | AB67: =IFERROR(VLOOKUP(Y67,'Ingredients + Stock'!B:D,3,FALSE),"") | AC67: =IFERROR(VLOOKUP(Y67,'Ingredients + Stock'!B:G,6,FALSE),0) | AD67: =IFERROR(VLOOKUP(AA67,'Unit Conversion'!A:D,4,FALSE),1) | AE67: =IFERROR(VLOOKUP(AB67,'Unit Conversion'!A:D,4,FALSE),1) | AF67: =IF(AA67="","",Z67*AD67/AE67) | AG67: =AF67*AC67 | AH67: =IFERROR(IF(VLOOKUP(AA67,'Unit Conversion'!A:B,2,FALSE)=VLOOKUP(AB67,'Unit Conversion'!A:B,2,FALSE),"OK","Check W/V mismatch"),"Check unit")
V68: 4 | W68: REC-001 | X68: Sourdough Loaf | Y68: Salt | Z68: 20 | AA68: g | AB68: =IFERROR(VLOOKUP(Y68,'Ingredients + Stock'!B:D,3,FALSE),"") | AC68: =IFERROR(VLOOKUP(Y68,'Ingredients + Stock'!B:G,6,FALSE),0) | AD68: =IFERROR(VLOOKUP(AA68,'Unit Conversion'!A:D,4,FALSE),1) | AE68: =IFERROR(VLOOKUP(AB68,'Unit Conversion'!A:D,4,FALSE),1) | AF68: =IF(AA68="","",Z68*AD68/AE68) | AG68: =AF68*AC68 | AH68: =IFERROR(IF(VLOOKUP(AA68,'Unit Conversion'!A:B,2,FALSE)=VLOOKUP(AB68,'Unit Conversion'!A:B,2,FALSE),"OK","Check W/V mismatch"),"Check unit")
V69: 5 | W69: REC-001 | X69: Sourdough Loaf | Y69: Olive Oil | Z69: 2 | AA69: tbsp | AB69: =IFERROR(VLOOKUP(Y69,'Ingredients + Stock'!B:D,3,FALSE),"") | AC69: =IFERROR(VLOOKUP(Y69,'Ingredients + Stock'!B:G,6,FALSE),0) | AD69: =IFERROR(VLOOKUP(AA69,'Unit Conversion'!A:D,4,FALSE),1) | AE69: =IFERROR(VLOOKUP(AB69,'Unit Conversion'!A:D,4,FALSE),1) | AF69: =IF(AA69="","",Z69*AD69/AE69) | AG69: =AF69*AC69 | AH69: =IFERROR(IF(VLOOKUP(AA69,'Unit Conversion'!A:B,2,FALSE)=VLOOKUP(AB69,'Unit Conversion'!A:B,2,FALSE),"OK","Check W/V mismatch"),"Check unit") | AI69: 2 tbsp = test tsp/tbsp conversion
V70: 6 | W70: REC-002 | X70: Chocolate Chip Cookies | Y70: All-Purpose Flour | Z70: 360 | AA70: g | AB70: =IFERROR(VLOOKUP(Y70,'Ingredients + Stock'!B:D,3,FALSE),"") | AC70: =IFERROR(VLOOKUP(Y70,'Ingredients + Stock'!B:G,6,FALSE),0) | AD70: =IFERROR(VLOOKUP(AA70,'Unit Conversion'!A:D,4,FALSE),1) | AE70: =IFERROR(VLOOKUP(AB70,'Unit Conversion'!A:D,4,FALSE),1) | AF70: =IF(AA70="","",Z70*AD70/AE70) | AG70: =AF70*AC70 | AH70: =IFERROR(IF(VLOOKUP(AA70,'Unit Conversion'!A:B,2,FALSE)=VLOOKUP(AB70,'Unit Conversion'!A:B,2,FALSE),"OK","Check W/V mismatch"),"Check unit")
V71: 7 | W71: REC-002 | X71: Chocolate Chip Cookies | Y71: Sugar | Z71: 200 | AA71: g | AB71: =IFERROR(VLOOKUP(Y71,'Ingredients + Stock'!B:D,3,FALSE),"") | AC71: =IFERROR(VLOOKUP(Y71,'Ingredients + Stock'!B:G,6,FALSE),0) | AD71: =IFERROR(VLOOKUP(AA71,'Unit Conversion'!A:D,4,FALSE),1) | AE71: =IFERROR(VLOOKUP(AB71,'Unit Conversion'!A:D,4,FALSE),1) | AF71: =IF(AA71="","",Z71*AD71/AE71) | AG71: =AF71*AC71 | AH71: =IFERROR(IF(VLOOKUP(AA71,'Unit Conversion'!A:B,2,FALSE)=VLOOKUP(AB71,'Unit Conversion'!A:B,2,FALSE),"OK","Check W/V mismatch"),"Check unit")
V72: 8 | W72: REC-002 | X72: Chocolate Chip Cookies | Y72: Butter | Z72: 225 | AA72: g | AB72: =IFERROR(VLOOKUP(Y72,'Ingredients + Stock'!B:D,3,FALSE),"") | AC72: =IFERROR(VLOOKUP(Y72,'Ingredients + Stock'!B:G,6,FALSE),0) | AD72: =IFERROR(VLOOKUP(AA72,'Unit Conversion'!A:D,4,FALSE),1) | AE72: =IFERROR(VLOOKUP(AB72,'Unit Conversion'!A:D,4,FALSE),1) | AF72: =IF(AA72="","",Z72*AD72/AE72) | AG72: =AF72*AC72 | AH72: =IFERROR(IF(VLOOKUP(AA72,'Unit Conversion'!A:B,2,FALSE)=VLOOKUP(AB72,'Unit Conversion'!A:B,2,FALSE),"OK","Check W/V mismatch"),"Check unit")
V73: 9 | W73: REC-002 | X73: Chocolate Chip Cookies | Y73: Vanilla Extract | Z73: 2 | AA73: tsp | AB73: =IFERROR(VLOOKUP(Y73,'Ingredients + Stock'!B:D,3,FALSE),"") | AC73: =IFERROR(VLOOKUP(Y73,'Ingredients + Stock'!B:G,6,FALSE),0) | AD73: =IFERROR(VLOOKUP(AA73,'Unit Conversion'!A:D,4,FALSE),1) | AE73: =IFERROR(VLOOKUP(AB73,'Unit Conversion'!A:D,4,FALSE),1) | AF73: =IF(AA73="","",Z73*AD73/AE73) | AG73: =AF73*AC73 | AH73: =IFERROR(IF(VLOOKUP(AA73,'Unit Conversion'!A:B,2,FALSE)=VLOOKUP(AB73,'Unit Conversion'!A:B,2,FALSE),"OK","Check W/V mismatch"),"Check unit") | AI73: tsp conversion test
V74: 10 | W74: REC-002 | X74: Chocolate Chip Cookies | Y74: Chocolate Chips | Z74: 340 | AA74: g | AB74: =IFERROR(VLOOKUP(Y74,'Ingredients + Stock'!B:D,3,FALSE),"") | AC74: =IFERROR(VLOOKUP(Y74,'Ingredients + Stock'!B:G,6,FALSE),0) | AD74: =IFERROR(VLOOKUP(AA74,'Unit Conversion'!A:D,4,FALSE),1) | AE74: =IFERROR(VLOOKUP(AB74,'Unit Conversion'!A:D,4,FALSE),1) | AF74: =IF(AA74="","",Z74*AD74/AE74) | AG74: =AF74*AC74 | AH74: =IFERROR(IF(VLOOKUP(AA74,'Unit Conversion'!A:B,2,FALSE)=VLOOKUP(AB74,'Unit Conversion'!A:B,2,FALSE),"OK","Check W/V mismatch"),"Check unit")
V75: 11 | W75: REC-002 | X75: Chocolate Chip Cookies | Y75: Eggs | Z75: 2 | AA75: pcs | AB75: =IFERROR(VLOOKUP(Y75,'Ingredients + Stock'!B:D,3,FALSE),"") | AC75: =IFERROR(VLOOKUP(Y75,'Ingredients + Stock'!B:G,6,FALSE),0) | AD75: =IFERROR(VLOOKUP(AA75,'Unit Conversion'!A:D,4,FALSE),1) | AE75: =IFERROR(VLOOKUP(AB75,'Unit Conversion'!A:D,4,FALSE),1) | AF75: =IF(AA75="","",Z75*AD75/AE75) | AG75: =AF75*AC75 | AH75: =IFERROR(IF(VLOOKUP(AA75,'Unit Conversion'!A:B,2,FALSE)=VLOOKUP(AB75,'Unit Conversion'!A:B,2,FALSE),"OK","Check W/V mismatch"),"Check unit") | AI75: pcs test
V76: 12 | W76: REC-003 | X76: Cinnamon Rolls 6-pack | Y76: Bread Flour | Z76: 500 | AA76: g | AB76: =IFERROR(VLOOKUP(Y76,'Ingredients + Stock'!B:D,3,FALSE),"") | AC76: =IFERROR(VLOOKUP(Y76,'Ingredients + Stock'!B:G,6,FALSE),0) | AD76: =IFERROR(VLOOKUP(AA76,'Unit Conversion'!A:D,4,FALSE),1) | AE76: =IFERROR(VLOOKUP(AB76,'Unit Conversion'!A:D,4,FALSE),1) | AF76: =IF(AA76="","",Z76*AD76/AE76) | AG76: =AF76*AC76 | AH76: =IFERROR(IF(VLOOKUP(AA76,'Unit Conversion'!A:B,2,FALSE)=VLOOKUP(AB76,'Unit Conversion'!A:B,2,FALSE),"OK","Check W/V mismatch"),"Check unit")
V77: 13 | W77: REC-003 | X77: Cinnamon Rolls 6-pack | Y77: Cinnamon | Z77: 2 | AA77: tbsp | AB77: =IFERROR(VLOOKUP(Y77,'Ingredients + Stock'!B:D,3,FALSE),"") | AC77: =IFERROR(VLOOKUP(Y77,'Ingredients + Stock'!B:G,6,FALSE),0) | AD77: =IFERROR(VLOOKUP(AA77,'Unit Conversion'!A:D,4,FALSE),1) | AE77: =IFERROR(VLOOKUP(AB77,'Unit Conversion'!A:D,4,FALSE),1) | AF77: =IF(AA77="","",Z77*AD77/AE77) | AG77: =AF77*AC77 | AH77: =IFERROR(IF(VLOOKUP(AA77,'Unit Conversion'!A:B,2,FALSE)=VLOOKUP(AB77,'Unit Conversion'!A:B,2,FALSE),"OK","Check W/V mismatch"),"Check unit") | AI77: tbsp test
V78: 14 | W78: REC-003 | X78: Cinnamon Rolls 6-pack | Y78: Brown Sugar | Z78: 100 | AA78: g | AB78: =IFERROR(VLOOKUP(Y78,'Ingredients + Stock'!B:D,3,FALSE),"") | AC78: =IFERROR(VLOOKUP(Y78,'Ingredients + Stock'!B:G,6,FALSE),0) | AD78: =IFERROR(VLOOKUP(AA78,'Unit Conversion'!A:D,4,FALSE),1) | AE78: =IFERROR(VLOOKUP(AB78,'Unit Conversion'!A:D,4,FALSE),1) | AF78: =IF(AA78="","",Z78*AD78/AE78) | AG78: =AF78*AC78 | AH78: =IFERROR(IF(VLOOKUP(AA78,'Unit Conversion'!A:B,2,FALSE)=VLOOKUP(AB78,'Unit Conversion'!A:B,2,FALSE),"OK","Check W/V mismatch"),"Check unit")
AB79: =IF(Y79="","",IFERROR(VLOOKUP(Y79,'Ingredients + Stock'!B:D,3,FALSE),"")) | AC79: =IF(Y79="","",IFERROR(VLOOKUP(Y79,'Ingredients + Stock'!B:G,6,FALSE),0)) | AD79: =IF(AA79="","",IFERROR(VLOOKUP(AA79,'Unit Conversion'!A:D,4,FALSE),1)) | AE79: =IF(AB79="","",IFERROR(VLOOKUP(AB79,'Unit Conversion'!A:D,4,FALSE),1)) | AF79: =IF(AA79="","",Z79*AD79/AE79) | AG79: =AF79*AC79 | AH79: =IF(AA79="","",IFERROR(IF(VLOOKUP(AA79,'Unit Conversion'!A:B,2,FALSE)=VLOOKUP(AB79,'Unit Conversion'!A:B,2,FALSE),"OK","Check W/V mismatch"),"Check unit"))
AB80: =IF(Y80="","",IFERROR(VLOOKUP(Y80,'Ingredients + Stock'!B:D,3,FALSE),"")) | AC80: =IF(Y80="","",IFERROR(VLOOKUP(Y80,'Ingredients + Stock'!B:G,6,FALSE),0)) | AD80: =IF(AA80="","",IFERROR(VLOOKUP(AA80,'Unit Conversion'!A:D,4,FALSE),1)) | AE80: =IF(AB80="","",IFERROR(VLOOKUP(AB80,'Unit Conversion'!A:D,4,FALSE),1)) | AF80: =IF(AA80="","",Z80*AD80/AE80) | AG80: =AF80*AC80 | AH80: =IF(AA80="","",IFERROR(IF(VLOOKUP(AA80,'Unit Conversion'!A:B,2,FALSE)=VLOOKUP(AB80,'Unit Conversion'!A:B,2,FALSE),"OK","Check W/V mismatch"),"Check unit"))
AB81: =IF(Y81="","",IFERROR(VLOOKUP(Y81,'Ingredients + Stock'!B:D,3,FALSE),"")) | AC81: =IF(Y81="","",IFERROR(VLOOKUP(Y81,'Ingredients + Stock'!B:G,6,FALSE),0)) | AD81: =IF(AA81="","",IFERROR(VLOOKUP(AA81,'Unit Conversion'!A:D,4,FALSE),1)) | AE81: =IF(AB81="","",IFERROR(VLOOKUP(AB81,'Unit Conversion'!A:D,4,FALSE),1)) | AF81: =IF(AA81="","",Z81*AD81/AE81) | AG81: =AF81*AC81 | AH81: =IF(AA81="","",IFERROR(IF(VLOOKUP(AA81,'Unit Conversion'!A:B,2,FALSE)=VLOOKUP(AB81,'Unit Conversion'!A:B,2,FALSE),"OK","Check W/V mismatch"),"Check unit"))
...

Sheet Recipe Calculator
A1: Recipe Calculator v4 - Multi-Recipe + Unit Conversion (Fixed missing formulas per review)
A3: RECIPE 1
A4: Recipe Name: | B4: Sourdough Loaf | D4: Select from Library: | E4: REC-001
A5: Batch Yield: | B5: 2
A6: Portion Size: | B6: 900g loaf
A8: Ingredient | B8: Qty | C8: Unit (Recipe) | D8: Stock Unit | E8: Cost/Stock Unit $ | F8: Recipe Factor | G8: Stock Factor | H8: Converted Qty | I8: Line Cost $ | J8: Type Match
A9: Bread Flour | B9: 1000 | C9: g | D9: =IF(A9="","",IFERROR(VLOOKUP(A9,'Ingredients + Stock'!B:D,3,FALSE),"")) | E9: =IF(A9="","",IFERROR(VLOOKUP(A9,'Ingredients + Stock'!B:G,6,FALSE),0)) | F9: =IF(C9="","",IFERROR(VLOOKUP(C9,'Unit Conversion'!A:D,4,FALSE),1)) | G9: =IF(D9="","",IFERROR(VLOOKUP(D9,'Unit Conversion'!A:D,4,FALSE),1)) | H9: =IF(C9="","",B9*F9/G9) | I9: =H9*E9 | J9: =IF(C9="","",IFERROR(IF(VLOOKUP(C9,'Unit Conversion'!A:B,2,FALSE)=VLOOKUP(D9,'Unit Conversion'!A:B,2,FALSE),"OK","Check W/V"),"Check"))
A10: Water | B10: 700 | C10: ml | D10: =IF(A10="","",IFERROR(VLOOKUP(A10,'Ingredients + Stock'!B:D,3,FALSE),"")) | E10: =IF(A10="","",IFERROR(VLOOKUP(A10,'Ingredients + Stock'!B:G,6,FALSE),0)) | F10: =IF(C10="","",IFERROR(VLOOKUP(C10,'Unit Conversion'!A:D,4,FALSE),1)) | G10: =IF(D10="","",IFERROR(VLOOKUP(D10,'Unit Conversion'!A:D,4,FALSE),1)) | H10: =IF(C10="","",B10*F10/G10) | I10: =H10*E10 | J10: =IF(C10="","",IFERROR(IF(VLOOKUP(C10,'Unit Conversion'!A:B,2,FALSE)=VLOOKUP(D10,'Unit Conversion'!A:B,2,FALSE),"OK","Check W/V"),"Check"))
A11: Sourdough Starter | B11: 200 | C11: g | D11: =IF(A11="","",IFERROR(VLOOKUP(A11,'Ingredients + Stock'!B:D,3,FALSE),"")) | E11: =IF(A11="","",IFERROR(VLOOKUP(A11,'Ingredients + Stock'!B:G,6,FALSE),0)) | F11: =IF(C11="","",IFERROR(VLOOKUP(C11,'Unit Conversion'!A:D,4,FALSE),1)) | G11: =IF(D11="","",IFERROR(VLOOKUP(D11,'Unit Conversion'!A:D,4,FALSE),1)) | H11: =IF(C11="","",B11*F11/G11) | I11: =H11*E11 | J11: =IF(C11="","",IFERROR(IF(VLOOKUP(C11,'Unit Conversion'!A:B,2,FALSE)=VLOOKUP(D11,'Unit Conversion'!A:B,2,FALSE),"OK","Check W/V"),"Check"))
A12: Salt | B12: 20 | C12: g | D12: =IF(A12="","",IFERROR(VLOOKUP(A12,'Ingredients + Stock'!B:D,3,FALSE),"")) | E12: =IF(A12="","",IFERROR(VLOOKUP(A12,'Ingredients + Stock'!B:G,6,FALSE),0)) | F12: =IF(C12="","",IFERROR(VLOOKUP(C12,'Unit Conversion'!A:D,4,FALSE),1)) | G12: =IF(D12="","",IFERROR(VLOOKUP(D12,'Unit Conversion'!A:D,4,FALSE),1)) | H12: =IF(C12="","",B12*F12/G12) | I12: =H12*E12 | J12: =IF(C12="","",IFERROR(IF(VLOOKUP(C12,'Unit Conversion'!A:B,2,FALSE)=VLOOKUP(D12,'Unit Conversion'!A:B,2,FALSE),"OK","Check W/V"),"Check"))
A13: Olive Oil | B13: 2 | C13: tbsp | D13: =IF(A13="","",IFERROR(VLOOKUP(A13,'Ingredients + Stock'!B:D,3,FALSE),"")) | E13: =IF(A13="","",IFERROR(VLOOKUP(A13,'Ingredients + Stock'!B:G,6,FALSE),0)) | F13: =IF(C13="","",IFERROR(VLOOKUP(C13,'Unit Conversion'!A:D,4,FALSE),1)) | G13: =IF(D13="","",IFERROR(VLOOKUP(D13,'Unit Conversion'!A:D,4,FALSE),1)) | H13: =IF(C13="","",B13*F13/G13) | I13: =H13*E13 | J13: =IF(C13="","",IFERROR(IF(VLOOKUP(C13,'Unit Conversion'!A:B,2,FALSE)=VLOOKUP(D13,'Unit Conversion'!A:B,2,FALSE),"OK","Check W/V"),"Check"))
D14: =IF(A14="","",IFERROR(VLOOKUP(A14,'Ingredients + Stock'!B:D,3,FALSE),"")) | E14: =IF(A14="","",IFERROR(VLOOKUP(A14,'Ingredients + Stock'!B:G,6,FALSE),0)) | F14: =IF(C14="","",IFERROR(VLOOKUP(C14,'Unit Conversion'!A:D,4,FALSE),1)) | G14: =IF(D14="","",IFERROR(VLOOKUP(D14,'Unit Conversion'!A:D,4,FALSE),1)) | H14: =IF(C14="","",B14*F14/G14) | I14: =H14*E14 | J14: =IF(C14="","",IFERROR(IF(VLOOKUP(C14,'Unit Conversion'!A:B,2,FALSE)=VLOOKUP(D14,'Unit Conversion'!A:B,2,FALSE),"OK","Check W/V"),"Check"))
D15: =IF(A15="","",IFERROR(VLOOKUP(A15,'Ingredients + Stock'!B:D,3,FALSE),"")) | E15: =IF(A15="","",IFERROR(VLOOKUP(A15,'Ingredients + Stock'!B:G,6,FALSE),0)) | F15: =IF(C15="","",IFERROR(VLOOKUP(C15,'Unit Conversion'!A:D,4,FALSE),1)) | G15: =IF(D15="","",IFERROR(VLOOKUP(D15,'Unit Conversion'!A:D,4,FALSE),1)) | H15: =IF(C15="","",B15*F15/G15) | I15: =H15*E15 | J15: =IF(C15="","",IFERROR(IF(VLOOKUP(C15,'Unit Conversion'!A:B,2,FALSE)=VLOOKUP(D15,'Unit Conversion'!A:B,2,FALSE),"OK","Check W/V"),"Check"))
D16: =IF(A16="","",IFERROR(VLOOKUP(A16,'Ingredients + Stock'!B:D,3,FALSE),"")) | E16: =IF(A16="","",IFERROR(VLOOKUP(A16,'Ingredients + Stock'!B:G,6,FALSE),0)) | F16: =IF(C16="","",IFERROR(VLOOKUP(C16,'Unit Conversion'!A:D,4,FALSE),1)) | G16: =IF(D16="","",IFERROR(VLOOKUP(D16,'Unit Conversion'!A:D,4,FALSE),1)) | H16: =IF(C16="","",B16*F16/G16) | I16: =H16*E16 | J16: =IF(C16="","",IFERROR(IF(VLOOKUP(C16,'Unit Conversion'!A:B,2,FALSE)=VLOOKUP(D16,'Unit Conversion'!A:B,2,FALSE),"OK","Check W/V"),"Check"))
D17: =IF(A17="","",IFERROR(VLOOKUP(A17,'Ingredients + Stock'!B:D,3,FALSE),"")) | E17: =IF(A17="","",IFERROR(VLOOKUP(A17,'Ingredients + Stock'!B:G,6,FALSE),0)) | F17: =IF(C17="","",IFERROR(VLOOKUP(C17,'Unit Conversion'!A:D,4,FALSE),1)) | G17: =IF(D17="","",IFERROR(VLOOKUP(D17,'Unit Conversion'!A:D,4,FALSE),1)) | H17: =IF(C17="","",B17*F17/G17) | I17: =H17*E17 | J17: =IF(C17="","",IFERROR(IF(VLOOKUP(C17,'Unit Conversion'!A:B,2,FALSE)=VLOOKUP(D17,'Unit Conversion'!A:B,2,FALSE),"OK","Check W/V"),"Check"))
D18: =IF(A18="","",IFERROR(VLOOKUP(A18,'Ingredients + Stock'!B:D,3,FALSE),"")) | E18: =IF(A18="","",IFERROR(VLOOKUP(A18,'Ingredients + Stock'!B:G,6,FALSE),0)) | F18: =IF(C18="","",IFERROR(VLOOKUP(C18,'Unit Conversion'!A:D,4,FALSE),1)) | G18: =IF(D18="","",IFERROR(VLOOKUP(D18,'Unit Conversion'!A:D,4,FALSE),1)) | H18: =IF(C18="","",B18*F18/G18) | I18: =H18*E18 | J18: =IF(C18="","",IFERROR(IF(VLOOKUP(C18,'Unit Conversion'!A:B,2,FALSE)=VLOOKUP(D18,'Unit Conversion'!A:B,2,FALSE),"OK","Check W/V"),"Check"))
D19: =IF(A19="","",IFERROR(VLOOKUP(A19,'Ingredients + Stock'!B:D,3,FALSE),"")) | E19: =IF(A19="","",IFERROR(VLOOKUP(A19,'Ingredients + Stock'!B:G,6,FALSE),0)) | F19: =IF(C19="","",IFERROR(VLOOKUP(C19,'Unit Conversion'!A:D,4,FALSE),1)) | G19: =IF(D19="","",IFERROR(VLOOKUP(D19,'Unit Conversion'!A:D,4,FALSE),1)) | H19: =IF(C19="","",B19*F19/G19) | I19: =H19*E19 | J19: =IF(C19="","",IFERROR(IF(VLOOKUP(C19,'Unit Conversion'!A:B,2,FALSE)=VLOOKUP(D19,'Unit Conversion'!A:B,2,FALSE),"OK","Check W/V"),"Check"))
D20: =IF(A20="","",IFERROR(VLOOKUP(A20,'Ingredients + Stock'!B:D,3,FALSE),"")) | E20: =IF(A20="","",IFERROR(VLOOKUP(A20,'Ingredients + Stock'!B:G,6,FALSE),0)) | F20: =IF(C20="","",IFERROR(VLOOKUP(C20,'Unit Conversion'!A:D,4,FALSE),1)) | G20: =IF(D20="","",IFERROR(VLOOKUP(D20,'Unit Conversion'!A:D,4,FALSE),1)) | H20: =IF(C20="","",B20*F20/G20) | I20: =H20*E20 | J20: =IF(C20="","",IFERROR(IF(VLOOKUP(C20,'Unit Conversion'!A:B,2,FALSE)=VLOOKUP(D20,'Unit Conversion'!A:B,2,FALSE),"OK","Check W/V"),"Check"))
A22: Total Ingredient Cost | I22: =SUM(I9:I20)
A24: Labor Hours | B24: 1.5 | D24: Rate | E24: ='Instructions + Setup'!B22 | F24: Labor Total | G24: =B24*E24
A25: Packaging per unit | B25: ='Instructions + Setup'!B25 | D25: Packaging Total (batch) | E25: =B25*B5
A26: Overhead % | B26: ='Instructions + Setup'!B23/100 | D26: Overhead $ | E26: =I22*B26
A27: Waste % | B27: ='Instructions + Setup'!B24/100 | D27: Waste $ | E27: =(I22+G24+E25+E26)*B27
A28: Other $ | B28: 0
A30: TOTAL BATCH COST | G30: =I22+G24+E25+E26+E27+B28
A31: COST PER UNIT | G31: =IF(B5=0,0,G30/B5)
A33: Suggested Pricing
A34: Method | B34: Multiplier | C34: Price | D34: Profit | E34: Margin %
A35: 2x Wholesale | B35: 2 | C35: =G31*B35 | D35: =C35-G31 | E35: =D35/C35
A36: 2.5x Standard | B36: 2.5 | C36: =G31*B36 | D36: =C36-G31 | E36: =D36/C36
A37: 3x Premium | B37: 3 | C37: =G31*B37 | D37: =C37-G31 | E37: =D37/C37
A38: 65% Margin Recommended | B38: 0.65 | C38: =G31/(1-0.65) | D38: =C38-G31 | E38: =D38/C38
A40: RECIPE 2 - Second recipe space (addresses review: room for more than 1 recipe)
A41: Recipe Name: | B41: Chocolate Chip Cookies
A42: Batch Yield: | B42: 12
A44: Ingredient | B44: Qty | C44: Unit (Recipe) | D44: Stock Unit | E44: Cost/Stock Unit $ | F44: Recipe Factor | G44: Stock Factor | H44: Converted Qty | I44: Line Cost $ | J44: Type Match
A45: All-Purpose Flour | B45: 360 | C45: g | D45: =IF(A45="","",IFERROR(VLOOKUP(A45,'Ingredients + Stock'!B:D,3,FALSE),"")) | E45: =IF(A45="","",IFERROR(VLOOKUP(A45,'Ingredients + Stock'!B:G,6,FALSE),0)) | F45: =IF(C45="","",IFERROR(VLOOKUP(C45,'Unit Conversion'!A:D,4,FALSE),1)) | G45: =IF(D45="","",IFERROR(VLOOKUP(D45,'Unit Conversion'!A:D,4,FALSE),1)) | H45: =IF(C45="","",B45*F45/G45) | I45: =H45*E45 | J45: =IF(C45="","",IFERROR(IF(VLOOKUP(C45,'Unit Conversion'!A:B,2,FALSE)=VLOOKUP(D45,'Unit Conversion'!A:B,2,FALSE),"OK","Check W/V"),"Check"))
A46: Sugar | B46: 200 | C46: g | D46: =IF(A46="","",IFERROR(VLOOKUP(A46,'Ingredients + Stock'!B:D,3,FALSE),"")) | E46: =IF(A46="","",IFERROR(VLOOKUP(A46,'Ingredients + Stock'!B:G,6,FALSE),0)) | F46: =IF(C46="","",IFERROR(VLOOKUP(C46,'Unit Conversion'!A:D,4,FALSE),1)) | G46: =IF(D46="","",IFERROR(VLOOKUP(D46,'Unit Conversion'!A:D,4,FALSE),1)) | H46: =IF(C46="","",B46*F46/G46) | I46: =H46*E46 | J46: =IF(C46="","",IFERROR(IF(VLOOKUP(C46,'Unit Conversion'!A:B,2,FALSE)=VLOOKUP(D46,'Unit Conversion'!A:B,2,FALSE),"OK","Check W/V"),"Check"))
A47: Butter | B47: 225 | C47: g | D47: =IF(A47="","",IFERROR(VLOOKUP(A47,'Ingredients + Stock'!B:D,3,FALSE),"")) | E47: =IF(A47="","",IFERROR(VLOOKUP(A47,'Ingredients + Stock'!B:G,6,FALSE),0)) | F47: =IF(C47="","",IFERROR(VLOOKUP(C47,'Unit Conversion'!A:D,4,FALSE),1)) | G47: =IF(D47="","",IFERROR(VLOOKUP(D47,'Unit Conversion'!A:D,4,FALSE),1)) | H47: =IF(C47="","",B47*F47/G47) | I47: =H47*E47 | J47: =IF(C47="","",IFERROR(IF(VLOOKUP(C47,'Unit Conversion'!A:B,2,FALSE)=VLOOKUP(D47,'Unit Conversion'!A:B,2,FALSE),"OK","Check W/V"),"Check"))
A48: Vanilla Extract | B48: 2 | C48: tsp | D48: =IF(A48="","",IFERROR(VLOOKUP(A48,'Ingredients + Stock'!B:D,3,FALSE),"")) | E48: =IF(A48="","",IFERROR(VLOOKUP(A48,'Ingredients + Stock'!B:G,6,FALSE),0)) | F48: =IF(C48="","",IFERROR(VLOOKUP(C48,'Unit Conversion'!A:D,4,FALSE),1)) | G48: =IF(D48="","",IFERROR(VLOOKUP(D48,'Unit Conversion'!A:D,4,FALSE),1)) | H48: =IF(C48="","",B48*F48/G48) | I48: =H48*E48 | J48: =IF(C48="","",IFERROR(IF(VLOOKUP(C48,'Unit Conversion'!A:B,2,FALSE)=VLOOKUP(D48,'Unit Conversion'!A:B,2,FALSE),"OK","Check W/V"),"Check"))
...

Sheet Product List
A1: ID | B1: Product Name | C1: Category | D1: SKU | E1: Batch Yield | F1: Recipe Link (from Library) | G1: Batch Cost $ (from Library) | H1: Cost/Unit $ | I1: Selling Price $ | J1: Profit/Unit $ | K1: Margin % | L1: Status | M1: Units Sold | N1: Revenue $ | O1: Total Cost $ | P1: Total Profit $ | Q1: Allergens | R1: Prep Time | S1: Shelf Life | T1: Notes
A2: 1 | B2: Sourdough Loaf | C2: Bread | D2: BRD-001 | E2: 2 | F2: REC-001 | G2: =IFERROR(VLOOKUP(F2,'Recipe Library'!B:Q,16,FALSE),0) | H2: =IF(E2=0,0,G2/E2) | I2: 0 | J2: =I2-H2 | K2: =IF(I2=0,0,J2/I2) | L2: Free | M2: =SUMIF(Orders!D:D,B2,Orders!E:E) | N2: =M2*I2 | O2: =M2*H2 | P2: =N2-O2 | Q2: Gluten | R2: 1440 | S2: 3 | T2: Best seller
A3: 2 | B3: Chocolate Chip Cookies dozen | C3: Cookies | D3: CK-002 | E3: 12 | F3: REC-002 | G3: =IFERROR(VLOOKUP(F3,'Recipe Library'!B:Q,16,FALSE),0) | H3: =IF(E3=0,0,G3/E3) | I3: 0 | J3: =I3-H3 | K3: =IF(I3=0,0,J3/I3) | L3: Free | M3: =SUMIF(Orders!D:D,B3,Orders!E:E) | N3: =M3*I3 | O3: =M3*H3 | P3: =N3-O3 | Q3: Gluten Dairy Eggs | R3: 45 | S3: 5
A4: 3 | B4: Cinnamon Roll 6-pack | C4: Pastry | D4: PAS-003 | E4: 6 | F4: REC-003 | G4: =IFERROR(VLOOKUP(F4,'Recipe Library'!B:Q,16,FALSE),0) | H4: =IF(E4=0,0,G4/E4) | I4: 0 | J4: =I4-H4 | K4: =IF(I4=0,0,J4/I4) | L4: Free | M4: =SUMIF(Orders!D:D,B4,Orders!E:E) | N4: =M4*I4 | O4: =M4*H4 | P4: =N4-O4 | Q4: Gluten Dairy | R4: 90 | S4: 2 | T4: Weekend

Sheet Overhead Expenses
A1: Overhead Monthly Expenses - Calculate True Overhead Rate (NEW per customer review)
A3: Fixed Monthly Overhead - Costs you pay even if you don't bake
A4: Category | B4: Item | C4: Monthly Cost $ | D4: Annual Cost $ | E4: Type | F4: Notes
A5: Rent | B5: Shared commercial kitchen / home kitchen allocation | C5: 350 | D5: =C5*12 | E5: Fixed
A6: Utilities | B6: Electricity + gas | C6: 95 | D6: =C6*12 | E6: Fixed
A7: Insurance | B7: Cottage food liability + business policy | C7: 35 | D7: =C7*12 | E7: Fixed
A8: Licenses | B8: State cottage food permit + business license | C8: 15 | D8: =C8*12 | E8: Fixed | F8: ~$180/year
A9: Internet/Phone | B9: Website + phone line | C9: 40 | D9: =C9*12 | E9: Fixed
A10: Software | B10: Accounting + Google Workspace + Canva | C10: 25 | D10: =C10*12 | E10: Fixed
A11: Marketing | B11: Instagram/Facebook ads + flyers | C11: 60 | D11: =C11*12 | E11: Variable
A12: Transportation | B12: Farmers market gas + delivery | C12: 75 | D12: =C12*12 | E12: Variable
A13: Packaging Storage | B13: Bins, shelves, labels | C13: 12 | D13: =C13*12 | E13: Fixed
A14: Cleaning | B14: Sanitizer + cleaning supplies | C14: 18 | D14: =C14*12 | E14: Fixed
A15: Accounting | B15: CPA + bookkeeping | C15: 30 | D15: =C15*12 | E15: Fixed
A16: Other | B16: Miscellaneous | C16: 25 | D16: =C16*12 | E16: Variable
A18: TOTAL MONTHLY OVERHEAD | C18: =SUM(C5:C16) | D18: =SUM(D5:D16)
A20: Overhead Rate Calculations
A21: Metric | B21: Value | C21: Formula | D21: How Used
A22: Total Monthly Overhead | B22: =C18 | C22: SUM of Monthly column | D22: Used for % calc
A23: Total Annual Overhead | B23: =D18 | C23: Monthly x 12 | D23: Yearly
A24: Daily Overhead (30 days) | B24: =C18/30 | C24: Monthly / 30 | D24: Per day cost
A25: Hourly Overhead (80 hrs/month from Setup) | B25: =IF('Instructions + Setup'!B29=0,0,C18/'Instructions + Setup'!B29) | C25: Monthly / Working Hours | D25: Use in Recipe labor overhead
A26: Overhead per Order (100 orders/month) | B26: =IF('Instructions + Setup'!B30=0,0,C18/'Instructions + Setup'!B30) | C26: Monthly / Expected Orders | D26: Per order overhead
A27: Expected Monthly Revenue (enter) | B27: 2000 | D27: Enter your expected revenue
A28: Overhead % = Overhead / Revenue | B28: =IF(B27=0,0,B22/B27) | C28: Monthly Overhead / Expected Revenue | D28: Use this % in Recipe Calculator Overhead %

Sheet Startup Costs
A1: Startup Costs + Break-Even Analysis - How Much Profit to Recover Investment (NEW per customer review)
A3: One-Time Startup Investment
A4: Category | B4: Item | C4: Cost $ | D4: Date Purchased | E4: Vendor | F4: Useful Life (months) | G4: Monthly Depreciation $ | H4: Notes
A5: Equipment | B5: KitchenAid 6 qt stand mixer | C5: 449.99 | D5: 46032 | E5: Amazon | F5: 60 | G5: =IF(F5=0,0,C5/F5)
A6: Equipment | B6: Dutch oven / oven upgrade | C6: 349 | D6: 46034 | E6: Sur La Table | F6: 60 | G6: =IF(F6=0,0,C6/F6)
A7: Equipment | B7: Extra refrigerator | C7: 649 | D7: 46037 | E7: Home Depot | F7: 60 | G7: =IF(F7=0,0,C7/F7)
A8: Equipment | B8: Baking sheets, pans, mixing bowls | C8: 175 | D8: 46030 | E8: Restaurant Depot | F8: 36 | G8: =IF(F8=0,0,C8/F8)
A9: Equipment | B9: Digital scale + packaging sealer | C9: 85 | D9: 46031 | E9: Amazon | F9: 36 | G9: =IF(F9=0,0,C9/F9)
A10: Initial Inventory | B10: Flour, sugar, butter, eggs opening stock | C10: 250 | D10: 46037 | E10: Costco | F10: 1 | G10: =IF(F10=0,0,C10/F10) | H10: One-time
A11: Packaging | B11: Boxes, bags, labels, stickers | C11: 150 | D11: 46038 | E11: WebstaurantStore | F11: 1 | G11: =IF(F11=0,0,C11/F11)
A12: Licenses | B12: Cottage food permit + business license | C12: 200 | D12: 46027 | E12: State / City | F12: 12 | G12: =IF(F12=0,0,C12/F12) | H12: First year
A13: Branding | B13: Logo + website + domain | C13: 250 | D13: 46028 | E13: Fiverr + Squarespace | F13: 24 | G13: =IF(F13=0,0,C13/F13)
A14: Marketing | B14: Flyers, banners, samples | C14: 120 | D14: 46042 | E14: Local print shop | F14: 1 | G14: =IF(F14=0,0,C14/F14)
A15: Training | B15: ServSafe Food Manager certification | C15: 150 | D15: 46025 | E15: ServSafe | F15: 60 | G15: =IF(F15=0,0,C15/F15)
A16: Other | B16: Miscellaneous initial supplies | C16: 100 | D16: 46047 | F16: 1 | G16: =IF(F16=0,0,C16/F16)
A18: TOTAL STARTUP INVESTMENT | C18: =SUM(C5:C16) | G18: =SUM(G5:G16)
A20: Break-Even Analysis - Graphic
A21: Metric | B21: Value | C21: Formula / Input
A22: Total Startup (from above) | B22: =C18
A23: Average Monthly Profit (from Bookkeeping or enter) | B23: 500 | C23: Enter your avg monthly net profit (Dashboard or Bookkeeping H102/12) or use Bookkeeping!H102/6 etc
A24: Months to Break-Even | B24: =IF(B23=0,0,B22/B23)
A25: Break-Even Date (from today) | B25: =TODAY()+B24*30
A26: Profit Needed per Day to Recover in 12 months | B26: =IF(B23=0,0,B22/12/30)
A27: Orders Needed to Recover (if avg order $25 profit) | B27: =IF(25=0,0,B22/25)
A29: Month | B29: Monthly Profit $ | C29: Cumulative Profit $ | D29: Remaining to Recover $ | E29: Recovered? % | F29: Startup Investment Line $
A30: 1 | B30: =$B$23 | C30: =B30*A30 | D30: =$B$22-C30 | E30: =IF($B$22=0,0,C30/$B$22) | F30: =$B$22
A31: 2 | B31: =$B$23 | C31: =B31*A31 | D31: =$B$22-C31 | E31: =IF($B$22=0,0,C31/$B$22) | F31: =$B$22
A32: 3 | B32: =$B$23 | C32: =B32*A32 | D32: =$B$22-C32 | E32: =IF($B$22=0,0,C32/$B$22) | F32: =$B$22
A33: 4 | B33: =$B$23 | C33: =B33*A33 | D33: =$B$22-C33 | E33: =IF($B$22=0,0,C33/$B$22) | F33: =$B$22
A34: 5 | B34: =$B$23 | C34: =B34*A34 | D34: =$B$22-C34 | E34: =IF($B$22=0,0,C34/$B$22) | F34: =$B$22
A35: 6 | B35: =$B$23 | C35: =B35*A35 | D35: =$B$22-C35 | E35: =IF($B$22=0,0,C35/$B$22) | F35: =$B$22
A36: 7 | B36: =$B$23 | C36: =B36*A36 | D36: =$B$22-C36 | E36: =IF($B$22=0,0,C36/$B$22) | F36: =$B$22
A37: 8 | B37: =$B$23 | C37: =B37*A37 | D37: =$B$22-C37 | E37: =IF($B$22=0,0,C37/$B$22) | F37: =$B$22
A38: 9 | B38: =$B$23 | C38: =B38*A38 | D38: =$B$22-C38 | E38: =IF($B$22=0,0,C38/$B$22) | F38: =$B$22
A39: 10 | B39: =$B$23 | C39: =B39*A39 | D39: =$B$22-C39 | E39: =IF($B$22=0,0,C39/$B$22) | F39: =$B$22
A40: 11 | B40: =$B$23 | C40: =B40*A40 | D40: =$B$22-C40 | E40: =IF($B$22=0,0,C40/$B$22) | F40: =$B$22
A41: 12 | B41: =$B$23 | C41: =B41*A41 | D41: =$B$22-C41 | E41: =IF($B$22=0,0,C41/$B$22) | F41: =$B$22
... A53: 24 | B53: =$B$23 | C53: =B53*A53 | D53: =$B$22-C53 | E53: =IF($B$22=0,0,C53/$B$22) | F53: =$B$22

Sheet Dashboard
A1: Dashboard v4 — Donation Stand
A2: Free products · donations tracked in Bookkeeping
A4: DONATIONS VS. COST
A5: Total Donations Received | B5: =SUMIFS(Bookkeeping!F:F,Bookkeeping!D:D,"Donations") | C5: Every Bookkeeping income row with Category = Donations
A6: Total Costs (Bookkeeping) | B6: =Bookkeeping!G102 | C6: Everything you spent (ingredients, supplies, fees…)
A7: Net — Donations after Costs | B7: =B5-B6 | C7: Positive = the stand covered its costs
A8: Free Items Given Away | B8: =SUM('Product List'!M:M) | C8: Log each free item in Orders with a $0 price
A10: KPI | B10: Value | C10: Source
A11: Total Revenue YTD | B11: =Bookkeeping!F102
A12: Total Expenses YTD | B12: =Bookkeeping!G102
A13: Net Profit YTD | B13: =Bookkeeping!H102
A14: Total Startup Investment | B14: ='Startup Costs'!C18
A15: Months to Break-Even | B15: ='Startup Costs'!B24
A16: Monthly Overhead | B16: ='Overhead Expenses'!C18
A17: Hourly Overhead | B17: ='Overhead Expenses'!B25
A18: Overhead % Auto | B18: ='Overhead Expenses'!B28
A19: Active Recipes | B19: =COUNTA('Recipe Library'!B5:B54)
A20: Total Stock Value | B20: ='Ingredients + Stock'!K52

Sheet Orders
A1: Order ID | B1: Order Date | C1: Customer Name | D1: Product | E1: Quantity | F1: Unit Price $ | G1: Subtotal $ | H1: Discount $ | I1: Total $ | J1: Due Date | K1: Status | L1: Payment Status | M1: Deposit $ | N1: Balance Due $ | O1: Fulfillment | P1: Delivery Address | Q1: Delivery Fee $ | R1: Profit $ | S1: Notes
A2: ORD-1002 | B2: 46253 | C2: Emma Johnson | D2: Sourdough Loaf | E2: 1 | F2: 0 | G2: =E2*F2 | I2: =G2-H2 | K2: Pending | L2: Unpaid | N2: =I2-M2
A3: ORD-1003 | B3: 46255 | C3: Emma Johnson | D3: Sourdough Loaf | E3: 1 | F3: 0 | G3: =E3*F3 | I3: =G3-H3 | K3: Pending | L3: Unpaid | N3: =I3-M3
A4: ORD-1004 | B4: 46260 | C4: Emma Johnson | D4: Sourdough Loaf | E4: 1 | F4: 0 | G4: =E4*F4 | I4: =G4-H4 | K4: Pending | L4: Unpaid | N4: =I4-M4
A5: ORD-1005 | B5: 46250 | C5: Emma Johnson | D5: Sourdough Loaf | E5: 1 | F5: 0 | G5: =E5*F5 | I5: =G5-H5 | K5: Pending | L5: Unpaid | N5: =I5-M5
A6: ORD-1006 | B6: 46246 | C6: Liam Smith | D6: Sourdough Loaf | E6: 1 | F6: 0 | G6: =E6*F6 | I6: =G6-H6 | K6: Pending | L6: Unpaid | N6: =I6-M6
A7: ORD-1007 | B7: 46243 | C7: Liam Smith | D7: Sourdough Loaf | E7: 1 | F7: 0 | G7: =E7*F7 | I7: =G7-H7 | K7: Pending | L7: Unpaid | N7: =I7-M7
A8: ORD-1008 | B8: 46257 | C8: Liam Smith | D8: Sourdough Loaf | E8: 1 | F8: 0 | G8: =E8*F8 | I8: =G8-H8 | K8: Pending | L8: Unpaid | N8: =I8-M8
A9: ORD-1009 | B9: 46247 | C9: Liam Smith | D9: Sourdough Loaf | E9: 1 | F9: 0 | G9: =E9*F9 | I9: =G9-H9 | K9: Pending | L9: Unpaid | N9: =I9-M9
A10: ORD-1010 | B10: 46260 | C10: Liam Smith | D10: Sourdough Loaf | E10: 1 | F10: 0 | G10: =E10*F10 | I10: =G10-H10 | K10: Pending | L10: Unpaid | N10: =I10-M10
A11: ORD-1011 | B11: 46254 | C11: Liam Smith | D11: Sourdough Loaf | E11: 1 | F11: 0 | G11: =E11*F11 | I11: =G11-H11 | K11: Pending | L11: Unpaid | N11: =I11-M11
A12: ORD-1012 | B12: 46252 | C12: Emma Johnson | D12: Sourdough Loaf | E12: 1 | F12: 0 | G12: =E12*F12 | I12: =G12-H12 | K12: Pending | L12: Unpaid | N12: =I12-M12
A13: ORD-1013 | B13: 46258 | C13: Liam Smith | D13: Sourdough Loaf | E13: 1 | F13: 0 | G13: =E13*F13 | I13: =G13-H13 | K13: Pending | L13: Unpaid | N13: =I13-M13
... A21: ORD-1021 | B21: 46244 | C21: Emma Johnson | D21: Sourdough Loaf | E21: 1 | F21: 0 | G21: =E21*F21 | I21: =G21-H21 | K21: Pending | L21: Unpaid | N21: =I21-M21

Sheet Bookkeeping
A1: ID | B1: Date | C1: Type | D1: Category | E1: Description | F1: Income $ | G1: Expense $ | H1: Net $ | I1: Month | J1: Payment Method | K1: Tax Deductible | L1: Vendor | M1: Running Balance $
A2: 1 | B2: 46236 | C2: Income | D2: Donations | F2: 100 | G2: 0 | H2: =F2-G2 | I2: =TEXT(B2,"YYYY-MM") | M2: =IF(ROW()=2,H2,M1+H2)
A3: 2 | B3: 46237 | C3: Expense | D3: Supplies | F3: 0 | G3: 50 | H3: =F3-G3 | I3: =TEXT(B3,"YYYY-MM") | M3: =IF(ROW()=2,H2,M2+H3)
A4: 3 | B4: 46238 | C4: Income | D4: Donations | F4: 100 | G4: 0 | H4: =F4-G4 | I4: =TEXT(B4,"YYYY-MM") | M4: =IF(ROW()=2,H2,M3+H4)
A5: 4 | B5: 46239 | C5: Expense | D5: Supplies | F5: 0 | G5: 50 | H5: =F5-G5 | I5: =TEXT(B5,"YYYY-MM") | M5: =IF(ROW()=2,H2,M4+H5)
A6: 5 | B6: 46240 | C6: Income | D6: Donations | F6: 100 | G6: 0 | H6: =F6-G6 | I6: =TEXT(B6,"YYYY-MM") | M6: =IF(ROW()=2,H2,M5+H6)
A7: 6 | B7: 46241 | C7: Expense | D7: Supplies | F7: 0 | G7: 50 | H7: =F7-G7 | I7: =TEXT(B7,"YYYY-MM") | M7: =IF(ROW()=2,H2,M6+H7)
A8: 7 | B8: 46242 | C8: Income | D8: Donations | F8: 100 | G8: 0 | H8: =F8-G8 | I8: =TEXT(B8,"YYYY-MM") | M8: =IF(ROW()=2,H2,M7+H8)
A9: 8 | B9: 46243 | C9: Expense | D9: Supplies | F9: 0 | G9: 50 | H9: =F9-G9 | I9: =TEXT(B9,"YYYY-MM") | M9: =IF(ROW()=2,H2,M8+H9)
A10: 9 | B10: 46244 | C10: Income | D10: Donations | F10: 100 | G10: 0 | H10: =F10-G10 | I10: =TEXT(B10,"YYYY-MM") | M10: =IF(ROW()=2,H2,M9+H10)
A11: 10 | B11: 46245 | C11: Expense | D11: Supplies | F11: 0 | G11: 50 | H11: =F11-G11 | I11: =TEXT(B11,"YYYY-MM") | M11: =IF(ROW()=2,H2,M10+H11)
F102: =SUM(F2:F101) | G102: =SUM(G2:G101) | H102: =F102-G102

Sheet Markets & Events
A1: Date | B1: Event Name | C1: Revenue $ | D1: Booth Fee $ | E1: Other Costs $ | F1: Total Costs $ | G1: Net Profit $ | H1: ROI % | I1: Hours | J1: Net/Hour $ | K1: Units Sold | L1: Worth It?
A2: 46236 | B2: Farmers Market | C2: 400 | D2: 50 | F2: =D2+E2 | G2: =C2-F2 | H2: =IF(F2=0,0,G2/F2)
A3: 46237 | B3: Farmers Market | C3: 400 | D3: 50 | F3: =D3+E3 | G3: =C3-F3 | H3: =IF(F3=0,0,G3/F3)
A4: 46238 | B4: Farmers Market | C4: 400 | D4: 50 | F4: =D4+E4 | G4: =C4-F4 | H4: =IF(F4=0,0,G4/F4)
A5: 46239 | B5: Farmers Market | C5: 400 | D5: 50 | F5: =D5+E5 | G5: =C5-F5 | H5: =IF(F5=0,0,G5/F5)
A6: 46240 | B6: Farmers Market | C6: 400 | D6: 50 | F6: =D6+E6 | G6: =C6-F6 | H6: =IF(F6=0,0,G6/F6)
A7: 46241 | B7: Farmers Market | C7: 400 | D7: 50 | F7: =D7+E7 | G7: =C7-F7 | H7: =IF(F7=0,0,G7/F7)
A8: 46242 | B8: Farmers Market | C8: 400 | D8: 50 | F8: =D8+E8 | G8: =C8-F8 | H8: =IF(F8=0,0,G8/F8)
A9: 46243 | B9: Farmers Market | C9: 400 | D9: 50 | F9: =D9+E9 | G9: =C9-F9 | H9: =IF(F9=0,0,G9/F9)
A10: 46244 | B10: Farmers Market | C10: 400 | D10: 50 | F10: =D10+E10 | G10: =C10-F10 | H10: =IF(F10=0,0,G10/F10)
A11: 46245 | B11: Farmers Market | C11: 400 | D11: 50 | F11: =D11+E11 | G11: =C11-F11 | H11: =IF(F11=0,0,G11/F11)

Sheet Customers
A1: Customer ID | B1: Customer Name | C1: Contact | D1: Total Orders | E1: Total Spent $ | F1: Last Order | G1: Balance Owed $ | H1: Tag | I1: Allergies | J1: Preferences
A2: CUST-1002 | B2: Liam Smith | D2: =COUNTIF(Orders!C:C,B2) | E2: =SUMIF(Orders!C:C,B2,Orders!I:I)
A3: CUST-1003 | B3: Liam Smith | D3: =COUNTIF(Orders!C:C,B3) | E3: =SUMIF(Orders!C:C,B3,Orders!I:I)
A4: CUST-1004 | B4: Emma Johnson | D4: =COUNTIF(Orders!C:C,B4) | E4: =SUMIF(Orders!C:C,B4,Orders!I:I)
A5: CUST-1005 | B5: Emma Johnson | D5: =COUNTIF(Orders!C:C,B5) | E5: =SUMIF(Orders!C:C,B5,Orders!I:I)
A6: CUST-1006 | B6: Emma Johnson | D6: =COUNTIF(Orders!C:C,B6) | E6: =SUMIF(Orders!C:C,B6,Orders!I:I)
A7: CUST-1007 | B7: Liam Smith | D7: =COUNTIF(Orders!C:C,B7) | E7: =SUMIF(Orders!C:C,B7,Orders!I:I)
A8: CUST-1008 | B8: Emma Johnson | D8: =COUNTIF(Orders!C:C,B8) | E8: =SUMIF(Orders!C:C,B8,Orders!I:I)
A9: CUST-1009 | B9: Liam Smith | D9: =COUNTIF(Orders!C:C,B9) | E9: =SUMIF(Orders!C:C,B9,Orders!I:I)
A10: CUST-1010 | B10: Liam Smith | D10: =COUNTIF(Orders!C:C,B10) | E10: =SUMIF(Orders!C:C,B10,Orders!I:I)
A11: CUST-1011 | B11: Liam Smith | D11: =COUNTIF(Orders!C:C,B11) | E11: =SUMIF(Orders!C:C,B11,Orders!I:I)

Sheet Analytics (BONUS)
A1: Analytics BONUS v4
A3: Metric | B3: Value
A4: Total Recipes | B4: =COUNTA('Recipe Library'!B5:B54)
A5: Total Startup | B5: ='Startup Costs'!C18
A6: Months to Break-Even | B6: ='Startup Costs'!B24
