Workbook
Name BusinessName: '⚙️ Setup'!$C$6
Name CalMonth: '⚙️ Setup'!$C$18
Name CalYear: '⚙️ Setup'!$C$19
Name ClientsList: OFFSET('👥 Clients'!$C$8,0,0,MAX(1,COUNTA('👥 Clients'!$C$8:$C$47)),1)
Name Currency: '⚙️ Setup'!$C$10
Name DefaultMargin: '⚙️ Setup'!$C$12
Name DepositPct: '⚙️ Setup'!$C$13
Name DueSoonDays: '⚙️ Setup'!$C$14
Name EventList: OFFSET('📅 Events'!$C$8,0,0,MAX(1,COUNTA('📅 Events'!$C$8:$C$47)),1)
Name EventStatuses: '⚙️ Setup'!$C$47:$C$52
Name EventTypes: OFFSET('⚙️ Setup'!$B$23,0,0,MAX(1,COUNTA('⚙️ Setup'!$B$23:$B$42)),1)
Name ExpenseCategories: OFFSET('⚙️ Setup'!$C$23,0,0,MAX(1,COUNTA('⚙️ Setup'!$C$23:$C$42)),1)
Name IngredientCategories: OFFSET('⚙️ Setup'!$G$23,0,0,MAX(1,COUNTA('⚙️ Setup'!$G$23:$G$42)),1)
Name MenuCategories: OFFSET('⚙️ Setup'!$F$23,0,0,MAX(1,COUNTA('⚙️ Setup'!$F$23:$F$42)),1)
Name MenuItems: OFFSET('🍽️ Menu Costing'!$C$8,0,0,MAX(1,COUNTA('🍽️ Menu Costing'!$C$8:$C$37)),1)
Name PaymentMethods: OFFSET('⚙️ Setup'!$D$23,0,0,MAX(1,COUNTA('⚙️ Setup'!$D$23:$D$42)),1)
Name PaymentStatuses: '⚙️ Setup'!$D$47:$D$49
Name ReportYear: '⚙️ Setup'!$C$15
Name StaffRoles: OFFSET('⚙️ Setup'!$E$23,0,0,MAX(1,COUNTA('⚙️ Setup'!$E$23:$E$42)),1)
Name SuppliersList: OFFSET('🚚 Suppliers'!$C$8,0,0,MAX(1,COUNTA('🚚 Suppliers'!$C$8:$C$37)),1)
Name TaxRate: '⚙️ Setup'!$C$11
Name Tick: '⚙️ Setup'!$E$47:$E$48

Sheet _Data
A1: Ultimate Catering Business Spreadsheet - calculation engine (hidden). Every number on the Dashboard and the reports is computed here. | H1: Month | I1: Cash in | J1: Cash out | K1: Net | L1: Events | N1: Expense category | O1: Spend | AA1: Upcoming date | AB1: Upcoming event | AC1: Status | AE1: KPI | AF1: Value
H2: Jan | I2: =SUMPRODUCT(--(('💰 Payments'!$E$8:$E$67<>"")*(MONTH('💰 Payments'!$E$8:$E$67)=1)),'💰 Payments'!$J$8:$J$67) -> 0 | J2: =SUMPRODUCT(--(('💸 Expenses'!$C$8:$C$67<>"")*(MONTH('💸 Expenses'!$C$8:$C$67)=1)),'💸 Expenses'!$G$8:$G$67) -> 0 | K2: =I2-J2 -> 0 | L2: =SUMPRODUCT(('📅 Events'!$E$8:$E$47<>"")*(MONTH('📅 Events'!$E$8:$E$47)=1)*1) -> 0 | N2: Ingredients | O2: =SUMIF('💸 Expenses'!$E$8:$E$67,$N2,'💸 Expenses'!$G$8:$G$67) -> 0 | AA2: =IFERROR(AGGREGATE(15,6,'📅 Events'!$E$8:$E$47/('📅 Events'!$E$8:$E$47>=TODAY())*('📅 Events'!$Q$8:$Q$47<>"❌ Cancelled")*('📅 Events'!$Q$8:$Q$47<>"🎉 Completed"),1),"") | AB2: =IF($AA2="","",INDEX('📅 Events'!$D$8:$D$47,MATCH($AA2,'📅 Events'!$E$8:$E$47,0))&" - "&INDEX('📅 Events'!$F$8:$F$47,MATCH($AA2,'📅 Events'!$E$8:$E$47,0))) | AC2: =IF($AA2="","",INDEX('📅 Events'!$Q$8:$Q$47,MATCH($AA2,'📅 Events'!$E$8:$E$47,0))) | AE2: Cash received (deposits + payments) | AF2: =SUM('💰 Payments'!$J$8:$J$67) -> 0
H3: Feb | I3: =SUMPRODUCT(--(('💰 Payments'!$E$8:$E$67<>"")*(MONTH('💰 Payments'!$E$8:$E$67)=2)),'💰 Payments'!$J$8:$J$67) -> 0 | J3: =SUMPRODUCT(--(('💸 Expenses'!$C$8:$C$67<>"")*(MONTH('💸 Expenses'!$C$8:$C$67)=2)),'💸 Expenses'!$G$8:$G$67) -> 0 | K3: =I3-J3 -> 0 | L3: =SUMPRODUCT(('📅 Events'!$E$8:$E$47<>"")*(MONTH('📅 Events'!$E$8:$E$47)=2)*1) -> 0 | N3: Packaging | O3: =SUMIF('💸 Expenses'!$E$8:$E$67,$N3,'💸 Expenses'!$G$8:$G$67) -> 0 | AA3: =IFERROR(AGGREGATE(15,6,'📅 Events'!$E$8:$E$47/('📅 Events'!$E$8:$E$47>=TODAY())*('📅 Events'!$Q$8:$Q$47<>"❌ Cancelled")*('📅 Events'!$Q$8:$Q$47<>"🎉 Completed"),2),"") | AB3: =IF($AA3="","",INDEX('📅 Events'!$D$8:$D$47,MATCH($AA3,'📅 Events'!$E$8:$E$47,0))&" - "&INDEX('📅 Events'!$F$8:$F$47,MATCH($AA3,'📅 Events'!$E$8:$E$47,0))) | AC3: =IF($AA3="","",INDEX('📅 Events'!$Q$8:$Q$47,MATCH($AA3,'📅 Events'!$E$8:$E$47,0))) | AE3: Total expenses | AF3: =SUM('💸 Expenses'!$G$8:$G$67) -> 0
H4: Mar | I4: =SUMPRODUCT(--(('💰 Payments'!$E$8:$E$67<>"")*(MONTH('💰 Payments'!$E$8:$E$67)=3)),'💰 Payments'!$J$8:$J$67) -> 0 | J4: =SUMPRODUCT(--(('💸 Expenses'!$C$8:$C$67<>"")*(MONTH('💸 Expenses'!$C$8:$C$67)=3)),'💸 Expenses'!$G$8:$G$67) -> 0 | K4: =I4-J4 -> 0 | L4: =SUMPRODUCT(('📅 Events'!$E$8:$E$47<>"")*(MONTH('📅 Events'!$E$8:$E$47)=3)*1) -> 0 | N4: Staff / Labor | O4: =SUMIF('💸 Expenses'!$E$8:$E$67,$N4,'💸 Expenses'!$G$8:$G$67) -> 0 | AA4: =IFERROR(AGGREGATE(15,6,'📅 Events'!$E$8:$E$47/('📅 Events'!$E$8:$E$47>=TODAY())*('📅 Events'!$Q$8:$Q$47<>"❌ Cancelled")*('📅 Events'!$Q$8:$Q$47<>"🎉 Completed"),3),"") | AB4: =IF($AA4="","",INDEX('📅 Events'!$D$8:$D$47,MATCH($AA4,'📅 Events'!$E$8:$E$47,0))&" - "&INDEX('📅 Events'!$F$8:$F$47,MATCH($AA4,'📅 Events'!$E$8:$E$47,0))) | AC4: =IF($AA4="","",INDEX('📅 Events'!$Q$8:$Q$47,MATCH($AA4,'📅 Events'!$E$8:$E$47,0))) | AE4: Net profit | AF4: =$AF$2-$AF$3 -> 0
H5: Apr | I5: =SUMPRODUCT(--(('💰 Payments'!$E$8:$E$67<>"")*(MONTH('💰 Payments'!$E$8:$E$67)=4)),'💰 Payments'!$J$8:$J$67) -> 0 | J5: =SUMPRODUCT(--(('💸 Expenses'!$C$8:$C$67<>"")*(MONTH('💸 Expenses'!$C$8:$C$67)=4)),'💸 Expenses'!$G$8:$G$67) -> 0 | K5: =I5-J5 -> 0 | L5: =SUMPRODUCT(('📅 Events'!$E$8:$E$47<>"")*(MONTH('📅 Events'!$E$8:$E$47)=4)*1) -> 0 | N5: Transportation | O5: =SUMIF('💸 Expenses'!$E$8:$E$67,$N5,'💸 Expenses'!$G$8:$G$67) -> 0 | AA5: =IFERROR(AGGREGATE(15,6,'📅 Events'!$E$8:$E$47/('📅 Events'!$E$8:$E$47>=TODAY())*('📅 Events'!$Q$8:$Q$47<>"❌ Cancelled")*('📅 Events'!$Q$8:$Q$47<>"🎉 Completed"),4),"") | AB5: =IF($AA5="","",INDEX('📅 Events'!$D$8:$D$47,MATCH($AA5,'📅 Events'!$E$8:$E$47,0))&" - "&INDEX('📅 Events'!$F$8:$F$47,MATCH($AA5,'📅 Events'!$E$8:$E$47,0))) | AC5: =IF($AA5="","",INDEX('📅 Events'!$Q$8:$Q$47,MATCH($AA5,'📅 Events'!$E$8:$E$47,0))) | AE5: Net profit margin | AF5: =IFERROR($AF$4/$AF$2,0) -> 0
H6: May | I6: =SUMPRODUCT(--(('💰 Payments'!$E$8:$E$67<>"")*(MONTH('💰 Payments'!$E$8:$E$67)=5)),'💰 Payments'!$J$8:$J$67) -> 0 | J6: =SUMPRODUCT(--(('💸 Expenses'!$C$8:$C$67<>"")*(MONTH('💸 Expenses'!$C$8:$C$67)=5)),'💸 Expenses'!$G$8:$G$67) -> 0 | K6: =I6-J6 -> 0 | L6: =SUMPRODUCT(('📅 Events'!$E$8:$E$47<>"")*(MONTH('📅 Events'!$E$8:$E$47)=5)*1) -> 0 | N6: Equipment | O6: =SUMIF('💸 Expenses'!$E$8:$E$67,$N6,'💸 Expenses'!$G$8:$G$67) -> 0 | AA6: =IFERROR(AGGREGATE(15,6,'📅 Events'!$E$8:$E$47/('📅 Events'!$E$8:$E$47>=TODAY())*('📅 Events'!$Q$8:$Q$47<>"❌ Cancelled")*('📅 Events'!$Q$8:$Q$47<>"🎉 Completed"),5),"") | AB6: =IF($AA6="","",INDEX('📅 Events'!$D$8:$D$47,MATCH($AA6,'📅 Events'!$E$8:$E$47,0))&" - "&INDEX('📅 Events'!$F$8:$F$47,MATCH($AA6,'📅 Events'!$E$8:$E$47,0))) | AC6: =IF($AA6="","",INDEX('📅 Events'!$Q$8:$Q$47,MATCH($AA6,'📅 Events'!$E$8:$E$47,0))) | AE6: Events on the books | AF6: =COUNTA('📅 Events'!$C$8:$C$47) -> 0
H7: Jun | I7: =SUMPRODUCT(--(('💰 Payments'!$E$8:$E$67<>"")*(MONTH('💰 Payments'!$E$8:$E$67)=6)),'💰 Payments'!$J$8:$J$67) -> 0 | J7: =SUMPRODUCT(--(('💸 Expenses'!$C$8:$C$67<>"")*(MONTH('💸 Expenses'!$C$8:$C$67)=6)),'💸 Expenses'!$G$8:$G$67) -> 0 | K7: =I7-J7 -> 0 | L7: =SUMPRODUCT(('📅 Events'!$E$8:$E$47<>"")*(MONTH('📅 Events'!$E$8:$E$47)=6)*1) -> 0 | N7: Kitchen Rental | O7: =SUMIF('💸 Expenses'!$E$8:$E$67,$N7,'💸 Expenses'!$G$8:$G$67) -> 0 | AA7: =IFERROR(AGGREGATE(15,6,'📅 Events'!$E$8:$E$47/('📅 Events'!$E$8:$E$47>=TODAY())*('📅 Events'!$Q$8:$Q$47<>"❌ Cancelled")*('📅 Events'!$Q$8:$Q$47<>"🎉 Completed"),6),"") | AB7: =IF($AA7="","",INDEX('📅 Events'!$D$8:$D$47,MATCH($AA7,'📅 Events'!$E$8:$E$47,0))&" - "&INDEX('📅 Events'!$F$8:$F$47,MATCH($AA7,'📅 Events'!$E$8:$E$47,0))) | AC7: =IF($AA7="","",INDEX('📅 Events'!$Q$8:$Q$47,MATCH($AA7,'📅 Events'!$E$8:$E$47,0))) | AE7: Events completed | AF7: =COUNTIF('📅 Events'!$Q$8:$Q$47,"🎉 Completed") -> 0
H8: Jul | I8: =SUMPRODUCT(--(('💰 Payments'!$E$8:$E$67<>"")*(MONTH('💰 Payments'!$E$8:$E$67)=7)),'💰 Payments'!$J$8:$J$67) -> 0 | J8: =SUMPRODUCT(--(('💸 Expenses'!$C$8:$C$67<>"")*(MONTH('💸 Expenses'!$C$8:$C$67)=7)),'💸 Expenses'!$G$8:$G$67) -> 0 | K8: =I8-J8 -> 0 | L8: =SUMPRODUCT(('📅 Events'!$E$8:$E$47<>"")*(MONTH('📅 Events'!$E$8:$E$47)=7)*1) -> 0 | N8: Marketing | O8: =SUMIF('💸 Expenses'!$E$8:$E$67,$N8,'💸 Expenses'!$G$8:$G$67) -> 0 | AA8: =IFERROR(AGGREGATE(15,6,'📅 Events'!$E$8:$E$47/('📅 Events'!$E$8:$E$47>=TODAY())*('📅 Events'!$Q$8:$Q$47<>"❌ Cancelled")*('📅 Events'!$Q$8:$Q$47<>"🎉 Completed"),7),"") | AB8: =IF($AA8="","",INDEX('📅 Events'!$D$8:$D$47,MATCH($AA8,'📅 Events'!$E$8:$E$47,0))&" - "&INDEX('📅 Events'!$F$8:$F$47,MATCH($AA8,'📅 Events'!$E$8:$E$47,0))) | AC8: =IF($AA8="","",INDEX('📅 Events'!$Q$8:$Q$47,MATCH($AA8,'📅 Events'!$E$8:$E$47,0))) | AE8: Events confirmed (upcoming) | AF8: =COUNTIF('📅 Events'!$Q$8:$Q$47,"💰 Deposit Paid")+COUNTIF('📅 Events'!$Q$8:$Q$47,"✅ Confirmed") -> 0
H9: Aug | I9: =SUMPRODUCT(--(('💰 Payments'!$E$8:$E$67<>"")*(MONTH('💰 Payments'!$E$8:$E$67)=8)),'💰 Payments'!$J$8:$J$67) -> 0 | J9: =SUMPRODUCT(--(('💸 Expenses'!$C$8:$C$67<>"")*(MONTH('💸 Expenses'!$C$8:$C$67)=8)),'💸 Expenses'!$G$8:$G$67) -> 0 | K9: =I9-J9 -> 0 | L9: =SUMPRODUCT(('📅 Events'!$E$8:$E$47<>"")*(MONTH('📅 Events'!$E$8:$E$47)=8)*1) -> 0 | N9: Insurance | O9: =SUMIF('💸 Expenses'!$E$8:$E$67,$N9,'💸 Expenses'!$G$8:$G$67) -> 0 | AA9: =IFERROR(AGGREGATE(15,6,'📅 Events'!$E$8:$E$47/('📅 Events'!$E$8:$E$47>=TODAY())*('📅 Events'!$Q$8:$Q$47<>"❌ Cancelled")*('📅 Events'!$Q$8:$Q$47<>"🎉 Completed"),8),"") | AB9: =IF($AA9="","",INDEX('📅 Events'!$D$8:$D$47,MATCH($AA9,'📅 Events'!$E$8:$E$47,0))&" - "&INDEX('📅 Events'!$F$8:$F$47,MATCH($AA9,'📅 Events'!$E$8:$E$47,0))) | AC9: =IF($AA9="","",INDEX('📅 Events'!$Q$8:$Q$47,MATCH($AA9,'📅 Events'!$E$8:$E$47,0))) | AE9: Events cancelled | AF9: =COUNTIF('📅 Events'!$Q$8:$Q$47,"❌ Cancelled") -> 0
H10: Sep | I10: =SUMPRODUCT(--(('💰 Payments'!$E$8:$E$67<>"")*(MONTH('💰 Payments'!$E$8:$E$67)=9)),'💰 Payments'!$J$8:$J$67) -> 0 | J10: =SUMPRODUCT(--(('💸 Expenses'!$C$8:$C$67<>"")*(MONTH('💸 Expenses'!$C$8:$C$67)=9)),'💸 Expenses'!$G$8:$G$67) -> 0 | K10: =I10-J10 -> 0 | L10: =SUMPRODUCT(('📅 Events'!$E$8:$E$47<>"")*(MONTH('📅 Events'!$E$8:$E$47)=9)*1) -> 0 | N10: Utilities | O10: =SUMIF('💸 Expenses'!$E$8:$E$67,$N10,'💸 Expenses'!$G$8:$G$67) -> 0 | AA10: =IFERROR(AGGREGATE(15,6,'📅 Events'!$E$8:$E$47/('📅 Events'!$E$8:$E$47>=TODAY())*('📅 Events'!$Q$8:$Q$47<>"❌ Cancelled")*('📅 Events'!$Q$8:$Q$47<>"🎉 Completed"),9),"") | AB10: =IF($AA10="","",INDEX('📅 Events'!$D$8:$D$47,MATCH($AA10,'📅 Events'!$E$8:$E$47,0))&" - "&INDEX('📅 Events'!$F$8:$F$47,MATCH($AA10,'📅 Events'!$E$8:$E$47,0))) | AC10: =IF($AA10="","",INDEX('📅 Events'!$Q$8:$Q$47,MATCH($AA10,'📅 Events'!$E$8:$E$47,0))) | AE10: Average order value | AF10: =IFERROR(AVERAGEIF('📅 Events'!$Q$8:$Q$47,"<>❌ Cancelled",'📅 Events'!$L$8:$L$47),0) -> 0
H11: Oct | I11: =SUMPRODUCT(--(('💰 Payments'!$E$8:$E$67<>"")*(MONTH('💰 Payments'!$E$8:$E$67)=10)),'💰 Payments'!$J$8:$J$67) -> 0 | J11: =SUMPRODUCT(--(('💸 Expenses'!$C$8:$C$67<>"")*(MONTH('💸 Expenses'!$C$8:$C$67)=10)),'💸 Expenses'!$G$8:$G$67) -> 0 | K11: =I11-J11 -> 0 | L11: =SUMPRODUCT(('📅 Events'!$E$8:$E$47<>"")*(MONTH('📅 Events'!$E$8:$E$47)=10)*1) -> 0 | N11: Software | O11: =SUMIF('💸 Expenses'!$E$8:$E$67,$N11,'💸 Expenses'!$G$8:$G$67) -> 0 | AA11: =IFERROR(AGGREGATE(15,6,'📅 Events'!$E$8:$E$47/('📅 Events'!$E$8:$E$47>=TODAY())*('📅 Events'!$Q$8:$Q$47<>"❌ Cancelled")*('📅 Events'!$Q$8:$Q$47<>"🎉 Completed"),10),"") | AB11: =IF($AA11="","",INDEX('📅 Events'!$D$8:$D$47,MATCH($AA11,'📅 Events'!$E$8:$E$47,0))&" - "&INDEX('📅 Events'!$F$8:$F$47,MATCH($AA11,'📅 Events'!$E$8:$E$47,0))) | AC11: =IF($AA11="","",INDEX('📅 Events'!$Q$8:$Q$47,MATCH($AA11,'📅 Events'!$E$8:$E$47,0))) | AE11: Average guests per event | AF11: =IFERROR(AVERAGEIF('📅 Events'!$Q$8:$Q$47,"<>❌ Cancelled",'📅 Events'!$G$8:$G$47),0) -> 0
H12: Nov | I12: =SUMPRODUCT(--(('💰 Payments'!$E$8:$E$67<>"")*(MONTH('💰 Payments'!$E$8:$E$67)=11)),'💰 Payments'!$J$8:$J$67) -> 0 | J12: =SUMPRODUCT(--(('💸 Expenses'!$C$8:$C$67<>"")*(MONTH('💸 Expenses'!$C$8:$C$67)=11)),'💸 Expenses'!$G$8:$G$67) -> 0 | K12: =I12-J12 -> 0 | L12: =SUMPRODUCT(('📅 Events'!$E$8:$E$47<>"")*(MONTH('📅 Events'!$E$8:$E$47)=11)*1) -> 0 | N12: Miscellaneous | O12: =SUMIF('💸 Expenses'!$E$8:$E$67,$N12,'💸 Expenses'!$G$8:$G$67) -> 0 | AA12: =IFERROR(AGGREGATE(15,6,'📅 Events'!$E$8:$E$47/('📅 Events'!$E$8:$E$47>=TODAY())*('📅 Events'!$Q$8:$Q$47<>"❌ Cancelled")*('📅 Events'!$Q$8:$Q$47<>"🎉 Completed"),11),"") | AB12: =IF($AA12="","",INDEX('📅 Events'!$D$8:$D$47,MATCH($AA12,'📅 Events'!$E$8:$E$47,0))&" - "&INDEX('📅 Events'!$F$8:$F$47,MATCH($AA12,'📅 Events'!$E$8:$E$47,0))) | AC12: =IF($AA12="","",INDEX('📅 Events'!$Q$8:$Q$47,MATCH($AA12,'📅 Events'!$E$8:$E$47,0))) | AE12: Average profit per event | AF12: =IFERROR(AVERAGEIF('📅 Events'!$Q$8:$Q$47,"<>❌ Cancelled",'📅 Events'!$M$8:$M$47),0) -> 0
H13: Dec | I13: =SUMPRODUCT(--(('💰 Payments'!$E$8:$E$67<>"")*(MONTH('💰 Payments'!$E$8:$E$67)=12)),'💰 Payments'!$J$8:$J$67) -> 0 | J13: =SUMPRODUCT(--(('💸 Expenses'!$C$8:$C$67<>"")*(MONTH('💸 Expenses'!$C$8:$C$67)=12)),'💸 Expenses'!$G$8:$G$67) -> 0 | K13: =I13-J13 -> 0 | L13: =SUMPRODUCT(('📅 Events'!$E$8:$E$47<>"")*(MONTH('📅 Events'!$E$8:$E$47)=12)*1) -> 0 | AA13: =IFERROR(AGGREGATE(15,6,'📅 Events'!$E$8:$E$47/('📅 Events'!$E$8:$E$47>=TODAY())*('📅 Events'!$Q$8:$Q$47<>"❌ Cancelled")*('📅 Events'!$Q$8:$Q$47<>"🎉 Completed"),12),"") | AB13: =IF($AA13="","",INDEX('📅 Events'!$D$8:$D$47,MATCH($AA13,'📅 Events'!$E$8:$E$47,0))&" - "&INDEX('📅 Events'!$F$8:$F$47,MATCH($AA13,'📅 Events'!$E$8:$E$47,0))) | AC13: =IF($AA13="","",INDEX('📅 Events'!$Q$8:$Q$47,MATCH($AA13,'📅 Events'!$E$8:$E$47,0))) | AE13: Guests catered (completed) | AF13: =SUMIF('📅 Events'!$Q$8:$Q$47,"🎉 Completed",'📅 Events'!$G$8:$G$47) -> 0
AA14: =IFERROR(AGGREGATE(15,6,'📅 Events'!$E$8:$E$47/('📅 Events'!$E$8:$E$47>=TODAY())*('📅 Events'!$Q$8:$Q$47<>"❌ Cancelled")*('📅 Events'!$Q$8:$Q$47<>"🎉 Completed"),13),"") | AB14: =IF($AA14="","",INDEX('📅 Events'!$D$8:$D$47,MATCH($AA14,'📅 Events'!$E$8:$E$47,0))&" - "&INDEX('📅 Events'!$F$8:$F$47,MATCH($AA14,'📅 Events'!$E$8:$E$47,0))) | AC14: =IF($AA14="","",INDEX('📅 Events'!$Q$8:$Q$47,MATCH($AA14,'📅 Events'!$E$8:$E$47,0))) | AE14: Outstanding receivables | AF14: =SUM('💰 Payments'!$K$8:$K$67) -> 0
N15: Event type | O15: Revenue | AA15: =IFERROR(AGGREGATE(15,6,'📅 Events'!$E$8:$E$47/('📅 Events'!$E$8:$E$47>=TODAY())*('📅 Events'!$Q$8:$Q$47<>"❌ Cancelled")*('📅 Events'!$Q$8:$Q$47<>"🎉 Completed"),14),"") | AB15: =IF($AA15="","",INDEX('📅 Events'!$D$8:$D$47,MATCH($AA15,'📅 Events'!$E$8:$E$47,0))&" - "&INDEX('📅 Events'!$F$8:$F$47,MATCH($AA15,'📅 Events'!$E$8:$E$47,0))) | AC15: =IF($AA15="","",INDEX('📅 Events'!$Q$8:$Q$47,MATCH($AA15,'📅 Events'!$E$8:$E$47,0))) | AE15: Overdue invoices | AF15: =SUMPRODUCT(('💰 Payments'!$K$8:$K$67>0)*('💰 Payments'!$L$8:$L$67<>"")*('💰 Payments'!$L$8:$L$67<TODAY())) -> 0
N16: Wedding | O16: =SUMIFS('📅 Events'!$L$8:$L$47,'📅 Events'!$F$8:$F$47,$N16,'📅 Events'!$Q$8:$Q$47,"<>❌ Cancelled") -> 0 | AA16: =IFERROR(AGGREGATE(15,6,'📅 Events'!$E$8:$E$47/('📅 Events'!$E$8:$E$47>=TODAY())*('📅 Events'!$Q$8:$Q$47<>"❌ Cancelled")*('📅 Events'!$Q$8:$Q$47<>"🎉 Completed"),15),"") | AB16: =IF($AA16="","",INDEX('📅 Events'!$D$8:$D$47,MATCH($AA16,'📅 Events'!$E$8:$E$47,0))&" - "&INDEX('📅 Events'!$F$8:$F$47,MATCH($AA16,'📅 Events'!$E$8:$E$47,0))) | AC16: =IF($AA16="","",INDEX('📅 Events'!$Q$8:$Q$47,MATCH($AA16,'📅 Events'!$E$8:$E$47,0))) | AE16: Invoices still open | AF16: =COUNTIF('💰 Payments'!$K$8:$K$67,">0") -> 0
N17: Corporate | O17: =SUMIFS('📅 Events'!$L$8:$L$47,'📅 Events'!$F$8:$F$47,$N17,'📅 Events'!$Q$8:$Q$47,"<>❌ Cancelled") -> 0 | AA17: =IFERROR(AGGREGATE(15,6,'📅 Events'!$E$8:$E$47/('📅 Events'!$E$8:$E$47>=TODAY())*('📅 Events'!$Q$8:$Q$47<>"❌ Cancelled")*('📅 Events'!$Q$8:$Q$47<>"🎉 Completed"),16),"") | AB17: =IF($AA17="","",INDEX('📅 Events'!$D$8:$D$47,MATCH($AA17,'📅 Events'!$E$8:$E$47,0))&" - "&INDEX('📅 Events'!$F$8:$F$47,MATCH($AA17,'📅 Events'!$E$8:$E$47,0))) | AC17: =IF($AA17="","",INDEX('📅 Events'!$Q$8:$Q$47,MATCH($AA17,'📅 Events'!$E$8:$E$47,0))) | AE17: Ingredient & packaging spend | AF17: =SUMIF('💸 Expenses'!$E$8:$E$67,"Ingredients",'💸 Expenses'!$G$8:$G$67)+SUMIF('💸 Expenses'!$E$8:$E$67,"Packaging",'💸 Expenses'!$G$8:$G$67) -> 0
N18: Birthday | O18: =SUMIFS('📅 Events'!$L$8:$L$47,'📅 Events'!$F$8:$F$47,$N18,'📅 Events'!$Q$8:$Q$47,"<>❌ Cancelled") -> 0 | AA18: =IFERROR(AGGREGATE(15,6,'📅 Events'!$E$8:$E$47/('📅 Events'!$E$8:$E$47>=TODAY())*('📅 Events'!$Q$8:$Q$47<>"❌ Cancelled")*('📅 Events'!$Q$8:$Q$47<>"🎉 Completed"),17),"") | AB18: =IF($AA18="","",INDEX('📅 Events'!$D$8:$D$47,MATCH($AA18,'📅 Events'!$E$8:$E$47,0))&" - "&INDEX('📅 Events'!$F$8:$F$47,MATCH($AA18,'📅 Events'!$E$8:$E$47,0))) | AC18: =IF($AA18="","",INDEX('📅 Events'!$Q$8:$Q$47,MATCH($AA18,'📅 Events'!$E$8:$E$47,0))) | AE18: Staff / labor spend | AF18: =SUMIF('💸 Expenses'!$E$8:$E$67,"Staff / Labor",'💸 Expenses'!$G$8:$G$67) -> 0
N19: Private Party | O19: =SUMIFS('📅 Events'!$L$8:$L$47,'📅 Events'!$F$8:$F$47,$N19,'📅 Events'!$Q$8:$Q$47,"<>❌ Cancelled") -> 0 | AA19: =IFERROR(AGGREGATE(15,6,'📅 Events'!$E$8:$E$47/('📅 Events'!$E$8:$E$47>=TODAY())*('📅 Events'!$Q$8:$Q$47<>"❌ Cancelled")*('📅 Events'!$Q$8:$Q$47<>"🎉 Completed"),18),"") | AB19: =IF($AA19="","",INDEX('📅 Events'!$D$8:$D$47,MATCH($AA19,'📅 Events'!$E$8:$E$47,0))&" - "&INDEX('📅 Events'!$F$8:$F$47,MATCH($AA19,'📅 Events'!$E$8:$E$47,0))) | AC19: =IF($AA19="","",INDEX('📅 Events'!$Q$8:$Q$47,MATCH($AA19,'📅 Events'!$E$8:$E$47,0))) | AE19: Food cost % of revenue | AF19: =IFERROR($AF$17/$AF$2,0) -> 0
N20: Buffet | O20: =SUMIFS('📅 Events'!$L$8:$L$47,'📅 Events'!$F$8:$F$47,$N20,'📅 Events'!$Q$8:$Q$47,"<>❌ Cancelled") -> 0 | AA20: =IFERROR(AGGREGATE(15,6,'📅 Events'!$E$8:$E$47/('📅 Events'!$E$8:$E$47>=TODAY())*('📅 Events'!$Q$8:$Q$47<>"❌ Cancelled")*('📅 Events'!$Q$8:$Q$47<>"🎉 Completed"),19),"") | AB20: =IF($AA20="","",INDEX('📅 Events'!$D$8:$D$47,MATCH($AA20,'📅 Events'!$E$8:$E$47,0))&" - "&INDEX('📅 Events'!$F$8:$F$47,MATCH($AA20,'📅 Events'!$E$8:$E$47,0))) | AC20: =IF($AA20="","",INDEX('📅 Events'!$Q$8:$Q$47,MATCH($AA20,'📅 Events'!$E$8:$E$47,0))) | AE20: Labor cost % of revenue | AF20: =IFERROR($AF$18/$AF$2,0) -> 0
N21: Cocktail | O21: =SUMIFS('📅 Events'!$L$8:$L$47,'📅 Events'!$F$8:$F$47,$N21,'📅 Events'!$Q$8:$Q$47,"<>❌ Cancelled") -> 0 | AA21: =IFERROR(AGGREGATE(15,6,'📅 Events'!$E$8:$E$47/('📅 Events'!$E$8:$E$47>=TODAY())*('📅 Events'!$Q$8:$Q$47<>"❌ Cancelled")*('📅 Events'!$Q$8:$Q$47<>"🎉 Completed"),20),"") | AB21: =IF($AA21="","",INDEX('📅 Events'!$D$8:$D$47,MATCH($AA21,'📅 Events'!$E$8:$E$47,0))&" - "&INDEX('📅 Events'!$F$8:$F$47,MATCH($AA21,'📅 Events'!$E$8:$E$47,0))) | AC21: =IF($AA21="","",INDEX('📅 Events'!$Q$8:$Q$47,MATCH($AA21,'📅 Events'!$E$8:$E$47,0))) | AE21: Repeat customer % | AF21: =IFERROR(SUMPRODUCT((COUNTIF('👥 Clients'!$C$8:$C$47,'👥 Clients'!$C$8:$C$47&"")>1)*(('👥 Clients'!$C$8:$C$47&"")<>"")*1)/COUNTA('👥 Clients'!$C$8:$C$47),0) -> 0
N22: Conference | O22: =SUMIFS('📅 Events'!$L$8:$L$47,'📅 Events'!$F$8:$F$47,$N22,'📅 Events'!$Q$8:$Q$47,"<>❌ Cancelled") -> 0 | AA22: =IFERROR(AGGREGATE(15,6,'📅 Events'!$E$8:$E$47/('📅 Events'!$E$8:$E$47>=TODAY())*('📅 Events'!$Q$8:$Q$47<>"❌ Cancelled")*('📅 Events'!$Q$8:$Q$47<>"🎉 Completed"),21),"") | AB22: =IF($AA22="","",INDEX('📅 Events'!$D$8:$D$47,MATCH($AA22,'📅 Events'!$E$8:$E$47,0))&" - "&INDEX('📅 Events'!$F$8:$F$47,MATCH($AA22,'📅 Events'!$E$8:$E$47,0))) | AC22: =IF($AA22="","",INDEX('📅 Events'!$Q$8:$Q$47,MATCH($AA22,'📅 Events'!$E$8:$E$47,0))) | AE22: Inventory value | AF22: =SUM('📦 Inventory'!$I$8:$I$47) -> 0
N23: Festival | O23: =SUMIFS('📅 Events'!$L$8:$L$47,'📅 Events'!$F$8:$F$47,$N23,'📅 Events'!$Q$8:$Q$47,"<>❌ Cancelled") -> 0 | AA23: =IFERROR(AGGREGATE(15,6,'📅 Events'!$E$8:$E$47/('📅 Events'!$E$8:$E$47>=TODAY())*('📅 Events'!$Q$8:$Q$47<>"❌ Cancelled")*('📅 Events'!$Q$8:$Q$47<>"🎉 Completed"),22),"") | AB23: =IF($AA23="","",INDEX('📅 Events'!$D$8:$D$47,MATCH($AA23,'📅 Events'!$E$8:$E$47,0))&" - "&INDEX('📅 Events'!$F$8:$F$47,MATCH($AA23,'📅 Events'!$E$8:$E$47,0))) | AC23: =IF($AA23="","",INDEX('📅 Events'!$Q$8:$Q$47,MATCH($AA23,'📅 Events'!$E$8:$E$47,0))) | AE23: Ingredients below minimum | AF23: =COUNTIF('📦 Inventory'!$K$8:$K$47,"🔴 Reorder") -> 0
N24: Other | O24: =SUMIFS('📅 Events'!$L$8:$L$47,'📅 Events'!$F$8:$F$47,$N24,'📅 Events'!$Q$8:$Q$47,"<>❌ Cancelled") -> 0 | AA24: =IFERROR(AGGREGATE(15,6,'📅 Events'!$E$8:$E$47/('📅 Events'!$E$8:$E$47>=TODAY())*('📅 Events'!$Q$8:$Q$47<>"❌ Cancelled")*('📅 Events'!$Q$8:$Q$47<>"🎉 Completed"),23),"") | AB24: =IF($AA24="","",INDEX('📅 Events'!$D$8:$D$47,MATCH($AA24,'📅 Events'!$E$8:$E$47,0))&" - "&INDEX('📅 Events'!$F$8:$F$47,MATCH($AA24,'📅 Events'!$E$8:$E$47,0))) | AC24: =IF($AA24="","",INDEX('📅 Events'!$Q$8:$Q$47,MATCH($AA24,'📅 Events'!$E$8:$E$47,0))) | AE24: Shopping lines open | AF24: =SUMPRODUCT(ISNUMBER('🛒 Shopping List'!$G$8:$G$47)*('🛒 Shopping List'!$G$8:$G$47>0)*('🛒 Shopping List'!$J$8:$J$47<>"✓")) -> 0
Q25: Client | R25: Received | T25: Menu item | U25: Booked | AA25: =IFERROR(AGGREGATE(15,6,'📅 Events'!$E$8:$E$47/('📅 Events'!$E$8:$E$47>=TODAY())*('📅 Events'!$Q$8:$Q$47<>"❌ Cancelled")*('📅 Events'!$Q$8:$Q$47<>"🎉 Completed"),24),"") | AB25: =IF($AA25="","",INDEX('📅 Events'!$D$8:$D$47,MATCH($AA25,'📅 Events'!$E$8:$E$47,0))&" - "&INDEX('📅 Events'!$F$8:$F$47,MATCH($AA25,'📅 Events'!$E$8:$E$47,0))) | AC25: =IF($AA25="","",INDEX('📅 Events'!$Q$8:$Q$47,MATCH($AA25,'📅 Events'!$E$8:$E$47,0))) | AE25: Shopping list estimated cost | AF25: =SUMPRODUCT(ISNUMBER('🛒 Shopping List'!$G$8:$G$47)*('🛒 Shopping List'!$G$8:$G$47>0)*('🛒 Shopping List'!$J$8:$J$47<>"✓"),'🛒 Shopping List'!$I$8:$I$47) -> 0
Q26: =IF('👥 Clients'!$C$8="","",'👥 Clients'!$C$8) | R26: =IF($Q26="","",SUMIF('💰 Payments'!$D$8:$D$67,$Q26,'💰 Payments'!$J$8:$J$67)) | T26: =IF('🍽️ Menu Costing'!$C$8="","",'🍽️ Menu Costing'!$C$8) | U26: =IF($T26="","",SUMPRODUCT(('📅 Events'!$H$8:$H$47<>"")*IFERROR(--ISNUMBER(SEARCH($T26,'📅 Events'!$H$8:$H$47)),0))) | AA26: =IFERROR(AGGREGATE(15,6,'📅 Events'!$E$8:$E$47/('📅 Events'!$E$8:$E$47>=TODAY())*('📅 Events'!$Q$8:$Q$47<>"❌ Cancelled")*('📅 Events'!$Q$8:$Q$47<>"🎉 Completed"),25),"") | AB26: =IF($AA26="","",INDEX('📅 Events'!$D$8:$D$47,MATCH($AA26,'📅 Events'!$E$8:$E$47,0))&" - "&INDEX('📅 Events'!$F$8:$F$47,MATCH($AA26,'📅 Events'!$E$8:$E$47,0))) | AC26: =IF($AA26="","",INDEX('📅 Events'!$Q$8:$Q$47,MATCH($AA26,'📅 Events'!$E$8:$E$47,0))) | AE26: Unpaid staff shifts | AF26: =SUMPRODUCT(('👷 Staff & Labor'!$C$8:$C$57<>"")*('👷 Staff & Labor'!$J$8:$J$57<>"✓")) -> 0
N27: Status | O27: Events | Q27: =IF('👥 Clients'!$C$9="","",'👥 Clients'!$C$9) | R27: =IF($Q27="","",SUMIF('💰 Payments'!$D$8:$D$67,$Q27,'💰 Payments'!$J$8:$J$67)) | T27: =IF('🍽️ Menu Costing'!$C$9="","",'🍽️ Menu Costing'!$C$9) | U27: =IF($T27="","",SUMPRODUCT(('📅 Events'!$H$8:$H$47<>"")*IFERROR(--ISNUMBER(SEARCH($T27,'📅 Events'!$H$8:$H$47)),0))) | AA27: =IFERROR(AGGREGATE(15,6,'📅 Events'!$E$8:$E$47/('📅 Events'!$E$8:$E$47>=TODAY())*('📅 Events'!$Q$8:$Q$47<>"❌ Cancelled")*('📅 Events'!$Q$8:$Q$47<>"🎉 Completed"),26),"") | AB27: =IF($AA27="","",INDEX('📅 Events'!$D$8:$D$47,MATCH($AA27,'📅 Events'!$E$8:$E$47,0))&" - "&INDEX('📅 Events'!$F$8:$F$47,MATCH($AA27,'📅 Events'!$E$8:$E$47,0))) | AC27: =IF($AA27="","",INDEX('📅 Events'!$Q$8:$Q$47,MATCH($AA27,'📅 Events'!$E$8:$E$47,0))) | AE27: Equipment value | AF27: =SUM('🍳 Equipment'!$J$8:$J$42) -> 0
N28: 💬 Inquiry | O28: =COUNTIF('📅 Events'!$Q$8:$Q$47,$N28) -> 0 | Q28: =IF('👥 Clients'!$C$10="","",'👥 Clients'!$C$10) | R28: =IF($Q28="","",SUMIF('💰 Payments'!$D$8:$D$67,$Q28,'💰 Payments'!$J$8:$J$67)) | T28: =IF('🍽️ Menu Costing'!$C$10="","",'🍽️ Menu Costing'!$C$10) | U28: =IF($T28="","",SUMPRODUCT(('📅 Events'!$H$8:$H$47<>"")*IFERROR(--ISNUMBER(SEARCH($T28,'📅 Events'!$H$8:$H$47)),0))) | AA28: =IFERROR(AGGREGATE(15,6,'📅 Events'!$E$8:$E$47/('📅 Events'!$E$8:$E$47>=TODAY())*('📅 Events'!$Q$8:$Q$47<>"❌ Cancelled")*('📅 Events'!$Q$8:$Q$47<>"🎉 Completed"),27),"") | AB28: =IF($AA28="","",INDEX('📅 Events'!$D$8:$D$47,MATCH($AA28,'📅 Events'!$E$8:$E$47,0))&" - "&INDEX('📅 Events'!$F$8:$F$47,MATCH($AA28,'📅 Events'!$E$8:$E$47,0))) | AC28: =IF($AA28="","",INDEX('📅 Events'!$Q$8:$Q$47,MATCH($AA28,'📅 Events'!$E$8:$E$47,0))) | AE28: Equipment needing service | AF28: =COUNTIF('🍳 Equipment'!$L$8:$L$42,"🔧 Service")+COUNTIF('🍳 Equipment'!$L$8:$L$42,"🟡 Soon") -> 0
N29: 📝 Quote Sent | O29: =COUNTIF('📅 Events'!$Q$8:$Q$47,$N29) -> 0 | Q29: =IF('👥 Clients'!$C$11="","",'👥 Clients'!$C$11) | R29: =IF($Q29="","",SUMIF('💰 Payments'!$D$8:$D$67,$Q29,'💰 Payments'!$J$8:$J$67)) | T29: =IF('🍽️ Menu Costing'!$C$11="","",'🍽️ Menu Costing'!$C$11) | U29: =IF($T29="","",SUMPRODUCT(('📅 Events'!$H$8:$H$47<>"")*IFERROR(--ISNUMBER(SEARCH($T29,'📅 Events'!$H$8:$H$47)),0))) | AA29: =IFERROR(AGGREGATE(15,6,'📅 Events'!$E$8:$E$47/('📅 Events'!$E$8:$E$47>=TODAY())*('📅 Events'!$Q$8:$Q$47<>"❌ Cancelled")*('📅 Events'!$Q$8:$Q$47<>"🎉 Completed"),28),"") | AB29: =IF($AA29="","",INDEX('📅 Events'!$D$8:$D$47,MATCH($AA29,'📅 Events'!$E$8:$E$47,0))&" - "&INDEX('📅 Events'!$F$8:$F$47,MATCH($AA29,'📅 Events'!$E$8:$E$47,0))) | AC29: =IF($AA29="","",INDEX('📅 Events'!$Q$8:$Q$47,MATCH($AA29,'📅 Events'!$E$8:$E$47,0))) | AE29: Tax collected on sales | AF29: ='🧾 Tax Tracker'!$C$11 -> 0
N30: 💰 Deposit Paid | O30: =COUNTIF('📅 Events'!$Q$8:$Q$47,$N30) -> 0 | Q30: =IF('👥 Clients'!$C$12="","",'👥 Clients'!$C$12) | R30: =IF($Q30="","",SUMIF('💰 Payments'!$D$8:$D$67,$Q30,'💰 Payments'!$J$8:$J$67)) | T30: =IF('🍽️ Menu Costing'!$C$12="","",'🍽️ Menu Costing'!$C$12) | U30: =IF($T30="","",SUMPRODUCT(('📅 Events'!$H$8:$H$47<>"")*IFERROR(--ISNUMBER(SEARCH($T30,'📅 Events'!$H$8:$H$47)),0))) | AA30: =IFERROR(AGGREGATE(15,6,'📅 Events'!$E$8:$E$47/('📅 Events'!$E$8:$E$47>=TODAY())*('📅 Events'!$Q$8:$Q$47<>"❌ Cancelled")*('📅 Events'!$Q$8:$Q$47<>"🎉 Completed"),29),"") | AB30: =IF($AA30="","",INDEX('📅 Events'!$D$8:$D$47,MATCH($AA30,'📅 Events'!$E$8:$E$47,0))&" - "&INDEX('📅 Events'!$F$8:$F$47,MATCH($AA30,'📅 Events'!$E$8:$E$47,0))) | AC30: =IF($AA30="","",INDEX('📅 Events'!$Q$8:$Q$47,MATCH($AA30,'📅 Events'!$E$8:$E$47,0))) | AE30: Estimated tax still due | AF30: ='🧾 Tax Tracker'!$C$13 -> 0
N31: ✅ Confirmed | O31: =COUNTIF('📅 Events'!$Q$8:$Q$47,$N31) -> 0 | Q31: =IF('👥 Clients'!$C$13="","",'👥 Clients'!$C$13) | R31: =IF($Q31="","",SUMIF('💰 Payments'!$D$8:$D$67,$Q31,'💰 Payments'!$J$8:$J$67)) | T31: =IF('🍽️ Menu Costing'!$C$13="","",'🍽️ Menu Costing'!$C$13) | U31: =IF($T31="","",SUMPRODUCT(('📅 Events'!$H$8:$H$47<>"")*IFERROR(--ISNUMBER(SEARCH($T31,'📅 Events'!$H$8:$H$47)),0))) | AA31: =IFERROR(AGGREGATE(15,6,'📅 Events'!$E$8:$E$47/('📅 Events'!$E$8:$E$47>=TODAY())*('📅 Events'!$Q$8:$Q$47<>"❌ Cancelled")*('📅 Events'!$Q$8:$Q$47<>"🎉 Completed"),30),"") | AB31: =IF($AA31="","",INDEX('📅 Events'!$D$8:$D$47,MATCH($AA31,'📅 Events'!$E$8:$E$47,0))&" - "&INDEX('📅 Events'!$F$8:$F$47,MATCH($AA31,'📅 Events'!$E$8:$E$47,0))) | AC31: =IF($AA31="","",INDEX('📅 Events'!$Q$8:$Q$47,MATCH($AA31,'📅 Events'!$E$8:$E$47,0))) | AE31: Quote calculator: recommended price | AF31: ='🧮 Quote Calculator'!$E$16 -> 0
N32: 🎉 Completed | O32: =COUNTIF('📅 Events'!$Q$8:$Q$47,$N32) -> 0 | Q32: =IF('👥 Clients'!$C$14="","",'👥 Clients'!$C$14) | R32: =IF($Q32="","",SUMIF('💰 Payments'!$D$8:$D$67,$Q32,'💰 Payments'!$J$8:$J$67)) | T32: =IF('🍽️ Menu Costing'!$C$14="","",'🍽️ Menu Costing'!$C$14) | U32: =IF($T32="","",SUMPRODUCT(('📅 Events'!$H$8:$H$47<>"")*IFERROR(--ISNUMBER(SEARCH($T32,'📅 Events'!$H$8:$H$47)),0))) | AA32: =IFERROR(AGGREGATE(15,6,'📅 Events'!$E$8:$E$47/('📅 Events'!$E$8:$E$47>=TODAY())*('📅 Events'!$Q$8:$Q$47<>"❌ Cancelled")*('📅 Events'!$Q$8:$Q$47<>"🎉 Completed"),31),"") | AB32: =IF($AA32="","",INDEX('📅 Events'!$D$8:$D$47,MATCH($AA32,'📅 Events'!$E$8:$E$47,0))&" - "&INDEX('📅 Events'!$F$8:$F$47,MATCH($AA32,'📅 Events'!$E$8:$E$47,0))) | AC32: =IF($AA32="","",INDEX('📅 Events'!$Q$8:$Q$47,MATCH($AA32,'📅 Events'!$E$8:$E$47,0))) | AE32: Quote calculator: price per guest | AF32: ='🧮 Quote Calculator'!$E$17 -> 0
N33: ❌ Cancelled | O33: =COUNTIF('📅 Events'!$Q$8:$Q$47,$N33) -> 0 | Q33: =IF('👥 Clients'!$C$15="","",'👥 Clients'!$C$15) | R33: =IF($Q33="","",SUMIF('💰 Payments'!$D$8:$D$67,$Q33,'💰 Payments'!$J$8:$J$67)) | T33: =IF('🍽️ Menu Costing'!$C$15="","",'🍽️ Menu Costing'!$C$15) | U33: =IF($T33="","",SUMPRODUCT(('📅 Events'!$H$8:$H$47<>"")*IFERROR(--ISNUMBER(SEARCH($T33,'📅 Events'!$H$8:$H$47)),0))) | AA33: =IFERROR(AGGREGATE(15,6,'📅 Events'!$E$8:$E$47/('📅 Events'!$E$8:$E$47>=TODAY())*('📅 Events'!$Q$8:$Q$47<>"❌ Cancelled")*('📅 Events'!$Q$8:$Q$47<>"🎉 Completed"),32),"") | AB33: =IF($AA33="","",INDEX('📅 Events'!$D$8:$D$47,MATCH($AA33,'📅 Events'!$E$8:$E$47,0))&" - "&INDEX('📅 Events'!$F$8:$F$47,MATCH($AA33,'📅 Events'!$E$8:$E$47,0))) | AC33: =IF($AA33="","",INDEX('📅 Events'!$Q$8:$Q$47,MATCH($AA33,'📅 Events'!$E$8:$E$47,0))) | AE33: Menu items priced | AF33: =COUNTA('🍽️ Menu Costing'!$C$8:$C$37) -> 0
Q34: =IF('👥 Clients'!$C$16="","",'👥 Clients'!$C$16) | R34: =IF($Q34="","",SUMIF('💰 Payments'!$D$8:$D$67,$Q34,'💰 Payments'!$J$8:$J$67)) | T34: =IF('🍽️ Menu Costing'!$C$16="","",'🍽️ Menu Costing'!$C$16) | U34: =IF($T34="","",SUMPRODUCT(('📅 Events'!$H$8:$H$47<>"")*IFERROR(--ISNUMBER(SEARCH($T34,'📅 Events'!$H$8:$H$47)),0))) | AA34: =IFERROR(AGGREGATE(15,6,'📅 Events'!$E$8:$E$47/('📅 Events'!$E$8:$E$47>=TODAY())*('📅 Events'!$Q$8:$Q$47<>"❌ Cancelled")*('📅 Events'!$Q$8:$Q$47<>"🎉 Completed"),33),"") | AB34: =IF($AA34="","",INDEX('📅 Events'!$D$8:$D$47,MATCH($AA34,'📅 Events'!$E$8:$E$47,0))&" - "&INDEX('📅 Events'!$F$8:$F$47,MATCH($AA34,'📅 Events'!$E$8:$E$47,0))) | AC34: =IF($AA34="","",INDEX('📅 Events'!$Q$8:$Q$47,MATCH($AA34,'📅 Events'!$E$8:$E$47,0))) | AE34: Average menu margin | AF34: =IFERROR(AVERAGE('🍽️ Menu Costing'!$J$8:$J$37),0) -> 0
Q35: =IF('👥 Clients'!$C$17="","",'👥 Clients'!$C$17) | R35: =IF($Q35="","",SUMIF('💰 Payments'!$D$8:$D$67,$Q35,'💰 Payments'!$J$8:$J$67)) | T35: =IF('🍽️ Menu Costing'!$C$17="","",'🍽️ Menu Costing'!$C$17) | U35: =IF($T35="","",SUMPRODUCT(('📅 Events'!$H$8:$H$47<>"")*IFERROR(--ISNUMBER(SEARCH($T35,'📅 Events'!$H$8:$H$47)),0))) | AA35: =IFERROR(AGGREGATE(15,6,'📅 Events'!$E$8:$E$47/('📅 Events'!$E$8:$E$47>=TODAY())*('📅 Events'!$Q$8:$Q$47<>"❌ Cancelled")*('📅 Events'!$Q$8:$Q$47<>"🎉 Completed"),34),"") | AB35: =IF($AA35="","",INDEX('📅 Events'!$D$8:$D$47,MATCH($AA35,'📅 Events'!$E$8:$E$47,0))&" - "&INDEX('📅 Events'!$F$8:$F$47,MATCH($AA35,'📅 Events'!$E$8:$E$47,0))) | AC35: =IF($AA35="","",INDEX('📅 Events'!$Q$8:$Q$47,MATCH($AA35,'📅 Events'!$E$8:$E$47,0))) | AE35: Best earning event type | AF35: =IF(MAX($O$16:$O$24)=0,"-",INDEX($N$16:$N$24,MATCH(MAX($O$16:$O$24),$O$16:$O$24,0))) -> 0
Q36: =IF('👥 Clients'!$C$18="","",'👥 Clients'!$C$18) | R36: =IF($Q36="","",SUMIF('💰 Payments'!$D$8:$D$67,$Q36,'💰 Payments'!$J$8:$J$67)) | T36: =IF('🍽️ Menu Costing'!$C$18="","",'🍽️ Menu Costing'!$C$18) | U36: =IF($T36="","",SUMPRODUCT(('📅 Events'!$H$8:$H$47<>"")*IFERROR(--ISNUMBER(SEARCH($T36,'📅 Events'!$H$8:$H$47)),0))) | AA36: =IFERROR(AGGREGATE(15,6,'📅 Events'!$E$8:$E$47/('📅 Events'!$E$8:$E$47>=TODAY())*('📅 Events'!$Q$8:$Q$47<>"❌ Cancelled")*('📅 Events'!$Q$8:$Q$47<>"🎉 Completed"),35),"") | AB36: =IF($AA36="","",INDEX('📅 Events'!$D$8:$D$47,MATCH($AA36,'📅 Events'!$E$8:$E$47,0))&" - "&INDEX('📅 Events'!$F$8:$F$47,MATCH($AA36,'📅 Events'!$E$8:$E$47,0))) | AC36: =IF($AA36="","",INDEX('📅 Events'!$Q$8:$Q$47,MATCH($AA36,'📅 Events'!$E$8:$E$47,0))) | AE36: Highest value client | AF36: =IF(MAX($R$26:$R$40)=0,"-",INDEX($Q$26:$Q$40,MATCH(MAX($R$26:$R$40),$R$26:$R$40,0))) -> 0
Q37: =IF('👥 Clients'!$C$19="","",'👥 Clients'!$C$19) | R37: =IF($Q37="","",SUMIF('💰 Payments'!$D$8:$D$67,$Q37,'💰 Payments'!$J$8:$J$67)) | T37: =IF('🍽️ Menu Costing'!$C$19="","",'🍽️ Menu Costing'!$C$19) | U37: =IF($T37="","",SUMPRODUCT(('📅 Events'!$H$8:$H$47<>"")*IFERROR(--ISNUMBER(SEARCH($T37,'📅 Events'!$H$8:$H$47)),0))) | AA37: =IFERROR(AGGREGATE(15,6,'📅 Events'!$E$8:$E$47/('📅 Events'!$E$8:$E$47>=TODAY())*('📅 Events'!$Q$8:$Q$47<>"❌ Cancelled")*('📅 Events'!$Q$8:$Q$47<>"🎉 Completed"),36),"") | AB37: =IF($AA37="","",INDEX('📅 Events'!$D$8:$D$47,MATCH($AA37,'📅 Events'!$E$8:$E$47,0))&" - "&INDEX('📅 Events'!$F$8:$F$47,MATCH($AA37,'📅 Events'!$E$8:$E$47,0))) | AC37: =IF($AA37="","",INDEX('📅 Events'!$Q$8:$Q$47,MATCH($AA37,'📅 Events'!$E$8:$E$47,0)))
Q38: =IF('👥 Clients'!$C$20="","",'👥 Clients'!$C$20) | R38: =IF($Q38="","",SUMIF('💰 Payments'!$D$8:$D$67,$Q38,'💰 Payments'!$J$8:$J$67)) | T38: =IF('🍽️ Menu Costing'!$C$20="","",'🍽️ Menu Costing'!$C$20) | U38: =IF($T38="","",SUMPRODUCT(('📅 Events'!$H$8:$H$47<>"")*IFERROR(--ISNUMBER(SEARCH($T38,'📅 Events'!$H$8:$H$47)),0))) | AA38: =IFERROR(AGGREGATE(15,6,'📅 Events'!$E$8:$E$47/('📅 Events'!$E$8:$E$47>=TODAY())*('📅 Events'!$Q$8:$Q$47<>"❌ Cancelled")*('📅 Events'!$Q$8:$Q$47<>"🎉 Completed"),37),"") | AB38: =IF($AA38="","",INDEX('📅 Events'!$D$8:$D$47,MATCH($AA38,'📅 Events'!$E$8:$E$47,0))&" - "&INDEX('📅 Events'!$F$8:$F$47,MATCH($AA38,'📅 Events'!$E$8:$E$47,0))) | AC38: =IF($AA38="","",INDEX('📅 Events'!$Q$8:$Q$47,MATCH($AA38,'📅 Events'!$E$8:$E$47,0)))
Q39: =IF('👥 Clients'!$C$21="","",'👥 Clients'!$C$21) | R39: =IF($Q39="","",SUMIF('💰 Payments'!$D$8:$D$67,$Q39,'💰 Payments'!$J$8:$J$67)) | T39: =IF('🍽️ Menu Costing'!$C$21="","",'🍽️ Menu Costing'!$C$21) | U39: =IF($T39="","",SUMPRODUCT(('📅 Events'!$H$8:$H$47<>"")*IFERROR(--ISNUMBER(SEARCH($T39,'📅 Events'!$H$8:$H$47)),0))) | AA39: =IFERROR(AGGREGATE(15,6,'📅 Events'!$E$8:$E$47/('📅 Events'!$E$8:$E$47>=TODAY())*('📅 Events'!$Q$8:$Q$47<>"❌ Cancelled")*('📅 Events'!$Q$8:$Q$47<>"🎉 Completed"),38),"") | AB39: =IF($AA39="","",INDEX('📅 Events'!$D$8:$D$47,MATCH($AA39,'📅 Events'!$E$8:$E$47,0))&" - "&INDEX('📅 Events'!$F$8:$F$47,MATCH($AA39,'📅 Events'!$E$8:$E$47,0))) | AC39: =IF($AA39="","",INDEX('📅 Events'!$Q$8:$Q$47,MATCH($AA39,'📅 Events'!$E$8:$E$47,0)))
Q40: =IF('👥 Clients'!$C$22="","",'👥 Clients'!$C$22) | R40: =IF($Q40="","",SUMIF('💰 Payments'!$D$8:$D$67,$Q40,'💰 Payments'!$J$8:$J$67)) | T40: =IF('🍽️ Menu Costing'!$C$22="","",'🍽️ Menu Costing'!$C$22) | U40: =IF($T40="","",SUMPRODUCT(('📅 Events'!$H$8:$H$47<>"")*IFERROR(--ISNUMBER(SEARCH($T40,'📅 Events'!$H$8:$H$47)),0))) | AA40: =IFERROR(AGGREGATE(15,6,'📅 Events'!$E$8:$E$47/('📅 Events'!$E$8:$E$47>=TODAY())*('📅 Events'!$Q$8:$Q$47<>"❌ Cancelled")*('📅 Events'!$Q$8:$Q$47<>"🎉 Completed"),39),"") | AB40: =IF($AA40="","",INDEX('📅 Events'!$D$8:$D$47,MATCH($AA40,'📅 Events'!$E$8:$E$47,0))&" - "&INDEX('📅 Events'!$F$8:$F$47,MATCH($AA40,'📅 Events'!$E$8:$E$47,0))) | AC40: =IF($AA40="","",INDEX('📅 Events'!$Q$8:$Q$47,MATCH($AA40,'📅 Events'!$E$8:$E$47,0)))
...

Sheet ⚙️ Setup
B2: Settings & lists
B3: Set up once - every tab reads from here | G3: 🏠 Back to Dashboard
B5: 1 · Your business
B6: Business name | H6: Shown on the Dashboard and the Invoice tab.
B7: Dashboard note | H7: A little reminder for the team - shown under the Dashboard title.
B9: 2 · Money settings
B10: Currency symbol | C10: $ | H10: Pick from the dropdown, or type your own symbol.
B11: Sales tax / VAT rate | C11: 0 | H11: Applied on the Invoice tab and in the Tax Tracker.
B12: Target profit margin | C12: 0.35 | H12: The Quote Calculator prices events to hit this.
B13: Deposit to confirm | C13: 0.4 | H13: Suggested deposit share of the total price.
B14: “Due soon” window (days) | C14: 7 | H14: Dates inside this window glow amber on every tab.
B15: Report year | C15: 2026 | H15: Drives the P&L and the Tax Tracker.
B17: 3 · Calendar
B18: Month to show | C18: 9 | H18: The Event Calendar tab shows this month (1 = January ... 12 = December).
B19: Year to show | C19: 2026
B21: 4 · Your dropdown lists (edit freely)
A22: Event types | B22: Expense categories | C22: Payment methods | D22: Staff roles | E22: Menu categories | F22: Ingredient categories
A23: Wedding | B23: Ingredients | C23: Cash | D23: Head Chef | E23: Starter | F23: Produce
A24: Corporate | B24: Packaging | C24: Bank Transfer | D24: Chef | E24: Main | F24: Meat & Fish
A25: Birthday | B25: Staff / Labor | C25: Card | D25: Sous Chef | E25: Dessert | F25: Dairy
A26: Private Party | B26: Transportation | C26: Cheque | D26: Server | E26: Sides | F26: Pantry
A27: Buffet | B27: Equipment | C27: Mobile Wallet | D27: Bartender | E27: Beverage | F27: Bakery
A28: Cocktail | B28: Kitchen Rental | C28: Other | D28: Driver | E28: Canapé | F28: Beverages
A29: Conference | B29: Marketing | D29: Setup Crew | E29: Other | F29: Packaging
A30: Festival | B30: Insurance | D30: Cleaner | F30: Other
A31: Other | B31: Utilities | D31: Manager
B32: Software | D32: Other
B33: Miscellaneous
B44: 5 · Fixed lists (the status formulas depend on these exact texts - locked)
B46: Event statuses | C46: Payment statuses | D46: Tick
B47: 💬 Inquiry | C47: 🔴 Unpaid | D47: ✓
B48: 📝 Quote Sent | C48: 🟠 Partial
B49: 💰 Deposit Paid | C49: 🟢 Paid in full
B50: ✅ Confirmed
B51: 🎉 Completed
B52: ❌ Cancelled
B56: Tip: empty rows in a list simply don't appear in the dropdowns. Add options at the bottom of a column and they show up everywhere, instantly.
B58: ▶ Setup | C58: 🏠 Home | D58: Clients | E58: Events | F58: Quote | G58: Menu | H58: Stock
B59: Shop | C59: Expenses | D59: Payments | E59: Staff | F59: Equip | G59: Suppliers | H59: Calendar
B60: P&L | C60: Tax | D60: Checks | E60: Invoice | F60: Help

Sheet 📊 Dashboard
B2: =IF(BusinessName="","Your Catering Business",BusinessName) -> Your Catering Business | K2: ="Cash in "&Currency&TEXT('_Data'!$AF$2,"#,##0") -> Cash in 0
B3: =IF('⚙️ Setup'!$C$7="","Events • Clients • Quotes • Food Cost • Profit",'⚙️ Setup'!$C$7) -> Events • Clients • Quotes • Food Cost • Profit
B5: CASH IN | F5: CASH OUT | J5: NET PROFIT | N5: NET MARGIN
B6: ='_Data'!$AF$2 -> 0 | F6: ='_Data'!$AF$3 -> 0 | J6: ='_Data'!$AF$4 -> 0 | N6: ='_Data'!$AF$5 -> 0
B8: EVENTS ON THE BOOKS | F8: CONFIRMED & COMING UP | J8: OUTSTANDING | N8: OVERDUE INVOICES
B9: =SUMPRODUCT(('📅 Events'!$Q$8:$Q$47<>"")*('📅 Events'!$Q$8:$Q$47<>"❌ Cancelled")) -> 0 | F9: ='_Data'!$AF$8 -> 0 | J9: ='_Data'!$AF$14 -> 0 | N9: ='_Data'!$AF$15 -> 0
B11: FOOD COST % | F11: LABOR % | J11: AVG ORDER VALUE | N11: GUESTS SERVED
B12: ='_Data'!$AF$19 -> 0 | F12: ='_Data'!$AF$20 -> 0 | J12: ='_Data'!$AF$10 -> 0 | N12: ='_Data'!$AF$13 -> 0
B14: INVENTORY VALUE | F14: LOW STOCK | J14: SHOPPING TO BUY | N14: UNPAID SHIFTS
B15: ='_Data'!$AF$22 -> 0 | F15: ='_Data'!$AF$23 -> 0 | J15: ='_Data'!$AF$24&" lines · "&Currency&TEXT('_Data'!$AF$25,"#,##0") -> 0 lines | N15: ='_Data'!$AF$26 -> 0
B18: How the season is going
B19: Collected vs invoiced | E19: =IFERROR(REPT("█",ROUND(MIN(1,IFERROR(('_Data'!$AF$2)/(SUM('💰 Payments'!$F$8:$F$67)),0))*18,0))&REPT("░",18-ROUND(MIN(1,IFERROR(('_Data'!$AF$2)/(SUM('💰 Payments'!$F$8:$F$67)),0))*18,0)),"░░░░░░░░░░░░░░░░░░") -> ░░░░░░░░░░░░░░░░░░ | M19: =IFERROR(TEXT(MIN(1,'_Data'!$AF$2/(SUM('💰 Payments'!$F$8:$F$67))),"0%"),"0%") -> 0%
B20: Costs vs cash in | E20: =IFERROR(REPT("█",ROUND(MIN(1,IFERROR((SUM('💸 Expenses'!$G$8:$G$67))/('_Data'!$AF$2),0))*18,0))&REPT("░",18-ROUND(MIN(1,IFERROR((SUM('💸 Expenses'!$G$8:$G$67))/('_Data'!$AF$2),0))*18,0)),"░░░░░░░░░░░░░░░░░░") -> ░░░░░░░░░░░░░░░░░░ | M20: =IFERROR(TEXT(MIN(1,SUM('💸 Expenses'!$G$8:$G$67)/('_Data'!$AF$2)),"0%"),"0%") -> 0%
B23: The picture
B67: Every number on this page updates itself from the other tabs - nothing here is typed by hand.
B69: Setup | E69: ▶ 🏠 Home | H69: Clients | K69: Events | N69: Quote
B70: Menu | E70: Stock | H70: Shop | K70: Expenses | N70: Payments
B71: Staff | E71: Equip | H71: Suppliers | K71: Calendar | N71: P&L
B72: Tax | E72: Checks | H72: Invoice | K72: Help

Sheet 👥 Clients
B2: Clients
B3: Everyone you cook for - balances and history in one place | M3: 🏠 Back to Dashboard
B5: ="Clients: "&COUNTA('👥 Clients'!$C$8:$C$47) -> Clients: 0 | D5: ="Repeat rate: "&TEXT('_Data'!$AF$21,"0%") -> Repeat rate: 0% | F5: ="Quotes out: "&Currency&TEXT(SUM('👥 Clients'!$K$8:$K$47),"#,##0") -> Quotes out: $0 | H5: ="Still owed: "&Currency&TEXT('_Data'!$AF$14,"#,##0") -> Still owed: $0
B7: # | C7: Client / company | D7: Phone | E7: Email | F7: Next event | G7: Event type | H7: Guests | I7: Venue / address | J7: Package | K7: Quoted | L7: Deposit | M7: Balance due | N7: Payment status | O7: Notes
B8: =IF($C8="","",ROW()-7) | M8: =IF(OR($K8="",$L8=""),"",ROUND($K8-$L8,2))
B9: =IF($C9="","",ROW()-7) | M9: =IF(OR($K9="",$L9=""),"",ROUND($K9-$L9,2))
B10: =IF($C10="","",ROW()-7) | M10: =IF(OR($K10="",$L10=""),"",ROUND($K10-$L10,2))
B11: =IF($C11="","",ROW()-7) | M11: =IF(OR($K11="",$L11=""),"",ROUND($K11-$L11,2))
B12: =IF($C12="","",ROW()-7) | M12: =IF(OR($K12="",$L12=""),"",ROUND($K12-$L12,2))
B13: =IF($C13="","",ROW()-7) | M13: =IF(OR($K13="",$L13=""),"",ROUND($K13-$L13,2))
B14: =IF($C14="","",ROW()-7) | M14: =IF(OR($K14="",$L14=""),"",ROUND($K14-$L14,2))
B15: =IF($C15="","",ROW()-7) | M15: =IF(OR($K15="",$L15=""),"",ROUND($K15-$L15,2))
B16: =IF($C16="","",ROW()-7) | M16: =IF(OR($K16="",$L16=""),"",ROUND($K16-$L16,2))
B17: =IF($C17="","",ROW()-7) | M17: =IF(OR($K17="",$L17=""),"",ROUND($K17-$L17,2))
B18: =IF($C18="","",ROW()-7) | M18: =IF(OR($K18="",$L18=""),"",ROUND($K18-$L18,2))
B19: =IF($C19="","",ROW()-7) | M19: =IF(OR($K19="",$L19=""),"",ROUND($K19-$L19,2))
... B47: =IF($C47="","",ROW()-7) | M47: =IF(OR($K47="",$L47=""),"",ROUND($K47-$L47,2))
B48: TOTALS | H48: =SUM('👥 Clients'!$H$8:$H$47) -> 0 | K48: =SUM('👥 Clients'!$K$8:$K$47) -> 0 | L48: =SUM('👥 Clients'!$L$8:$L$47) -> 0 | M48: =SUM('👥 Clients'!$K$8:$K$47)-SUM('👥 Clients'!$L$8:$L$47) -> 0
B50: How this tab works
B51: The Balance due column calculates itself (quote minus deposit) - type over the white cells only. Payment status drives the colours here and the receivables cards on the Dashboard.
B55: Setup | D55: 🏠 Home | F55: ▶ Clients | H55: Events | J55: Quote | L55: Menu | N55: Stock
B56: Shop | D56: Expenses | F56: Payments | H56: Staff | J56: Equip | L56: Suppliers | N56: Calendar
B57: P&L | D57: Tax | F57: Checks | H57: Invoice | J57: Help

Sheet 📅 Events
B2: Events
B3: Every booking - costs, pricing and profit per event | P3: 🏠 Back to Dashboard
B5: ="Bookings: "&SUMPRODUCT(('📅 Events'!$Q$8:$Q$47<>"")*('📅 Events'!$Q$8:$Q$47<>"❌ Cancelled")) -> Bookings: 0 | D5: ="In the pipeline: "&COUNTIF('📅 Events'!$Q$8:$Q$47,"📝 Quote Sent") + COUNTIF('📅 Events'!$Q$8:$Q$47,"💰 Deposit Paid") + COUNTIF('📅 Events'!$Q$8:$Q$47,"✅ Confirmed") + COUNTIF('📅 Events'!$Q$8:$Q$47,"🎉 Completed") -> In the pipeline: 0 | F5: ="Booked value: "&Currency&TEXT(SUMPRODUCT(('📅 Events'!$Q$8:$Q$47<>"❌ Cancelled")*'📅 Events'!$L$8:$L$47),"#,##0") -> Booked value: $0 | H5: ="Expected profit: "&Currency&TEXT(SUMPRODUCT(('📅 Events'!$Q$8:$Q$47<>"❌ Cancelled")*'📅 Events'!$L$8:$L$47)-SUMPRODUCT(('📅 Events'!$Q$8:$Q$47<>"❌ Cancelled")*'📅 Events'!$K$8:$K$47),"#,##0") -> Expected profit: $0
B7: # | C7: Event ID | D7: Client | E7: Date | F7: Type | G7: Guests | H7: Menu / dishes | I7: Crew | J7: Equipment needed | K7: Cost | L7: Price | M7: Profit | N7: Margin | O7: Deposit | P7: Balance | Q7: Status | R7: Notes
B8: =IF($C8="","",ROW()-7) | M8: =IF(OR($K8="",$L8=""),"",ROUND($L8-$K8,2)) | N8: =IFERROR(IF($M8="","",$M8/$L8),"") | P8: =IF($L8="","",ROUND($L8-$O8,2))
B9: =IF($C9="","",ROW()-7) | M9: =IF(OR($K9="",$L9=""),"",ROUND($L9-$K9,2)) | N9: =IFERROR(IF($M9="","",$M9/$L9),"") | P9: =IF($L9="","",ROUND($L9-$O9,2))
B10: =IF($C10="","",ROW()-7) | M10: =IF(OR($K10="",$L10=""),"",ROUND($L10-$K10,2)) | N10: =IFERROR(IF($M10="","",$M10/$L10),"") | P10: =IF($L10="","",ROUND($L10-$O10,2))
B11: =IF($C11="","",ROW()-7) | M11: =IF(OR($K11="",$L11=""),"",ROUND($L11-$K11,2)) | N11: =IFERROR(IF($M11="","",$M11/$L11),"") | P11: =IF($L11="","",ROUND($L11-$O11,2))
B12: =IF($C12="","",ROW()-7) | M12: =IF(OR($K12="",$L12=""),"",ROUND($L12-$K12,2)) | N12: =IFERROR(IF($M12="","",$M12/$L12),"") | P12: =IF($L12="","",ROUND($L12-$O12,2))
B13: =IF($C13="","",ROW()-7) | M13: =IF(OR($K13="",$L13=""),"",ROUND($L13-$K13,2)) | N13: =IFERROR(IF($M13="","",$M13/$L13),"") | P13: =IF($L13="","",ROUND($L13-$O13,2))
B14: =IF($C14="","",ROW()-7) | M14: =IF(OR($K14="",$L14=""),"",ROUND($L14-$K14,2)) | N14: =IFERROR(IF($M14="","",$M14/$L14),"") | P14: =IF($L14="","",ROUND($L14-$O14,2))
B15: =IF($C15="","",ROW()-7) | M15: =IF(OR($K15="",$L15=""),"",ROUND($L15-$K15,2)) | N15: =IFERROR(IF($M15="","",$M15/$L15),"") | P15: =IF($L15="","",ROUND($L15-$O15,2))
B16: =IF($C16="","",ROW()-7) | M16: =IF(OR($K16="",$L16=""),"",ROUND($L16-$K16,2)) | N16: =IFERROR(IF($M16="","",$M16/$L16),"") | P16: =IF($L16="","",ROUND($L16-$O16,2))
B17: =IF($C17="","",ROW()-7) | M17: =IF(OR($K17="",$L17=""),"",ROUND($L17-$K17,2)) | N17: =IFERROR(IF($M17="","",$M17/$L17),"") | P17: =IF($L17="","",ROUND($L17-$O17,2))
B18: =IF($C18="","",ROW()-7) | M18: =IF(OR($K18="",$L18=""),"",ROUND($L18-$K18,2)) | N18: =IFERROR(IF($M18="","",$M18/$L18),"") | P18: =IF($L18="","",ROUND($L18-$O18,2))
B19: =IF($C19="","",ROW()-7) | M19: =IF(OR($K19="",$L19=""),"",ROUND($L19-$K19,2)) | N19: =IFERROR(IF($M19="","",$M19/$L19),"") | P19: =IF($L19="","",ROUND($L19-$O19,2))
... B47: =IF($C47="","",ROW()-7) | M47: =IF(OR($K47="",$L47=""),"",ROUND($L47-$K47,2)) | N47: =IFERROR(IF($M47="","",$M47/$L47),"") | P47: =IF($L47="","",ROUND($L47-$O47,2))
B48: TOTALS | G48: =SUMPRODUCT(--('📅 Events'!$E$8:$E$47<>""),'📅 Events'!$G$8:$G$47) -> 0 | I48: =SUMPRODUCT(--('📅 Events'!$E$8:$E$47<>""),'📅 Events'!$I$8:$I$47) -> 0 | K48: =SUMPRODUCT(--('📅 Events'!$E$8:$E$47<>""),'📅 Events'!$K$8:$K$47) -> 0 | L48: =SUMPRODUCT(--('📅 Events'!$E$8:$E$47<>""),'📅 Events'!$L$8:$L$47) -> 0 | M48: =SUMPRODUCT(--('📅 Events'!$E$8:$E$47<>""),'📅 Events'!$M$8:$M$47) -> 0 | O48: =SUMPRODUCT(--('📅 Events'!$E$8:$E$47<>""),'📅 Events'!$O$8:$O$47) -> 0 | P48: =SUM('📅 Events'!$L$8:$L$47)-SUM('📅 Events'!$O$8:$O$47) -> 0
B50: How this tab works
B51: Profit, Margin and Balance calculate themselves - never type in the tinted columns. The Status pipeline feeds the Pipeline doughnut on the Dashboard; dates go amber inside your due-soon window and red once a live event has passed.
B55: Setup | D55: 🏠 Home | F55: Clients | H55: ▶ Events | J55: Quote | L55: Menu | N55: Stock | P55: Shop
B56: Expenses | D56: Payments | F56: Staff | H56: Equip | J56: Suppliers | L56: Calendar | N56: P&L | P56: Tax
B57: Checks | D57: Invoice | F57: Help

Sheet 🧮 Quote Calculator
B2: Quote Calculator
B3: Price an event in 30 seconds - margin, deposit and per-guest numbers included | D3: 🏠 Back to Dashboard
B8: 1 · Your inputs | D8: 2 · The quote (automatic)
B10: Client / enquiry
B11: Event date
B12: Guests
B14: Food cost per guest | D14: Food total | E14: =IF($C$12="","",ROUND($C$12*$C$14,2))
B15: Kitchen & service crew | D15: Total cost | E15: =IF($C$12="","",ROUND($C$12*$C$14+$C$15+$C$16+$C$17+$C$18,2))
B16: Equipment & rentals | D16: RECOMMENDED PRICE | E16: =IF($E$15="","",ROUND($E$15/(1-$C$20),2))
B17: Transport & fuel | D17: Price per guest | E17: =IF($E$16="","",ROUND($E$16/$C$12,2))
B18: Other costs | D18: Profit on the job | E18: =IF($E$16="","",ROUND($E$16-$E$15,2))
D19: Margin | E19: =IFERROR(IF($E$18="","",$E$18/$E$16),"")
B20: Target margin | C20: =DefaultMargin -> 0.35 | D20: Deposit to confirm | E20: =IF($E$16="","",ROUND($E$16*$C$21,2))
B21: Deposit % | C21: =DepositPct -> 0.4 | D21: Balance after deposit | E21: =IF($E$16="","",ROUND($E$16*(1-$C$21),2))
D22: Cost per guest | E22: =IF($E$15="","",ROUND($E$15/$C$12,2))
B24: =IF($E$16="","",Currency&TEXT($E$16,"#,##0.00")&" for the event · "&Currency&TEXT($E$17,"#,##0.00")&" per guest")
B27: How the math works
B28: • Price = Total cost ÷ (1 - margin). At a 35% target margin, $1,000 of costs prices at $1,538 - you keep $538.
B29: • The margin and deposit start from your Setup defaults; type over them here for a one-off quote without changing the defaults.
B30: • When they say yes: add the event on the Events tab, the deposit on the Payments tab, and the ingredients on the Shopping List.
B32: Setup | D32: 🏠 Home
B33: Clients | D33: Events
B34: ▶ Quote | D34: Menu
B35: Stock | D35: Shop
B36: Expenses | D36: Payments
B37: Staff | D37: Equip
B38: Suppliers | D38: Calendar
B39: P&L | D39: Tax
B40: Checks | D40: Invoice
B41: Help

Sheet 🍽️ Menu Costing
B2: Menu Costing
B3: Cost every dish - margins that make the quotes honest | I3: 🏠 Back to Dashboard
B5: ="Dishes priced: "&COUNTA('🍽️ Menu Costing'!$C$8:$C$37) -> Dishes priced: 0 | D5: ="Avg cost: "&Currency&TEXT(IFERROR(AVERAGE('🍽️ Menu Costing'!$G$8:$G$37),0),"0.00") -> Avg cost: $0.00 | F5: ="Avg price: "&Currency&TEXT(IFERROR(AVERAGE('🍽️ Menu Costing'!$H$8:$H$37),0),"0.00") -> Avg price: $0.00 | H5: ="Avg margin: "&TEXT('_Data'!$AF$34,"0%") -> Avg margin: 0%
B7: # | C7: Menu item | D7: Category | E7: Key ingredients | F7: Portion | G7: Cost / portion | H7: Menu price | I7: Profit | J7: Margin | K7: Notes
B8: =IF($C8="","",ROW()-7) | I8: =IF(OR($G8="",$H8=""),"",ROUND($H8-$G8,2)) | J8: =IFERROR(IF($I8="","",$I8/$H8),"")
B9: =IF($C9="","",ROW()-7) | I9: =IF(OR($G9="",$H9=""),"",ROUND($H9-$G9,2)) | J9: =IFERROR(IF($I9="","",$I9/$H9),"")
B10: =IF($C10="","",ROW()-7) | I10: =IF(OR($G10="",$H10=""),"",ROUND($H10-$G10,2)) | J10: =IFERROR(IF($I10="","",$I10/$H10),"")
B11: =IF($C11="","",ROW()-7) | I11: =IF(OR($G11="",$H11=""),"",ROUND($H11-$G11,2)) | J11: =IFERROR(IF($I11="","",$I11/$H11),"")
B12: =IF($C12="","",ROW()-7) | I12: =IF(OR($G12="",$H12=""),"",ROUND($H12-$G12,2)) | J12: =IFERROR(IF($I12="","",$I12/$H12),"")
B13: =IF($C13="","",ROW()-7) | I13: =IF(OR($G13="",$H13=""),"",ROUND($H13-$G13,2)) | J13: =IFERROR(IF($I13="","",$I13/$H13),"")
B14: =IF($C14="","",ROW()-7) | I14: =IF(OR($G14="",$H14=""),"",ROUND($H14-$G14,2)) | J14: =IFERROR(IF($I14="","",$I14/$H14),"")
B15: =IF($C15="","",ROW()-7) | I15: =IF(OR($G15="",$H15=""),"",ROUND($H15-$G15,2)) | J15: =IFERROR(IF($I15="","",$I15/$H15),"")
B16: =IF($C16="","",ROW()-7) | I16: =IF(OR($G16="",$H16=""),"",ROUND($H16-$G16,2)) | J16: =IFERROR(IF($I16="","",$I16/$H16),"")
B17: =IF($C17="","",ROW()-7) | I17: =IF(OR($G17="",$H17=""),"",ROUND($H17-$G17,2)) | J17: =IFERROR(IF($I17="","",$I17/$H17),"")
B18: =IF($C18="","",ROW()-7) | I18: =IF(OR($G18="",$H18=""),"",ROUND($H18-$G18,2)) | J18: =IFERROR(IF($I18="","",$I18/$H18),"")
B19: =IF($C19="","",ROW()-7) | I19: =IF(OR($G19="",$H19=""),"",ROUND($H19-$G19,2)) | J19: =IFERROR(IF($I19="","",$I19/$H19),"")
... B37: =IF($C37="","",ROW()-7) | I37: =IF(OR($G37="",$H37=""),"",ROUND($H37-$G37,2)) | J37: =IFERROR(IF($I37="","",$I37/$H37),"")
B38: MENU TOTALS | G38: =SUM('🍽️ Menu Costing'!$G$8:$G$37) -> 0 | H38: =SUM('🍽️ Menu Costing'!$H$8:$H$37) -> 0 | I38: =SUM('🍽️ Menu Costing'!$H$8:$H$37)-SUM('🍽️ Menu Costing'!$G$8:$G$37) -> 0
B58: How this tab works
B59: Cost per portion = everything on the plate: ingredients plus a share of packaging. If the margin bar glows amber the dish is under your Setup target. Use these numbers in the Quote Calculator (food cost per guest) so every quote is backed by real food costs.
B65: Setup | D65: 🏠 Home | F65: Clients | H65: Events | J65: Quote
B66: ▶ Menu | D66: Stock | F66: Shop | H66: Expenses | J66: Payments
B67: Staff | D67: Equip | F67: Suppliers | H67: Calendar | J67: P&L
B68: Tax | D68: Checks | F68: Invoice | H68: Help

Sheet 📦 Inventory
B2: Inventory
B3: Know what's on the shelf - and what to reorder this week | J3: 🏠 Back to Dashboard
B5: ="Items tracked: "&COUNTA('📦 Inventory'!$C$8:$C$47) -> Items tracked: 0 | D5: ="Stock value: "&Currency&TEXT(SUMPRODUCT(('📦 Inventory'!$C$8:$C$47<>"")*'📦 Inventory'!$F$8:$F$47*'📦 Inventory'!$H$8:$H$47),"#,##0.00") -> Stock value: $0.00 | F5: ="Below minimum: "&'_Data'!$AF$23 -> Below minimum: 0 | H5: ="Reorder spend: "&Currency&TEXT(SUMPRODUCT(('📦 Inventory'!$C$8:$C$47<>"")*('📦 Inventory'!$F$8:$F$47<'📦 Inventory'!$G$8:$G$47)*('📦 Inventory'!$G$8:$G$47-'📦 Inventory'!$F$8:$F$47)*'📦 Inventory'!$H$8:$H$47),"#,##0.00") -> Reorder spend: $0.00
B7: # | C7: Ingredient | D7: Category | E7: Unit | F7: In stock | G7: Min level | H7: Unit cost | I7: Stock value | J7: Supplier | K7: Status | L7: Notes
B8: =IF($C8="","",ROW()-7) | I8: =IF(OR($F8="",$H8=""),"",ROUND($F8*$H8,2)) | K8: =IF($C8="","",IF($F8<$G8,"🔴 Reorder",IF($F8<$G8*1.5,"🟡 Low","🟢 OK")))
B9: =IF($C9="","",ROW()-7) | I9: =IF(OR($F9="",$H9=""),"",ROUND($F9*$H9,2)) | K9: =IF($C9="","",IF($F9<$G9,"🔴 Reorder",IF($F9<$G9*1.5,"🟡 Low","🟢 OK")))
B10: =IF($C10="","",ROW()-7) | I10: =IF(OR($F10="",$H10=""),"",ROUND($F10*$H10,2)) | K10: =IF($C10="","",IF($F10<$G10,"🔴 Reorder",IF($F10<$G10*1.5,"🟡 Low","🟢 OK")))
B11: =IF($C11="","",ROW()-7) | I11: =IF(OR($F11="",$H11=""),"",ROUND($F11*$H11,2)) | K11: =IF($C11="","",IF($F11<$G11,"🔴 Reorder",IF($F11<$G11*1.5,"🟡 Low","🟢 OK")))
B12: =IF($C12="","",ROW()-7) | I12: =IF(OR($F12="",$H12=""),"",ROUND($F12*$H12,2)) | K12: =IF($C12="","",IF($F12<$G12,"🔴 Reorder",IF($F12<$G12*1.5,"🟡 Low","🟢 OK")))
B13: =IF($C13="","",ROW()-7) | I13: =IF(OR($F13="",$H13=""),"",ROUND($F13*$H13,2)) | K13: =IF($C13="","",IF($F13<$G13,"🔴 Reorder",IF($F13<$G13*1.5,"🟡 Low","🟢 OK")))
B14: =IF($C14="","",ROW()-7) | I14: =IF(OR($F14="",$H14=""),"",ROUND($F14*$H14,2)) | K14: =IF($C14="","",IF($F14<$G14,"🔴 Reorder",IF($F14<$G14*1.5,"🟡 Low","🟢 OK")))
B15: =IF($C15="","",ROW()-7) | I15: =IF(OR($F15="",$H15=""),"",ROUND($F15*$H15,2)) | K15: =IF($C15="","",IF($F15<$G15,"🔴 Reorder",IF($F15<$G15*1.5,"🟡 Low","🟢 OK")))
B16: =IF($C16="","",ROW()-7) | I16: =IF(OR($F16="",$H16=""),"",ROUND($F16*$H16,2)) | K16: =IF($C16="","",IF($F16<$G16,"🔴 Reorder",IF($F16<$G16*1.5,"🟡 Low","🟢 OK")))
B17: =IF($C17="","",ROW()-7) | I17: =IF(OR($F17="",$H17=""),"",ROUND($F17*$H17,2)) | K17: =IF($C17="","",IF($F17<$G17,"🔴 Reorder",IF($F17<$G17*1.5,"🟡 Low","🟢 OK")))
B18: =IF($C18="","",ROW()-7) | I18: =IF(OR($F18="",$H18=""),"",ROUND($F18*$H18,2)) | K18: =IF($C18="","",IF($F18<$G18,"🔴 Reorder",IF($F18<$G18*1.5,"🟡 Low","🟢 OK")))
B19: =IF($C19="","",ROW()-7) | I19: =IF(OR($F19="",$H19=""),"",ROUND($F19*$H19,2)) | K19: =IF($C19="","",IF($F19<$G19,"🔴 Reorder",IF($F19<$G19*1.5,"🟡 Low","🟢 OK")))
... B47: =IF($C47="","",ROW()-7) | I47: =IF(OR($F47="",$H47=""),"",ROUND($F47*$H47,2)) | K47: =IF($C47="","",IF($F47<$G47,"🔴 Reorder",IF($F47<$G47*1.5,"🟡 Low","🟢 OK")))
B48: TOTAL STOCK VALUE | I48: =SUMPRODUCT(('📦 Inventory'!$C$8:$C$47<>"")*'📦 Inventory'!$F$8:$F$47*'📦 Inventory'!$H$8:$H$47) -> 0
B50: How this tab works
B51: Status is automatic: below your minimum it turns red (Reorder), under 1.5x the minimum it glows amber (Low), otherwise green (OK). The Shopping List checks these quantities before telling you what to buy - keep them honest after every shop.
B55: Setup | D55: 🏠 Home | F55: Clients | H55: Events | J55: Quote
B56: Menu | D56: ▶ Stock | F56: Shop | H56: Expenses | J56: Payments
B57: Staff | D57: Equip | F57: Suppliers | H57: Calendar | J57: P&L
B58: Tax | D58: Checks | F58: Invoice | H58: Help

Sheet 🛒 Shopping List
B2: Shopping List
B3: Buy exactly what each event needs - nothing more, nothing less | J3: 🏠 Back to Dashboard
B5: ="Lines to buy: "&'_Data'!$AF$24 -> Lines to buy: 0 | D5: ="Estimated cost: "&Currency&TEXT('_Data'!$AF$25,"#,##0.00") -> Estimated cost: $0.00 | F5: ="Bought: "&COUNTIF('🛒 Shopping List'!$J$8:$J$47,"✓")&" of "&COUNTA('🛒 Shopping List'!$D$8:$D$47) -> Bought: 0 of 0
B7: # | C7: Event | D7: Ingredient | E7: Needed | F7: In stock | G7: To buy | H7: Supplier | I7: Est. cost | J7: Bought | K7: Bought on | L7: Notes
B8: =IF($D8="","",ROW()-7) | F8: =IF($D8="","",IFERROR(SUMIF('📦 Inventory'!$C$8:$C$47,$D8,'📦 Inventory'!$F$8:$F$47),0)) | G8: =IF($E8="","",MAX(0,ROUND($E8-$F8,1))) | I8: =IF(OR($G8="",NOT(ISNUMBER($G8))),"",ROUND($G8*IFERROR(SUMIF('📦 Inventory'!$C$8:$C$47,$D8,'📦 Inventory'!$H$8:$H$47),0),2))
B9: =IF($D9="","",ROW()-7) | F9: =IF($D9="","",IFERROR(SUMIF('📦 Inventory'!$C$8:$C$47,$D9,'📦 Inventory'!$F$8:$F$47),0)) | G9: =IF($E9="","",MAX(0,ROUND($E9-$F9,1))) | I9: =IF(OR($G9="",NOT(ISNUMBER($G9))),"",ROUND($G9*IFERROR(SUMIF('📦 Inventory'!$C$8:$C$47,$D9,'📦 Inventory'!$H$8:$H$47),0),2))
B10: =IF($D10="","",ROW()-7) | F10: =IF($D10="","",IFERROR(SUMIF('📦 Inventory'!$C$8:$C$47,$D10,'📦 Inventory'!$F$8:$F$47),0)) | G10: =IF($E10="","",MAX(0,ROUND($E10-$F10,1))) | I10: =IF(OR($G10="",NOT(ISNUMBER($G10))),"",ROUND($G10*IFERROR(SUMIF('📦 Inventory'!$C$8:$C$47,$D10,'📦 Inventory'!$H$8:$H$47),0),2))
B11: =IF($D11="","",ROW()-7) | F11: =IF($D11="","",IFERROR(SUMIF('📦 Inventory'!$C$8:$C$47,$D11,'📦 Inventory'!$F$8:$F$47),0)) | G11: =IF($E11="","",MAX(0,ROUND($E11-$F11,1))) | I11: =IF(OR($G11="",NOT(ISNUMBER($G11))),"",ROUND($G11*IFERROR(SUMIF('📦 Inventory'!$C$8:$C$47,$D11,'📦 Inventory'!$H$8:$H$47),0),2))
B12: =IF($D12="","",ROW()-7) | F12: =IF($D12="","",IFERROR(SUMIF('📦 Inventory'!$C$8:$C$47,$D12,'📦 Inventory'!$F$8:$F$47),0)) | G12: =IF($E12="","",MAX(0,ROUND($E12-$F12,1))) | I12: =IF(OR($G12="",NOT(ISNUMBER($G12))),"",ROUND($G12*IFERROR(SUMIF('📦 Inventory'!$C$8:$C$47,$D12,'📦 Inventory'!$H$8:$H$47),0),2))
B13: =IF($D13="","",ROW()-7) | F13: =IF($D13="","",IFERROR(SUMIF('📦 Inventory'!$C$8:$C$47,$D13,'📦 Inventory'!$F$8:$F$47),0)) | G13: =IF($E13="","",MAX(0,ROUND($E13-$F13,1))) | I13: =IF(OR($G13="",NOT(ISNUMBER($G13))),"",ROUND($G13*IFERROR(SUMIF('📦 Inventory'!$C$8:$C$47,$D13,'📦 Inventory'!$H$8:$H$47),0),2))
B14: =IF($D14="","",ROW()-7) | F14: =IF($D14="","",IFERROR(SUMIF('📦 Inventory'!$C$8:$C$47,$D14,'📦 Inventory'!$F$8:$F$47),0)) | G14: =IF($E14="","",MAX(0,ROUND($E14-$F14,1))) | I14: =IF(OR($G14="",NOT(ISNUMBER($G14))),"",ROUND($G14*IFERROR(SUMIF('📦 Inventory'!$C$8:$C$47,$D14,'📦 Inventory'!$H$8:$H$47),0),2))
B15: =IF($D15="","",ROW()-7) | F15: =IF($D15="","",IFERROR(SUMIF('📦 Inventory'!$C$8:$C$47,$D15,'📦 Inventory'!$F$8:$F$47),0)) | G15: =IF($E15="","",MAX(0,ROUND($E15-$F15,1))) | I15: =IF(OR($G15="",NOT(ISNUMBER($G15))),"",ROUND($G15*IFERROR(SUMIF('📦 Inventory'!$C$8:$C$47,$D15,'📦 Inventory'!$H$8:$H$47),0),2))
B16: =IF($D16="","",ROW()-7) | F16: =IF($D16="","",IFERROR(SUMIF('📦 Inventory'!$C$8:$C$47,$D16,'📦 Inventory'!$F$8:$F$47),0)) | G16: =IF($E16="","",MAX(0,ROUND($E16-$F16,1))) | I16: =IF(OR($G16="",NOT(ISNUMBER($G16))),"",ROUND($G16*IFERROR(SUMIF('📦 Inventory'!$C$8:$C$47,$D16,'📦 Inventory'!$H$8:$H$47),0),2))
B17: =IF($D17="","",ROW()-7) | F17: =IF($D17="","",IFERROR(SUMIF('📦 Inventory'!$C$8:$C$47,$D17,'📦 Inventory'!$F$8:$F$47),0)) | G17: =IF($E17="","",MAX(0,ROUND($E17-$F17,1))) | I17: =IF(OR($G17="",NOT(ISNUMBER($G17))),"",ROUND($G17*IFERROR(SUMIF('📦 Inventory'!$C$8:$C$47,$D17,'📦 Inventory'!$H$8:$H$47),0),2))
B18: =IF($D18="","",ROW()-7) | F18: =IF($D18="","",IFERROR(SUMIF('📦 Inventory'!$C$8:$C$47,$D18,'📦 Inventory'!$F$8:$F$47),0)) | G18: =IF($E18="","",MAX(0,ROUND($E18-$F18,1))) | I18: =IF(OR($G18="",NOT(ISNUMBER($G18))),"",ROUND($G18*IFERROR(SUMIF('📦 Inventory'!$C$8:$C$47,$D18,'📦 Inventory'!$H$8:$H$47),0),2))
B19: =IF($D19="","",ROW()-7) | F19: =IF($D19="","",IFERROR(SUMIF('📦 Inventory'!$C$8:$C$47,$D19,'📦 Inventory'!$F$8:$F$47),0)) | G19: =IF($E19="","",MAX(0,ROUND($E19-$F19,1))) | I19: =IF(OR($G19="",NOT(ISNUMBER($G19))),"",ROUND($G19*IFERROR(SUMIF('📦 Inventory'!$C$8:$C$47,$D19,'📦 Inventory'!$H$8:$H$47),0),2))
... B47: =IF($D47="","",ROW()-7) | F47: =IF($D47="","",IFERROR(SUMIF('📦 Inventory'!$C$8:$C$47,$D47,'📦 Inventory'!$F$8:$F$47),0)) | G47: =IF($E47="","",MAX(0,ROUND($E47-$F47,1))) | I47: =IF(OR($G47="",NOT(ISNUMBER($G47))),"",ROUND($G47*IFERROR(SUMIF('📦 Inventory'!$C$8:$C$47,$D47,'📦 Inventory'!$H$8:$H$47),0),2))
B48: STILL TO BUY | I48: =SUMPRODUCT(--(('🛒 Shopping List'!$J$8:$J$47<>"✓")*('🛒 Shopping List'!$D$8:$D$47<>"")),'🛒 Shopping List'!$I$8:$I$47) -> 0
B50: How this tab works
B51: In stock and To buy are looked up from the Inventory tab automatically - type the event, ingredient and how much you need. Estimated cost uses the unit cost on the Inventory tab; the total only counts lines you haven't ticked off yet.
B55: Setup | D55: 🏠 Home | F55: Clients | H55: Events | J55: Quote
B56: Menu | D56: Stock | F56: ▶ Shop | H56: Expenses | J56: Payments
B57: Staff | D57: Equip | F57: Suppliers | H57: Calendar | J57: P&L
B58: Tax | D58: Checks | F58: Invoice | H58: Help

Sheet 💸 Expenses
B2: Expenses
B3: Every cost, categorised - the P&L builds itself from here | H3: 🏠 Back to Dashboard
B5: ="Total spend: "&Currency&TEXT(SUM('💸 Expenses'!$G$8:$G$67),"#,##0") -> Total spend: $0 | D5: ="This month: "&Currency&TEXT(SUMPRODUCT(('💸 Expenses'!$C$8:$C$67<>"")*(MONTH('💸 Expenses'!$C$8:$C$67)=MONTH(TODAY()))*(YEAR('💸 Expenses'!$C$8:$C$67)=YEAR(TODAY()))*'💸 Expenses'!$G$8:$G$67),"#,##0") -> This month: $0 | F5: ="Food & packaging: "&Currency&TEXT('_Data'!$AF$17,"#,##0") -> Food & packaging: $0 | H5: ="No receipt: "&COUNTA('💸 Expenses'!$C$8:$C$67)-COUNTIF('💸 Expenses'!$J$8:$J$67,"✓") -> No receipt: 0
B7: # | C7: Date | D7: Vendor | E7: Category | F7: What / description | G7: Amount | H7: Paid by | I7: Event | J7: Receipt
B8: =IF($C8="","",ROW()-7)
B9: =IF($C9="","",ROW()-7)
B10: =IF($C10="","",ROW()-7)
B11: =IF($C11="","",ROW()-7)
B12: =IF($C12="","",ROW()-7)
B13: =IF($C13="","",ROW()-7)
B14: =IF($C14="","",ROW()-7)
B15: =IF($C15="","",ROW()-7)
B16: =IF($C16="","",ROW()-7)
B17: =IF($C17="","",ROW()-7)
B18: =IF($C18="","",ROW()-7)
B19: =IF($C19="","",ROW()-7)
... B67: =IF($C67="","",ROW()-7)
