Workbook
Name BusinessName: '⚙️ Lists & Settings'!$C$6
Name Categories: OFFSET('⚙️ Lists & Settings'!$C$23,0,0,MAX(1,COUNTA('⚙️ Lists & Settings'!$C$23:$C$42)),1)
Name Currency: '⚙️ Lists & Settings'!$C$10
Name EventList: OFFSET('🏪 Craft Fairs'!$B$8,0,0,MAX(1,COUNTA('🏪 Craft Fairs'!$B$8:$B$31)),1)
Name HourlyWage: '⚙️ Lists & Settings'!$C$12
Name MaterialsList: OFFSET('🧵 Yarn & Materials'!$B$8,0,0,MAX(1,COUNTA('🧵 Yarn & Materials'!$B$8:$B$31)),1)
Name Message: '⚙️ Lists & Settings'!$C$7
Name OverheadPct: '⚙️ Lists & Settings'!$C$13
Name PaymentMethods: OFFSET('⚙️ Lists & Settings'!$D$23,0,0,MAX(1,COUNTA('⚙️ Lists & Settings'!$D$23:$D$42)),1)
Name ProductsList: OFFSET('🧶 Product Catalog'!$C$8,0,0,MAX(1,COUNTA('🧶 Product Catalog'!$C$8:$C$31)),1)
Name ReportYear: '⚙️ Lists & Settings'!$C$11
Name Suppliers: OFFSET('⚙️ Lists & Settings'!$G$23,0,0,MAX(1,COUNTA('⚙️ Lists & Settings'!$G$23:$G$42)),1)
Name TargetMargin: '⚙️ Lists & Settings'!$C$14
Name Tick: '⚙️ Lists & Settings'!$C$47:$C$48
Name Units: OFFSET('⚙️ Lists & Settings'!$F$23,0,0,MAX(1,COUNTA('⚙️ Lists & Settings'!$F$23:$F$42)),1)
Name YarnWeights: OFFSET('⚙️ Lists & Settings'!$E$23,0,0,MAX(1,COUNTA('⚙️ Lists & Settings'!$E$23:$E$42)),1)

Sheet _Data
A1: Ultimate Crochet Craft Fair Tracker v1.0 - calculation engine (hidden; do not edit) | H1: # | I1: Month | J1: Revenue | K1: COGS | L1: Fees | M1: Net | N1: Margin | P1: Method | Q1: Value | S1: Category | T1: Value | V1: # | W1: Product | X1: Units | Y1: Revenue | Z1: Stock | AA1: Margin | AB1: Profit | AC1: # | AD1: Event | AE1: Sales | AF1: Net | AK1: Ordered | AL1: Item | AN1: Ordered | AO1: Item
H2: 1 | I2: January | J2: =SUMIFS('💰 Sales Log'!$H$8:$H$67,'💰 Sales Log'!$B$8:$B$67,">="&DATE(ReportYear,1,1),'💰 Sales Log'!$B$8:$B$67,"<"&EDATE(DATE(ReportYear,1,1),1)) -> 0 | K2: =SUMIFS('💰 Sales Log'!$M$8:$M$67,'💰 Sales Log'!$B$8:$B$67,">="&DATE(ReportYear,1,1),'💰 Sales Log'!$B$8:$B$67,"<"&EDATE(DATE(ReportYear,1,1),1)) -> 0 | L2: =SUMIFS('🏪 Craft Fairs'!$K$8:$K$31,'🏪 Craft Fairs'!$C$8:$C$31,">="&DATE(ReportYear,1,1),'🏪 Craft Fairs'!$C$8:$C$31,"<"&EDATE(DATE(ReportYear,1,1),1)) -> 0 | M2: =J2-K2-L2 -> 0 | N2: =IFERROR(M2/J2,0) -> 0 | P2: Cash | Q2: =SUMIFS('💰 Sales Log'!$H$8:$H$67,'💰 Sales Log'!$I$8:$I$67,$P$2) -> 816 | S2: Booth fees | T2: =SUM('🏪 Craft Fairs'!$F$8:$F$31) -> 360 | V2: 1 | W2: =IF('🧶 Product Catalog'!$C$8="","",'🧶 Product Catalog'!$C$8) -> Amigurumi Bunny | X2: =IF($W2="","",SUMIFS('💰 Sales Log'!$E$8:$E$67,'💰 Sales Log'!$D$8:$D$67,$W2)) -> 6 | Y2: =IF($W2="","",SUMIFS('💰 Sales Log'!$H$8:$H$67,'💰 Sales Log'!$D$8:$D$67,$W2)) -> 168 | Z2: =IF($W2="","",INDEX('🧶 Product Catalog'!$M$8:$M$31,MATCH($W2,'🧶 Product Catalog'!$C$8:$C$31,0))) -> 5 | AA2: =IF(OR($W2="",$X2=0),"",INDEX('🧶 Product Catalog'!$K$8:$K$31,MATCH($W2,'🧶 Product Catalog'!$C$8:$C$31,0))) -> 0.82142857 | AB2: =IF($W2="","",$Y2-SUMIFS('💰 Sales Log'!$M$8:$M$67,'💰 Sales Log'!$D$8:$D$67,$W2)) -> 138 | AC2: 1 | AD2: =IF('🏪 Craft Fairs'!$B$8="","",'🏪 Craft Fairs'!$B$8) -> Spring Makers Market | AE2: =IF($AD2="","",SUMIFS('💰 Sales Log'!$H$8:$H$67,'💰 Sales Log'!$C$8:$C$67,$AD2)) -> 300 | AF2: =IF($AD2="","",$AE2-SUMIFS('🏪 Craft Fairs'!$K$8:$K$31,'💰 Sales Log'!$C$8:$C$67,$AD2)-SUMIFS('💰 Sales Log'!$M$8:$M$67,'💰 Sales Log'!$C$8:$C$67,$AD2)) -> 151.2 | AH2: Gross sales (all time) | AI2: =SUM('💰 Sales Log'!$H$8:$H$67) -> 1760 | AK2: =IF('🔄 Reorder List'!$B$10="","",'🔄 Reorder List'!$I$10) | AL2: =IF('🔄 Reorder List'!$B$10="","",'🔄 Reorder List'!$B$10) | AN2: =IF('🔄 Reorder List'!$B$25="","",'🔄 Reorder List'!$I$25) | AO2: =IF('🔄 Reorder List'!$B$25="","",'🔄 Reorder List'!$B$25)
H3: 2 | I3: February | J3: =SUMIFS('💰 Sales Log'!$H$8:$H$67,'💰 Sales Log'!$B$8:$B$67,">="&DATE(ReportYear,2,1),'💰 Sales Log'!$B$8:$B$67,"<"&EDATE(DATE(ReportYear,2,1),1)) -> 0 | K3: =SUMIFS('💰 Sales Log'!$M$8:$M$67,'💰 Sales Log'!$B$8:$B$67,">="&DATE(ReportYear,2,1),'💰 Sales Log'!$B$8:$B$67,"<"&EDATE(DATE(ReportYear,2,1),1)) -> 0 | L3: =SUMIFS('🏪 Craft Fairs'!$K$8:$K$31,'🏪 Craft Fairs'!$C$8:$C$31,">="&DATE(ReportYear,2,1),'🏪 Craft Fairs'!$C$8:$C$31,"<"&EDATE(DATE(ReportYear,2,1),1)) -> 0 | M3: =J3-K3-L3 -> 0 | N3: =IFERROR(M3/J3,0) -> 0 | P3: Card | Q3: =SUMIFS('💰 Sales Log'!$H$8:$H$67,'💰 Sales Log'!$I$8:$I$67,$P$3) -> 609 | S3: Travel | T3: =SUM('🏪 Craft Fairs'!$G$8:$G$31) -> 89 | V3: 2 | W3: =IF('🧶 Product Catalog'!$C$9="","",'🧶 Product Catalog'!$C$9) -> Chunky Beanie | X3: =IF($W3="","",SUMIFS('💰 Sales Log'!$E$8:$E$67,'💰 Sales Log'!$D$8:$D$67,$W3)) -> 5 | Y3: =IF($W3="","",SUMIFS('💰 Sales Log'!$H$8:$H$67,'💰 Sales Log'!$D$8:$D$67,$W3)) -> 120 | Z3: =IF($W3="","",INDEX('🧶 Product Catalog'!$M$8:$M$31,MATCH($W3,'🧶 Product Catalog'!$C$8:$C$31,0))) -> 10 | AA3: =IF(OR($W3="",$X3=0),"",INDEX('🧶 Product Catalog'!$K$8:$K$31,MATCH($W3,'🧶 Product Catalog'!$C$8:$C$31,0))) -> 0.7375 | AB3: =IF($W3="","",$Y3-SUMIFS('💰 Sales Log'!$M$8:$M$67,'💰 Sales Log'!$D$8:$D$67,$W3)) -> 88.5 | AC3: 2 | AD3: =IF('🏪 Craft Fairs'!$B$9="","",'🏪 Craft Fairs'!$B$9) -> Easter Craft Bazaar | AE3: =IF($AD3="","",SUMIFS('💰 Sales Log'!$H$8:$H$67,'💰 Sales Log'!$C$8:$C$67,$AD3)) -> 174 | AF3: =IF($AD3="","",$AE3-SUMIFS('🏪 Craft Fairs'!$K$8:$K$31,'💰 Sales Log'!$C$8:$C$67,$AD3)-SUMIFS('💰 Sales Log'!$M$8:$M$67,'💰 Sales Log'!$C$8:$C$67,$AD3)) -> 89.6 | AH3: Discounts given | AI3: =SUM('💰 Sales Log'!$G$8:$G$67) -> 2 | AK3: =IF('🔄 Reorder List'!$B$11="","",'🔄 Reorder List'!$I$11) | AL3: =IF('🔄 Reorder List'!$B$11="","",'🔄 Reorder List'!$B$11) | AN3: =IF('🔄 Reorder List'!$B$26="","",'🔄 Reorder List'!$I$26) | AO3: =IF('🔄 Reorder List'!$B$26="","",'🔄 Reorder List'!$B$26)
H4: 3 | I4: March | J4: =SUMIFS('💰 Sales Log'!$H$8:$H$67,'💰 Sales Log'!$B$8:$B$67,">="&DATE(ReportYear,3,1),'💰 Sales Log'!$B$8:$B$67,"<"&EDATE(DATE(ReportYear,3,1),1)) -> 300 | K4: =SUMIFS('💰 Sales Log'!$M$8:$M$67,'💰 Sales Log'!$B$8:$B$67,">="&DATE(ReportYear,3,1),'💰 Sales Log'!$B$8:$B$67,"<"&EDATE(DATE(ReportYear,3,1),1)) -> 58.8 | L4: =SUMIFS('🏪 Craft Fairs'!$K$8:$K$31,'🏪 Craft Fairs'!$C$8:$C$31,">="&DATE(ReportYear,3,1),'🏪 Craft Fairs'!$C$8:$C$31,"<"&EDATE(DATE(ReportYear,3,1),1)) -> 90 | M4: =J4-K4-L4 -> 151.2 | N4: =IFERROR(M4/J4,0) -> 0 | P4: Bank transfer | Q4: =SUMIFS('💰 Sales Log'!$H$8:$H$67,'💰 Sales Log'!$I$8:$I$67,$P$4) -> 170 | S4: Parking | T4: =SUM('🏪 Craft Fairs'!$H$8:$H$31) -> 31 | V4: 3 | W4: =IF('🧶 Product Catalog'!$C$10="","",'🧶 Product Catalog'!$C$10) -> Granny Square Cardigan | X4: =IF($W4="","",SUMIFS('💰 Sales Log'!$E$8:$E$67,'💰 Sales Log'!$D$8:$D$67,$W4)) -> 1 | Y4: =IF($W4="","",SUMIFS('💰 Sales Log'!$H$8:$H$67,'💰 Sales Log'!$D$8:$D$67,$W4)) -> 95 | Z4: =IF($W4="","",INDEX('🧶 Product Catalog'!$M$8:$M$31,MATCH($W4,'🧶 Product Catalog'!$C$8:$C$31,0))) -> 2 | AA4: =IF(OR($W4="",$X4=0),"",INDEX('🧶 Product Catalog'!$K$8:$K$31,MATCH($W4,'🧶 Product Catalog'!$C$8:$C$31,0))) -> 0.78315789 | AB4: =IF($W4="","",$Y4-SUMIFS('💰 Sales Log'!$M$8:$M$67,'💰 Sales Log'!$D$8:$D$67,$W4)) -> 74.4 | AC4: 3 | AD4: =IF('🏪 Craft Fairs'!$B$10="","",'🏪 Craft Fairs'!$B$10) -> School Fete Stall | AE4: =IF($AD4="","",SUMIFS('💰 Sales Log'!$H$8:$H$67,'💰 Sales Log'!$C$8:$C$67,$AD4)) -> 244 | AF4: =IF($AD4="","",$AE4-SUMIFS('🏪 Craft Fairs'!$K$8:$K$31,'💰 Sales Log'!$C$8:$C$67,$AD4)-SUMIFS('💰 Sales Log'!$M$8:$M$67,'💰 Sales Log'!$C$8:$C$67,$AD4)) -> 156.5 | AH4: Cost of products sold | AI4: =SUM('💰 Sales Log'!$M$8:$M$67) -> 363.5 | AK4: =IF('🔄 Reorder List'!$B$12="","",'🔄 Reorder List'!$I$12) | AL4: =IF('🔄 Reorder List'!$B$12="","",'🔄 Reorder List'!$B$12) | AN4: =IF('🔄 Reorder List'!$B$27="","",'🔄 Reorder List'!$I$27) | AO4: =IF('🔄 Reorder List'!$B$27="","",'🔄 Reorder List'!$B$27)
H5: 4 | I5: April | J5: =SUMIFS('💰 Sales Log'!$H$8:$H$67,'💰 Sales Log'!$B$8:$B$67,">="&DATE(ReportYear,4,1),'💰 Sales Log'!$B$8:$B$67,"<"&EDATE(DATE(ReportYear,4,1),1)) -> 174 | K5: =SUMIFS('💰 Sales Log'!$M$8:$M$67,'💰 Sales Log'!$B$8:$B$67,">="&DATE(ReportYear,4,1),'💰 Sales Log'!$B$8:$B$67,"<"&EDATE(DATE(ReportYear,4,1),1)) -> 30.4 | L5: =SUMIFS('🏪 Craft Fairs'!$K$8:$K$31,'🏪 Craft Fairs'!$C$8:$C$31,">="&DATE(ReportYear,4,1),'🏪 Craft Fairs'!$C$8:$C$31,"<"&EDATE(DATE(ReportYear,4,1),1)) -> 54 | M5: =J5-K5-L5 -> 89.6 | N5: =IFERROR(M5/J5,0) -> 0 | P5: Mobile wallet | Q5: =SUMIFS('💰 Sales Log'!$H$8:$H$67,'💰 Sales Log'!$I$8:$I$67,$P$5) -> 0 | S5: Food & drinks | T5: =SUM('🏪 Craft Fairs'!$I$8:$I$31) -> 60 | V5: 4 | W5: =IF('🧶 Product Catalog'!$C$11="","",'🧶 Product Catalog'!$C$11) -> Market Tote Bag | X5: =IF($W5="","",SUMIFS('💰 Sales Log'!$E$8:$E$67,'💰 Sales Log'!$D$8:$D$67,$W5)) -> 8 | Y5: =IF($W5="","",SUMIFS('💰 Sales Log'!$H$8:$H$67,'💰 Sales Log'!$D$8:$D$67,$W5)) -> 256 | Z5: =IF($W5="","",INDEX('🧶 Product Catalog'!$M$8:$M$31,MATCH($W5,'🧶 Product Catalog'!$C$8:$C$31,0))) -> 3 | AA5: =IF(OR($W5="",$X5=0),"",INDEX('🧶 Product Catalog'!$K$8:$K$31,MATCH($W5,'🧶 Product Catalog'!$C$8:$C$31,0))) -> 0.778125 | AB5: =IF($W5="","",$Y5-SUMIFS('💰 Sales Log'!$M$8:$M$67,'💰 Sales Log'!$D$8:$D$67,$W5)) -> 199.2 | AC5: 4 | AD5: =IF('🏪 Craft Fairs'!$B$11="","",'🏪 Craft Fairs'!$B$11) -> Summer Night Bazaar | AE5: =IF($AD5="","",SUMIFS('💰 Sales Log'!$H$8:$H$67,'💰 Sales Log'!$C$8:$C$67,$AD5)) -> 398 | AF5: =IF($AD5="","",$AE5-SUMIFS('🏪 Craft Fairs'!$K$8:$K$31,'💰 Sales Log'!$C$8:$C$67,$AD5)-SUMIFS('💰 Sales Log'!$M$8:$M$67,'💰 Sales Log'!$C$8:$C$67,$AD5)) -> 199.2 | AH5: Event expenses (all fairs) | AI5: =SUM('🏪 Craft Fairs'!$K$8:$K$31) -> 680 | AK5: =IF('🔄 Reorder List'!$B$13="","",'🔄 Reorder List'!$I$13) | AL5: =IF('🔄 Reorder List'!$B$13="","",'🔄 Reorder List'!$B$13) | AN5: =IF('🔄 Reorder List'!$B$28="","",'🔄 Reorder List'!$I$28) | AO5: =IF('🔄 Reorder List'!$B$28="","",'🔄 Reorder List'!$B$28)
H6: 5 | I6: May | J6: =SUMIFS('💰 Sales Log'!$H$8:$H$67,'💰 Sales Log'!$B$8:$B$67,">="&DATE(ReportYear,5,1),'💰 Sales Log'!$B$8:$B$67,"<"&EDATE(DATE(ReportYear,5,1),1)) -> 244 | K6: =SUMIFS('💰 Sales Log'!$M$8:$M$67,'💰 Sales Log'!$B$8:$B$67,">="&DATE(ReportYear,5,1),'💰 Sales Log'!$B$8:$B$67,"<"&EDATE(DATE(ReportYear,5,1),1)) -> 43.5 | L6: =SUMIFS('🏪 Craft Fairs'!$K$8:$K$31,'🏪 Craft Fairs'!$C$8:$C$31,">="&DATE(ReportYear,5,1),'🏪 Craft Fairs'!$C$8:$C$31,"<"&EDATE(DATE(ReportYear,5,1),1)) -> 44 | M6: =J6-K6-L6 -> 156.5 | N6: =IFERROR(M6/J6,0) -> 0 | P6: Online order | Q6: =SUMIFS('💰 Sales Log'!$H$8:$H$67,'💰 Sales Log'!$I$8:$I$67,$P$6) -> 165 | S6: Display & decor | T6: =SUM('🏪 Craft Fairs'!$J$8:$J$31) -> 140 | V6: 5 | W6: =IF('🧶 Product Catalog'!$C$12="","",'🧶 Product Catalog'!$C$12) -> Cozy Scarf | X6: =IF($W6="","",SUMIFS('💰 Sales Log'!$E$8:$E$67,'💰 Sales Log'!$D$8:$D$67,$W6)) -> 2 | Y6: =IF($W6="","",SUMIFS('💰 Sales Log'!$H$8:$H$67,'💰 Sales Log'!$D$8:$D$67,$W6)) -> 76 | Z6: =IF($W6="","",INDEX('🧶 Product Catalog'!$M$8:$M$31,MATCH($W6,'🧶 Product Catalog'!$C$8:$C$31,0))) -> 4 | AA6: =IF(OR($W6="",$X6=0),"",INDEX('🧶 Product Catalog'!$K$8:$K$31,MATCH($W6,'🧶 Product Catalog'!$C$8:$C$31,0))) -> 0.73684211 | AB6: =IF($W6="","",$Y6-SUMIFS('💰 Sales Log'!$M$8:$M$67,'💰 Sales Log'!$D$8:$D$67,$W6)) -> 56 | AC6: 5 | AD6: =IF('🏪 Craft Fairs'!$B$12="","",'🏪 Craft Fairs'!$B$12) -> Farmers Market Pop-up | AE6: =IF($AD6="","",SUMIFS('💰 Sales Log'!$H$8:$H$67,'💰 Sales Log'!$C$8:$C$67,$AD6)) -> 309 | AF6: =IF($AD6="","",$AE6-SUMIFS('🏪 Craft Fairs'!$K$8:$K$31,'💰 Sales Log'!$C$8:$C$67,$AD6)-SUMIFS('💰 Sales Log'!$M$8:$M$67,'💰 Sales Log'!$C$8:$C$67,$AD6)) -> 163.4 | AH6: Net profit | AI6: =AI2-AI4-AI5 -> 716.5 | AK6: =IF('🔄 Reorder List'!$B$14="","",'🔄 Reorder List'!$I$14) | AL6: =IF('🔄 Reorder List'!$B$14="","",'🔄 Reorder List'!$B$14) | AN6: =IF('🔄 Reorder List'!$B$29="","",'🔄 Reorder List'!$I$29) | AO6: =IF('🔄 Reorder List'!$B$29="","",'🔄 Reorder List'!$B$29)
H7: 6 | I7: June | J7: =SUMIFS('💰 Sales Log'!$H$8:$H$67,'💰 Sales Log'!$B$8:$B$67,">="&DATE(ReportYear,6,1),'💰 Sales Log'!$B$8:$B$67,"<"&EDATE(DATE(ReportYear,6,1),1)) -> 398 | K7: =SUMIFS('💰 Sales Log'!$M$8:$M$67,'💰 Sales Log'!$B$8:$B$67,">="&DATE(ReportYear,6,1),'💰 Sales Log'!$B$8:$B$67,"<"&EDATE(DATE(ReportYear,6,1),1)) -> 82.8 | L7: =SUMIFS('🏪 Craft Fairs'!$K$8:$K$31,'🏪 Craft Fairs'!$C$8:$C$31,">="&DATE(ReportYear,6,1),'🏪 Craft Fairs'!$C$8:$C$31,"<"&EDATE(DATE(ReportYear,6,1),1)) -> 116 | M7: =J7-K7-L7 -> 199.2 | N7: =IFERROR(M7/J7,0) -> 0 | P7: Other | Q7: =SUMIFS('💰 Sales Log'!$H$8:$H$67,'💰 Sales Log'!$I$8:$I$67,$P$7) -> 0 | V7: 6 | W7: =IF('🧶 Product Catalog'!$C$13="","",'🧶 Product Catalog'!$C$13) -> Baby Booties | X7: =IF($W7="","",SUMIFS('💰 Sales Log'!$E$8:$E$67,'💰 Sales Log'!$D$8:$D$67,$W7)) -> 5 | Y7: =IF($W7="","",SUMIFS('💰 Sales Log'!$H$8:$H$67,'💰 Sales Log'!$D$8:$D$67,$W7)) -> 90 | Z7: =IF($W7="","",INDEX('🧶 Product Catalog'!$M$8:$M$31,MATCH($W7,'🧶 Product Catalog'!$C$8:$C$31,0))) -> 3 | AA7: =IF(OR($W7="",$X7=0),"",INDEX('🧶 Product Catalog'!$K$8:$K$31,MATCH($W7,'🧶 Product Catalog'!$C$8:$C$31,0))) -> 0.82222222 | AB7: =IF($W7="","",$Y7-SUMIFS('💰 Sales Log'!$M$8:$M$67,'💰 Sales Log'!$D$8:$D$67,$W7)) -> 74 | AC7: 6 | AD7: =IF('🏪 Craft Fairs'!$B$13="","",'🏪 Craft Fairs'!$B$13) -> Online Order Batch | AE7: =IF($AD7="","",SUMIFS('💰 Sales Log'!$H$8:$H$67,'💰 Sales Log'!$C$8:$C$67,$AD7)) -> 335 | AF7: =IF($AD7="","",$AE7-SUMIFS('🏪 Craft Fairs'!$K$8:$K$31,'💰 Sales Log'!$C$8:$C$67,$AD7)-SUMIFS('💰 Sales Log'!$M$8:$M$67,'💰 Sales Log'!$C$8:$C$67,$AD7)) -> 259.6 | AH7: Profit margin | AI7: =IFERROR(AI6/AI2,0) -> 0.40710227 | AK7: =IF('🔄 Reorder List'!$B$15="","",'🔄 Reorder List'!$I$15) | AL7: =IF('🔄 Reorder List'!$B$15="","",'🔄 Reorder List'!$B$15) | AN7: =IF('🔄 Reorder List'!$B$30="","",'🔄 Reorder List'!$I$30) | AO7: =IF('🔄 Reorder List'!$B$30="","",'🔄 Reorder List'!$B$30)
H8: 7 | I8: July | J8: =SUMIFS('💰 Sales Log'!$H$8:$H$67,'💰 Sales Log'!$B$8:$B$67,">="&DATE(ReportYear,7,1),'💰 Sales Log'!$B$8:$B$67,"<"&EDATE(DATE(ReportYear,7,1),1)) -> 309 | K8: =SUMIFS('💰 Sales Log'!$M$8:$M$67,'💰 Sales Log'!$B$8:$B$67,">="&DATE(ReportYear,7,1),'💰 Sales Log'!$B$8:$B$67,"<"&EDATE(DATE(ReportYear,7,1),1)) -> 72.6 | L8: =SUMIFS('🏪 Craft Fairs'!$K$8:$K$31,'🏪 Craft Fairs'!$C$8:$C$31,">="&DATE(ReportYear,7,1),'🏪 Craft Fairs'!$C$8:$C$31,"<"&EDATE(DATE(ReportYear,7,1),1)) -> 73 | M8: =J8-K8-L8 -> 163.4 | N8: =IFERROR(M8/J8,0) -> 0 | V8: 7 | W8: =IF('🧶 Product Catalog'!$C$14="","",'🧶 Product Catalog'!$C$14) -> Flower Coaster Set | X8: =IF($W8="","",SUMIFS('💰 Sales Log'!$E$8:$E$67,'💰 Sales Log'!$D$8:$D$67,$W8)) -> 14 | Y8: =IF($W8="","",SUMIFS('💰 Sales Log'!$H$8:$H$67,'💰 Sales Log'!$D$8:$D$67,$W8)) -> 222 | Z8: =IF($W8="","",INDEX('🧶 Product Catalog'!$M$8:$M$31,MATCH($W8,'🧶 Product Catalog'!$C$8:$C$31,0))) -> 5 | AA8: =IF(OR($W8="",$X8=0),"",INDEX('🧶 Product Catalog'!$K$8:$K$31,MATCH($W8,'🧶 Product Catalog'!$C$8:$C$31,0))) -> 0.83125 | AB8: =IF($W8="","",$Y8-SUMIFS('💰 Sales Log'!$M$8:$M$67,'💰 Sales Log'!$D$8:$D$67,$W8)) -> 184.2 | AC8: 7 | AD8: =IF('🏪 Craft Fairs'!$B$14="","",'🏪 Craft Fairs'!$B$14) -> Autumn Craft Fair | AE8: =IF($AD8="","",SUMIFS('💰 Sales Log'!$H$8:$H$67,'💰 Sales Log'!$C$8:$C$67,$AD8)) -> 0 | AF8: =IF($AD8="","",$AE8-SUMIFS('🏪 Craft Fairs'!$K$8:$K$31,'💰 Sales Log'!$C$8:$C$67,$AD8)-SUMIFS('💰 Sales Log'!$M$8:$M$67,'💰 Sales Log'!$C$8:$C$67,$AD8)) -> -145 | AH8: Units sold | AI8: =SUM('💰 Sales Log'!$E$8:$E$67) -> 77 | AK8: =IF('🔄 Reorder List'!$B$16="","",'🔄 Reorder List'!$I$16) | AL8: =IF('🔄 Reorder List'!$B$16="","",'🔄 Reorder List'!$B$16) | AN8: =IF('🔄 Reorder List'!$B$31="","",'🔄 Reorder List'!$I$31) | AO8: =IF('🔄 Reorder List'!$B$31="","",'🔄 Reorder List'!$B$31)
H9: 8 | I9: August | J9: =SUMIFS('💰 Sales Log'!$H$8:$H$67,'💰 Sales Log'!$B$8:$B$67,">="&DATE(ReportYear,8,1),'💰 Sales Log'!$B$8:$B$67,"<"&EDATE(DATE(ReportYear,8,1),1)) -> 335 | K9: =SUMIFS('💰 Sales Log'!$M$8:$M$67,'💰 Sales Log'!$B$8:$B$67,">="&DATE(ReportYear,8,1),'💰 Sales Log'!$B$8:$B$67,"<"&EDATE(DATE(ReportYear,8,1),1)) -> 75.4 | L9: =SUMIFS('🏪 Craft Fairs'!$K$8:$K$31,'🏪 Craft Fairs'!$C$8:$C$31,">="&DATE(ReportYear,8,1),'🏪 Craft Fairs'!$C$8:$C$31,"<"&EDATE(DATE(ReportYear,8,1),1)) -> 0 | M9: =J9-K9-L9 -> 259.6 | N9: =IFERROR(M9/J9,0) -> 0 | V9: 8 | W9: =IF('🧶 Product Catalog'!$C$15="","",'🧶 Product Catalog'!$C$15) -> Lap Blanket | X9: =IF($W9="","",SUMIFS('💰 Sales Log'!$E$8:$E$67,'💰 Sales Log'!$D$8:$D$67,$W9)) -> 2 | Y9: =IF($W9="","",SUMIFS('💰 Sales Log'!$H$8:$H$67,'💰 Sales Log'!$D$8:$D$67,$W9)) -> 150 | Z9: =IF($W9="","",INDEX('🧶 Product Catalog'!$M$8:$M$31,MATCH($W9,'🧶 Product Catalog'!$C$8:$C$31,0))) -> 1 | AA9: =IF(OR($W9="",$X9=0),"",INDEX('🧶 Product Catalog'!$K$8:$K$31,MATCH($W9,'🧶 Product Catalog'!$C$8:$C$31,0))) -> 0.74933333 | AB9: =IF($W9="","",$Y9-SUMIFS('💰 Sales Log'!$M$8:$M$67,'💰 Sales Log'!$D$8:$D$67,$W9)) -> 112.4 | AC9: 8 | AD9: =IF('🏪 Craft Fairs'!$B$15="","",'🏪 Craft Fairs'!$B$15) -> Winter Holiday Market | AE9: =IF($AD9="","",SUMIFS('💰 Sales Log'!$H$8:$H$67,'💰 Sales Log'!$C$8:$C$67,$AD9)) -> 0 | AF9: =IF($AD9="","",$AE9-SUMIFS('🏪 Craft Fairs'!$K$8:$K$31,'💰 Sales Log'!$C$8:$C$67,$AD9)-SUMIFS('💰 Sales Log'!$M$8:$M$67,'💰 Sales Log'!$C$8:$C$67,$AD9)) -> -158 | AH9: Sales log entries | AI9: =COUNTA('💰 Sales Log'!$B$8:$B$67) -> 22 | AK9: =IF('🔄 Reorder List'!$B$17="","",'🔄 Reorder List'!$I$17) | AL9: =IF('🔄 Reorder List'!$B$17="","",'🔄 Reorder List'!$B$17) | AN9: =IF('🔄 Reorder List'!$B$32="","",'🔄 Reorder List'!$I$32) | AO9: =IF('🔄 Reorder List'!$B$32="","",'🔄 Reorder List'!$B$32)
H10: 9 | I10: September | J10: =SUMIFS('💰 Sales Log'!$H$8:$H$67,'💰 Sales Log'!$B$8:$B$67,">="&DATE(ReportYear,9,1),'💰 Sales Log'!$B$8:$B$67,"<"&EDATE(DATE(ReportYear,9,1),1)) -> 0 | K10: =SUMIFS('💰 Sales Log'!$M$8:$M$67,'💰 Sales Log'!$B$8:$B$67,">="&DATE(ReportYear,9,1),'💰 Sales Log'!$B$8:$B$67,"<"&EDATE(DATE(ReportYear,9,1),1)) -> 0 | L10: =SUMIFS('🏪 Craft Fairs'!$K$8:$K$31,'🏪 Craft Fairs'!$C$8:$C$31,">="&DATE(ReportYear,9,1),'🏪 Craft Fairs'!$C$8:$C$31,"<"&EDATE(DATE(ReportYear,9,1),1)) -> 145 | M10: =J10-K10-L10 -> -145 | N10: =IFERROR(M10/J10,0) -> 0 | V10: 9 | W10: =IF('🧶 Product Catalog'!$C$16="","",'🧶 Product Catalog'!$C$16) -> Ear Warmer Headband | X10: =IF($W10="","",SUMIFS('💰 Sales Log'!$E$8:$E$67,'💰 Sales Log'!$D$8:$D$67,$W10)) -> 10 | Y10: =IF($W10="","",SUMIFS('💰 Sales Log'!$H$8:$H$67,'💰 Sales Log'!$D$8:$D$67,$W10)) -> 160 | Z10: =IF($W10="","",INDEX('🧶 Product Catalog'!$M$8:$M$31,MATCH($W10,'🧶 Product Catalog'!$C$8:$C$31,0))) -> 0 | AA10: =IF(OR($W10="",$X10=0),"",INDEX('🧶 Product Catalog'!$K$8:$K$31,MATCH($W10,'🧶 Product Catalog'!$C$8:$C$31,0))) -> 0.7875 | AB10: =IF($W10="","",$Y10-SUMIFS('💰 Sales Log'!$M$8:$M$67,'💰 Sales Log'!$D$8:$D$67,$W10)) -> 126 | AC10: 9 | AD10: =IF('🏪 Craft Fairs'!$B$16="","",'🏪 Craft Fairs'!$B$16) | AE10: =IF($AD10="","",SUMIFS('💰 Sales Log'!$H$8:$H$67,'💰 Sales Log'!$C$8:$C$67,$AD10)) -> 0 | AF10: =IF($AD10="","",$AE10-SUMIFS('🏪 Craft Fairs'!$K$8:$K$31,'💰 Sales Log'!$C$8:$C$67,$AD10)-SUMIFS('💰 Sales Log'!$M$8:$M$67,'💰 Sales Log'!$C$8:$C$67,$AD10)) -> 0 | AH10: Average sale value | AI10: =IFERROR(AI2/AI9,0) -> 80 | AK10: =IF('🔄 Reorder List'!$B$18="","",'🔄 Reorder List'!$I$18) | AL10: =IF('🔄 Reorder List'!$B$18="","",'🔄 Reorder List'!$B$18) | AN10: =IF('🔄 Reorder List'!$B$33="","",'🔄 Reorder List'!$I$33) | AO10: =IF('🔄 Reorder List'!$B$33="","",'🔄 Reorder List'!$B$33)
H11: 10 | I11: October | J11: =SUMIFS('💰 Sales Log'!$H$8:$H$67,'💰 Sales Log'!$B$8:$B$67,">="&DATE(ReportYear,10,1),'💰 Sales Log'!$B$8:$B$67,"<"&EDATE(DATE(ReportYear,10,1),1)) -> 0 | K11: =SUMIFS('💰 Sales Log'!$M$8:$M$67,'💰 Sales Log'!$B$8:$B$67,">="&DATE(ReportYear,10,1),'💰 Sales Log'!$B$8:$B$67,"<"&EDATE(DATE(ReportYear,10,1),1)) -> 0 | L11: =SUMIFS('🏪 Craft Fairs'!$K$8:$K$31,'🏪 Craft Fairs'!$C$8:$C$31,">="&DATE(ReportYear,10,1),'🏪 Craft Fairs'!$C$8:$C$31,"<"&EDATE(DATE(ReportYear,10,1),1)) -> 0 | M11: =J11-K11-L11 -> 0 | N11: =IFERROR(M11/J11,0) -> 0 | V11: 10 | W11: =IF('🧶 Product Catalog'!$C$17="","",'🧶 Product Catalog'!$C$17) -> Stuffed Octopus | X11: =IF($W11="","",SUMIFS('💰 Sales Log'!$E$8:$E$67,'💰 Sales Log'!$D$8:$D$67,$W11)) -> 3 | Y11: =IF($W11="","",SUMIFS('💰 Sales Log'!$H$8:$H$67,'💰 Sales Log'!$D$8:$D$67,$W11)) -> 78 | Z11: =IF($W11="","",INDEX('🧶 Product Catalog'!$M$8:$M$31,MATCH($W11,'🧶 Product Catalog'!$C$8:$C$31,0))) -> 7 | AA11: =IF(OR($W11="",$X11=0),"",INDEX('🧶 Product Catalog'!$K$8:$K$31,MATCH($W11,'🧶 Product Catalog'!$C$8:$C$31,0))) -> 0.79230769 | AB11: =IF($W11="","",$Y11-SUMIFS('💰 Sales Log'!$M$8:$M$67,'💰 Sales Log'!$D$8:$D$67,$W11)) -> 61.8 | AC11: 10 | AD11: =IF('🏪 Craft Fairs'!$B$17="","",'🏪 Craft Fairs'!$B$17) | AE11: =IF($AD11="","",SUMIFS('💰 Sales Log'!$H$8:$H$67,'💰 Sales Log'!$C$8:$C$67,$AD11)) -> 0 | AF11: =IF($AD11="","",$AE11-SUMIFS('🏪 Craft Fairs'!$K$8:$K$31,'💰 Sales Log'!$C$8:$C$67,$AD11)-SUMIFS('💰 Sales Log'!$M$8:$M$67,'💰 Sales Log'!$C$8:$C$67,$AD11)) -> 0 | AH11: Average profit per item | AI11: =IFERROR(AI6/AI8,0) -> 9.3051948 | AK11: =IF('🔄 Reorder List'!$B$19="","",'🔄 Reorder List'!$I$19) | AL11: =IF('🔄 Reorder List'!$B$19="","",'🔄 Reorder List'!$B$19) | AN11: =IF('🔄 Reorder List'!$B$34="","",'🔄 Reorder List'!$I$34) | AO11: =IF('🔄 Reorder List'!$B$34="","",'🔄 Reorder List'!$B$34)
H12: 11 | I12: November | J12: =SUMIFS('💰 Sales Log'!$H$8:$H$67,'💰 Sales Log'!$B$8:$B$67,">="&DATE(ReportYear,11,1),'💰 Sales Log'!$B$8:$B$67,"<"&EDATE(DATE(ReportYear,11,1),1)) -> 0 | K12: =SUMIFS('💰 Sales Log'!$M$8:$M$67,'💰 Sales Log'!$B$8:$B$67,">="&DATE(ReportYear,11,1),'💰 Sales Log'!$B$8:$B$67,"<"&EDATE(DATE(ReportYear,11,1),1)) -> 0 | L12: =SUMIFS('🏪 Craft Fairs'!$K$8:$K$31,'🏪 Craft Fairs'!$C$8:$C$31,">="&DATE(ReportYear,11,1),'🏪 Craft Fairs'!$C$8:$C$31,"<"&EDATE(DATE(ReportYear,11,1),1)) -> 158 | M12: =J12-K12-L12 -> -158 | N12: =IFERROR(M12/J12,0) -> 0 | V12: 11 | W12: =IF('🧶 Product Catalog'!$C$18="","",'🧶 Product Catalog'!$C$18) -> Table Runner | X12: =IF($W12="","",SUMIFS('💰 Sales Log'!$E$8:$E$67,'💰 Sales Log'!$D$8:$D$67,$W12)) -> 3 | Y12: =IF($W12="","",SUMIFS('💰 Sales Log'!$H$8:$H$67,'💰 Sales Log'!$D$8:$D$67,$W12)) -> 165 | Z12: =IF($W12="","",INDEX('🧶 Product Catalog'!$M$8:$M$31,MATCH($W12,'🧶 Product Catalog'!$C$8:$C$31,0))) -> 0 | AA12: =IF(OR($W12="",$X12=0),"",INDEX('🧶 Product Catalog'!$K$8:$K$31,MATCH($W12,'🧶 Product Catalog'!$C$8:$C$31,0))) -> 0.78181818 | AB12: =IF($W12="","",$Y12-SUMIFS('💰 Sales Log'!$M$8:$M$67,'💰 Sales Log'!$D$8:$D$67,$W12)) -> 129 | AC12: 11 | AD12: =IF('🏪 Craft Fairs'!$B$18="","",'🏪 Craft Fairs'!$B$18) | AE12: =IF($AD12="","",SUMIFS('💰 Sales Log'!$H$8:$H$67,'💰 Sales Log'!$C$8:$C$67,$AD12)) -> 0 | AF12: =IF($AD12="","",$AE12-SUMIFS('🏪 Craft Fairs'!$K$8:$K$31,'💰 Sales Log'!$C$8:$C$67,$AD12)-SUMIFS('💰 Sales Log'!$M$8:$M$67,'💰 Sales Log'!$C$8:$C$67,$AD12)) -> 0 | AH12: Fairs on the books | AI12: =COUNTA('🏪 Craft Fairs'!$B$8:$B$31) -> 8 | AK12: =IF('🔄 Reorder List'!$B$20="","",'🔄 Reorder List'!$I$20) | AL12: =IF('🔄 Reorder List'!$B$20="","",'🔄 Reorder List'!$B$20)
H13: 12 | I13: December | J13: =SUMIFS('💰 Sales Log'!$H$8:$H$67,'💰 Sales Log'!$B$8:$B$67,">="&DATE(ReportYear,12,1),'💰 Sales Log'!$B$8:$B$67,"<"&EDATE(DATE(ReportYear,12,1),1)) -> 0 | K13: =SUMIFS('💰 Sales Log'!$M$8:$M$67,'💰 Sales Log'!$B$8:$B$67,">="&DATE(ReportYear,12,1),'💰 Sales Log'!$B$8:$B$67,"<"&EDATE(DATE(ReportYear,12,1),1)) -> 0 | L13: =SUMIFS('🏪 Craft Fairs'!$K$8:$K$31,'🏪 Craft Fairs'!$C$8:$C$31,">="&DATE(ReportYear,12,1),'🏪 Craft Fairs'!$C$8:$C$31,"<"&EDATE(DATE(ReportYear,12,1),1)) -> 0 | M13: =J13-K13-L13 -> 0 | N13: =IFERROR(M13/J13,0) -> 0 | V13: 12 | W13: =IF('🧶 Product Catalog'!$C$19="","",'🧶 Product Catalog'!$C$19) -> Keychain Charm | X13: =IF($W13="","",SUMIFS('💰 Sales Log'!$E$8:$E$67,'💰 Sales Log'!$D$8:$D$67,$W13)) -> 18 | Y13: =IF($W13="","",SUMIFS('💰 Sales Log'!$H$8:$H$67,'💰 Sales Log'!$D$8:$D$67,$W13)) -> 180 | Z13: =IF($W13="","",INDEX('🧶 Product Catalog'!$M$8:$M$31,MATCH($W13,'🧶 Product Catalog'!$C$8:$C$31,0))) -> 0 | AA13: =IF(OR($W13="",$X13=0),"",INDEX('🧶 Product Catalog'!$K$8:$K$31,MATCH($W13,'🧶 Product Catalog'!$C$8:$C$31,0))) -> 0.85 | AB13: =IF($W13="","",$Y13-SUMIFS('💰 Sales Log'!$M$8:$M$67,'💰 Sales Log'!$D$8:$D$67,$W13)) -> 153 | AC13: 12 | AD13: =IF('🏪 Craft Fairs'!$B$19="","",'🏪 Craft Fairs'!$B$19) | AE13: =IF($AD13="","",SUMIFS('💰 Sales Log'!$H$8:$H$67,'💰 Sales Log'!$C$8:$C$67,$AD13)) -> 0 | AF13: =IF($AD13="","",$AE13-SUMIFS('🏪 Craft Fairs'!$K$8:$K$31,'💰 Sales Log'!$C$8:$C$67,$AD13)-SUMIFS('💰 Sales Log'!$M$8:$M$67,'💰 Sales Log'!$C$8:$C$67,$AD13)) -> 0 | AH13: Fairs worked | AI13: =SUMPRODUCT(('💰 Sales Log'!$C$8:$C$67<>"")/COUNTIF('💰 Sales Log'!$C$8:$C$67,'💰 Sales Log'!$C$8:$C$67&"")) -> 6 | AK13: =IF('🔄 Reorder List'!$B$21="","",'🔄 Reorder List'!$I$21) | AL13: =IF('🔄 Reorder List'!$B$21="","",'🔄 Reorder List'!$B$21)
V14: 13 | W14: =IF('🧶 Product Catalog'!$C$20="","",'🧶 Product Catalog'!$C$20) | X14: =IF($W14="","",SUMIFS('💰 Sales Log'!$E$8:$E$67,'💰 Sales Log'!$D$8:$D$67,$W14)) -> 0 | Y14: =IF($W14="","",SUMIFS('💰 Sales Log'!$H$8:$H$67,'💰 Sales Log'!$D$8:$D$67,$W14)) -> 0 | Z14: =IF($W14="","",INDEX('🧶 Product Catalog'!$M$8:$M$31,MATCH($W14,'🧶 Product Catalog'!$C$8:$C$31,0))) -> 0 | AA14: =IF(OR($W14="",$X14=0),"",INDEX('🧶 Product Catalog'!$K$8:$K$31,MATCH($W14,'🧶 Product Catalog'!$C$8:$C$31,0))) -> 0 | AB14: =IF($W14="","",$Y14-SUMIFS('💰 Sales Log'!$M$8:$M$67,'💰 Sales Log'!$D$8:$D$67,$W14)) -> 0 | AC14: 13 | AD14: =IF('🏪 Craft Fairs'!$B$20="","",'🏪 Craft Fairs'!$B$20) | AE14: =IF($AD14="","",SUMIFS('💰 Sales Log'!$H$8:$H$67,'💰 Sales Log'!$C$8:$C$67,$AD14)) -> 0 | AF14: =IF($AD14="","",$AE14-SUMIFS('🏪 Craft Fairs'!$K$8:$K$31,'💰 Sales Log'!$C$8:$C$67,$AD14)-SUMIFS('💰 Sales Log'!$M$8:$M$67,'💰 Sales Log'!$C$8:$C$67,$AD14)) -> 0 | AH14: Inventory value (at unit cost) | AI14: =SUMPRODUCT('🧶 Product Catalog'!$M$8:$M$31*'🧶 Product Catalog'!$I$8:$I$31) -> 270.2
V15: 14 | W15: =IF('🧶 Product Catalog'!$C$21="","",'🧶 Product Catalog'!$C$21) | X15: =IF($W15="","",SUMIFS('💰 Sales Log'!$E$8:$E$67,'💰 Sales Log'!$D$8:$D$67,$W15)) -> 0 | Y15: =IF($W15="","",SUMIFS('💰 Sales Log'!$H$8:$H$67,'💰 Sales Log'!$D$8:$D$67,$W15)) -> 0 | Z15: =IF($W15="","",INDEX('🧶 Product Catalog'!$M$8:$M$31,MATCH($W15,'🧶 Product Catalog'!$C$8:$C$31,0))) -> 0 | AA15: =IF(OR($W15="",$X15=0),"",INDEX('🧶 Product Catalog'!$K$8:$K$31,MATCH($W15,'🧶 Product Catalog'!$C$8:$C$31,0))) -> 0 | AB15: =IF($W15="","",$Y15-SUMIFS('💰 Sales Log'!$M$8:$M$67,'💰 Sales Log'!$D$8:$D$67,$W15)) -> 0 | AC15: 14 | AD15: =IF('🏪 Craft Fairs'!$B$21="","",'🏪 Craft Fairs'!$B$21) | AE15: =IF($AD15="","",SUMIFS('💰 Sales Log'!$H$8:$H$67,'💰 Sales Log'!$C$8:$C$67,$AD15)) -> 0 | AF15: =IF($AD15="","",$AE15-SUMIFS('🏪 Craft Fairs'!$K$8:$K$31,'💰 Sales Log'!$C$8:$C$67,$AD15)-SUMIFS('💰 Sales Log'!$M$8:$M$67,'💰 Sales Log'!$C$8:$C$67,$AD15)) -> 0 | AH15: Products below minimum | AI15: =SUMPRODUCT(('🧶 Product Catalog'!$C$8:$C$31<>"")*('🧶 Product Catalog'!$M$8:$M$31<'🧶 Product Catalog'!$N$8:$N$31)) -> 7
V16: 15 | W16: =IF('🧶 Product Catalog'!$C$22="","",'🧶 Product Catalog'!$C$22) | X16: =IF($W16="","",SUMIFS('💰 Sales Log'!$E$8:$E$67,'💰 Sales Log'!$D$8:$D$67,$W16)) -> 0 | Y16: =IF($W16="","",SUMIFS('💰 Sales Log'!$H$8:$H$67,'💰 Sales Log'!$D$8:$D$67,$W16)) -> 0 | Z16: =IF($W16="","",INDEX('🧶 Product Catalog'!$M$8:$M$31,MATCH($W16,'🧶 Product Catalog'!$C$8:$C$31,0))) -> 0 | AA16: =IF(OR($W16="",$X16=0),"",INDEX('🧶 Product Catalog'!$K$8:$K$31,MATCH($W16,'🧶 Product Catalog'!$C$8:$C$31,0))) -> 0 | AB16: =IF($W16="","",$Y16-SUMIFS('💰 Sales Log'!$M$8:$M$67,'💰 Sales Log'!$D$8:$D$67,$W16)) -> 0 | AC16: 15 | AD16: =IF('🏪 Craft Fairs'!$B$22="","",'🏪 Craft Fairs'!$B$22) | AE16: =IF($AD16="","",SUMIFS('💰 Sales Log'!$H$8:$H$67,'💰 Sales Log'!$C$8:$C$67,$AD16)) -> 0 | AF16: =IF($AD16="","",$AE16-SUMIFS('🏪 Craft Fairs'!$K$8:$K$31,'💰 Sales Log'!$C$8:$C$67,$AD16)-SUMIFS('💰 Sales Log'!$M$8:$M$67,'💰 Sales Log'!$C$8:$C$67,$AD16)) -> 0 | AH16: Materials below threshold | AI16: =SUMPRODUCT(('🧵 Yarn & Materials'!$B$8:$B$31<>"")*('🧵 Yarn & Materials'!$K$8:$K$31<='🧵 Yarn & Materials'!$M$8:$M$31)) -> 5
V17: 16 | W17: =IF('🧶 Product Catalog'!$C$23="","",'🧶 Product Catalog'!$C$23) | X17: =IF($W17="","",SUMIFS('💰 Sales Log'!$E$8:$E$67,'💰 Sales Log'!$D$8:$D$67,$W17)) -> 0 | Y17: =IF($W17="","",SUMIFS('💰 Sales Log'!$H$8:$H$67,'💰 Sales Log'!$D$8:$D$67,$W17)) -> 0 | Z17: =IF($W17="","",INDEX('🧶 Product Catalog'!$M$8:$M$31,MATCH($W17,'🧶 Product Catalog'!$C$8:$C$31,0))) -> 0 | AA17: =IF(OR($W17="",$X17=0),"",INDEX('🧶 Product Catalog'!$K$8:$K$31,MATCH($W17,'🧶 Product Catalog'!$C$8:$C$31,0))) -> 0 | AB17: =IF($W17="","",$Y17-SUMIFS('💰 Sales Log'!$M$8:$M$67,'💰 Sales Log'!$D$8:$D$67,$W17)) -> 0 | AC17: 16 | AD17: =IF('🏪 Craft Fairs'!$B$23="","",'🏪 Craft Fairs'!$B$23) | AE17: =IF($AD17="","",SUMIFS('💰 Sales Log'!$H$8:$H$67,'💰 Sales Log'!$C$8:$C$67,$AD17)) -> 0 | AF17: =IF($AD17="","",$AE17-SUMIFS('🏪 Craft Fairs'!$K$8:$K$31,'💰 Sales Log'!$C$8:$C$67,$AD17)-SUMIFS('💰 Sales Log'!$M$8:$M$67,'💰 Sales Log'!$C$8:$C$67,$AD17)) -> 0 | AH17: Estimated reorder cost | AI17: =SUM('🔄 Reorder List'!$G$10:$G$34) -> 342.7
V18: 17 | W18: =IF('🧶 Product Catalog'!$C$24="","",'🧶 Product Catalog'!$C$24) | X18: =IF($W18="","",SUMIFS('💰 Sales Log'!$E$8:$E$67,'💰 Sales Log'!$D$8:$D$67,$W18)) -> 0 | Y18: =IF($W18="","",SUMIFS('💰 Sales Log'!$H$8:$H$67,'💰 Sales Log'!$D$8:$D$67,$W18)) -> 0 | Z18: =IF($W18="","",INDEX('🧶 Product Catalog'!$M$8:$M$31,MATCH($W18,'🧶 Product Catalog'!$C$8:$C$31,0))) -> 0 | AA18: =IF(OR($W18="",$X18=0),"",INDEX('🧶 Product Catalog'!$K$8:$K$31,MATCH($W18,'🧶 Product Catalog'!$C$8:$C$31,0))) -> 0 | AB18: =IF($W18="","",$Y18-SUMIFS('💰 Sales Log'!$M$8:$M$67,'💰 Sales Log'!$D$8:$D$67,$W18)) -> 0 | AC18: 17 | AD18: =IF('🏪 Craft Fairs'!$B$24="","",'🏪 Craft Fairs'!$B$24) | AE18: =IF($AD18="","",SUMIFS('💰 Sales Log'!$H$8:$H$67,'💰 Sales Log'!$C$8:$C$67,$AD18)) -> 0 | AF18: =IF($AD18="","",$AE18-SUMIFS('🏪 Craft Fairs'!$K$8:$K$31,'💰 Sales Log'!$C$8:$C$67,$AD18)-SUMIFS('💰 Sales Log'!$M$8:$M$67,'💰 Sales Log'!$C$8:$C$67,$AD18)) -> 0 | AH18: Sell-through rate | AI18: =IFERROR(AI8/AI19,0) -> 0.65254237
V19: 18 | W19: =IF('🧶 Product Catalog'!$C$25="","",'🧶 Product Catalog'!$C$25) | X19: =IF($W19="","",SUMIFS('💰 Sales Log'!$E$8:$E$67,'💰 Sales Log'!$D$8:$D$67,$W19)) -> 0 | Y19: =IF($W19="","",SUMIFS('💰 Sales Log'!$H$8:$H$67,'💰 Sales Log'!$D$8:$D$67,$W19)) -> 0 | Z19: =IF($W19="","",INDEX('🧶 Product Catalog'!$M$8:$M$31,MATCH($W19,'🧶 Product Catalog'!$C$8:$C$31,0))) -> 0 | AA19: =IF(OR($W19="",$X19=0),"",INDEX('🧶 Product Catalog'!$K$8:$K$31,MATCH($W19,'🧶 Product Catalog'!$C$8:$C$31,0))) -> 0 | AB19: =IF($W19="","",$Y19-SUMIFS('💰 Sales Log'!$M$8:$M$67,'💰 Sales Log'!$D$8:$D$67,$W19)) -> 0 | AC19: 18 | AD19: =IF('🏪 Craft Fairs'!$B$25="","",'🏪 Craft Fairs'!$B$25) | AE19: =IF($AD19="","",SUMIFS('💰 Sales Log'!$H$8:$H$67,'💰 Sales Log'!$C$8:$C$67,$AD19)) -> 0 | AF19: =IF($AD19="","",$AE19-SUMIFS('🏪 Craft Fairs'!$K$8:$K$31,'💰 Sales Log'!$C$8:$C$67,$AD19)-SUMIFS('💰 Sales Log'!$M$8:$M$67,'💰 Sales Log'!$C$8:$C$67,$AD19)) -> 0 | AH19: Units made (all batches) | AI19: =SUM('📦 Made & Stocked'!$D$8:$D$37) -> 118
V20: 19 | W20: =IF('🧶 Product Catalog'!$C$26="","",'🧶 Product Catalog'!$C$26) | X20: =IF($W20="","",SUMIFS('💰 Sales Log'!$E$8:$E$67,'💰 Sales Log'!$D$8:$D$67,$W20)) -> 0 | Y20: =IF($W20="","",SUMIFS('💰 Sales Log'!$H$8:$H$67,'💰 Sales Log'!$D$8:$D$67,$W20)) -> 0 | Z20: =IF($W20="","",INDEX('🧶 Product Catalog'!$M$8:$M$31,MATCH($W20,'🧶 Product Catalog'!$C$8:$C$31,0))) -> 0 | AA20: =IF(OR($W20="",$X20=0),"",INDEX('🧶 Product Catalog'!$K$8:$K$31,MATCH($W20,'🧶 Product Catalog'!$C$8:$C$31,0))) -> 0 | AB20: =IF($W20="","",$Y20-SUMIFS('💰 Sales Log'!$M$8:$M$67,'💰 Sales Log'!$D$8:$D$67,$W20)) -> 0 | AC20: 19 | AD20: =IF('🏪 Craft Fairs'!$B$26="","",'🏪 Craft Fairs'!$B$26) | AE20: =IF($AD20="","",SUMIFS('💰 Sales Log'!$H$8:$H$67,'💰 Sales Log'!$C$8:$C$67,$AD20)) -> 0 | AF20: =IF($AD20="","",$AE20-SUMIFS('🏪 Craft Fairs'!$K$8:$K$31,'💰 Sales Log'!$C$8:$C$67,$AD20)-SUMIFS('💰 Sales Log'!$M$8:$M$67,'💰 Sales Log'!$C$8:$C$67,$AD20)) -> 0 | AH20: Best-selling product | AI20: =IFERROR(INDEX($W$2:$W$25,MATCH(MAX($Y$2:$Y$25),$Y$2:$Y$25,0)),"") -> Market Tote Bag
V21: 20 | W21: =IF('🧶 Product Catalog'!$C$27="","",'🧶 Product Catalog'!$C$27) | X21: =IF($W21="","",SUMIFS('💰 Sales Log'!$E$8:$E$67,'💰 Sales Log'!$D$8:$D$67,$W21)) -> 0 | Y21: =IF($W21="","",SUMIFS('💰 Sales Log'!$H$8:$H$67,'💰 Sales Log'!$D$8:$D$67,$W21)) -> 0 | Z21: =IF($W21="","",INDEX('🧶 Product Catalog'!$M$8:$M$31,MATCH($W21,'🧶 Product Catalog'!$C$8:$C$31,0))) -> 0 | AA21: =IF(OR($W21="",$X21=0),"",INDEX('🧶 Product Catalog'!$K$8:$K$31,MATCH($W21,'🧶 Product Catalog'!$C$8:$C$31,0))) -> 0 | AB21: =IF($W21="","",$Y21-SUMIFS('💰 Sales Log'!$M$8:$M$67,'💰 Sales Log'!$D$8:$D$67,$W21)) -> 0 | AC21: 20 | AD21: =IF('🏪 Craft Fairs'!$B$27="","",'🏪 Craft Fairs'!$B$27) | AE21: =IF($AD21="","",SUMIFS('💰 Sales Log'!$H$8:$H$67,'💰 Sales Log'!$C$8:$C$67,$AD21)) -> 0 | AF21: =IF($AD21="","",$AE21-SUMIFS('🏪 Craft Fairs'!$K$8:$K$31,'💰 Sales Log'!$C$8:$C$67,$AD21)-SUMIFS('💰 Sales Log'!$M$8:$M$67,'💰 Sales Log'!$C$8:$C$67,$AD21)) -> 0 | AH21: Best craft fair | AI21: =IFERROR(INDEX($AD$2:$AD$25,MATCH(MAX($AF$2:$AF$25),$AF$2:$AF$25,0)),"") -> Online Order Batch
V22: 21 | W22: =IF('🧶 Product Catalog'!$C$28="","",'🧶 Product Catalog'!$C$28) | X22: =IF($W22="","",SUMIFS('💰 Sales Log'!$E$8:$E$67,'💰 Sales Log'!$D$8:$D$67,$W22)) -> 0 | Y22: =IF($W22="","",SUMIFS('💰 Sales Log'!$H$8:$H$67,'💰 Sales Log'!$D$8:$D$67,$W22)) -> 0 | Z22: =IF($W22="","",INDEX('🧶 Product Catalog'!$M$8:$M$31,MATCH($W22,'🧶 Product Catalog'!$C$8:$C$31,0))) -> 0 | AA22: =IF(OR($W22="",$X22=0),"",INDEX('🧶 Product Catalog'!$K$8:$K$31,MATCH($W22,'🧶 Product Catalog'!$C$8:$C$31,0))) -> 0 | AB22: =IF($W22="","",$Y22-SUMIFS('💰 Sales Log'!$M$8:$M$67,'💰 Sales Log'!$D$8:$D$67,$W22)) -> 0 | AC22: 21 | AD22: =IF('🏪 Craft Fairs'!$B$28="","",'🏪 Craft Fairs'!$B$28) | AE22: =IF($AD22="","",SUMIFS('💰 Sales Log'!$H$8:$H$67,'💰 Sales Log'!$C$8:$C$67,$AD22)) -> 0 | AF22: =IF($AD22="","",$AE22-SUMIFS('🏪 Craft Fairs'!$K$8:$K$31,'💰 Sales Log'!$C$8:$C$67,$AD22)-SUMIFS('💰 Sales Log'!$M$8:$M$67,'💰 Sales Log'!$C$8:$C$67,$AD22)) -> 0 | AH22: Most units sold | AI22: =IFERROR(INDEX($W$2:$W$25,MATCH(MAX($X$2:$X$25),$X$2:$X$25,0)),"") -> Keychain Charm
V23: 22 | W23: =IF('🧶 Product Catalog'!$C$29="","",'🧶 Product Catalog'!$C$29) | X23: =IF($W23="","",SUMIFS('💰 Sales Log'!$E$8:$E$67,'💰 Sales Log'!$D$8:$D$67,$W23)) -> 0 | Y23: =IF($W23="","",SUMIFS('💰 Sales Log'!$H$8:$H$67,'💰 Sales Log'!$D$8:$D$67,$W23)) -> 0 | Z23: =IF($W23="","",INDEX('🧶 Product Catalog'!$M$8:$M$31,MATCH($W23,'🧶 Product Catalog'!$C$8:$C$31,0))) -> 0 | AA23: =IF(OR($W23="",$X23=0),"",INDEX('🧶 Product Catalog'!$K$8:$K$31,MATCH($W23,'🧶 Product Catalog'!$C$8:$C$31,0))) -> 0 | AB23: =IF($W23="","",$Y23-SUMIFS('💰 Sales Log'!$M$8:$M$67,'💰 Sales Log'!$D$8:$D$67,$W23)) -> 0 | AC23: 22 | AD23: =IF('🏪 Craft Fairs'!$B$29="","",'🏪 Craft Fairs'!$B$29) | AE23: =IF($AD23="","",SUMIFS('💰 Sales Log'!$H$8:$H$67,'💰 Sales Log'!$C$8:$C$67,$AD23)) -> 0 | AF23: =IF($AD23="","",$AE23-SUMIFS('🏪 Craft Fairs'!$K$8:$K$31,'💰 Sales Log'!$C$8:$C$67,$AD23)-SUMIFS('💰 Sales Log'!$M$8:$M$67,'💰 Sales Log'!$C$8:$C$67,$AD23)) -> 0 | AH23: Highest revenue product | AI23: =IFERROR(INDEX($W$2:$W$25,MATCH(MAX($Y$2:$Y$25),$Y$2:$Y$25,0)),"") -> Market Tote Bag
V24: 23 | W24: =IF('🧶 Product Catalog'!$C$30="","",'🧶 Product Catalog'!$C$30) | X24: =IF($W24="","",SUMIFS('💰 Sales Log'!$E$8:$E$67,'💰 Sales Log'!$D$8:$D$67,$W24)) -> 0 | Y24: =IF($W24="","",SUMIFS('💰 Sales Log'!$H$8:$H$67,'💰 Sales Log'!$D$8:$D$67,$W24)) -> 0 | Z24: =IF($W24="","",INDEX('🧶 Product Catalog'!$M$8:$M$31,MATCH($W24,'🧶 Product Catalog'!$C$8:$C$31,0))) -> 0 | AA24: =IF(OR($W24="",$X24=0),"",INDEX('🧶 Product Catalog'!$K$8:$K$31,MATCH($W24,'🧶 Product Catalog'!$C$8:$C$31,0))) -> 0 | AB24: =IF($W24="","",$Y24-SUMIFS('💰 Sales Log'!$M$8:$M$67,'💰 Sales Log'!$D$8:$D$67,$W24)) -> 0 | AC24: 23 | AD24: =IF('🏪 Craft Fairs'!$B$30="","",'🏪 Craft Fairs'!$B$30) | AE24: =IF($AD24="","",SUMIFS('💰 Sales Log'!$H$8:$H$67,'💰 Sales Log'!$C$8:$C$67,$AD24)) -> 0 | AF24: =IF($AD24="","",$AE24-SUMIFS('🏪 Craft Fairs'!$K$8:$K$31,'💰 Sales Log'!$C$8:$C$67,$AD24)-SUMIFS('💰 Sales Log'!$M$8:$M$67,'💰 Sales Log'!$C$8:$C$67,$AD24)) -> 0 | AH24: Highest profit product | AI24: =IFERROR(INDEX($W$2:$W$25,MATCH(MAX($AB$2:$AB$25),$AB$2:$AB$25,0)),"") -> Market Tote Bag
V25: 24 | W25: =IF('🧶 Product Catalog'!$C$31="","",'🧶 Product Catalog'!$C$31) | X25: =IF($W25="","",SUMIFS('💰 Sales Log'!$E$8:$E$67,'💰 Sales Log'!$D$8:$D$67,$W25)) -> 0 | Y25: =IF($W25="","",SUMIFS('💰 Sales Log'!$H$8:$H$67,'💰 Sales Log'!$D$8:$D$67,$W25)) -> 0 | Z25: =IF($W25="","",INDEX('🧶 Product Catalog'!$M$8:$M$31,MATCH($W25,'🧶 Product Catalog'!$C$8:$C$31,0))) -> 0 | AA25: =IF(OR($W25="",$X25=0),"",INDEX('🧶 Product Catalog'!$K$8:$K$31,MATCH($W25,'🧶 Product Catalog'!$C$8:$C$31,0))) -> 0 | AB25: =IF($W25="","",$Y25-SUMIFS('💰 Sales Log'!$M$8:$M$67,'💰 Sales Log'!$D$8:$D$67,$W25)) -> 0 | AC25: 24 | AD25: =IF('🏪 Craft Fairs'!$B$31="","",'🏪 Craft Fairs'!$B$31) | AE25: =IF($AD25="","",SUMIFS('💰 Sales Log'!$H$8:$H$67,'💰 Sales Log'!$C$8:$C$67,$AD25)) -> 0 | AF25: =IF($AD25="","",$AE25-SUMIFS('🏪 Craft Fairs'!$K$8:$K$31,'💰 Sales Log'!$C$8:$C$67,$AD25)-SUMIFS('💰 Sales Log'!$M$8:$M$67,'💰 Sales Log'!$C$8:$C$67,$AD25)) -> 0 | AH25: Highest margin product | AI25: =IFERROR(INDEX($W$2:$W$25,MATCH(MAX($AA$2:$AA$25),$AA$2:$AA$25,0)),"") -> Keychain Charm
AH26: Slowest mover | AI26: =IFERROR(INDEX($W$2:$W$25,MATCH(MIN($X$2:$X$25),$X$2:$X$25,0)),"") -> Granny Square Cardigan
AH27: Pricing calculator: suggested price | AI27: ='💵 Pricing Calculator'!$J$17 -> 52

Sheet ⚙️ Lists & Settings
B2: ⚙️ Lists & Settings
B3: Your studio basics + every dropdown list in one place | H3: 🏠 Dashboard
B5: Your studio
B6: Business name | C6: Willow & Wren Crochet Studio | E6: Shown big on the Dashboard banner.
B7: Season note | C7: Autumn fair season - stock up on chunky yarn! | E7: A little reminder for yourself (optional).
B9: Money & targets
B10: Currency symbol | C10: $ | E10: Every money column shows this symbol.
B11: Report year | C11: 2026 | E11: The Dashboard's month chart follows this year.
B12: Your hourly wage | C12: 14 | E12: Used by the Pricing Calculator to pay yourself properly.
B13: Overhead % | C13: 0.1 | E13: Card fees, electricity, glue, parking... a little on top of everything.
B14: Target profit margin | C14: 0.45 | E14: The default margin the Pricing Calculator aims for.
B16: These five columns feed every dropdown in the workbook. Rename anything, add new rows or delete ones you don't use - the dropdowns update automatically. Keep each list inside its own column and leave no big gaps between entries.
C22: Product categories | D22: Payment methods | E22: Yarn weights | F22: Units | G22: Suppliers
C23: Toys & Amigurumi | D23: Cash | E23: Lace | F23: balls | G23: Local yarn shop
C24: Wearables | D24: Card | E24: Sock / 4-ply | F24: metres | G24: Online yarn store
C25: Home & Decor | D25: Bank transfer | E25: DK / light | F25: grams | G25: Wholesale craft
C26: Accessories | D26: Mobile wallet | E26: Worsted / aran | F26: skeins | G26: Market stall
C27: Baby & Kids | D27: Online order | E27: Chunky | F27: cones | G27: Second-hand / stash
C28: Seasonal | D28: Other | E28: Super chunky | F28: pieces | G28: Other
E29: Mixed / other
B44: Built-in marks (fixed)
B45: The tick marks below power every ✓ box in the workbook. They're fixed on purpose so the green tick highlights keep working - just pick them from the dropdowns.
C46: Tick marks
C47: ✓
C48: ✗ Skip
B52: 💡 Change a setting once and every sheet follows - currency, year, wage and dropdowns all live here.
B54: ▶ Settings | D54: 🏠 Home | F54: Products | H54: Yarn
B55: Stock | D55: Fairs | F55: Sales | H55: Event $
B56: Reorder | D56: Packing | F56: Pricing | H56: Monthly
B57: Help

Sheet 📊 Dashboard
B2: =IF(BusinessName="","My Crochet Studio",BusinessName) -> Willow & Wren Crochet Studio | H2: =IF(Message="","Plan it, make it, sell it.",Message) -> Autumn fair season - stock up on chunky yarn!
B3: 🧶 Your craft fair business at a glance | H3: PREMIUM EDITION • 14 tabs
B5: ="Sales logged: "&TEXT('_Data'!$AI$9,"0") -> Sales logged: 22 | E5: ="Units sold: "&TEXT('_Data'!$AI$8,"#,##0") -> Units sold: 77 | H5: ="Fairs booked: "&TEXT('_Data'!$AI$12,"0") -> Fairs booked: 8 | K5: =IF('_Data'!$AI$15+'_Data'!$AI$16>0,"! Restock needed - see Reorder List","Stock levels look healthy") -> Restock needed - see Reorder List
B7: GROSS SALES | D7: NET PROFIT | F7: PROFIT MARGIN | H7: UNITS SOLD | J7: AVERAGE SALE | L7: STOCK VALUE
B8: =Currency&TEXT('_Data'!$AI$2,"#,##0.00") -> $1,760.00 | D8: =Currency&TEXT('_Data'!$AI$6,"#,##0.00") -> $716.50 | F8: =TEXT('_Data'!$AI$7,"0.0%") -> 40.7% | H8: =TEXT('_Data'!$AI$8,"#,##0") -> 77 | J8: =Currency&TEXT('_Data'!$AI$10,"#,##0.00") -> $80.00 | L8: =Currency&TEXT('_Data'!$AI$14,"#,##0.00") -> $270.20
B11: FAIRS WORKED | D11: BEST CRAFT FAIR | F11: TOP SELLER | H11: TOP EARNER | J11: ITEMS MADE | L11: REORDER BILL
B12: =TEXT('_Data'!$AI$13,"0")&" of "&TEXT('_Data'!$AI$12,"0") -> 6 of 8 | D12: ='_Data'!$AI$21 -> Online Order Batch | F12: ='_Data'!$AI$22 -> Keychain Charm | H12: ='_Data'!$AI$23 -> Market Tote Bag | J12: =TEXT('_Data'!$AI$19,"#,##0") -> 118 | L12: =Currency&TEXT('_Data'!$AI$17,"#,##0.00") -> $342.70
B15: Your year at a glance
B67: Top products (by revenue)
B68: # | C68: Product | H68: Units | I68: Revenue | J68: Profit | K68: Margin
B69: 1 | C69: =IFERROR(INDEX($W$2:$W$25,MATCH(LARGE($Y$2:$Y$25,1),$Y$2:$Y$25,0)),"") -> Market Tote Bag | H69: =IFERROR(INDEX($X$2:$X$25,MATCH($C69,$W$2:$W$25,0)),"") -> 8 | I69: =IFERROR(LARGE($Y$2:$Y$25,1),0) -> 256 | J69: =IFERROR(INDEX($AB$2:$AB$25,MATCH($C69,$W$2:$W$25,0)),"") -> 199.2 | K69: =IFERROR(INDEX($AA$2:$AA$25,MATCH($C69,$W$2:$W$25,0)),"") -> 0.778125
B70: 2 | C70: =IFERROR(INDEX($W$2:$W$25,MATCH(LARGE($Y$2:$Y$25,2),$Y$2:$Y$25,0)),"") -> Flower Coaster Set | H70: =IFERROR(INDEX($X$2:$X$25,MATCH($C70,$W$2:$W$25,0)),"") -> 14 | I70: =IFERROR(LARGE($Y$2:$Y$25,2),0) -> 222 | J70: =IFERROR(INDEX($AB$2:$AB$25,MATCH($C70,$W$2:$W$25,0)),"") -> 186.2 | K70: =IFERROR(INDEX($AA$2:$AA$25,MATCH($C70,$W$2:$W$25,0)),"") -> 0.83125
B71: 3 | C71: =IFERROR(INDEX($W$2:$W$25,MATCH(LARGE($Y$2:$Y$25,3),$Y$2:$Y$25,0)),"") -> Keychain Charm | H71: =IFERROR(INDEX($X$2:$X$25,MATCH($C71,$W$2:$W$25,0)),"") -> 18 | I71: =IFERROR(LARGE($Y$2:$Y$25,3),0) -> 180 | J71: =IFERROR(INDEX($AB$2:$AB$25,MATCH($C71,$W$2:$W$25,0)),"") -> 153 | K71: =IFERROR(INDEX($AA$2:$AA$25,MATCH($C71,$W$2:$W$25,0)),"") -> 0.85
B72: 4 | C72: =IFERROR(INDEX($W$2:$W$25,MATCH(LARGE($Y$2:$Y$25,4),$Y$2:$Y$25,0)),"") -> Amigurumi Bunny | H72: =IFERROR(INDEX($X$2:$X$25,MATCH($C72,$W$2:$W$25,0)),"") -> 6 | I72: =IFERROR(LARGE($Y$2:$Y$25,4),0) -> 168 | J72: =IFERROR(INDEX($AB$2:$AB$25,MATCH($C72,$W$2:$W$25,0)),"") -> 138 | K72: =IFERROR(INDEX($AA$2:$AA$25,MATCH($C72,$W$2:$W$25,0)),"") -> 0.82142857
B73: 5 | C73: =IFERROR(INDEX($W$2:$W$25,MATCH(LARGE($Y$2:$Y$25,5),$Y$2:$Y$25,0)),"") -> Table Runner | H73: =IFERROR(INDEX($X$2:$X$25,MATCH($C73,$W$2:$W$25,0)),"") -> 3 | I73: =IFERROR(LARGE($Y$2:$Y$25,5),0) -> 165 | J73: =IFERROR(INDEX($AB$2:$AB$25,MATCH($C73,$W$2:$W$25,0)),"") -> 129 | K73: =IFERROR(INDEX($AA$2:$AA$25,MATCH($C73,$W$2:$W$25,0)),"") -> 0.78181818
B75: Restock radar
B77: ="Products below minimum: "&TEXT('_Data'!$AI$15,"0") -> Products below minimum: 7 | F77: ="Materials running low: "&TEXT('_Data'!$AI$16,"0") -> Materials running low: 5 | J77: ="Estimated shopping list: "&Currency&TEXT('_Data'!$AI$17,"#,##0.00") -> Estimated shopping list: $342.70
B79: The Reorder List tab turns these into a ready-to-buy shopping list with suppliers and costs - tick items off as you order.
B81: 💡 Every number on this page is live - log a sale on the Sales Log tab and watch it land here instantly.
B83: Settings | D83: ▶ 🏠 Home | F83: Products | H83: Yarn | J83: Stock | L83: Fairs
B84: Sales | D84: Event $ | F84: Reorder | H84: Packing | J84: Pricing | L84: Monthly
B85: Help

Sheet 🧶 Product Catalog
B2: 🧶 Product Catalog
B3: One row for everything you make - prices, costs and stock at a glance | N3: 🏠 Dashboard
B5: ="Products: "&TEXT(COUNTA('🧶 Product Catalog'!$C$8:$C$31),"0") -> 12 | E5: ="Avg price: "&Currency&TEXT(IFERROR(AVERAGE('🧶 Product Catalog'!$F$8:$F$31),0),"#,##0.00") -> 36.08 | H5: ="Stock value: "&Currency&TEXT('_Data'!$AI$14,"#,##0.00") -> $270.20 | K5: =IF('_Data'!$AI$15>0,"! "&TEXT('_Data'!$AI$15,"0")&" products low on stock","Stock levels OK") -> ! 7 products low on stock
A7: # | B7: SKU / code | C7: Product | D7: Category | E7: Description | F7: Price | G7: Yarn cost | H7: Packaging | I7: Cost / item | J7: Profit / item | K7: Margin | L7: Hours to make | M7: In stock | N7: Keep min. | O7: Stock status | P7: Photo / link
B8: CB-001 | C8: Amigurumi Bunny | D8: Toys & Amigurumi | E8: Soft cotton bunny with safety eyes | F8: 28 | G8: 4.2 | H8: 0.8 | I8: =IF($C8="","",ROUND(N($G8)+N($H8),2)) -> 5 | J8: =IF(OR($C8="",$F8=""),"",ROUND($F8-$I8,2)) -> 23 | K8: =IF(OR($C8="",$F8=""),"",IFERROR($J8/$F8,0)) -> 0.82142857 | L8: 2.5 | M8: =IF($C8="",0,SUMIFS('📦 Made & Stocked'!$J$8:$J$37,'📦 Made & Stocked'!$B$8:$B$37,$C8)) -> 5 | N8: 4 | O8: =IF($C8="","",IF(N($M8)<=0,"🔴 Out of stock",IF(N($M8)<$N8,"🟠 Low stock","🟢 In stock"))) -> 🟢 In stock | P8: photos/bunny.jpg
B9: CB-002 | C9: Chunky Beanie | D9: Wearables | E9: Super chunky merino beanie | F9: 24 | G9: 5.6 | H9: 0.7 | I9: =IF($C9="","",ROUND(N($G9)+N($H9),2)) -> 6.3 | J9: =IF(OR($C9="",$F9=""),"",ROUND($F9-$I9,2)) -> 17.7 | K9: =IF(OR($C9="",$F9=""),"",IFERROR($J9/$F9,0)) -> 0.7375 | L9: 1.5 | M9: =IF($C9="",0,SUMIFS('📦 Made & Stocked'!$J$8:$J$37,'📦 Made & Stocked'!$B$8:$B$37,$C9)) -> 10 | N9: 6 | O9: =IF($C9="","",IF(N($M9)<=0,"🔴 Out of stock",IF(N($M9)<$N9,"🟠 Low stock","🟢 In stock"))) -> 🟢 In stock | P9: photos/beanie.jpg
B10: CB-003 | C10: Granny Square Cardigan | D10: Wearables | E10: Hand-joined granny squares | F10: 95 | G10: 18.4 | H10: 2.2 | I10: =IF($C10="","",ROUND(N($G10)+N($H10),2)) -> 20.6 | J10: =IF(OR($C10="",$F10=""),"",ROUND($F10-$I10,2)) -> 74.4 | K10: =IF(OR($C10="",$F10=""),"",IFERROR($J10/$F10,0)) -> 0.78315789 | L10: 12 | M10: =IF($C10="",0,SUMIFS('📦 Made & Stocked'!$J$8:$J$37,'📦 Made & Stocked'!$B$8:$B$37,$C10)) -> 2 | N10: 2 | O10: =IF($C10="","",IF(N($M10)<=0,"🔴 Out of stock",IF(N($M10)<$N10,"🟠 Low stock","🟢 In stock"))) -> 🟢 In stock | P10: photos/cardigan.jpg
B11: CB-004 | C11: Market Tote Bag | D11: Accessories | E11: Sturdy cotton market tote | F11: 32 | G11: 6.1 | H11: 1 | I11: =IF($C11="","",ROUND(N($G11)+N($H11),2)) -> 7.1 | J11: =IF(OR($C11="",$F11=""),"",ROUND($F11-$I11,2)) -> 24.9 | K11: =IF(OR($C11="",$F11=""),"",IFERROR($J11/$F11,0)) -> 0.778125 | L11: 3 | M11: =IF($C11="",0,SUMIFS('📦 Made & Stocked'!$J$8:$J$37,'📦 Made & Stocked'!$B$8:$B$37,$C11)) -> 3 | N11: 5 | O11: =IF($C11="","",IF(N($M11)<=0,"🔴 Out of stock",IF(N($M11)<$N11,"🟠 Low stock","🟢 In stock"))) -> 🟠 Low stock | P11: photos/tote.jpg
B12: CB-005 | C12: Cozy Scarf | D12: Wearables | E12: Worsted wool scarf | F12: 38 | G12: 8.9 | H12: 1.1 | I12: =IF($C12="","",ROUND(N($G12)+N($H12),2)) -> 10 | J12: =IF(OR($C12="",$F12=""),"",ROUND($F12-$I12,2)) -> 28 | K12: =IF(OR($C12="",$F12=""),"",IFERROR($J12/$F12,0)) -> 0.73684211 | L12: 4 | M12: =IF($C12="",0,SUMIFS('📦 Made & Stocked'!$J$8:$J$37,'📦 Made & Stocked'!$B$8:$B$37,$C12)) -> 4 | N12: 4 | O12: =IF($C12="","",IF(N($M12)<=0,"🔴 Out of stock",IF(N($M12)<$N12,"🟠 Low stock","🟢 In stock"))) -> 🟢 In stock | P12: photos/scarf.jpg
B13: CB-006 | C13: Baby Booties | D13: Baby & Kids | E13: Tiny soft booties, pair | F13: 18 | G13: 2.6 | H13: 0.6 | I13: =IF($C13="","",ROUND(N($G13)+N($H13),2)) -> 3.2 | J13: =IF(OR($C13="",$F13=""),"",ROUND($F13-$I13,2)) -> 14.8 | K13: =IF(OR($C13="",$F13=""),"",IFERROR($J13/$F13,0)) -> 0.82222222 | L13: 1.2 | M13: =IF($C13="",0,SUMIFS('📦 Made & Stocked'!$J$8:$J$37,'📦 Made & Stocked'!$B$8:$B$37,$C13)) -> 3 | N13: 6 | O13: =IF($C13="","",IF(N($M13)<=0,"🔴 Out of stock",IF(N($M13)<$N13,"🟠 Low stock","🟢 In stock"))) -> 🟠 Low stock | P13: photos/booties.jpg
B14: CB-007 | C14: Flower Coaster Set | D14: Home & Decor | E14: Set of 4 cotton coasters | F14: 16 | G14: 2.2 | H14: 0.5 | I14: =IF($C14="","",ROUND(N($G14)+N($H14),2)) -> 2.7 | J14: =IF(OR($C14="",$F14=""),"",ROUND($F14-$I14,2)) -> 13.3 | K14: =IF(OR($C14="",$F14=""),"",IFERROR($J14/$F14,0)) -> 0.83125 | L14: 1 | M14: =IF($C14="",0,SUMIFS('📦 Made & Stocked'!$J$8:$J$37,'📦 Made & Stocked'!$B$8:$B$37,$C14)) -> 5 | N14: 8 | O14: =IF($C14="","",IF(N($M14)<=0,"🔴 Out of stock",IF(N($M14)<$N14,"🟠 Low stock","🟢 In stock"))) -> 🟠 Low stock | P14: photos/coasters.jpg
B15: CB-008 | C15: Lap Blanket | D15: Home & Decor | E15: Granny stripe lap blanket | F15: 75 | G15: 16.8 | H15: 2 | I15: =IF($C15="","",ROUND(N($G15)+N($H15),2)) -> 18.8 | J15: =IF(OR($C15="",$F15=""),"",ROUND($F15-$I15,2)) -> 56.2 | K15: =IF(OR($C15="",$F15=""),"",IFERROR($J15/$F15,0)) -> 0.74933333 | L15: 10 | M15: =IF($C15="",0,SUMIFS('📦 Made & Stocked'!$J$8:$J$37,'📦 Made & Stocked'!$B$8:$B$37,$C15)) -> 1 | N15: 2 | O15: =IF($C15="","",IF(N($M15)<=0,"🔴 Out of stock",IF(N($M15)<$N15,"🟠 Low stock","🟢 In stock"))) -> 🟠 Low stock | P15: photos/blanket.jpg
B16: CB-009 | C16: Ear Warmer Headband | D16: Accessories | E16: Twisted ear warmer | F16: 16 | G16: 2.9 | H16: 0.5 | I16: =IF($C16="","",ROUND(N($G16)+N($H16),2)) -> 3.4 | J16: =IF(OR($C16="",$F16=""),"",ROUND($F16-$I16,2)) -> 12.6 | K16: =IF(OR($C16="",$F16=""),"",IFERROR($J16/$F16,0)) -> 0.7875 | L16: 1 | M16: =IF($C16="",0,SUMIFS('📦 Made & Stocked'!$J$8:$J$37,'📦 Made & Stocked'!$B$8:$B$37,$C16)) -> 0 | N16: 4 | O16: =IF($C16="","",IF(N($M16)<=0,"🔴 Out of stock",IF(N($M16)<$N16,"🟠 Low stock","🟢 In stock"))) -> 🔴 Out of stock | P16: photos/earwarmer.jpg
B17: CB-010 | C17: Stuffed Octopus | D17: Toys & Amigurumi | E17: Squishy friend octopus | F17: 26 | G17: 4.6 | H17: 0.8 | I17: =IF($C17="","",ROUND(N($G17)+N($H17),2)) -> 5.4 | J17: =IF(OR($C17="",$F17=""),"",ROUND($F17-$I17,2)) -> 20.6 | K17: =IF(OR($C17="",$F17=""),"",IFERROR($J17/$F17,0)) -> 0.79230769 | L17: 2.5 | M17: =IF($C17="",0,SUMIFS('📦 Made & Stocked'!$J$8:$J$37,'📦 Made & Stocked'!$B$8:$B$37,$C17)) -> 7 | N17: 4 | O17: =IF($C17="","",IF(N($M17)<=0,"🔴 Out of stock",IF(N($M17)<$N17,"🟠 Low stock","🟢 In stock"))) -> 🟢 In stock | P17: photos/octopus.jpg
B18: CB-011 | C18: Table Runner | D18: Home & Decor | E18: Lacy cotton table runner | F18: 55 | G18: 10.4 | H18: 1.6 | I18: =IF($C18="","",ROUND(N($G18)+N($H18),2)) -> 12 | J18: =IF(OR($C18="",$F18=""),"",ROUND($F18-$I18,2)) -> 43 | K18: =IF(OR($C18="",$F18=""),"",IFERROR($J18/$F18,0)) -> 0.78181818 | L18: 7 | M18: =IF($C18="",0,SUMIFS('📦 Made & Stocked'!$J$8:$J$37,'📦 Made & Stocked'!$B$8:$B$37,$C18)) -> 0 | N18: 2 | O18: =IF($C18="","",IF(N($M18)<=0,"🔴 Out of stock",IF(N($M18)<$N18,"🟠 Low stock","🟢 In stock"))) -> 🔴 Out of stock | P18: photos/runner.jpg
B19: CB-012 | C19: Keychain Charm | D19: Accessories | E19: Mini amigurumi keychain | F19: 10 | G19: 1.1 | H19: 0.4 | I19: =IF($C19="","",ROUND(N($G19)+N($H19),2)) -> 1.5 | J19: =IF(OR($C19="",$F19=""),"",ROUND($F19-$I19,2)) -> 8.5 | K19: =IF(OR($C19="",$F19=""),"",IFERROR($J19/$F19,0)) -> 0.85 | L19: 0.5 | M19: =IF($C19="",0,SUMIFS('📦 Made & Stocked'!$J$8:$J$37,'📦 Made & Stocked'!$B$8:$B$37,$C19)) -> 0 | N19: 6 | O19: =IF($C19="","",IF(N($M19)<=0,"🔴 Out of stock",IF(N($M19)<$N19,"🟠 Low stock","🟢 In stock"))) -> 🔴 Out of stock | P19: photos/charm.jpg
I20: =IF($C20="","",ROUND(N($G20)+N($H20),2)) -> 0 | J20: =IF(OR($C20="",$F20=""),"",ROUND($F20-$I20,2)) -> 0 | K20: =IF(OR($C20="",$F20=""),"",IFERROR($J20/$F20,0)) -> 0 | M20: =IF($C20="",0,SUMIFS('📦 Made & Stocked'!$J$8:$J$37,'📦 Made & Stocked'!$B$8:$B$37,$C20)) -> 0 | O20: =IF($C20="","",IF(N($M20)<=0,"🔴 Out of stock",IF(N($M20)<$N20,"🟠 Low stock","🟢 In stock"))) -> 0
I21: =IF($C21="","",ROUND(N($G21)+N($H21),2)) -> 0 | J21: =IF(OR($C21="",$F21=""),"",ROUND($F21-$I21,2)) -> 0 | K21: =IF(OR($C21="",$F21=""),"",IFERROR($J21/$F21,0)) -> 0 | M21: =IF($C21="",0,SUMIFS('📦 Made & Stocked'!$J$8:$J$37,'📦 Made & Stocked'!$B$8:$B$37,$C21)) -> 0 | O21: =IF($C21="","",IF(N($M21)<=0,"🔴 Out of stock",IF(N($M21)<$N21,"🟠 Low stock","🟢 In stock"))) -> 0
I22: =IF($C22="","",ROUND(N($G22)+N($H22),2)) -> 0 | J22: =IF(OR($C22="",$F22=""),"",ROUND($F22-$I22,2)) -> 0 | K22: =IF(OR($C22="",$F22=""),"",IFERROR($J22/$F22,0)) -> 0 | M22: =IF($C22="",0,SUMIFS('📦 Made & Stocked'!$J$8:$J$37,'📦 Made & Stocked'!$B$8:$B$37,$C22)) -> 0 | O22: =IF($C22="","",IF(N($M22)<=0,"🔴 Out of stock",IF(N($M22)<$N22,"🟠 Low stock","🟢 In stock"))) -> 0
I23: =IF($C23="","",ROUND(N($G23)+N($H23),2)) -> 0 | J23: =IF(OR($C23="",$F23=""),"",ROUND($F23-$I23,2)) -> 0 | K23: =IF(OR($C23="",$F23=""),"",IFERROR($J23/$F23,0)) -> 0 | M23: =IF($C23="",0,SUMIFS('📦 Made & Stocked'!$J$8:$J$37,'📦 Made & Stocked'!$B$8:$B$37,$C23)) -> 0 | O23: =IF($C23="","",IF(N($M23)<=0,"🔴 Out of stock",IF(N($M23)<$N23,"🟠 Low stock","🟢 In stock"))) -> 0
I24: =IF($C24="","",ROUND(N($G24)+N($H24),2)) -> 0 | J24: =IF(OR($C24="",$F24=""),"",ROUND($F24-$I24,2)) -> 0 | K24: =IF(OR($C24="",$F24=""),"",IFERROR($J24/$F24,0)) -> 0 | M24: =IF($C24="",0,SUMIFS('📦 Made & Stocked'!$J$8:$J$37,'📦 Made & Stocked'!$B$8:$B$37,$C24)) -> 0 | O24: =IF($C24="","",IF(N($M24)<=0,"🔴 Out of stock",IF(N($M24)<$N24,"🟠 Low stock","🟢 In stock"))) -> 0
I25: =IF($C25="","",ROUND(N($G25)+N($H25),2)) -> 0 | J25: =IF(OR($C25="",$F25=""),"",ROUND($F25-$I25,2)) -> 0 | K25: =IF(OR($C25="",$F25=""),"",IFERROR($J25/$F25,0)) -> 0 | M25: =IF($C25="",0,SUMIFS('📦 Made & Stocked'!$J$8:$J$37,'📦 Made & Stocked'!$B$8:$B$37,$C25)) -> 0 | O25: =IF($C25="","",IF(N($M25)<=0,"🔴 Out of stock",IF(N($M25)<$N25,"🟠 Low stock","🟢 In stock"))) -> 0
I26: =IF($C26="","",ROUND(N($G26)+N($H26),2)) -> 0 | J26: =IF(OR($C26="",$F26=""),"",ROUND($F26-$I26,2)) -> 0 | K26: =IF(OR($C26="",$F26=""),"",IFERROR($J26/$F26,0)) -> 0 | M26: =IF($C26="",0,SUMIFS('📦 Made & Stocked'!$J$8:$J$37,'📦 Made & Stocked'!$B$8:$B$37,$C26)) -> 0 | O26: =IF($C26="","",IF(N($M26)<=0,"🔴 Out of stock",IF(N($M26)<$N26,"🟠 Low stock","🟢 In stock"))) -> 0
I27: =IF($C27="","",ROUND(N($G27)+N($H27),2)) -> 0 | J27: =IF(OR($C27="",$F27=""),"",ROUND($F27-$I27,2)) -> 0 | K27: =IF(OR($C27="",$F27=""),"",IFERROR($J27/$F27,0)) -> 0 | M27: =IF($C27="",0,SUMIFS('📦 Made & Stocked'!$J$8:$J$37,'📦 Made & Stocked'!$B$8:$B$37,$C27)) -> 0 | O27: =IF($C27="","",IF(N($M27)<=0,"🔴 Out of stock",IF(N($M27)<$N27,"🟠 Low stock","🟢 In stock"))) -> 0
I28: =IF($C28="","",ROUND(N($G28)+N($H28),2)) -> 0 | J28: =IF(OR($C28="",$F28=""),"",ROUND($F28-$I28,2)) -> 0 | K28: =IF(OR($C28="",$F28=""),"",IFERROR($J28/$F28,0)) -> 0 | M28: =IF($C28="",0,SUMIFS('📦 Made & Stocked'!$J$8:$J$37,'📦 Made & Stocked'!$B$8:$B$37,$C28)) -> 0 | O28: =IF($C28="","",IF(N($M28)<=0,"🔴 Out of stock",IF(N($M28)<$N28,"🟠 Low stock","🟢 In stock"))) -> 0
I29: =IF($C29="","",ROUND(N($G29)+N($H29),2)) -> 0 | J29: =IF(OR($C29="",$F29=""),"",ROUND($F29-$I29,2)) -> 0 | K29: =IF(OR($C29="",$F29=""),"",IFERROR($J29/$F29,0)) -> 0 | M29: =IF($C29="",0,SUMIFS('📦 Made & Stocked'!$J$8:$J$37,'📦 Made & Stocked'!$B$8:$B$37,$C29)) -> 0 | O29: =IF($C29="","",IF(N($M29)<=0,"🔴 Out of stock",IF(N($M29)<$N29,"🟠 Low stock","🟢 In stock"))) -> 0
I30: =IF($C30="","",ROUND(N($G30)+N($H30),2)) -> 0 | J30: =IF(OR($C30="",$F30=""),"",ROUND($F30-$I30,2)) -> 0 | K30: =IF(OR($C30="",$F30=""),"",IFERROR($J30/$F30,0)) -> 0 | M30: =IF($C30="",0,SUMIFS('📦 Made & Stocked'!$J$8:$J$37,'📦 Made & Stocked'!$B$8:$B$37,$C30)) -> 0 | O30: =IF($C30="","",IF(N($M30)<=0,"🔴 Out of stock",IF(N($M30)<$N30,"🟠 Low stock","🟢 In stock"))) -> 0
I31: =IF($C31="","",ROUND(N($G31)+N($H31),2)) -> 0 | J31: =IF(OR($C31="",$F31=""),"",ROUND($F31-$I31,2)) -> 0 | K31: =IF(OR($C31="",$F31=""),"",IFERROR($J31/$F31,0)) -> 0 | M31: =IF($C31="",0,SUMIFS('📦 Made & Stocked'!$J$8:$J$37,'📦 Made & Stocked'!$B$8:$B$37,$C31)) -> 0 | O31: =IF($C31="","",IF(N($M31)<=0,"🔴 Out of stock",IF(N($M31)<$N31,"🟠 Low stock","🟢 In stock"))) -> 0
C33: =COUNTA('🧶 Product Catalog'!$C$8:$C$31) -> 12 | F33: =IFERROR(AVERAGE('🧶 Product Catalog'!$F$8:$F$31),0) -> 36.08 | I33: =IFERROR(AVERAGE('🧶 Product Catalog'!$I$8:$I$31),0) -> 8 | J33: =IFERROR(AVERAGE('🧶 Product Catalog'!$J$8:$J$31),0) -> 28.08 | M33: =SUM('🧶 Product Catalog'!$M$8:$M$31) -> 40
B35: How this tab works
B36: Cost / item = yarn + packaging. Profit and margin follow your price automatically. In stock is live from the Made & Stocked tab - every batch you log updates it instantly. Keep min. is your reorder trigger - dip below it and the item appears on the Reorder List tab.
B40: 💡 Cream cells are yours to type in; white cells calculate. Dropdowns keep every column honest.
B42: Settings | D42: 🏠 Home | F42: ▶ Products | H42: Yarn | J42: Stock | L42: Fairs | N42: Sales
B43: Event $ | D43: Reorder | F43: Packing | H43: Pricing | J43: Monthly | L43: Help

Sheet 🧵 Yarn & Materials
B2: 🧵 Yarn & Materials
B3: Your whole stash with costs - and what's left on the shelf | L3: 🏠 Dashboard
B5: ="Materials: "&TEXT(COUNTA('🧵 Yarn & Materials'!$B$8:$B$31),"0") -> Materials: 10 | E5: ="Still on the shelf: "&TEXT(SUM('🧵 Yarn & Materials'!$K$8:$K$31),"#,##0") -> Still on the shelf: 74 | H5: ="Stash value: "&Currency&TEXT(SUM('🧵 Yarn & Materials'!$I$8:$I$31),"#,##0.00") -> Stash value: $360.30 | K5: =IF('_Data'!$AI$16>0,"! "&TEXT('_Data'!$AI$16,"0")&" materials running low","Stash looks healthy") -> ! 5 materials running low
A7: # | B7: Material | C7: Colour | D7: Brand | E7: Yarn weight | F7: Purchased | G7: Unit | H7: Cost / unit | I7: Total cost | J7: Used so far | K7: Remaining | L7: Supplier | M7: Low at | N7: Reorder?
B8: Cotton yarn - natural | C8: Natural | D8: Cotton Craft Co | E8: Worsted / aran | F8: 20 | G8: balls | H8: 3.4 | I8: =IF($B8="","",ROUND(N($F8)*N($H8),2)) -> 68 | J8: 16 | K8: =IF($B8="","",N($F8)-N($J8)) -> 4 | L8: Local yarn shop | M8: 5 | N8: =IF($B8="","",IF($K8<=$M8,"✅ Reorder","❌ OK")) -> ✅ Reorder
B9: Acrylic yarn - raspberry | C9: Raspberry | D9: Value Yarns | E9: Worsted / aran | F9: 15 | G9: balls | H9: 2.6 | I9: =IF($B9="","",ROUND(N($F9)*N($H9),2)) -> 39 | J9: 9 | K9: =IF($B9="","",N($F9)-N($J9)) -> 6 | L9: Online yarn store | M9: 4 | N9: =IF($B9="","",IF($K9<=$M9,"✅ Reorder","❌ OK")) -> ❌ OK
B10: Merino wool - sage | C10: Sage | D10: Highland Fibres | E10: DK / light | F10: 12 | G10: balls | H10: 6.8 | I10: =IF($B10="","",ROUND(N($F10)*N($H10),2)) -> 81.6 | J10: 10 | K10: =IF($B10="","",N($F10)-N($J10)) -> 2 | L10: Local yarn shop | M10: 4 | N10: =IF($B10="","",IF($K10<=$M10,"✅ Reorder","❌ OK")) -> ✅ Reorder
B11: Chenille chunky - cream | C11: Cream | D11: Snuggle Spun | E11: Super chunky | F11: 10 | G11: balls | H11: 4.9 | I11: =IF($B11="","",ROUND(N($F11)*N($H11),2)) -> 49 | J11: 6 | K11: =IF($B11="","",N($F11)-N($J11)) -> 4 | L11: Online yarn store | M11: 3 | N11: =IF($B11="","",IF($K11<=$M11,"✅ Reorder","❌ OK")) -> ❌ OK
B12: Cotton yarn - mustard | C12: Mustard | D12: Cotton Craft Co | E12: DK / light | F12: 8 | G12: balls | H12: 3.2 | I12: =IF($B12="","",ROUND(N($F12)*N($H12),2)) -> 25.6 | J12: 7 | K12: =IF($B12="","",N($F12)-N($J12)) -> 1 | L12: Local yarn shop | M12: 3 | N12: =IF($B12="","",IF($K12<=$M12,"✅ Reorder","❌ OK")) -> ✅ Reorder
B13: Wool blend - lavender | C13: Lavender | D13: Highland Fibres | E13: Worsted / aran | F13: 10 | G13: balls | H13: 5.4 | I13: =IF($B13="","",ROUND(N($F13)*N($H13),2)) -> 54 | J13: 4 | K13: =IF($B13="","",N($F13)-N($J13)) -> 6 | L13: Wholesale craft | M13: 3 | N13: =IF($B13="","",IF($K13<=$M13,"✅ Reorder","❌ OK")) -> ❌ OK
B14: Polyester stuffing | C14: White | D14: Craft Basics | E14: Mixed / other | F14: 6 | G14: pieces | H14: 2.1 | I14: =IF($B14="","",ROUND(N($F14)*N($H14),2)) -> 12.6 | J14: 4 | K14: =IF($B14="","",N($F14)-N($J14)) -> 2 | L14: Wholesale craft | M14: 2 | N14: =IF($B14="","",IF($K14<=$M14,"✅ Reorder","❌ OK")) -> ✅ Reorder
B15: Bamboo buttons | C15: Natural | D15: Craft Basics | E15: Mixed / other | F15: 40 | G15: pieces | H15: 0.35 | I15: =IF($B15="","",ROUND(N($F15)*N($H15),2)) -> 14 | J15: 22 | K15: =IF($B15="","",N($F15)-N($J15)) -> 18 | L15: Online yarn store | M15: 10 | N15: =IF($B15="","",IF($K15<=$M15,"✅ Reorder","❌ OK")) -> ❌ OK
B16: Safety eyes | C16: Black | D16: Craft Basics | E16: Mixed / other | F16: 30 | G16: pieces | H16: 0.25 | I16: =IF($B16="","",ROUND(N($F16)*N($H16),2)) -> 7.5 | J16: 24 | K16: =IF($B16="","",N($F16)-N($J16)) -> 6 | L16: Wholesale craft | M16: 10 | N16: =IF($B16="","",IF($K16<=$M16,"✅ Reorder","❌ OK")) -> ✅ Reorder
