Workbook
Name Actions: '⚙️ Settings & Instructions'!$E$46:$E$47
Name BudgetMax: '⚙️ Settings & Instructions'!$C$16
Name BudgetMin: '⚙️ Settings & Instructions'!$C$15
Name Currency: '⚙️ Settings & Instructions'!$C$10
Name Diets: OFFSET('⚙️ Settings & Instructions'!$D$26,0,0,MAX(1,COUNTA('⚙️ Settings & Instructions'!$D$26:$D$41)),1)
Name DrawSeed: '⚙️ Settings & Instructions'!$C$19
Name DrawStatus: '⚙️ Settings & Instructions'!$C$21
Name MaxSteals: '⚙️ Settings & Instructions'!$C$17
Name Message: '⚙️ Settings & Instructions'!$C$7
Name OnOff: '⚙️ Settings & Instructions'!$H$46:$H$47
Name ParticipantsList: OFFSET('👥 Participants'!$B$8,0,0,MAX(1,COUNTA('👥 Participants'!$B$8:$B$31)),1)
Name PartyDate: '⚙️ Settings & Instructions'!$C$12
Name PartyHost: '⚙️ Settings & Instructions'!$C$14
Name PartyLocation: '⚙️ Settings & Instructions'!$C$13
Name PartyName: '⚙️ Settings & Instructions'!$C$6
Name PartyYear: '⚙️ Settings & Instructions'!$C$11
Name Priorities: '⚙️ Settings & Instructions'!$F$46:$F$48
Name RSVP: '⚙️ Settings & Instructions'!$D$46:$D$48
Name StartPlayer: '⚙️ Settings & Instructions'!$C$18
Name Statuses: '⚙️ Settings & Instructions'!$C$46:$C$49
Name Teams: OFFSET('⚙️ Settings & Instructions'!$C$26,0,0,MAX(1,COUNTA('⚙️ Settings & Instructions'!$C$26:$C$41)),1)
Name Tick: '⚙️ Settings & Instructions'!$G$46:$G$47
Name WESeed: '⚙️ Settings & Instructions'!$C$20

Sheet _Data
AH1: Metric | AI1: Value
AH2: participants | AI2: =COUNTA('👥 Participants'!$B$8:$B$31) -> 0
AH3: rsvp_yes | AI3: =COUNTIF('👥 Participants'!$E$8:$E$31,"Yes") -> 0
AH4: rsvp_pending | AI4: =COUNTIF('👥 Participants'!$E$8:$E$31,"Maybe") -> 0
AH5: assigned | AI5: =SUMPRODUCT(--('🎅 Secret Santa Draw'!$E$8:$E$31<>"")) -> 0
AH6: purchased | AI6: =COUNTIF('👥 Participants'!$H$8:$H$31,"Gift Purchased")+COUNTIF('👥 Participants'!$H$8:$H$31,"Wrapped")+COUNTIF('👥 Participants'!$H$8:$H$31,"Complete") -> 0
AH7: wrapped | AI7: =COUNTIF('👥 Participants'!$H$8:$H$31,"Wrapped")+COUNTIF('👥 Participants'!$H$8:$H$31,"Complete") -> 0
AH8: complete | AI8: =COUNTIF('👥 Participants'!$H$8:$H$31,"Complete") -> 0
AH9: total_budget | AI9: =$AI$2*BudgetMax -> 0
AH10: spent | AI10: =SUM('💰 Budget Tracker'!$E$8:$E$31) -> 0
AH11: avg_gift | AI11: =IFERROR($AI$10/$AI$6,0) -> 0
AH12: rules_count | AI12: =0 -> 0
AH13: we_players | AI13: =0 -> 0
AH14: gifts_in_play | AI14: =0 -> 0
AH15: locked_gifts | AI15: =0 -> 0
AH16: completion | AI16: =IFERROR(($AI$6+$AI$7+$AI$8)/(3*$AI$2),0) -> 0
AH17: turns_done | AI17: =0 -> 0
AH18: current_turn | AI18: =0 -> 0
AH19: violations | AI19: =COUNTIF('🎅 Secret Santa Draw'!$F$8:$F$31,"?*")-COUNTIF('🎅 Secret Santa Draw'!$F$8:$F$31,"✅ OK") -> 0
AH20: over_budget | AI20: =COUNTIF('💰 Budget Tracker'!$F$8:$F$31,"🚨 Over budget") -> 0
AH21: diets | AI21: =COUNTA('👥 Participants'!$F$8:$F$31) -> 0
AH40: Not Started | AI40: =COUNTIF('👥 Participants'!$H$8:$H$31,"Not Started") -> 0
AH41: Gift Purchased | AI41: =COUNTIF('👥 Participants'!$H$8:$H$31,"Gift Purchased") -> 0
AH42: Wrapped | AI42: =COUNTIF('👥 Participants'!$H$8:$H$31,"Wrapped") -> 0
AH43: Complete | AI43: =COUNTIF('👥 Participants'!$H$8:$H$31,"Complete") -> 0
AH45: Yes | AI45: =COUNTIF('👥 Participants'!$E$8:$E$31,"Yes") -> 0
AH46: No | AI46: =COUNTIF('👥 Participants'!$E$8:$E$31,"No") -> 0
AH47: Maybe | AI47: =COUNTIF('👥 Participants'!$E$8:$E$31,"Maybe") -> 0

Sheet ⚙️ Settings & Instructions
B4: 🎉 THE PARTY
B6: Party name | C6: Your party name
B7: Dashboard message of the day | C7: Type a message for the dashboard banner
B9: 🎛️ RULES OF THE GAME
B10: Currency symbol | C10: $
B11: Party year (used everywhere) | C11: 2026
B12: Party date
B13: Location | C13: Where is the party?
B14: Host | C14: Who is hosting?
B15: Minimum gift budget | C15: 20
B16: Maximum gift budget | C16: 35
B17: Max steals per gift (White Elephant) | C17: 2
B18: Starting player seat (White Elephant) | C18: 1
B19: Secret Santa draw seed (change = re-draw) | C19: 5
B20: White Elephant seat seed | C20: 7
B21: Draw status | C21: Draft — re-draw allowed
B25: 📝 YOUR LISTS - rename or add, every dropdown follows
C26: Studio | D26: Vegetarian
C27: Shop | D27: Vegan
C28: Online | D28: Gluten-free
C29: Friends | D29: Halal
C30: Family | D30: Nut allergy
B44: 🔒 BUILT-IN LISTS (part of the engine - do not edit)
C45: Statuses | D45: RSVP | E45: Actions | F45: Priorities | G45: Tick | H45: OnOff
C46: Not Started | D46: Yes | E46: Pick | F46: Must-love | G46: ✓ | H46: On
C47: Gift Purchased | D47: No | E47: Steal | F47: Nice to have | H47: Off
C48: Wrapped | D48: Maybe | E48: Pass | F48: Just an idea
C49: Complete
B52: 📖 HOW TO RUN THE PARTY
B53: Formula cells are locked so nobody breaks the maths. The sheet password is “premium” - unlock via Review → Unprotect Sheet if you ever need to change a seed or a formula. Re-draw the Secret Santa any time: unlock, change the draw seed on this tab, watch 🎅 Secret Santa Draw shuffle, then set Draw status to Final and re-protect. White Elephant: log every Pick / Steal / Pass on 🔄 Game History - the 🎲 White Elephant tab updates holders, steal counts, locks and final gifts by itself.
B58: 💡 Cream cells are yours to type in; white cells calculate. Dropdowns keep every column honest.
B60: ▶ Settings | D60: Dashboard | F60: People
B61: Draw | D61: Budget | F61: Start Here

Sheet 🏠 Dashboard
B2: =IF(PartyName="","🎅 Secret Santa & White Elephant Command Centre","🎅 "&PartyName&" • Secret Santa & White Elephant Command Centre") -> 🎅 • Secret Santa & White Elephant Command Centre
B3: =IF(PartyDate="","", "🎄 "&TEXT(PartyDate,"dddd, dd mmmm yyyy")&" • "&PartyLocation&" • hosted by "&PartyHost&" • "&MAX(0,PartyDate-TODAY())&" days to go!")
B4: ="👥 "&'_Data'!$AI$2&" guests • "&'_Data'!$AI$5&" in the draw • "&'_Data'!$AI$13&" white-elephant players • draw: "&DrawStatus -> 👥 0 guests • 0 in the draw • 0 white-elephant players • draw:
B5: ="💬 "&Message -> 💬
B7: 🎉 PARTY AT A GLANCE
B8: PARTICIPANTS | D8: SANTA ASSIGNED | F8: GIFTS PURCHASED | H8: TOTAL BUDGET | J8: ACTUAL SPEND | L8: AVG GIFT COST
B9: ='_Data'!$AI$2 -> 0 | D9: ='_Data'!$AI$5&" of "&'_Data'!$AI$2 -> 0 of 0 | F9: ='_Data'!$AI$6 -> 0 | H9: =Currency&TEXT('_Data'!$AI$9,"#,##0") -> $0 | J9: =Currency&TEXT('_Data'!$AI$10,"#,##0") -> $0 | L9: =Currency&TEXT('_Data'!$AI$11,"#,##0.00") -> $0.00
B10: EXCLUSION RULES | D10: W-E PLAYERS | F10: GIFTS IN PLAY | H10: LOCKED GIFTS | J10: RSVP YES | L10: COMPLETION
B11: ='_Data'!$AI$12 -> 0 | D11: ='_Data'!$AI$13 -> 0 | F11: ='_Data'!$AI$14 -> 0 | H11: ='_Data'!$AI$15 -> 0 | J11: ='_Data'!$AI$3&" / "&'_Data'!$AI$2 -> 0 / 0 | L11: =TEXT('_Data'!$AI$16,"0%") -> 0%
B12: Gift readiness | D12: =IFERROR(REPT("█",ROUND(MIN(1,IFERROR(('_Data'!$AI$6)/('_Data'!$AI$2),0))*34,0))&REPT("░",34-ROUND(MIN(1,IFERROR(('_Data'!$AI$6)/('_Data'!$AI$2),0))*34,0)),"░░░░░░░░░░░░░░░░░░░░░░░░░░░░░░░░░░") -> ░░░░░░░░░░░░░░░░░░░░░░░░░░░░░░░░░░ | K12: =TEXT(IFERROR('_Data'!$AI$6/'_Data'!$AI$2,0),"0.0%") -> 0.0%
B13: RSVP confirmed | D13: =IFERROR(REPT("█",ROUND(MIN(1,IFERROR(('_Data'!$AI$3)/('_Data'!$AI$2),0))*34,0))&REPT("░",34-ROUND(MIN(1,IFERROR(('_Data'!$AI$3)/('_Data'!$AI$2),0))*34,0)),"░░░░░░░░░░░░░░░░░░░░░░░░░░░░░░░░░░") -> ░░░░░░░░░░░░░░░░░░░░░░░░░░░░░░░░░░ | K13: =TEXT(IFERROR('_Data'!$AI$3/'_Data'!$AI$2,0),"0.0%") -> 0.0%
B64: 🎲 GAME STATE • ⚠️ PARTY ALERTS
B65: Turns logged | F65: ='_Data'!$AI$17 -> 0 | I65: RSVP still maybe | M65: ='_Data'!$AI$4 -> 0
B66: Now playing (seat) | F66: ='_Data'!$AI$18 -> 0 | I66: Over-budget gifts | M66: ='_Data'!$AI$20 -> 0
B67: Gifts still stealable | F67: ='_Data'!$AI$14 -> 0 | I67: Draw rule hits | M67: ='_Data'!$AI$19 -> 0
B68: Gifts locked 🔒 | F68: ='_Data'!$AI$15 -> 0 | I68: Dietary needs noted | M68: ='_Data'!$AI$21 -> 0
B74: 💬 Novality Store wishes you a loud, glorious, steal-happy party.
B76: Settings | D76: ▶ Dashboard | F76: People | H76: Draw | J76: Budget | L76: Start Here

Sheet 👥 Participants
B2: 👥 Participants
B3: Everyone in the draw - RSVP, household and team feed the exclusion rules automatically. | H3: 🏠 Dashboard
B5: ="👥 In the draw: "&COUNTA($B$8:$B$31) -> 👥 In the draw: 0 | E5: ="✅ RSVP yes: "&COUNTIF($E$8:$E$31,"Yes") -> ✅ RSVP yes: 0 | H5: ="⏳ Awaiting: "&COUNTIF($E$8:$E$31,"Maybe")+COUNTIF($E$8:$E$31,"No") -> ⏳ Awaiting: 0 | K5: ="🎁 Ready (wrapped+done): "&COUNTIF($H$8:$H$31,"Wrapped")+COUNTIF($H$8:$H$31,"Complete") -> Ready: 0
A7: # | B7: Participant | C7: Team / dept | D7: Household / couple | E7: RSVP | F7: Dietary needs | G7: Gave to last year | H7: Gift status | I7: Wishes | J7: Notes
A8: 1
A9: 2
A10: 3
A11: 4
A12: 5
A13: 6
A14: 7
A15: 8
A16: 9
A17: 10
A18: 11
A19: 12
... A31: 24
B33: 💡 Cream cells are yours to type in; white cells calculate. Dropdowns keep every column honest.
B35: Settings | D35: Dashboard | F35: ▶ People | H35: Draw
B36: Budget | D36: Start Here

Sheet 🎅 Secret Santa Draw
B2: 🎅 Secret Santa Draw
B3: Change the seed on ⚙️ Settings to shuffle the draw - nobody ever draws themselves. | E3: 🏠 Dashboard
B5: ="🎅 Assigned: "&SUMPRODUCT(--($E$8:$E$31<>""))&" of "&COUNTA('👥 Participants'!$B$8:$B$31) -> 🎅 Assigned: 0 of 0 | F5: ="✅ Clean pairs: "&COUNTIF($F$8:$F$31,"✅ OK") -> ✅ Clean pairs: 0 | I5: ="⚠️ Rule hits: "&'_Data'!$AI$19 -> ⚠️ Rule hits: 0 | L5: ="🔒 Status: "&DrawStatus -> 🔒 Status: Draft — re-draw allowed
A7: # | B7: Giver | C7: Drawn (auto) | D7: Manual override | E7: FINAL recipient | F7: Rules check | G7: Gift status
A8: 1 | B8: =IF('👥 Participants'!$B$8="","",'👥 Participants'!$B$8) -> 0 | C8: =IF($B8="","",INDEX('👥 Participants'!$B$8:$B$31,MOD($A8-1+MOD(DrawSeed-1,MAX(1,COUNTA('👥 Participants'!$B$8:$B$31)-1)),COUNTA('👥 Participants'!$B$8:$B$31))+1)) | E8: =IF($B8="","",IF($D8<>"",$D8,$C8)) | F8: =IF($E8="","",IF(TRIM(IF($E8=$B8,"Self ",""))="","✅ OK",TRIM(IF($E8=$B8,"Self ","")))) | G8: =IF($B8="","",INDEX('👥 Participants'!$H$8:$H$31,MATCH($B8,'👥 Participants'!$B$8:$B$31,0)))
A9: 2 | B9: =IF('👥 Participants'!$B$9="","",'👥 Participants'!$B$9) -> 0 | C9: =IF($B9="","",INDEX('👥 Participants'!$B$8:$B$31,MOD($A9-1+MOD(DrawSeed-1,MAX(1,COUNTA('👥 Participants'!$B$8:$B$31)-1)),COUNTA('👥 Participants'!$B$8:$B$31))+1)) | E9: =IF($B9="","",IF($D9<>"",$D9,$C9)) | F9: =IF($E9="","",IF(TRIM(IF($E9=$B9,"Self ",""))="","✅ OK",TRIM(IF($E9=$B9,"Self ","")))) | G9: =IF($B9="","",INDEX('👥 Participants'!$H$8:$H$31,MATCH($B9,'👥 Participants'!$B$8:$B$31,0)))
A10: 3 | B10: =IF('👥 Participants'!$B$10="","",'👥 Participants'!$B$10) -> 0 | C10: =IF($B10="","",INDEX('👥 Participants'!$B$8:$B$31,MOD($A10-1+MOD(DrawSeed-1,MAX(1,COUNTA('👥 Participants'!$B$8:$B$31)-1)),COUNTA('👥 Participants'!$B$8:$B$31))+1)) | E10: =IF($B10="","",IF($D10<>"",$D10,$C10)) | F10: =IF($E10="","",IF(TRIM(IF($E10=$B10,"Self ",""))="","✅ OK",TRIM(IF($E10=$B10,"Self ","")))) | G10: =IF($B10="","",INDEX('👥 Participants'!$H$8:$H$31,MATCH($B10,'👥 Participants'!$B$8:$B$31,0)))
A11: 4 | B11: =IF('👥 Participants'!$B$11="","",'👥 Participants'!$B$11) -> 0 | C11: =IF($B11="","",INDEX('👥 Participants'!$B$8:$B$31,MOD($A11-1+MOD(DrawSeed-1,MAX(1,COUNTA('👥 Participants'!$B$8:$B$31)-1)),COUNTA('👥 Participants'!$B$8:$B$31))+1)) | E11: =IF($B11="","",IF($D11<>"",$D11,$C11)) | F11: =IF($E11="","",IF(TRIM(IF($E11=$B11,"Self ",""))="","✅ OK",TRIM(IF($E11=$B11,"Self ","")))) | G11: =IF($B11="","",INDEX('👥 Participants'!$H$8:$H$31,MATCH($B11,'👥 Participants'!$B$8:$B$31,0)))
A12: 5 | B12: =IF('👥 Participants'!$B$12="","",'👥 Participants'!$B$12) -> 0 | C12: =IF($B12="","",INDEX('👥 Participants'!$B$8:$B$31,MOD($A12-1+MOD(DrawSeed-1,MAX(1,COUNTA('👥 Participants'!$B$8:$B$31)-1)),COUNTA('👥 Participants'!$B$8:$B$31))+1)) | E12: =IF($B12="","",IF($D12<>"",$D12,$C12)) | F12: =IF($E12="","",IF(TRIM(IF($E12=$B12,"Self ",""))="","✅ OK",TRIM(IF($E12=$B12,"Self ","")))) | G12: =IF($B12="","",INDEX('👥 Participants'!$H$8:$H$31,MATCH($B12,'👥 Participants'!$B$8:$B$31,0)))
A13: 6 | B13: =IF('👥 Participants'!$B$13="","",'👥 Participants'!$B$13) -> 0 | C13: =IF($B13="","",INDEX('👥 Participants'!$B$8:$B$31,MOD($A13-1+MOD(DrawSeed-1,MAX(1,COUNTA('👥 Participants'!$B$8:$B$31)-1)),COUNTA('👥 Participants'!$B$8:$B$31))+1)) | E13: =IF($B13="","",IF($D13<>"",$D13,$C13)) | F13: =IF($E13="","",IF(TRIM(IF($E13=$B13,"Self ",""))="","✅ OK",TRIM(IF($E13=$B13,"Self ","")))) | G13: =IF($B13="","",INDEX('👥 Participants'!$H$8:$H$31,MATCH($B13,'👥 Participants'!$B$8:$B$31,0)))
A14: 7 | B14: =IF('👥 Participants'!$B$14="","",'👥 Participants'!$B$14) -> 0 | C14: =IF($B14="","",INDEX('👥 Participants'!$B$8:$B$31,MOD($A14-1+MOD(DrawSeed-1,MAX(1,COUNTA('👥 Participants'!$B$8:$B$31)-1)),COUNTA('👥 Participants'!$B$8:$B$31))+1)) | E14: =IF($B14="","",IF($D14<>"",$D14,$C14)) | F14: =IF($E14="","",IF(TRIM(IF($E14=$B14,"Self ",""))="","✅ OK",TRIM(IF($E14=$B14,"Self ","")))) | G14: =IF($B14="","",INDEX('👥 Participants'!$H$8:$H$31,MATCH($B14,'👥 Participants'!$B$8:$B$31,0)))
A15: 8 | B15: =IF('👥 Participants'!$B$15="","",'👥 Participants'!$B$15) -> 0 | C15: =IF($B15="","",INDEX('👥 Participants'!$B$8:$B$31,MOD($A15-1+MOD(DrawSeed-1,MAX(1,COUNTA('👥 Participants'!$B$8:$B$31)-1)),COUNTA('👥 Participants'!$B$8:$B$31))+1)) | E15: =IF($B15="","",IF($D15<>"",$D15,$C15)) | F15: =IF($E15="","",IF(TRIM(IF($E15=$B15,"Self ",""))="","✅ OK",TRIM(IF($E15=$B15,"Self ","")))) | G15: =IF($B15="","",INDEX('👥 Participants'!$H$8:$H$31,MATCH($B15,'👥 Participants'!$B$8:$B$31,0)))
A16: 9 | B16: =IF('👥 Participants'!$B$16="","",'👥 Participants'!$B$16) -> 0 | C16: =IF($B16="","",INDEX('👥 Participants'!$B$8:$B$31,MOD($A16-1+MOD(DrawSeed-1,MAX(1,COUNTA('👥 Participants'!$B$8:$B$31)-1)),COUNTA('👥 Participants'!$B$8:$B$31))+1)) | E16: =IF($B16="","",IF($D16<>"",$D16,$C16)) | F16: =IF($E16="","",IF(TRIM(IF($E16=$B16,"Self ",""))="","✅ OK",TRIM(IF($E16=$B16,"Self ","")))) | G16: =IF($B16="","",INDEX('👥 Participants'!$H$8:$H$31,MATCH($B16,'👥 Participants'!$B$8:$B$31,0)))
A17: 10 | B17: =IF('👥 Participants'!$B$17="","",'👥 Participants'!$B$17) -> 0 | C17: =IF($B17="","",INDEX('👥 Participants'!$B$8:$B$31,MOD($A17-1+MOD(DrawSeed-1,MAX(1,COUNTA('👥 Participants'!$B$8:$B$31)-1)),COUNTA('👥 Participants'!$B$8:$B$31))+1)) | E17: =IF($B17="","",IF($D17<>"",$D17,$C17)) | F17: =IF($E17="","",IF(TRIM(IF($E17=$B17,"Self ",""))="","✅ OK",TRIM(IF($E17=$B17,"Self ","")))) | G17: =IF($B17="","",INDEX('👥 Participants'!$H$8:$H$31,MATCH($B17,'👥 Participants'!$B$8:$B$31,0)))
A18: 11 | B18: =IF('👥 Participants'!$B$18="","",'👥 Participants'!$B$18) -> 0 | C18: =IF($B18="","",INDEX('👥 Participants'!$B$8:$B$31,MOD($A18-1+MOD(DrawSeed-1,MAX(1,COUNTA('👥 Participants'!$B$8:$B$31)-1)),COUNTA('👥 Participants'!$B$8:$B$31))+1)) | E18: =IF($B18="","",IF($D18<>"",$D18,$C18)) | F18: =IF($E18="","",IF(TRIM(IF($E18=$B18,"Self ",""))="","✅ OK",TRIM(IF($E18=$B18,"Self ","")))) | G18: =IF($B18="","",INDEX('👥 Participants'!$H$8:$H$31,MATCH($B18,'👥 Participants'!$B$8:$B$31,0)))
A19: 12 | B19: =IF('👥 Participants'!$B$19="","",'👥 Participants'!$B$19) -> 0 | C19: =IF($B19="","",INDEX('👥 Participants'!$B$8:$B$31,MOD($A19-1+MOD(DrawSeed-1,MAX(1,COUNTA('👥 Participants'!$B$8:$B$31)-1)),COUNTA('👥 Participants'!$B$8:$B$31))+1)) | E19: =IF($B19="","",IF($D19<>"",$D19,$C19)) | F19: =IF($E19="","",IF(TRIM(IF($E19=$B19,"Self ",""))="","✅ OK",TRIM(IF($E19=$B19,"Self ","")))) | G19: =IF($B19="","",INDEX('👥 Participants'!$H$8:$H$31,MATCH($B19,'👥 Participants'!$B$8:$B$31,0)))
A20: 13 | B20: =IF('👥 Participants'!$B$20="","",'👥 Participants'!$B$20) -> 0 | C20: =IF($B20="","",INDEX('👥 Participants'!$B$8:$B$31,MOD($A20-1+MOD(DrawSeed-1,MAX(1,COUNTA('👥 Participants'!$B$8:$B$31)-1)),COUNTA('👥 Participants'!$B$8:$B$31))+1)) | E20: =IF($B20="","",IF($D20<>"",$D20,$C20)) | F20: =IF($E20="","",IF(TRIM(IF($E20=$B20,"Self ",""))="","✅ OK",TRIM(IF($E20=$B20,"Self ","")))) | G20: =IF($B20="","",INDEX('👥 Participants'!$H$8:$H$31,MATCH($B20,'👥 Participants'!$B$8:$B$31,0)))
A21: 14 | B21: =IF('👥 Participants'!$B$21="","",'👥 Participants'!$B$21) -> 0 | C21: =IF($B21="","",INDEX('👥 Participants'!$B$8:$B$31,MOD($A21-1+MOD(DrawSeed-1,MAX(1,COUNTA('👥 Participants'!$B$8:$B$31)-1)),COUNTA('👥 Participants'!$B$8:$B$31))+1)) | E21: =IF($B21="","",IF($D21<>"",$D21,$C21)) | F21: =IF($E21="","",IF(TRIM(IF($E21=$B21,"Self ",""))="","✅ OK",TRIM(IF($E21=$B21,"Self ","")))) | G21: =IF($B21="","",INDEX('👥 Participants'!$H$8:$H$31,MATCH($B21,'👥 Participants'!$B$8:$B$31,0)))
A22: 15 | B22: =IF('👥 Participants'!$B$22="","",'👥 Participants'!$B$22) -> 0 | C22: =IF($B22="","",INDEX('👥 Participants'!$B$8:$B$31,MOD($A22-1+MOD(DrawSeed-1,MAX(1,COUNTA('👥 Participants'!$B$8:$B$31)-1)),COUNTA('👥 Participants'!$B$8:$B$31))+1)) | E22: =IF($B22="","",IF($D22<>"",$D22,$C22)) | F22: =IF($E22="","",IF(TRIM(IF($E22=$B22,"Self ",""))="","✅ OK",TRIM(IF($E22=$B22,"Self ","")))) | G22: =IF($B22="","",INDEX('👥 Participants'!$H$8:$H$31,MATCH($B22,'👥 Participants'!$B$8:$B$31,0)))
A23: 16 | B23: =IF('👥 Participants'!$B$23="","",'👥 Participants'!$B$23) -> 0 | C23: =IF($B23="","",INDEX('👥 Participants'!$B$8:$B$31,MOD($A23-1+MOD(DrawSeed-1,MAX(1,COUNTA('👥 Participants'!$B$8:$B$31)-1)),COUNTA('👥 Participants'!$B$8:$B$31))+1)) | E23: =IF($B23="","",IF($D23<>"",$D23,$C23)) | F23: =IF($E23="","",IF(TRIM(IF($E23=$B23,"Self ",""))="","✅ OK",TRIM(IF($E23=$B23,"Self ","")))) | G23: =IF($B23="","",INDEX('👥 Participants'!$H$8:$H$31,MATCH($B23,'👥 Participants'!$B$8:$B$31,0)))
A24: 17 | B24: =IF('👥 Participants'!$B$24="","",'👥 Participants'!$B$24) -> 0 | C24: =IF($B24="","",INDEX('👥 Participants'!$B$8:$B$31,MOD($A24-1+MOD(DrawSeed-1,MAX(1,COUNTA('👥 Participants'!$B$8:$B$31)-1)),COUNTA('👥 Participants'!$B$8:$B$31))+1)) | E24: =IF($B24="","",IF($D24<>"",$D24,$C24)) | F24: =IF($E24="","",IF(TRIM(IF($E24=$B24,"Self ",""))="","✅ OK",TRIM(IF($E24=$B24,"Self ","")))) | G24: =IF($B24="","",INDEX('👥 Participants'!$H$8:$H$31,MATCH($B24,'👥 Participants'!$B$8:$B$31,0)))
A25: 18 | B25: =IF('👥 Participants'!$B$25="","",'👥 Participants'!$B$25) -> 0 | C25: =IF($B25="","",INDEX('👥 Participants'!$B$8:$B$31,MOD($A25-1+MOD(DrawSeed-1,MAX(1,COUNTA('👥 Participants'!$B$8:$B$31)-1)),COUNTA('👥 Participants'!$B$8:$B$31))+1)) | E25: =IF($B25="","",IF($D25<>"",$D25,$C25)) | F25: =IF($E25="","",IF(TRIM(IF($E25=$B25,"Self ",""))="","✅ OK",TRIM(IF($E25=$B25,"Self ","")))) | G25: =IF($B25="","",INDEX('👥 Participants'!$H$8:$H$31,MATCH($B25,'👥 Participants'!$B$8:$B$31,0)))
A26: 19 | B26: =IF('👥 Participants'!$B$26="","",'👥 Participants'!$B$26) -> 0 | C26: =IF($B26="","",INDEX('👥 Participants'!$B$8:$B$31,MOD($A26-1+MOD(DrawSeed-1,MAX(1,COUNTA('👥 Participants'!$B$8:$B$31)-1)),COUNTA('👥 Participants'!$B$8:$B$31))+1)) | E26: =IF($B26="","",IF($D26<>"",$D26,$C26)) | F26: =IF($E26="","",IF(TRIM(IF($E26=$B26,"Self ",""))="","✅ OK",TRIM(IF($E26=$B26,"Self ","")))) | G26: =IF($B26="","",INDEX('👥 Participants'!$H$8:$H$31,MATCH($B26,'👥 Participants'!$B$8:$B$31,0)))
A27: 20 | B27: =IF('👥 Participants'!$B$27="","",'👥 Participants'!$B$27) -> 0 | C27: =IF($B27="","",INDEX('👥 Participants'!$B$8:$B$31,MOD($A27-1+MOD(DrawSeed-1,MAX(1,COUNTA('👥 Participants'!$B$8:$B$31)-1)),COUNTA('👥 Participants'!$B$8:$B$31))+1)) | E27: =IF($B27="","",IF($D27<>"",$D27,$C27)) | F27: =IF($E27="","",IF(TRIM(IF($E27=$B27,"Self ",""))="","✅ OK",TRIM(IF($E27=$B27,"Self ","")))) | G27: =IF($B27="","",INDEX('👥 Participants'!$H$8:$H$31,MATCH($B27,'👥 Participants'!$B$8:$B$31,0)))
A28: 21 | B28: =IF('👥 Participants'!$B$28="","",'👥 Participants'!$B$28) -> 0 | C28: =IF($B28="","",INDEX('👥 Participants'!$B$8:$B$31,MOD($A28-1+MOD(DrawSeed-1,MAX(1,COUNTA('👥 Participants'!$B$8:$B$31)-1)),COUNTA('👥 Participants'!$B$8:$B$31))+1)) | E28: =IF($B28="","",IF($D28<>"",$D28,$C28)) | F28: =IF($E28="","",IF(TRIM(IF($E28=$B28,"Self ",""))="","✅ OK",TRIM(IF($E28=$B28,"Self ","")))) | G28: =IF($B28="","",INDEX('👥 Participants'!$H$8:$H$31,MATCH($B28,'👥 Participants'!$B$8:$B$31,0)))
A29: 22 | B29: =IF('👥 Participants'!$B$29="","",'👥 Participants'!$B$29) -> 0 | C29: =IF($B29="","",INDEX('👥 Participants'!$B$8:$B$31,MOD($A29-1+MOD(DrawSeed-1,MAX(1,COUNTA('👥 Participants'!$B$8:$B$31)-1)),COUNTA('👥 Participants'!$B$8:$B$31))+1)) | E29: =IF($B29="","",IF($D29<>"",$D29,$C29)) | F29: =IF($E29="","",IF(TRIM(IF($E29=$B29,"Self ",""))="","✅ OK",TRIM(IF($E29=$B29,"Self ","")))) | G29: =IF($B29="","",INDEX('👥 Participants'!$H$8:$H$31,MATCH($B29,'👥 Participants'!$B$8:$B$31,0)))
A30: 23 | B30: =IF('👥 Participants'!$B$30="","",'👥 Participants'!$B$30) -> 0 | C30: =IF($B30="","",INDEX('👥 Participants'!$B$8:$B$31,MOD($A30-1+MOD(DrawSeed-1,MAX(1,COUNTA('👥 Participants'!$B$8:$B$31)-1)),COUNTA('👥 Participants'!$B$8:$B$31))+1)) | E30: =IF($B30="","",IF($D30<>"",$D30,$C30)) | F30: =IF($E30="","",IF(TRIM(IF($E30=$B30,"Self ",""))="","✅ OK",TRIM(IF($E30=$B30,"Self ","")))) | G30: =IF($B30="","",INDEX('👥 Participants'!$H$8:$H$31,MATCH($B30,'👥 Participants'!$B$8:$B$31,0)))
A31: 24 | B31: =IF('👥 Participants'!$B$31="","",'👥 Participants'!$B$31) -> 0 | C31: =IF($B31="","",INDEX('👥 Participants'!$B$8:$B$31,MOD($A31-1+MOD(DrawSeed-1,MAX(1,COUNTA('👥 Participants'!$B$8:$B$31)-1)),COUNTA('👥 Participants'!$B$8:$B$31))+1)) | E31: =IF($B31="","",IF($D31<>"",$D31,$C31)) | F31: =IF($E31="","",IF(TRIM(IF($E31=$B31,"Self ",""))="","✅ OK",TRIM(IF($E31=$B31,"Self ","")))) | G31: =IF($B31="","",INDEX('👥 Participants'!$H$8:$H$31,MATCH($B31,'👥 Participants'!$B$8:$B$31,0)))
B33: 🔀 DRAW CONTROLS
B34: Draw seed (change to re-draw) | D34: =DrawSeed | E34: Draw status | G34: =DrawStatus
B36: 🕵️ PRIVATE LOOKUP - type a name, see only their recipient
B37: I am... | F37: =IF($C37="","Type your name to peek at your recipient…",IFERROR("🎅 You are drawing: "&INDEX($E$8:$E$31,MATCH($C37,$B$8:$B$31,0))&" • budget "&Currency&TEXT(BudgetMin,"#,##0")&"–"&Currency&TEXT(BudgetMax,"#,##0")&" • "&TEXT(PartyDate,"dd mmm yyyy")&" — tell no one!","Name not found - check the spelling on 👥 Participants."))
B39: 💡 Re-draw: unlock the sheet (password “premium”), change the seed, re-protect. Overrides beat the auto-draw pair by pair.
B41: Settings | D41: Dashboard | F41: People
B42: ▶ Draw | D42: Budget | F42: Start Here

Sheet 💰 Budget Tracker
B2: 💰 Budget Tracker
B3: One row per giver: what they spent on their Secret Santa gift, checked against the party's min and max. | G3: 🏠 Dashboard
B5: ="💸 Total spent: "&Currency&TEXT(SUM($E$8:$E$31),"#,##0.00") -> 💸 Total spent: $0.00 | F5: ="📊 Average gift: "&Currency&TEXT('_Data'!$AI$11,"#,##0.00") -> 📊 Average gift: $0.00 | J5: ="🚨 Over budget: "&COUNTIF($F$8:$F$31,"🚨 Over budget") -> 🚨 Over budget: 0 | M5: ="🧾 Receipts filed: "&COUNTIF($G$8:$G$31,"✓") -> 🧾 Receipts filed: 0
A7: # | B7: Gift for (recipient) | C7: Min | D7: Max | E7: Actual spent | F7: Budget check | G7: Receipt? | H7: Receipt / order ref | I7: Notes
A8: 1 | B8: =IF('🎅 Secret Santa Draw'!$C$8="","",'🎅 Secret Santa Draw'!$C$8) -> 0 | C8: =BudgetMin -> 0 | D8: =BudgetMax -> 0 | F8: =IF($E8="","",IF($E8<$C8,"🔴 Under budget",IF($E8>$D8,"🚨 Over budget","✅ Within budget")))
A9: 2 | B9: =IF('🎅 Secret Santa Draw'!$C$9="","",'🎅 Secret Santa Draw'!$C$9) -> 0 | C9: =BudgetMin -> 0 | D9: =BudgetMax -> 0 | F9: =IF($E9="","",IF($E9<$C9,"🔴 Under budget",IF($E9>$D9,"🚨 Over budget","✅ Within budget")))
A10: 3 | B10: =IF('🎅 Secret Santa Draw'!$C$10="","",'🎅 Secret Santa Draw'!$C$10) -> 0 | C10: =BudgetMin -> 0 | D10: =BudgetMax -> 0 | F10: =IF($E10="","",IF($E10<$C10,"🔴 Under budget",IF($E10>$D10,"🚨 Over budget","✅ Within budget")))
A11: 4 | B11: =IF('🎅 Secret Santa Draw'!$C$11="","",'🎅 Secret Santa Draw'!$C$11) -> 0 | C11: =BudgetMin -> 0 | D11: =BudgetMax -> 0 | F11: =IF($E11="","",IF($E11<$C11,"🔴 Under budget",IF($E11>$D11,"🚨 Over budget","✅ Within budget")))
A12: 5 | B12: =IF('🎅 Secret Santa Draw'!$C$12="","",'🎅 Secret Santa Draw'!$C$12) -> 0 | C12: =BudgetMin -> 0 | D12: =BudgetMax -> 0 | F12: =IF($E12="","",IF($E12<$C12,"🔴 Under budget",IF($E12>$D12,"🚨 Over budget","✅ Within budget")))
A13: 6 | B13: =IF('🎅 Secret Santa Draw'!$C$13="","",'🎅 Secret Santa Draw'!$C$13) -> 0 | C13: =BudgetMin -> 0 | D13: =BudgetMax -> 0 | F13: =IF($E13="","",IF($E13<$C13,"🔴 Under budget",IF($E13>$D13,"🚨 Over budget","✅ Within budget")))
A14: 7 | B14: =IF('🎅 Secret Santa Draw'!$C$14="","",'🎅 Secret Santa Draw'!$C$14) -> 0 | C14: =BudgetMin -> 0 | D14: =BudgetMax -> 0 | F14: =IF($E14="","",IF($E14<$C14,"🔴 Under budget",IF($E14>$D14,"🚨 Over budget","✅ Within budget")))
A15: 8 | B15: =IF('🎅 Secret Santa Draw'!$C$15="","",'🎅 Secret Santa Draw'!$C$15) -> 0 | C15: =BudgetMin -> 0 | D15: =BudgetMax -> 0 | F15: =IF($E15="","",IF($E15<$C15,"🔴 Under budget",IF($E15>$D15,"🚨 Over budget","✅ Within budget")))
A16: 9 | B16: =IF('🎅 Secret Santa Draw'!$C$16="","",'🎅 Secret Santa Draw'!$C$16) -> 0 | C16: =BudgetMin -> 0 | D16: =BudgetMax -> 0 | F16: =IF($E16="","",IF($E16<$C16,"🔴 Under budget",IF($E16>$D16,"🚨 Over budget","✅ Within budget")))
A17: 10 | B17: =IF('🎅 Secret Santa Draw'!$C$17="","",'🎅 Secret Santa Draw'!$C$17) -> 0 | C17: =BudgetMin -> 0 | D17: =BudgetMax -> 0 | F17: =IF($E17="","",IF($E17<$C17,"🔴 Under budget",IF($E17>$D17,"🚨 Over budget","✅ Within budget")))
A18: 11 | B18: =IF('🎅 Secret Santa Draw'!$C$18="","",'🎅 Secret Santa Draw'!$C$18) -> 0 | C18: =BudgetMin -> 0 | D18: =BudgetMax -> 0 | F18: =IF($E18="","",IF($E18<$C18,"🔴 Under budget",IF($E18>$D18,"🚨 Over budget","✅ Within budget")))
A19: 12 | B19: =IF('🎅 Secret Santa Draw'!$C$19="","",'🎅 Secret Santa Draw'!$C$19) -> 0 | C19: =BudgetMin -> 0 | D19: =BudgetMax -> 0 | F19: =IF($E19="","",IF($E19<$C19,"🔴 Under budget",IF($E19>$D19,"🚨 Over budget","✅ Within budget")))
A20: 13 | B20: =IF('🎅 Secret Santa Draw'!$C$20="","",'🎅 Secret Santa Draw'!$C$20) -> 0 | C20: =BudgetMin -> 0 | D20: =BudgetMax -> 0 | F20: =IF($E20="","",IF($E20<$C20,"🔴 Under budget",IF($E20>$D20,"🚨 Over budget","✅ Within budget")))
A21: 14 | B21: =IF('🎅 Secret Santa Draw'!$C$21="","",'🎅 Secret Santa Draw'!$C$21) -> 0 | C21: =BudgetMin -> 0 | D21: =BudgetMax -> 0 | F21: =IF($E21="","",IF($E21<$C21,"🔴 Under budget",IF($E21>$D21,"🚨 Over budget","✅ Within budget")))
A22: 15 | B22: =IF('🎅 Secret Santa Draw'!$C$22="","",'🎅 Secret Santa Draw'!$C$22) -> 0 | C22: =BudgetMin -> 0 | D22: =BudgetMax -> 0 | F22: =IF($E22="","",IF($E22<$C22,"🔴 Under budget",IF($E22>$D22,"🚨 Over budget","✅ Within budget")))
A23: 16 | B23: =IF('🎅 Secret Santa Draw'!$C$23="","",'🎅 Secret Santa Draw'!$C$23) -> 0 | C23: =BudgetMin -> 0 | D23: =BudgetMax -> 0 | F23: =IF($E23="","",IF($E23<$C23,"🔴 Under budget",IF($E23>$D23,"🚨 Over budget","✅ Within budget")))
A24: 17 | B24: =IF('🎅 Secret Santa Draw'!$C$24="","",'🎅 Secret Santa Draw'!$C$24) -> 0 | C24: =BudgetMin -> 0 | D24: =BudgetMax -> 0 | F24: =IF($E24="","",IF($E24<$C24,"🔴 Under budget",IF($E24>$D24,"🚨 Over budget","✅ Within budget")))
A25: 18 | B25: =IF('🎅 Secret Santa Draw'!$C$25="","",'🎅 Secret Santa Draw'!$C$25) -> 0 | C25: =BudgetMin -> 0 | D25: =BudgetMax -> 0 | F25: =IF($E25="","",IF($E25<$C25,"🔴 Under budget",IF($E25>$D25,"🚨 Over budget","✅ Within budget")))
A26: 19 | B26: =IF('🎅 Secret Santa Draw'!$C$26="","",'🎅 Secret Santa Draw'!$C$26) -> 0 | C26: =BudgetMin -> 0 | D26: =BudgetMax -> 0 | F26: =IF($E26="","",IF($E26<$C26,"🔴 Under budget",IF($E26>$D26,"🚨 Over budget","✅ Within budget")))
A27: 20 | B27: =IF('🎅 Secret Santa Draw'!$C$27="","",'🎅 Secret Santa Draw'!$C$27) -> 0 | C27: =BudgetMin -> 0 | D27: =BudgetMax -> 0 | F27: =IF($E27="","",IF($E27<$C27,"🔴 Under budget",IF($E27>$D27,"🚨 Over budget","✅ Within budget")))
A28: 21 | B28: =IF('🎅 Secret Santa Draw'!$C$28="","",'🎅 Secret Santa Draw'!$C$28) -> 0 | C28: =BudgetMin -> 0 | D28: =BudgetMax -> 0 | F28: =IF($E28="","",IF($E28<$C28,"🔴 Under budget",IF($E28>$D28,"🚨 Over budget","✅ Within budget")))
A29: 22 | B29: =IF('🎅 Secret Santa Draw'!$C$29="","",'🎅 Secret Santa Draw'!$C$29) -> 0 | C29: =BudgetMin -> 0 | D29: =BudgetMax -> 0 | F29: =IF($E29="","",IF($E29<$C29,"🔴 Under budget",IF($E29>$D29,"🚨 Over budget","✅ Within budget")))
A30: 23 | B30: =IF('🎅 Secret Santa Draw'!$C$30="","",'🎅 Secret Santa Draw'!$C$30) -> 0 | C30: =BudgetMin -> 0 | D30: =BudgetMax -> 0 | F30: =IF($E30="","",IF($E30<$C30,"🔴 Under budget",IF($E30>$D30,"🚨 Over budget","✅ Within budget")))
A31: 24 | B31: =IF('🎅 Secret Santa Draw'!$C$31="","",'🎅 Secret Santa Draw'!$C$31) -> 0 | C31: =BudgetMin -> 0 | D31: =BudgetMax -> 0 | F31: =IF($E31="","",IF($E31<$C31,"🔴 Under budget",IF($E31>$D31,"🚨 Over budget","✅ Within budget")))
B32: TOTALS | E32: =SUM(E8:E31) -> 0
B34: 💡 Cream cells are yours to type in; white cells calculate. Dropdowns keep every column honest.
B36: Settings | D36: Dashboard | F36: People | H36: Draw
B37: ▶ Budget | D37: Start Here

Sheet 📖 Start Here
C14: 📖 START HERE
C15: your 5-minute tour of the Secret Santa & White Elephant Party Tracker
H30: 🏠 Back to Dashboard
B32: 🚀 QUICK START — FIVE STEPS TO LIVE
B33: 1 | C33: Open ⚙️ Settings & Instructions | E33: Type the party name, date, location, host, currency, gift budget min/max, max steals and the two seeds. Every tab reads these.
B35: 2 | C35: List your guests on 👥 Participants | E35: Names plus team, household/couple, RSVP, dietary needs and who they drew last year - the exclusion engine feeds off this.
B37: 3 | C37: Draw on 🎅 Secret Santa Draw | E37: The draw is a closed cycle: nobody can ever pick themselves. Change the seed to shuffle, override any pair by hand, then lock the draw with the status dropdown.
B39: 4 | C39: Arm your rules on 🚫 Exclusions & Rules | E39: Couples, same-team and last-year repeats toggle on/off; custom no-pairs go in the table. The draw flags every breach live.
B41: 5 | C41: Run the party | E41: 💰 Budget Tracker watches every spend, 🎁 Wishlists keeps ideas claimable, and 🎲 White Elephant plus 🔄 Game History run the steal-fest turn by turn.
B44: 🗺️ THE TAB TOUR
B45: Premium edition: every tab below. Basic edition: the tabs marked ● only.
C46: ● 🏠 Dashboard | E46: Participants, spend, readiness, game state, alerts and three live charts.
C47: ● 👥 Participants | E47: Guest list with RSVP, team, household, dietary needs and gift status.
C48: ● 🎅 Secret Santa Draw | E48: Auto draw, overrides, rules check and the private recipient lookup.
C49: ● 💰 Budget Tracker | E49: Min/max rules, actual spend, under/over flags and receipt tracking.
C50: ● 🎲 White Elephant | E50: Seats, gift numbers, steal counts, locks, holders and final gifts.
C51: ● 📖 Start Here | E51: This page.
C52: ○ 🚫 Exclusions & Rules | E52: House-rule toggles and custom no-pair list.
C53: ○ 🎁 Wishlists | E53: Per-guest ideas with priorities and anonymous claiming.
C54: ○ 🔄 Game History | E54: The turn log: every Pick, Steal and Pass in order.
C55: ○ 🎟️ Santa Cards | E55: Printable cut-out cards so each guest learns their recipient privately.
B57: 💡 TEN TIPS FROM PARTY ANIMALS
B58: 1 | C58: Set the gift budget min AND max - too-cheap gifts hurt feelings just as much as too-pricey ones.
B60: 2 | C60: Collect wishlists before the draw; three wishes each is plenty.
B62: 3 | C62: Households in the same couple get the same Household value - the couple rule then keeps them apart automatically.
B64: 4 | C64: Fill in “gave to last year” and arm the repeat rule: two years running the same pair feels lazy.
B66: 5 | C66: Print the Santa Cards, fold them, and let guests pick a card at random at the door - zero spoilers.
B68: 6 | C68: White Elephant: cap steals at 2. Three or more and the game stalls; one and nobody gets naughty.
B70: 7 | C70: Log steals on Game History as they happen (phone in Sheets) and the board stays honest without a whiteboard.
B72: 8 | C72: The private lookup shows one recipient at a time - perfect for passing the laptop round without spoilers.
B74: 9 | C74: Formula cells are protected with the password “premium”; unlock only when you need to change a seed.
B76: 10 | C76: Reuse the file every year: bump the party year and date, clear the logs, keep your lists.
B79: 🔒 THE GENTLE RULES
B80: • Cream-filled cells are yours to type in. White cells are formulas — leave them alone and they will keep working for you.
B82: • Sheets are protected to stop accidental edits. Review → Unprotect Sheet if you ever need to restructure something.
B84: • Add rows by copying an existing data row and inserting below it — the formulas, dropdowns and colours travel with the copy.
B86: • This file opens in Excel 2016+ and in Google Sheets (upload to Drive → open with Sheets). A few chart styles look slightly different in Sheets; every number still calculates.
B88: • The EXAMPLE edition is loaded with a fictional office party so you can see it working. The blank edition is the one you keep.
B91: 🤝 SUPPORT
B92: Thank you for buying this template — it was built by Novality Store, people who have hosted one too many white-elephant stampedes and know what a spreadsheet owes you in December. Message the shop any time and a human will help quickly.
...
