Workbook

Sheet Home
A1: ✈️ TRAVEL PLANNER — VERSION 2
A2: by Novality store ✦ plan • pack • spend smart • enjoy
A4: 🧳 TRIP SNAPSHOT
A5: Trip Name | B5: =IF('Destination Overview'!B5="","—",'Destination Overview'!B5) | C5: Destination | D5: =IF('Destination Overview'!B8="","—",'Destination Overview'!B9&", "&'Destination Overview'!B8)
A6: Departure | B6: =IF('Destination Overview'!B11="","—",'Destination Overview'!B11) | C6: Return | D6: =IF('Destination Overview'!B12="","—",'Destination Overview'!B12)
A7: Trip Length | B7: =IF('Destination Overview'!B14="","—",'Destination Overview'!B14&" days") | C7: Travelers | D7: =IF('Destination Overview'!B13="","—",'Destination Overview'!B13&" traveler(s)")
A8: Budget (Est.) | B8: ='Budget Tracker'!B15 | C8: Spent (Actual) | D8: ='Budget Tracker'!C15
A10: 🧭 QUICK NAVIGATION — 28 PLANNING SHEETS
A11: Pre-Trip Planning | B11: Destination Overview | C11: Trip basics — who, where, when and why | D11: =HYPERLINK("#'Destination Overview'!A1","Open →")
A12: Pre-Trip Planning | B12: Budget Tracker | C12: Estimated vs actual costs per category | D12: =HYPERLINK("#'Budget Tracker'!A1","Open →")
A13: Pre-Trip Planning | B13: Savings Goal | C13: Progress bar + savings log to hit your target | D13: =HYPERLINK("#'Savings Goal'!A1","Open →")
A14: Pre-Trip Planning | B14: Research & Ideas | C14: Must-see spots, links and inspiration | D14: =HYPERLINK("#'Research & Ideas'!A1","Open →")
A15: Pre-Trip Planning | B15: Visa & Documents | C15: Checklist so nothing expires or is forgotten | D15: =HYPERLINK("#'Visa & Documents'!A1","Open →")
A16: Pre-Trip Planning | B16: Booking Log | C16: Every confirmation number in one place | D16: =HYPERLINK("#'Booking Log'!A1","Open →")
A17: Packing & Prep | B17: Packing Checklist | C17: Categorized list with pack-progress % | D17: =HYPERLINK("#'Packing Checklist'!A1","Open →")
A18: Packing & Prep | B18: Weather Tracker | C18: Forecast + outfit planning per day | D18: =HYPERLINK("#'Weather Tracker'!A1","Open →")
A19: Packing & Prep | B19: Carry-On vs Checked | C19: What goes in which bag | D19: =HYPERLINK("#'Carry-On vs Checked'!A1","Open →")
A20: Packing & Prep | B20: Pre-Trip To-Do | C20: Bank alerts, pet sitter, mail hold… | D20: =HYPERLINK("#'Pre-Trip To-Do'!A1","Open →")
A21: Itinerary & Daily | B21: Daily Itinerary | C21: Day-by-day plan with times & costs | D21: =HYPERLINK("#'Daily Itinerary'!A1","Open →")
A22: Itinerary & Daily | B22: Hourly Schedule | C22: 7-day morning / afternoon / evening grid | D22: =HYPERLINK("#'Hourly Schedule'!A1","Open →")
A23: Itinerary & Daily | B23: Route Planner | C23: Order your stops + sketch a map | D23: =HYPERLINK("#'Route Planner'!A1","Open →")
A24: Itinerary & Daily | B24: Transportation Log | C24: Flights, trains & taxis with confirmations | D24: =HYPERLINK("#'Transportation Log'!A1","Open →")
A25: Itinerary & Daily | B25: Accommodation | C25: Up to 3 stays — Wi-Fi passwords included | D25: =HYPERLINK("#'Accommodation'!A1","Open →")
A26: Expense Tracking | B26: Expense Log | C26: 150-row daily spend log, auto-converted | D26: =HYPERLINK("#'Expense Log'!A1","Open →")
A27: Expense Tracking | B27: Currency Converter | C27: Rate table + quick converter | D27: =HYPERLINK("#'Currency Converter'!A1","Open →")
A28: Expense Tracking | B28: Tipping Guide | C28: What to tip in 12+ countries | D28: =HYPERLINK("#'Tipping Guide'!A1","Open →")
A29: Expense Tracking | B29: Trip Cost Summary | C29: Every total on one dashboard | D29: =HYPERLINK("#'Trip Cost Summary'!A1","Open →")
A30: Food & Activities | B30: Restaurant Wishlist | C30: Wish list with reservations & ratings | D30: =HYPERLINK("#'Restaurant Wishlist'!A1","Open →")
A31: Food & Activities | B31: Activity Planner | C31: Excursions — idea → booked → done | D31: =HYPERLINK("#'Activity Planner'!A1","Open →")
A32: Food & Activities | B32: Local Phrases | C32: 16 essentials to learn | D32: =HYPERLINK("#'Local Phrases'!A1","Open →")
A33: Food & Activities | B33: Etiquette Notes | C33: Do's and don'ts by topic | D33: =HYPERLINK("#'Etiquette Notes'!A1","Open →")
A34: Extras & Memories | B34: Emergency Contacts | C34: Embassy, hospital, insurance, family | D34: =HYPERLINK("#'Emergency Contacts'!A1","Open →")
A35: Extras & Memories | B35: Travel Journal | C35: Daily highlights & favorite moments | D35: =HYPERLINK("#'Travel Journal'!A1","Open →")
A36: Extras & Memories | B36: Ratings & Reviews | C36: Rate everything 1–5 | D36: =HYPERLINK("#'Ratings & Reviews'!A1","Open →")
A37: Extras & Memories | B37: Souvenir List | C37: Gift budget vs actual spending | D37: =HYPERLINK("#'Souvenir List'!A1","Open →")
A38: Extras & Memories | B38: Wi-Fi & Passwords | C38: Every network + password, saved | D38: =HYPERLINK("#'Wi-Fi & Passwords'!A1","Open →")
A40: 📌 HOW TO USE
A41: ✔ Yellow cells are yours to fill in — type, pick dates, or choose from the dropdown arrows.
A42: ✔ Blue-gray cells calculate automatically and are locked, so the formulas can never break.
A43: ✔ Status columns have dropdowns — tap ✓ when something is done, packed or visited.
...

Sheet Destination Overview
A1: 🌍 DESTINATION OVERVIEW
A2: The who / where / when of your trip — it feeds the Home snapshot
A4: Field | B4: Your Details | C4: Notes / Extra Info
A5: Trip Name | C5: e.g. “Cherry Blossom Japan 2027”
A6: Traveler Name(s) | C6: Everyone on the booking
A7: Home City / Base
A8: Destination Country
A9: Destination City / Cities | C9: One base or a multi-stop route
A10: Trip Purpose
A11: Departure Date
A12: Return Date
A13: Number of Travelers
A14: Trip Length (Days) | B14: =IF(COUNT(B11:B12)<2,"",B12-B11+1) | C14: Calculated from your dates
A15: Days Until Departure | B15: =IF(B11="","—",B11-TODAY()) | C15: Updates automatically each day
A16: Home Emergency Contact | C16: Name + phone
A17: Home Address
A18: Trip Notes / Why We're Going | C18: Free text

Sheet Budget Tracker
A1: 💰 BUDGET TRACKER
A2: Estimated vs actual for every category — variance updates itself
A4: Category | B4: Estimated Cost | C4: Actual Cost | D4: Difference | E4: % of Est. Used | F4: Status | G4: Notes | I4: 📊 SUMMARY
A5: ✈️ Flights | D5: =IF(COUNT(B5:C5)=0,"",B5-C5) | E5: =IF(OR(B5="",B5=0),"",C5/B5) | F5: =IF(COUNT(B5:C5)=0,"",IF(C5>B5,"⚠ Over budget","✓ On track")) | I5: Total Estimated | J5: =B15
A6: 🏨 Accommodation | D6: =IF(COUNT(B6:C6)=0,"",B6-C6) | E6: =IF(OR(B6="",B6=0),"",C6/B6) | F6: =IF(COUNT(B6:C6)=0,"",IF(C6>B6,"⚠ Over budget","✓ On track")) | I6: Total Actual | J6: =C15
A7: 🍽️ Food & Dining | D7: =IF(COUNT(B7:C7)=0,"",B7-C7) | E7: =IF(OR(B7="",B7=0),"",C7/B7) | F7: =IF(COUNT(B7:C7)=0,"",IF(C7>B7,"⚠ Over budget","✓ On track")) | I7: Remaining Budget | J7: =B15-C15
A8: 🚕 Local Transport | D8: =IF(COUNT(B8:C8)=0,"",B8-C8) | E8: =IF(OR(B8="",B8=0),"",C8/B8) | F8: =IF(COUNT(B8:C8)=0,"",IF(C8>B8,"⚠ Over budget","✓ On track")) | I8: % of Budget Used | J8: =IF(B15=0,"",C15/B15)
A9: 🎟️ Activities & Tours | D9: =IF(COUNT(B9:C9)=0,"",B9-C9) | E9: =IF(OR(B9="",B9=0),"",C9/B9) | F9: =IF(COUNT(B9:C9)=0,"",IF(C9>B9,"⚠ Over budget","✓ On track"))
A10: 🛍️ Shopping | D10: =IF(COUNT(B10:C10)=0,"",B10-C10) | E10: =IF(OR(B10="",B10=0),"",C10/B10) | F10: =IF(COUNT(B10:C10)=0,"",IF(C10>B10,"⚠ Over budget","✓ On track"))
A11: 🛡️ Travel Insurance | D11: =IF(COUNT(B11:C11)=0,"",B11-C11) | E11: =IF(OR(B11="",B11=0),"",C11/B11) | F11: =IF(COUNT(B11:C11)=0,"",IF(C11>B11,"⚠ Over budget","✓ On track"))
A12: 📋 Visas & Fees | D12: =IF(COUNT(B12:C12)=0,"",B12-C12) | E12: =IF(OR(B12="",B12=0),"",C12/B12) | F12: =IF(COUNT(B12:C12)=0,"",IF(C12>B12,"⚠ Over budget","✓ On track"))
A13: 🎁 Souvenirs | D13: =IF(COUNT(B13:C13)=0,"",B13-C13) | E13: =IF(OR(B13="",B13=0),"",C13/B13) | F13: =IF(COUNT(B13:C13)=0,"",IF(C13>B13,"⚠ Over budget","✓ On track"))
A14: ✨ Miscellaneous | D14: =IF(COUNT(B14:C14)=0,"",B14-C14) | E14: =IF(OR(B14="",B14=0),"",C14/B14) | F14: =IF(COUNT(B14:C14)=0,"",IF(C14>B14,"⚠ Over budget","✓ On track"))
A15: TOTAL | B15: =SUM(B5:B14) | C15: =SUM(C5:C14) | D15: =B15-C15 | E15: =IF(B15=0,"",C15/B15) | F15: =IF(COUNT(B5:C14)=0,"",IF(C15>B15,"⚠ Over by "&TEXT(C15-B15,"#,##0.00"),"✓ Under by "&TEXT(B15-C15,"#,##0.00")))

Sheet Savings Goal
A1: 🎯 SAVINGS GOAL TRACKER
A2: Watch the bar fill as you save — log every deposit below
A4: 🎯 GOAL OVERVIEW
A5: Savings Target | C5: Tip: match it to your Budget Tracker total
A6: Saved So Far | B6: =SUM(B12:B31)
A7: Still Needed | B7: =IF(B5="","",MAX(0,B5-B6))
A8: Progress | B8: =IF(OR(B5="",B5=0),"",MIN(1,B6/B5))
A9: =IF(OR(B5="",B5=0),"",REPT("█",MIN(20,ROUND(B6/B5*20,0)))&REPT("░",20-MIN(20,ROUND(B6/B5*20,0))))
A10: 🧾 SAVINGS LOG — every deposit gets you closer
A11: Date | B11: Amount Saved | C11: Source / Note | D11: Running Total
D12: =IF(B12="","",SUM($B$12:B12))
D13: =IF(B13="","",SUM($B$12:B13))
D14: =IF(B14="","",SUM($B$12:B14))
D15: =IF(B15="","",SUM($B$12:B15))
D16: =IF(B16="","",SUM($B$12:B16))
D17: =IF(B17="","",SUM($B$12:B17))
D18: =IF(B18="","",SUM($B$12:B18))
D19: =IF(B19="","",SUM($B$12:B19))
D20: =IF(B20="","",SUM($B$12:B20))
D21: =IF(B21="","",SUM($B$12:B21))
D22: =IF(B22="","",SUM($B$12:B22))
D23: =IF(B23="","",SUM($B$12:B23))
... D31: =IF(B31="","",SUM($B$12:B31))
A33: Tip: log each payday transfer — the jar fills itself.

Sheet Research & Ideas
A1: 🔎 RESEARCH & INSPIRATION
A2: Collect the dream list now — sort it into the itinerary later
A4: # | B4: Place / Attraction | C4: City / Area | D4: Why It's a Must / Notes | E4: Priority | F4: Visited? | H4: Link Title | I4: URL | J4: Category | K4: Notes
A5: 1
A6: 2
A7: 3
A8: 4
A9: 5
A10: 6
A11: 7
A12: 8
A13: 9
A14: 10
A15: 11
A16: 12
H17: 📍 PROGRESS
H18: Places visited | I18: =COUNTIF(F5:F16,"✓")&" of "&COUNTA(B5:B16)
A19: 💡 NOTES & INSPIRATION

Sheet Visa & Documents
A1: 🛂 VISA & DOCUMENT CHECKLIST
A2: Passport, visa, insurance, copies — nothing left behind
A4: Document | B4: Required? | C4: Status | D4: Deadline | E4: Notes | G4: 📊 PROGRESS
A5: Passport (valid 6+ months after return) | G5: Ready | H5: =COUNTIF(C5:C18,"Ready")
A6: Visa / eTA / travel authorization | G6: Still To Do | H6: =COUNTIF(B5:B18,"Yes")-COUNTIFS(B5:B18,"Yes",C5:C18,"Ready")
A7: Travel insurance policy | G7: % Ready | H7: =IFERROR(MIN(1,COUNTIFS(B5:B18,"Yes",C5:C18,"Ready")/COUNTIF(B5:B18,"Yes")),"")
A8: Vaccination certificates (if required)
A9: Prescription meds + doctor's note
A10: Driver's license / IDP
A11: National ID card
A12: Credit & debit cards (no foreign fees?)
A13: Cash in local currency
A14: Boarding passes / e-tickets
A15: Hotel & tour confirmations
A16: Copies of documents (cloud + paper)
A17: Passport photos (spare)
A18: Health / vaccination records
A20: Rule of thumb: many countries want a passport valid 6+ months beyond your return date.

Sheet Booking Log
A1: 🎟️ BOOKING CONFIRMATION LOG
A2: One row per booking — never scroll emails at a check-in desk again
A4: Type | B4: Provider | C4: Confirmation # | D4: Booked On | E4: Starts | F4: Ends | G4: Cost | H4: Paid? | I4: Notes | K4: 📊 SUMMARY
K5: Total Booked Cost | L5: =SUM(G5:G18)
K6: Confirmations Logged | L6: =COUNTIF(C5:C18,"?*")
K7: Still Unpaid | L7: =COUNTIF(H5:H18,"No")

Sheet Packing Checklist
A1: 🧳 PACKING CHECKLIST
A2: Clothing → toiletries → electronics → docs → meds — tick as you pack
A4: Category | B4: Item | C4: Qty | D4: Packed? | E4: Notes | G4: 📦 PROGRESS
A5: Clothing | B5: T-shirts & tops | G5: Total Items | H5: =COUNTA(B5:B64)
A6: Clothing | B6: Pants / jeans | G6: Packed | H6: =COUNTIF(D5:D64,"✓")
A7: Clothing | B7: Shorts | G7: Still To Pack | H7: =H5-H6
A8: Clothing | B8: Dresses / going-out outfits | G8: % Packed | H8: =IF(H5=0,"",H6/H5)
A9: Clothing | B9: Underwear & socks | C9: 7
A10: Clothing | B10: Pajamas
A11: Clothing | B11: Swimwear
A12: Clothing | B12: Light jacket / raincoat
A13: Clothing | B13: Comfortable walking shoes
A14: Clothing | B14: Formal outfit (1 set)
A15: Clothing | B15: Hat / cap
A16: Clothing | B16: Scarf / gloves (if cold)
A17: Toiletries | B17: Toothbrush & toothpaste
A18: Toiletries | B18: Shampoo & conditioner
A19: Toiletries | B19: Soap / body wash
A20: Toiletries | B20: Deodorant
A21: Toiletries | B21: Skincare (AM / PM)
... A63: Miscellaneous | B63: Earplugs & eye mask

Sheet Weather Tracker
A1: 🌤️ WEATHER TRACKER
A2: Check the forecast daily and plan outfits before you pack
A4: Date | B4: Location | C4: High °C | D4: Low °C | E4: Conditions | F4: Outfit / What to Wear | H4: 🌡️ SNAPSHOT
H5: Avg High | I5: =IF(COUNT(C5:C24)=0,"—",ROUND(AVERAGE(C5:C24),1))
H6: Avg Low | I6: =IF(COUNT(D5:D24)=0,"—",ROUND(AVERAGE(D5:D24),1))
H7: Coldest Low | I7: =IF(COUNT(D5:D24)=0,"—",MIN(D5:D24))
H8: Rainy Days | I8: =COUNTIF(E5:E24,"*Rain*")

Sheet Carry-On vs Checked
A1: 👜 CARRY-ON vs CHECKED
A2: Keep valuables & essentials with you — everything else goes below
A4: 🎒 CARRY-ON (with you) | F4: 🧳 CHECKED BAG (in the hold)
A5: Item | B5: Qty | C5: Packed? | D5: Notes | F5: Item | G5: Qty | H5: Packed? | I5: Notes
A6: Passport & travel documents | F6: Clothing sets for each day
A7: Prescription medications | F7: Comfortable shoes (2nd pair)
A8: Phone, chargers & power bank | F8: Full-size toiletries
A9: Change of clothes | F9: Hair dryer / styler
A10: Toiletries ≤ 100 ml | F10: Swimwear & beach items
A11: Snacks & empty water bottle | F11: Foldable bag for souvenirs
A12: Headphones / entertainment
A13: Sweater for the flight
A27: ="Packed: "&COUNTIF(C6:C25,"✓")&" of "&COUNTA(A6:A25) | F27: ="Packed: "&COUNTIF(H6:H25,"✓")&" of "&COUNTA(F6:F25)

Sheet Pre-Trip To-Do
A1: ✅ TO-DO BEFORE YOU GO
A2: The quiet list that saves the trip — bank, pets, plants, post
A4: Task | B4: Category | C4: Owner | D4: Due Date | E4: Done? | F4: Notes | H4: 🏁 READINESS
A5: Notify bank of travel dates | B5: Money & Bank | H5: Done | I5: =COUNTIF(E5:E34,"✓")
A6: Buy / check travel insurance | B6: Money & Bank | H6: Total Tasks | I6: =COUNTA(A5:A34)
A7: Get local currency or travel card | B7: Money & Bank | H7: % Ready | I7: =IF(H6=0,"",H5/H6)
A8: Pay upcoming bills | B8: Money & Bank
A9: Arrange pet sitter / boarding | B9: Pets
A10: Arrange house sitter / neighbor check | B10: Home
A11: Hold mail or arrange pickup | B11: Home
A12: Water plants / plant sitter | B12: Plants
A13: Pause deliveries & subscriptions | B13: Home
A14: Empty fridge of perishables | B14: Home
A15: Take out trash / recycling | B15: Home
A16: Laundry — empty hamper | B16: Home
A17: Lock windows & doors, hide valuables | B17: Home
A18: Unplug appliances & electronics | B18: Home
A19: Set out-of-office / finish handover | B19: Work
... A24: Buy plug adapters / converters | B24: Tech

Sheet Daily Itinerary
A1: 🗺️ DAY-BY-DAY ITINERARY
A2: 80 slots — time, activity, address, transport and cost per line
A4: Day | B4: Date | C4: Time / Block | D4: Activity | E4: Location / Address | F4: Transport | G4: Cost | H4: Booked? | I4: Notes | K4: 📊 SUMMARY
A5: 1 | C5: Morning | K5: Planned Activity Cost | L5: =SUM(G5:G84)
A6: 1 | C6: Afternoon | K6: Days Planned | L6: =IF(COUNT(A5:A84)=0,"—",MAX(A5:A84))
A7: 1 | C7: Evening
A8: 2 | C8: Morning
A9: 2 | C9: Afternoon
A10: 2 | C10: Evening
A11: 3 | C11: Morning
A12: 3 | C12: Afternoon
A13: 3 | C13: Evening
A14: 4 | C14: Morning
A15: 4 | C15: Afternoon
A16: 4 | C16: Evening
A17: 5 | C17: Morning
A18: 5 | C18: Afternoon
A19: 5 | C19: Evening

Sheet Hourly Schedule
A1: ⏰ HOURLY SCHEDULE GRID
A2: One week, hour by hour — morning, afternoon and evening blocks
A4: Block | B4: Time | C4: Day 1 | D4: Day 2 | E4: Day 3 | F4: Day 4 | G4: Day 5 | H4: Day 6 | I4: Day 7
B5: Date →
A6: ☀ MORNING | B6: 06:00
B7: 07:00
B8: 08:00
B9: 09:00
B10: 10:00
B11: 11:00
A12: 🌤 AFTERNOON | B12: 12:00
B13: 13:00
B14: 14:00
B15: 15:00
B16: 16:00
B17: 17:00
A18: 🌙 EVENING | B18: 18:00
B19: 19:00
B20: 20:00
B21: 21:00
B22: 22:00
B23: 23:00
A25: Tip: type plans into any hour. Morning ☀ 06–11 • Afternoon 🌤 12–17 • Evening 🌙 18–23.

Sheet Route Planner
A1: 🧭 MAP & ROUTE PLANNER
A2: Order your stops, then sketch the route on the grid
A4: Stop # | B4: Place | C4: Nearest Transit / Parking | D4: Est. Time | E4: Notes
A5: 1
A6: 2
A7: 3
A8: 4
A9: 5
A10: 6
A11: 7
A12: 8
A13: 9
A14: 10
U17: N ⬆
A34: Sketch your route: mark ⬤ start, letter the stops A–J, shade 🟨 must-sees, draw ➜ between cells.

Sheet Transportation Log
A1: 🚉 TRANSPORTATION LOG
A2: Every flight, train, bus and rideshare — times & confirmations
A4: Mode | B4: Operator / Airline | C4: From | D4: To | E4: Date | F4: Depart | G4: Arrive | H4: Confirmation # | I4: Seat / Terminal | J4: Cost | K4: Notes | M4: 📊 SUMMARY
M5: Total Transport Cost | N5: =SUM(J5:J34)
M6: Segments Logged | N6: =COUNTIF(A5:A34,"?*")

Sheet Accommodation
A1: 🏨 ACCOMMODATION DETAILS
A2: Up to 3 stays — dates, contacts, Wi-Fi and automatic totals
A4: 🏨 STAY 1 | E4: 📊 STAY SUMMARY
A5: Name | E5: Total Nights | F5: =B12+B30+B48
A6: Address | E6: Total Stay Cost | F6: =B14+B32+B50
A7: City | E7: Stays Planned | F7: =COUNTA(B5,B23,B41)
A8: Phone
A9: Confirmation #
A10: Check-In Date
A11: Check-Out Date
A12: Nights | B12: =IF(COUNT(B10:B11)<2,"",B11-B10)
A13: Cost per Night
A14: Total Stay Cost | B14: =IF(OR(B12="",B13=""),"",B12*B13)
A15: Wi-Fi Network
A16: Wi-Fi Password
A17: Check-In Time
A18: Check-Out Time
A19: Breakfast Included?
A20: Notes
A22: 🏨 STAY 2
A23: Name
A24: Address
A25: City
A26: Phone
A27: Confirmation #
... A29: Check-Out Date
A30: Nights | B30: =IF(COUNT(B28:B29)<2,"",B29-B28)
A31: Cost per Night
A32: Total Stay Cost | B32: =IF(OR(B30="",B31=""),"",B30*B31)
A33: Wi-Fi Network
A34: Wi-Fi Password
A35: Check-In Time
A36: Check-Out Time
A37: Breakfast Included?
A38: Notes
A40: 🏨 STAY 3
A41: Name
A42: Address
A43: City
A44: Phone
...

Sheet Currency Converter
A1: 💱 CURRENCY CONVERTER
A2: Rate table + instant converter — the Expense Log reads this table
A3: Home currency: | B3: USD | C3: Used for all totals across the planner
A4: Currency | B4: Code | C4: 1 Code → Home | D4: Rate Updated On | F4: ⚡ QUICK CONVERTER
A5: US Dollar | B5: USD | C5: 1 | F5: Amount
A6: Euro | B6: EUR | C6: 1.08 | F6: Currency code
A7: British Pound | B7: GBP | C7: 1.27 | F7: =In home currency | G7: =IF(OR(G5="",G6=""),"",G5*IFERROR(VLOOKUP(G6,$B$5:$C$16,2,FALSE),1))
A8: Japanese Yen | B8: JPY | C8: 0.0067
A9: Canadian Dollar | B9: CAD | C9: 0.73
A10: Australian Dollar | B10: AUD | C10: 0.66
A11: Swiss Franc | B11: CHF | C11: 1.12
A12: Chinese Yuan | B12: CNY | C12: 0.14
A13: Mexican Peso | B13: MXN | C13: 0.055
A14: Thai Baht | B14: THB | C14: 0.028
A15: Indian Rupee | B15: INR | C15: 0.012
A16: South Korean Won | B16: KRW | C16: 0.0007
A18: Rates are approximate — update column C before you travel. The Expense Log uses this table to auto-convert.

Sheet Expense Log
A1: 🧾 DAILY EXPENSE LOG
A2: 150 rows — enter amounts in any currency, totals convert automatically
A4: Date | B4: Day | C4: Category | D4: Item / Description | E4: Amount | F4: Currency | G4: Amount (Home) | H4: Payment | I4: Notes | K4: 📊 TOTALS
G5: =IF(E5="","",IF(F5="",E5,IFERROR(E5*VLOOKUP(F5,'Currency Converter'!$B$5:$C$16,2,FALSE),""))) | K5: Total Spent (Home) | L5: =SUM(G5:G154)
G6: =IF(E6="","",IF(F6="",E6,IFERROR(E6*VLOOKUP(F6,'Currency Converter'!$B$5:$C$16,2,FALSE),""))) | K6: Entries Logged | L6: =COUNT(E5:E154)
G7: =IF(E7="","",IF(F7="",E7,IFERROR(E7*VLOOKUP(F7,'Currency Converter'!$B$5:$C$16,2,FALSE),""))) | K7: Avg Spend / Day | L7: =IFERROR(ROUND(L5/'Destination Overview'!B14,2),"—")
G8: =IF(E8="","",IF(F8="",E8,IFERROR(E8*VLOOKUP(F8,'Currency Converter'!$B$5:$C$16,2,FALSE),"")))
G9: =IF(E9="","",IF(F9="",E9,IFERROR(E9*VLOOKUP(F9,'Currency Converter'!$B$5:$C$16,2,FALSE),"")))
G10: =IF(E10="","",IF(F10="",E10,IFERROR(E10*VLOOKUP(F10,'Currency Converter'!$B$5:$C$16,2,FALSE),"")))
G11: =IF(E11="","",IF(F11="",E11,IFERROR(E11*VLOOKUP(F11,'Currency Converter'!$B$5:$C$16,2,FALSE),"")))
G12: =IF(E12="","",IF(F12="",E12,IFERROR(E12*VLOOKUP(F12,'Currency Converter'!$B$5:$C$16,2,FALSE),"")))
G13: =IF(E13="","",IF(F13="",E13,IFERROR(E13*VLOOKUP(F13,'Currency Converter'!$B$5:$C$16,2,FALSE),"")))
G14: =IF(E14="","",IF(F14="",E14,IFERROR(E14*VLOOKUP(F14,'Currency Converter'!$B$5:$C$16,2,FALSE),"")))
G15: =IF(E15="","",IF(F15="",E15,IFERROR(E15*VLOOKUP(F15,'Currency Converter'!$B$5:$C$16,2,FALSE),"")))
G16: =IF(E16="","",IF(F16="",E16,IFERROR(E16*VLOOKUP(F16,'Currency Converter'!$B$5:$C$16,2,FALSE),"")))
G17: =IF(E17="","",IF(F17="",E17,IFERROR(E17*VLOOKUP(F17,'Currency Converter'!$B$5:$C$16,2,FALSE),"")))
G18: =IF(E18="","",IF(F18="",E18,IFERROR(E18*VLOOKUP(F18,'Currency Converter'!$B$5:$C$16,2,FALSE),"")))
G19: =IF(E19="","",IF(F19="",E19,IFERROR(E19*VLOOKUP(F19,'Currency Converter'!$B$5:$C$16,2,FALSE),"")))
... G154: =IF(E154="","",IF(F154="",E154,IFERROR(E154*VLOOKUP(F154,'Currency Converter'!$B$5:$C$16,2,FALSE),"")))
A156: 📊 SPENDING BY CATEGORY
A157: Category | C157: Total Spent
A158: Flights | C158: =SUMIF($C$5:$C$154,A158,$G$5:$G$154)
A159: Accommodation | C159: =SUMIF($C$5:$C$154,A159,$G$5:$G$154)
A160: Food & Dining | C160: =SUMIF($C$5:$C$154,A160,$G$5:$G$154)
A161: Local Transport | C161: =SUMIF($C$5:$C$154,A161,$G$5:$G$154)
A162: Activities & Tours | C162: =SUMIF($C$5:$C$154,A162,$G$5:$G$154)
A163: Shopping | C163: =SUMIF($C$5:$C$154,A163,$G$5:$G$154)
A164: Travel Insurance | C164: =SUMIF($C$5:$C$154,A164,$G$5:$G$154)
A165: Visas & Fees | C165: =SUMIF($C$5:$C$154,A165,$G$5:$G$154)
A166: Souvenirs | C166: =SUMIF($C$5:$C$154,A166,$G$5:$G$154)
A167: Miscellaneous | C167: =SUMIF($C$5:$C$154,A167,$G$5:$G$154)
A168: TOTAL | C168: =SUM(C158:C167)

Sheet Tipping Guide
A1: 💁 TIPPING GUIDE
A2: Country-by-country customs — never guess at the table again
A4: Country / Region | B4: Restaurants | C4: Taxis | D4: Hotels | E4: Tour Guides | F4: Notes
A5: 🇺🇸 USA | B5: 15–25% | C5: 10–15% | D5: $1–5 / bag | E5: 10–20% | F5: Tipping is expected almost everywhere
A6: 🇨🇦 Canada | B6: 15–20% | C6: 10–15% | D6: $1–5 / bag | E6: 10–20% | F6: Similar to the US
A7: 🇲🇽 Mexico | B7: 10–15% | C7: Round up | D7: 20–50 MXN | E7: 10–15% | F7: Cash preferred, in pesos
A8: 🇬🇧 United Kingdom | B8: 10–12.5% if no service | C8: Round up | D8: £1–2 / bag | E8: 10% | F8: Check bill — service often included
A9: 🇫🇷 France | B9: Round up / 5% | C9: Round up | D9: €1–2 / bag | E9: 10–15% | F9: Service compris — small tips welcome
A10: 🇮🇹 Italy | B10: 5–10% if no servizio | C10: Round up | D10: €1–2 / bag | E10: 10% | F10: Coperto charge is not a tip
A11: 🇪🇸 Spain | B11: Round up | C11: Round up | D11: €1–2 / bag | E11: €5–10 | F11: Tipping is modest and casual
A12: 🇩🇪 Germany | B12: 5–10%, round up | C12: Round up | D12: €1–3 / bag | E12: €5–10 | F12: Tell the server the total incl. tip
A13: 🇯🇵 Japan | B13: No tip | C13: No tip | D13: No tip | E13: No tip | F13: Tipping can cause confusion — a bow works
A14: 🇨🇳 China | B14: No tip | C14: No tip | D14: Sometimes expected | E14: Small gift | F14: Not customary in local spots
A15: 🇹🇭 Thailand | B15: 10% at nicer spots | C15: Round up | D15: 20–50 THB | E15: 100–300 THB | F15: Small tips appreciated
A16: 🇦🇺 Australia | B16: 10% optional | C16: Round up | D16: Optional | E16: 10% optional | F16: Not required, always appreciated
A22: Customs change fast — double-check for your exact destination. Blank rows below are for your own research.

Sheet Trip Cost Summary
A1: 📉 TRIP COST SUMMARY
A2: Every total in the planner, pulled into one dashboard
A4: 💰 COST BREAKDOWN
A5: Estimated budget (Budget Tracker) | B5: ='Budget Tracker'!B15 | C5: What you plan to spend
A6: Actual — budget sheet (Budget Tracker) | B6: ='Budget Tracker'!C15 | C6: Per-category actuals you typed
A7: Logged expenses (Expense Log) | B7: ='Expense Log'!L5 | C7: Every line of the daily expense log
A8: Transportation booked (Transportation Log) | B8: ='Transportation Log'!N5 | C8: Flights, trains, taxis…
A9: Accommodation booked (Accommodation) | B9: ='Accommodation'!F6 | C9: Nights × rate for all stays
A10: Itinerary activities (Daily Itinerary) | B10: ='Daily Itinerary'!L5 | C10: Costs planned in the itinerary
A11: Souvenirs & gifts actual (Souvenir List) | B11: ='Souvenir List'!E25 | C11: What you actually spent on gifts
A13: 🩺 BUDGET HEALTH
A14: Total Estimated | B14: =B5
A15: Total Actual (budget sheet) | B15: =B6
A16: Remaining vs Budget | B16: =IF(B5=0,"",B5-B6)
A17: % of Budget Used | B17: =IF(B5=0,"",B6/B5)
A18: Status | B18: =IF(B5=0,"Enter your budget to begin",IF(B6>B5,"⚠ Over budget by "&TEXT(B6-B5,"#,##0.00"),"✓ On track — "&TEXT(B5-B6,"#,##0.00")&" to spare"))
A20: Log day-to-day spending in the Expense Log — totals flow into this page automatically.

Sheet Restaurant Wishlist
A1: 🍽️ RESTAURANT WISHLIST
A2: Save every recommendation — book, visit, rate
A4: Restaurant | B4: Cuisine | C4: Address / Area | D4: Price | E4: Reservation | F4: Res. Date | G4: Priority | H4: Visited? | I4: Rating | J4: Notes | L4: 📊 SUMMARY
L5: Reservations Booked | M5: =COUNTIF(E5:E34,"Booked")
L6: Places Visited | M6: =COUNTIF(H5:H34,"✓")
L7: Avg Rating | M7: =IFERROR(ROUND(AVERAGE(I5:I34),1),"—")

Sheet Activity Planner
A1: 🎟️ ACTIVITY & EXCURSION PLANNER
A2: From 💡 idea to ✅ booked — dates, costs and confirmations
A4: Activity / Excursion | B4: Date | C4: Time | D4: Duration | E4: Location / Meet Point | F4: Cost | G4: Status | H4: Confirmation # | I4: Paid? | J4: Notes | L4: 📊 SUMMARY
L5: Booked | M5: =COUNTIF(G5:G34,"Booked")
L6: Total Cost | M6: =SUM(F5:F34)
L7: Still Just Ideas | M7: =COUNTIF(G5:G34,"Idea")

Sheet Local Phrases
A1: 🗣️ LOCAL PHRASES
A2: 16 essentials — fill them in before you land
A4: English | B4: Local Phrase | C4: Pronunciation | D4: Notes / When to Use
A5: Hello / Hi
A6: Good morning
A7: Good evening
A8: Please
A9: Thank you
A10: Yes / No
A11: Excuse me / Sorry
A12: How much does it cost?
A13: Where is the bathroom?
A14: Can you help me?
A15: I need a doctor
A16: Do you speak English?
... A28: Hotel front desks love helping with pronunciation — ask!

Sheet Etiquette Notes
A1: 🤝 CULTURAL ETIQUETTE NOTES
A2: Blend in, show respect — research the do's and don'ts
A4: Topic | B4: Customs & Tips | C4: Do ✅ | D4: Don't 🚫
A5: Greetings & introductions
A6: Dining & table manners
A7: Tipping customs
A8: Dress code (temples, churches, cities)
A9: Religious & sacred sites
A10: Photography rules
A11: Public transport etiquette
A12: Gift-giving
A13: Punctuality & time
A14: Gestures & body language

Sheet Emergency Contacts
A1: 🚨 EMERGENCY CONTACTS
A2: Print this page — save it offline before you fly
A4: Contact | B4: Phone / Number | C4: Address / Extra Info | D4: Notes
A5: Local police
A6: Local ambulance / emergency
A7: Nearest hospital (name)
A8: Nearest hospital (address)
A9: Nearest pharmacy / clinic
A10: My country's embassy
A11: Embassy address
A12: Embassy 24/7 line
A13: Consulate (if different)
A14: Travel insurance hotline
A15: Insurance policy #
A16: Airline / travel agency 24-7 line
... A26: 📞 Universal numbers: 112 (EU & much of the world) • 911 (US / Canada) • 999 (UK) • 000 (Australia) • 110 (Japan) • 110 / 119 (China).

Sheet Travel Journal
A1: 📓 TRAVEL JOURNAL & MEMORIES
A2: One line a day — the highlights you'll want to remember
A4: Date | B4: Place | C4: Highlight of the Day | D4: Favorite Moment | E4: Rating | F4: Photo to Print? | G4: Notes / Memories | I4: 📊 MEMORIES
I5: Average Rating | J5: =IFERROR(ROUND(AVERAGE(E5:E34),1),"—")
I6: Photos to Print | J6: =COUNTIF(F5:F34,"Yes")

Sheet Ratings & Reviews
A1: ⭐ RATINGS & REVIEWS
A2: Rate hotels, restaurants, activities — 1 (meh) to 5 (magical)
A4: Type | B4: Name | C4: City | D4: Rating (1-5) | E4: Value for Money | F4: Would Recommend? | G4: Comments | I4: 📊 SUMMARY
I5: Average Rating | J5: =IFERROR(ROUND(AVERAGE(D5:D34),1),"—")
I6: Would Recommend | J6: =COUNTIF(F5:F34,"Yes")

Sheet Souvenir List
A1: 🎁 SOUVENIR & GIFT LIST
A2: Who's getting what — budget vs actual, ticked off as you buy
A4: Item | B4: For | C4: Where to Buy | D4: Budget | E4: Actual | F4: Bought? | G4: Wrapped? | H4: Notes
A25: TOTAL | D25: =SUM(D5:D24) | E25: =SUM(E5:E24) | F25: =COUNTIF(F5:F24,"✓")&" bought"

Sheet Wi-Fi & Passwords
A1: 📶 WI-FI & PASSWORDS LOG
A2: Every network from hotel to café — no more asking twice
A4: Location | B4: Network Name (SSID) | C4: Password | D4: Notes
A26: 🔒 Avoid banking on public Wi-Fi — use a VPN or your phone's hotspot.
